Workbook
Name Scenario: Inputs!$F$8

Sheet Cover
A1: Case P: Belanou Combined Cycle Power Project, Republic of Kessara
A2: Case P companion model
A3: Units in column E; constants in column F; row totals in column G; first period in column J. Inputs: blue on yellow. Links from other sheets: green.
D4: Label | E4: Unit | F4: Constant | G4: Total
D5: Companion model for Chapters 39-45. Python mirror: model/case_p.py (source of truth).
D6: Select the scenario on the Inputs sheet (cell named Scenario):
D7: 1: FC base
D8: 2: FC banking
D9: 3: FC downside
D10: 4: Sens: availability -3 points
D11: 5: Sens: heat rate +2%
D12: 6: Sens: fixed opex +10%
D13: 7: Sens: capex +10% funded pro rata
D14: 8: Sens: COD delay 6 months, no LDs
D15: 9: Sens: base rate +200 bps (unhedged)
D16: 10: Sens: KCR devaluation 40%, 90-day lag
... D21: 15: Actual history
D22: Master check (0 = all pass) | F22: =Checks!$F$19
D23: Circularity: none. IDC/fee/premium/DSRA gross-up is solved in closed form on the Funding sheet
D24: (balance = alpha + beta x T; T = alpha/(g - beta)). Sculpting with tax uses the contractual
D25: repayment profile on Inputs; the Debt sheet recomputes the sculpted profile live and the
D26: Checks sheet reports the difference (Python iterates the profile to convergence, tolerance USD 1,000).
D27: Sheets: Cover, Inputs, Time, Construction, Operations, Tax, Funding, Debt, Reserves, Waterfall, Financials, Ratios, Returns, Checks, Outputs
D28: Sign convention: costs stored positive and subtracted explicitly.
D31: Build-along file Ch40_funding.xlsx: the companion model at the end of Chapter 40 (u09 Section 0.4 rows of Chapters 39 to 40; model version 1.4).
D32: Provisional rows: Construction row 38 (VAT facility interest), replaced by its formula in Chapter 41. They hold FC base (Scenario 1) values pasted in input color.
D33: Reconciles on Scenario 1 only (the provisional rows hold Scenario 1 values); other scenarios reconcile from Ch42_waterfall.xlsx.
D34: Next file: Ch41_operations.xlsx.
D35: Verification: model/build/verification.md.

Sheet Inputs
A1: Case P: Belanou Combined Cycle Power Project, Republic of Kessara
A2: Inputs: scenario selector, assumptions, contract terms
A3: Units in column E; constants in column F; row totals in column G; first period in column J. Inputs: blue on yellow. Links from other sheets: green.
D4: Label | E4: Unit | F4: Constant | G4: Total
D5: Scenario table: columns J-X = scenarios 1-15; semiannual rows: columns = periods; annual rows: columns = years 2015+ | J5: 2018H2 | K5: 2019H1 | L5: 2019H2 | M5: 2020H1 | N5: 2020H2 | O5: 2021H1 | P5: 2021H2 | Q5: 2022H1 | R5: 2022H2 | S5: 2023H1 | T5: 2023H2 | U5: 2024H1 | V5: 2024H2 | W5: 2025H1 | X5: 2025H2 | Y5: 2026H1 | Z5: 2026H2 | AA5: 2027H1 | AB5: 2027H2 | AC5: 2028H1 | AD5: 2028H2 | AE5: 2029H1 | AF5: 2029H2 | AG5: 2030H1 | AH5: 2030H2 | AI5: 2031H1 | AJ5: 2031H2 | AK5: 2032H1 | AL5: 2032H2 | AM5: 2033H1 | AN5: 2033H2 | AO5: 2034H1 | AP5: 2034H2 | AQ5: 2035H1 | AR5: 2035H2 | AS5: 2036H1 | AT5: 2036H2 | AU5: 2037H1 | AV5: 2037H2 | AW5: 2038H1 | AX5: 2038H2 | AY5: 2039H1 | AZ5: 2039H2 | BA5: 2040H1 | BB5: 2040H2 | BC5: 2041H1 | BD5: 2041H2 | BE5: 2042H1 | BF5: 2042H2 | BG5: 2043H1 | BH5: 2043H2 | BI5: 2044H1 | BJ5: 2044H2 | BK5: 2045H1 | BL5: 2045H2 | BM5: 2046H1 | BN5: 2046H2
B7: Scenario control
D8: Scenario selector (1-15, see table below) | E8: index | F8: 1
B9: Live scenario parameters (selected from the scenario table)
D10: Macro path (1 FC forward, 2 actual history, 3 COD re-forecast) [table] | E10: code | J10: 1 | K10: 1 | L10: 1 | M10: 1 | N10: 1 | O10: 1 | P10: 1 | Q10: 1 | R10: 1 | S10: 1 | T10: 1 | U10: 1 | V10: 1 | W10: 3 | X10: 2
D11: Construction case (1 FC budget, 2 actual) [table] | E11: code | J11: 1 | K11: 1 | L11: 1 | M11: 1 | N11: 1 | O11: 1 | P11: 1 | Q11: 1 | R11: 1 | S11: 1 | T11: 1 | U11: 1 | V11: 1 | W11: 2 | X11: 2
D12: COD delay (sensitivity) [table] | E12: months | J12: 0 | K12: 0 | L12: 0 | M12: 0 | N12: 0 | O12: 0 | P12: 0 | Q12: 6 | R12: 0 | S12: 0 | T12: 0 | U12: 0 | V12: 0 | W12: 0 | X12: 0
D13: Capex factor [table] | E13: factor | J13: 1 | K13: 1 | L13: 1 | M13: 1 | N13: 1 | O13: 1 | P13: 1.1 | Q13: 1 | R13: 1 | S13: 1 | T13: 1 | U13: 1 | V13: 1 | W13: 1 | X13: 1
D14: Availability adjustment [table] | E14: points | J14: 0 | K14: 0 | L14: -6.5 | M14: -3 | N14: 0 | O14: 0 | P14: 0 | Q14: 0 | R14: 0 | S14: 0 | T14: 0 | U14: 0 | V14: 0 | W14: 0 | X14: 0
D15: Dispatch factor when available [table] | E15: % | J15: 76.5 | K15: 72 | L15: 76.5 | M15: 76.5 | N15: 76.5 | O15: 76.5 | P15: 76.5 | Q15: 76.5 | R15: 76.5 | S15: 76.5 | T15: 76.5 | U15: 50 | V15: 76.5 | W15: 76.5 | X15: 76.5
D16: Plant heat rate factor [table] | E16: factor | J16: 1 | K16: 1 | L16: 1.015 | M16: 1 | N16: 1.02 | O16: 1 | P16: 1 | Q16: 1 | R16: 1 | S16: 1 | T16: 1 | U16: 1 | V16: 1 | W16: 1 | X16: 1
D17: Fixed opex factor [table] | E17: factor | J17: 1 | K17: 1 | L17: 1.1 | M17: 1 | N17: 1 | O17: 1.1 | P17: 1 | Q17: 1 | R17: 1 | S17: 1 | T17: 1 | U17: 1 | V17: 1 | W17: 1 | X17: 1
D18: Gas price factor [table] | E18: factor | J18: 1 | K18: 1 | L18: 1 | M18: 1 | N18: 1 | O18: 1 | P18: 1 | Q18: 1 | R18: 1 | S18: 1 | T18: 1 | U18: 1 | V18: 1.3 | W18: 1 | X18: 1
D19: Base rate shift from 2022H1 [table] | E19: % | J19: 0 | K19: 0 | L19: 0 | M19: 0 | N19: 0 | O19: 0 | P19: 0 | Q19: 0 | R19: 2 | S19: 0 | T19: 0 | U19: 0 | V19: 0 | W19: 0 | X19: 0
D20: KCR devaluation from 2022H1 [table] | E20: fraction | J20: 0 | K20: 0 | L20: 0 | M20: 0 | N20: 0 | O20: 0 | P20: 0 | Q20: 0 | R20: 0 | S20: 0.4 | T20: 0 | U20: 0 | V20: 0 | W20: 0 | X20: 0
D21: Extra days on SEKA capacity/VOM payments, 2022H1-2022H2 [table] | E21: days | J21: 0 | K21: 0 | L21: 0 | M21: 0 | N21: 0 | O21: 0 | P21: 0 | Q21: 0 | R21: 0 | S21: 90 | T21: 120 | U21: 0 | V21: 0 | W21: 0 | X21: 0
... D32: Actual 2022 dispatch path (1 = on) [table] | E32: flag | J32: 0 | K32: 0 | L32: 0 | M32: 0 | N32: 0 | O32: 0 | P32: 0 | Q32: 0 | R32: 0 | S32: 0 | T32: 0 | U32: 0 | V32: 0 | W32: 0 | X32: 1
D33: Macro path (1 FC forward, 2 actual history, 3 COD re-forecast) | E33: code | F33: =INDEX($J$10:$X$10,1,Scenario)
D34: Construction case (1 FC budget, 2 actual) | E34: code | F34: =INDEX($J$11:$X$11,1,Scenario)
D35: COD delay (sensitivity) | E35: months | F35: =INDEX($J$12:$X$12,1,Scenario)
D36: Capex factor | E36: factor | F36: =INDEX($J$13:$X$13,1,Scenario)
D37: Availability adjustment | E37: points | F37: =INDEX($J$14:$X$14,1,Scenario)
D38: Dispatch factor when available | E38: % | F38: =INDEX($J$15:$X$15,1,Scenario)
D39: Plant heat rate factor | E39: factor | F39: =INDEX($J$16:$X$16,1,Scenario)
D40: Fixed opex factor | E40: factor | F40: =INDEX($J$17:$X$17,1,Scenario)
D41: Gas price factor | E41: factor | F41: =INDEX($J$18:$X$18,1,Scenario)
D42: Base rate shift from 2022H1 | E42: % | F42: =INDEX($J$19:$X$19,1,Scenario)
D43: KCR devaluation from 2022H1 | E43: fraction | F43: =INDEX($J$20:$X$20,1,Scenario)
D44: Extra days on SEKA capacity/VOM payments, 2022H1-2022H2 | E44: days | F44: =INDEX($J$21:$X$21,1,Scenario)
D45: Offtaker crisis events (1 = on) | E45: flag | F45: =INDEX($J$22:$X$22,1,Scenario)
D46: Insurance market step-up from 2022H2 (1 = on) | E46: flag | F46: =INDEX($J$23:$X$23,1,Scenario)
D47: Repayment profile (1 FC contract, 2 COD re-sculpted) | E47: code | F47: =INDEX($J$24:$X$24,1,Scenario)
D48: Performance LD prepayment June 2022 (1 = on) | E48: flag | F48: =INDEX($J$25:$X$25,1,Scenario)
D49: Waiver and amendment 2023 (1 = on) | E49: flag | F49: =INDEX($J$26:$X$26,1,Scenario)
D50: 2025 bond refinancing (1 = on) | E50: flag | F50: =INDEX($J$27:$X$27,1,Scenario)
D51: Funding mode (1 committed amounts, 2 re-grossed pro rata) | E51: code | F51: =INDEX($J$28:$X$28,1,Scenario)
...

Sheet Time
A1: Case P: Belanou Combined Cycle Power Project, Republic of Kessara
A2: Time: semiannual operating timeline (monthly timeline on the Construction sheet)
A3: Units in column E; constants in column F; row totals in column G; first period in column J. Inputs: blue on yellow. Links from other sheets: green.
D4: Label | E4: Unit | F4: Constant | G4: Total
D5: Period ending | J5: 2018H2 | K5: 2019H1 | L5: 2019H2 | M5: 2020H1 | N5: 2020H2 | O5: 2021H1 | P5: 2021H2 | Q5: 2022H1 | R5: 2022H2 | S5: 2023H1 | T5: 2023H2 | U5: 2024H1 | V5: 2024H2 | W5: 2025H1 | X5: 2025H2 | Y5: 2026H1 | Z5: 2026H2 | AA5: 2027H1 | AB5: 2027H2 | AC5: 2028H1 | AD5: 2028H2 | AE5: 2029H1 | AF5: 2029H2 | AG5: 2030H1 | AH5: 2030H2 | AI5: 2031H1 | AJ5: 2031H2 | AK5: 2032H1 | AL5: 2032H2 | AM5: 2033H1 | AN5: 2033H2 | AO5: 2034H1 | AP5: 2034H2 | AQ5: 2035H1 | AR5: 2035H2 | AS5: 2036H1 | AT5: 2036H2 | AU5: 2037H1 | AV5: 2037H2 | AW5: 2038H1 | AX5: 2038H2 | AY5: 2039H1 | AZ5: 2039H2 | BA5: 2040H1 | BB5: 2040H2 | BC5: 2041H1 | BD5: 2041H2 | BE5: 2042H1 | BF5: 2042H2 | BG5: 2043H1 | BH5: 2043H2 | BI5: 2044H1 | BJ5: 2044H2 | BK5: 2045H1 | BL5: 2045H2 | BM5: 2046H1 | BN5: 2046H2
B7: Key dates (scenario-dependent)
D8: Commercial operation date | E8: date | F8: =IF(Inputs!$F$34<>1,Inputs!$F$191,EDATE(Inputs!$F$190,Inputs!$F$35))
D9: PPA term | E9: months | F9: =Inputs!$F$210*12
D10: PPA expiry | E10: date | F10: =EDATE(Time!$F$8,Time!$F$9)-1
D11: Construction months (NTP to COD) | E11: months | F11: =(YEAR(Time!$F$8)-YEAR(Inputs!$F$188))*12+MONTH(Time!$F$8)-MONTH(Inputs!$F$188)
D12: Period containing COD (period number) | E12: index | F12: =MATCH($F$8,$J$22:$BN$22,1)
D13: First debt service period | E13: index | F13: =Time!$F$12+1
D14: Last month of the funding period (month number) | E14: index | F14: =MATCH(INDEX($J$23:$BN$23,1,$F$12),Construction!$J$10:$BJ$10,0)
D15: Last operating period (period number) | E15: index | F15: =SUMPRODUCT($J$37:$BN$37,$J$20:$BN$20)
D16: FC FX drift per year (Kessara / US CPI expectations) | E16: factor | F16: =(1+Inputs!$F$213/100)/(1+Inputs!$F$214/100)
D17: Refinancing period (period number) | E17: index | F17: =MATCH(Inputs!$F$205,$J$23:$BN$23,0)
D18: Deferral period (period number) | E18: index | F18: =MATCH(Inputs!$F$200,$J$23:$BN$23,0)
B19: Semiannual timeline
D20: Period number | E20: index | J20: =I20+1 | K20: =J20+1 | L20: =K20+1 | M20: =L20+1 | N20: =M20+1 | O20: =N20+1 | P20: =O20+1 | Q20: =P20+1 | ... BN20: =BM20+1
D21: Months per period | E21: months | J21: =Inputs!$F$226 | K21: =Inputs!$F$226 | L21: =Inputs!$F$226 | M21: =Inputs!$F$226 | N21: =Inputs!$F$226 | O21: =Inputs!$F$226 | P21: =Inputs!$F$226 | Q21: =Inputs!$F$226 | ... BN21: =Inputs!$F$226
D22: Period start | E22: date | J22: =IF(J20=1,Inputs!$F$189,EDATE(I22,J21)) | K22: =IF(K20=1,Inputs!$F$189,EDATE(J22,K21)) | L22: =IF(L20=1,Inputs!$F$189,EDATE(K22,L21)) | M22: =IF(M20=1,Inputs!$F$189,EDATE(L22,M21)) | N22: =IF(N20=1,Inputs!$F$189,EDATE(M22,N21)) | O22: =IF(O20=1,Inputs!$F$189,EDATE(N22,O21)) | P22: =IF(P20=1,Inputs!$F$189,EDATE(O22,P21)) | Q22: =IF(Q20=1,Inputs!$F$189,EDATE(P22,Q21)) | ... BN22: =IF(BN20=1,Inputs!$F$189,EDATE(BM22,BN21))
D23: Period end | E23: date | J23: =EOMONTH(J22,J21-1) | K23: =EOMONTH(K22,K21-1) | L23: =EOMONTH(L22,L21-1) | M23: =EOMONTH(M22,M21-1) | N23: =EOMONTH(N22,N21-1) | O23: =EOMONTH(O22,O21-1) | P23: =EOMONTH(P22,P21-1) | Q23: =EOMONTH(Q22,Q21-1) | ... BN23: =EOMONTH(BN22,BN21-1)
D24: Year fraction 30/360 (months / 12) | E24: factor | J24: =J21/12 | K24: =K21/12 | L24: =L21/12 | M24: =M21/12 | N24: =N21/12 | O24: =O21/12 | P24: =P21/12 | Q24: =Q21/12 | ... BN24: =BN21/12
D25: Days in period | E25: days | J25: =J23-J22+1 | K25: =K23-K22+1 | L25: =L23-L22+1 | M25: =M23-M22+1 | N25: =N23-N22+1 | O25: =O23-O22+1 | P25: =P23-P22+1 | Q25: =Q23-Q22+1 | ... BN25: =BN23-BN22+1
D26: Calendar year | E26: year | J26: =YEAR(J22) | K26: =YEAR(K22) | L26: =YEAR(L22) | M26: =YEAR(M22) | N26: =YEAR(N22) | O26: =YEAR(O22) | P26: =YEAR(P22) | Q26: =YEAR(Q22) | ... BN26: =YEAR(BN22)
D27: Flag_FirstHalf (Jan-Jun) | E27: flag | J27: =IF(MONTH(J22)=1,1,0) | K27: =IF(MONTH(K22)=1,1,0) | L27: =IF(MONTH(L22)=1,1,0) | M27: =IF(MONTH(M22)=1,1,0) | N27: =IF(MONTH(N22)=1,1,0) | O27: =IF(MONTH(O22)=1,1,0) | P27: =IF(MONTH(P22)=1,1,0) | Q27: =IF(MONTH(Q22)=1,1,0) | ... BN27: =IF(MONTH(BN22)=1,1,0)
D28: Operations start in period | E28: date | J28: =MAX(J22,$F$8) | K28: =MAX(K22,$F$8) | L28: =MAX(L22,$F$8) | M28: =MAX(M22,$F$8) | N28: =MAX(N22,$F$8) | O28: =MAX(O22,$F$8) | P28: =MAX(P22,$F$8) | Q28: =MAX(Q22,$F$8) | ... BN28: =MAX(BN22,$F$8)
D29: Operations end in period | E29: date | J29: =MIN(J23,$F$10) | K29: =MIN(K23,$F$10) | L29: =MIN(L23,$F$10) | M29: =MIN(M23,$F$10) | N29: =MIN(N23,$F$10) | O29: =MIN(O23,$F$10) | P29: =MIN(P23,$F$10) | Q29: =MIN(Q23,$F$10) | ... BN29: =MIN(BN23,$F$10)
D30: Operating months in period | E30: months | J30: =IF(J29>=J28,(YEAR(J29)-YEAR(J28))*12+MONTH(J29)-MONTH(J28)+1,0) | K30: =IF(K29>=K28,(YEAR(K29)-YEAR(K28))*12+MONTH(K29)-MONTH(K28)+1,0) | L30: =IF(L29>=L28,(YEAR(L29)-YEAR(L28))*12+MONTH(L29)-MONTH(L28)+1,0) | M30: =IF(M29>=M28,(YEAR(M29)-YEAR(M28))*12+MONTH(M29)-MONTH(M28)+1,0) | N30: =IF(N29>=N28,(YEAR(N29)-YEAR(N28))*12+MONTH(N29)-MONTH(N28)+1,0) | O30: =IF(O29>=O28,(YEAR(O29)-YEAR(O28))*12+MONTH(O29)-MONTH(O28)+1,0) | P30: =IF(P29>=P28,(YEAR(P29)-YEAR(P28))*12+MONTH(P29)-MONTH(P28)+1,0) | Q30: =IF(Q29>=Q28,(YEAR(Q29)-YEAR(Q28))*12+MONTH(Q29)-MONTH(Q28)+1,0) | ... BN30: =IF(BN29>=BN28,(YEAR(BN29)-YEAR(BN28))*12+MONTH(BN29)-MONTH(BN28)+1,0)
D31: Operating days in period | E31: days | J31: =IF(J29>=J28,J29-J28+1,0) | K31: =IF(K29>=K28,K29-K28+1,0) | L31: =IF(L29>=L28,L29-L28+1,0) | M31: =IF(M29>=M28,M29-M28+1,0) | N31: =IF(N29>=N28,N29-N28+1,0) | O31: =IF(O29>=O28,O29-O28+1,0) | P31: =IF(P29>=P28,P29-P28+1,0) | Q31: =IF(Q29>=Q28,Q29-Q28+1,0) | ... BN31: =IF(BN29>=BN28,BN29-BN28+1,0)
D32: Operating months elapsed at period start | E32: months | J32: =MIN(MAX((YEAR(J22)-YEAR($F$8))*12+MONTH(J22)-MONTH($F$8),0),$F$9) | K32: =MIN(MAX((YEAR(K22)-YEAR($F$8))*12+MONTH(K22)-MONTH($F$8),0),$F$9) | L32: =MIN(MAX((YEAR(L22)-YEAR($F$8))*12+MONTH(L22)-MONTH($F$8),0),$F$9) | M32: =MIN(MAX((YEAR(M22)-YEAR($F$8))*12+MONTH(M22)-MONTH($F$8),0),$F$9) | N32: =MIN(MAX((YEAR(N22)-YEAR($F$8))*12+MONTH(N22)-MONTH($F$8),0),$F$9) | O32: =MIN(MAX((YEAR(O22)-YEAR($F$8))*12+MONTH(O22)-MONTH($F$8),0),$F$9) | P32: =MIN(MAX((YEAR(P22)-YEAR($F$8))*12+MONTH(P22)-MONTH($F$8),0),$F$9) | Q32: =MIN(MAX((YEAR(Q22)-YEAR($F$8))*12+MONTH(Q22)-MONTH($F$8),0),$F$9) | ... BN32: =MIN(MAX((YEAR(BN22)-YEAR($F$8))*12+MONTH(BN22)-MONTH($F$8),0),$F$9)
D33: Operating months elapsed at period end | E33: months | J33: =J32+J30 | K33: =K32+K30 | L33: =L32+L30 | M33: =M32+M30 | N33: =N32+N30 | O33: =O32+O30 | P33: =P32+P30 | Q33: =Q32+Q30 | ... BN33: =BN32+BN30
D34: Flag_CODPeriod | E34: flag | J34: =IF(J20=$F$12,1,0) | K34: =IF(K20=$F$12,1,0) | L34: =IF(L20=$F$12,1,0) | M34: =IF(M20=$F$12,1,0) | N34: =IF(N20=$F$12,1,0) | O34: =IF(O20=$F$12,1,0) | P34: =IF(P20=$F$12,1,0) | Q34: =IF(Q20=$F$12,1,0) | ... BN34: =IF(BN20=$F$12,1,0)
D35: Flag_DebtService (after COD period) | E35: flag | J35: =IF(J20>$F$12,1,0) | K35: =IF(K20>$F$12,1,0) | L35: =IF(L20>$F$12,1,0) | M35: =IF(M20>$F$12,1,0) | N35: =IF(N20>$F$12,1,0) | O35: =IF(O20>$F$12,1,0) | P35: =IF(P20>$F$12,1,0) | Q35: =IF(Q20>$F$12,1,0) | ... BN35: =IF(BN20>$F$12,1,0)
D36: Flag_Operations | E36: flag | J36: =IF(J30>0,1,0) | K36: =IF(K30>0,1,0) | L36: =IF(L30>0,1,0) | M36: =IF(M30>0,1,0) | N36: =IF(N30>0,1,0) | O36: =IF(O30>0,1,0) | P36: =IF(P30>0,1,0) | Q36: =IF(Q30>0,1,0) | ... BN36: =IF(BN30>0,1,0)
D37: Flag_LastOperatingPeriod | E37: flag | J37: =IF(AND(J30>0,K30=0),1,0) | K37: =IF(AND(K30>0,L30=0),1,0) | L37: =IF(AND(L30>0,M30=0),1,0) | M37: =IF(AND(M30>0,N30=0),1,0) | N37: =IF(AND(N30>0,O30=0),1,0) | O37: =IF(AND(O30>0,P30=0),1,0) | P37: =IF(AND(P30>0,Q30=0),1,0) | Q37: =IF(AND(Q30>0,R30=0),1,0) | ... BN37: =IF(AND(BN30>0,BO30=0),1,0)
D38: Flag_ShockPeriods | E38: flag | J38: =IF(AND(J22>=Inputs!$F$193,J22<EDATE(Inputs!$F$193,Inputs!$F$211)),1,0) | K38: =IF(AND(K22>=Inputs!$F$193,K22<EDATE(Inputs!$F$193,Inputs!$F$211)),1,0) | L38: =IF(AND(L22>=Inputs!$F$193,L22<EDATE(Inputs!$F$193,Inputs!$F$211)),1,0) | M38: =IF(AND(M22>=Inputs!$F$193,M22<EDATE(Inputs!$F$193,Inputs!$F$211)),1,0) | N38: =IF(AND(N22>=Inputs!$F$193,N22<EDATE(Inputs!$F$193,Inputs!$F$211)),1,0) | O38: =IF(AND(O22>=Inputs!$F$193,O22<EDATE(Inputs!$F$193,Inputs!$F$211)),1,0) | P38: =IF(AND(P22>=Inputs!$F$193,P22<EDATE(Inputs!$F$193,Inputs!$F$211)),1,0) | Q38: =IF(AND(Q22>=Inputs!$F$193,Q22<EDATE(Inputs!$F$193,Inputs!$F$211)),1,0) | ... BN38: =IF(AND(BN22>=Inputs!$F$193,BN22<EDATE(Inputs!$F$193,Inputs!$F$211)),1,0)
D39: Flag_FromShockStart | E39: flag | J39: =IF(J22>=Inputs!$F$193,1,0) | K39: =IF(K22>=Inputs!$F$193,1,0) | L39: =IF(L22>=Inputs!$F$193,1,0) | M39: =IF(M22>=Inputs!$F$193,1,0) | N39: =IF(N22>=Inputs!$F$193,1,0) | O39: =IF(O22>=Inputs!$F$193,1,0) | P39: =IF(P22>=Inputs!$F$193,1,0) | Q39: =IF(Q22>=Inputs!$F$193,1,0) | ... BN39: =IF(BN22>=Inputs!$F$193,1,0)
D40: Flag_TermSOFR | E40: flag | J40: =IF(J22>=Inputs!$F$196,1,0) | K40: =IF(K22>=Inputs!$F$196,1,0) | L40: =IF(L22>=Inputs!$F$196,1,0) | M40: =IF(M22>=Inputs!$F$196,1,0) | N40: =IF(N22>=Inputs!$F$196,1,0) | O40: =IF(O22>=Inputs!$F$196,1,0) | P40: =IF(P22>=Inputs!$F$196,1,0) | Q40: =IF(Q22>=Inputs!$F$196,1,0) | ... BN40: =IF(BN22>=Inputs!$F$196,1,0)
D41: Flag_InsuranceStepUp | E41: flag | J41: =IF(J22>=Inputs!$F$195,1,0) | K41: =IF(K22>=Inputs!$F$195,1,0) | L41: =IF(L22>=Inputs!$F$195,1,0) | M41: =IF(M22>=Inputs!$F$195,1,0) | N41: =IF(N22>=Inputs!$F$195,1,0) | O41: =IF(O22>=Inputs!$F$195,1,0) | P41: =IF(P22>=Inputs!$F$195,1,0) | Q41: =IF(Q22>=Inputs!$F$195,1,0) | ... BN41: =IF(BN22>=Inputs!$F$195,1,0)
...

Sheet Construction
A1: Case P: Belanou Combined Cycle Power Project, Republic of Kessara
A2: Construction: monthly uses of funds before financing costs, VAT
A3: Units in column E; constants in column F; row totals in column G; first period in column J. Inputs: blue on yellow. Links from other sheets: green.
D4: Label | E4: Unit | F4: Constant | G4: Total
D5: Month | J5: 2018-08 | K5: 2018-09 | L5: 2018-10 | M5: 2018-11 | N5: 2018-12 | O5: 2019-01 | P5: 2019-02 | Q5: 2019-03 | R5: 2019-04 | S5: 2019-05 | T5: 2019-06 | U5: 2019-07 | V5: 2019-08 | W5: 2019-09 | X5: 2019-10 | Y5: 2019-11 | Z5: 2019-12 | AA5: 2020-01 | AB5: 2020-02 | AC5: 2020-03 | AD5: 2020-04 | AE5: 2020-05 | AF5: 2020-06 | AG5: 2020-07 | AH5: 2020-08 | AI5: 2020-09 | AJ5: 2020-10 | AK5: 2020-11 | AL5: 2020-12 | AM5: 2021-01 | AN5: 2021-02 | AO5: 2021-03 | AP5: 2021-04 | AQ5: 2021-05 | AR5: 2021-06 | AS5: 2021-07 | AT5: 2021-08 | AU5: 2021-09 | AV5: 2021-10 | AW5: 2021-11 | AX5: 2021-12 | AY5: 2022-01 | AZ5: 2022-02 | BA5: 2022-03 | BB5: 2022-04 | BC5: 2022-05 | BD5: 2022-06 | BE5: 2022-07 | BF5: 2022-08 | BG5: 2022-09 | BH5: 2022-10 | BI5: 2022-11 | BJ5: 2022-12
B7: Monthly timeline (column J = August 2018)
D8: Month number | E8: index | J8: =I8+1 | K8: =J8+1 | L8: =K8+1 | M8: =L8+1 | N8: =M8+1 | O8: =N8+1 | P8: =O8+1 | Q8: =P8+1 | ... BJ8: =BI8+1
D9: Month start | E9: date | J9: =IF(J8=1,Inputs!$F$188,EDATE(I9,1)) | K9: =IF(K8=1,Inputs!$F$188,EDATE(J9,1)) | L9: =IF(L8=1,Inputs!$F$188,EDATE(K9,1)) | M9: =IF(M8=1,Inputs!$F$188,EDATE(L9,1)) | N9: =IF(N8=1,Inputs!$F$188,EDATE(M9,1)) | O9: =IF(O8=1,Inputs!$F$188,EDATE(N9,1)) | P9: =IF(P8=1,Inputs!$F$188,EDATE(O9,1)) | Q9: =IF(Q8=1,Inputs!$F$188,EDATE(P9,1)) | ... BJ9: =IF(BJ8=1,Inputs!$F$188,EDATE(BI9,1))
D10: Month end | E10: date | J10: =EOMONTH(J9,0) | K10: =EOMONTH(K9,0) | L10: =EOMONTH(L9,0) | M10: =EOMONTH(M9,0) | N10: =EOMONTH(N9,0) | O10: =EOMONTH(O9,0) | P10: =EOMONTH(P9,0) | Q10: =EOMONTH(Q9,0) | ... BJ10: =EOMONTH(BJ9,0)
D11: Days | E11: days | J11: =J10-J9+1 | K11: =K10-K9+1 | L11: =L10-L9+1 | M11: =M10-M9+1 | N11: =N10-N9+1 | O11: =O10-O9+1 | P11: =P10-P9+1 | Q11: =Q10-Q9+1 | ... BJ11: =BJ10-BJ9+1
D12: Semiannual period number | E12: index | J12: =MATCH(J9,Time!$J$22:$BN$22,1) | K12: =MATCH(K9,Time!$J$22:$BN$22,1) | L12: =MATCH(L9,Time!$J$22:$BN$22,1) | M12: =MATCH(M9,Time!$J$22:$BN$22,1) | N12: =MATCH(N9,Time!$J$22:$BN$22,1) | O12: =MATCH(O9,Time!$J$22:$BN$22,1) | P12: =MATCH(P9,Time!$J$22:$BN$22,1) | Q12: =MATCH(Q9,Time!$J$22:$BN$22,1) | ... BJ12: =MATCH(BJ9,Time!$J$22:$BN$22,1)
D13: Flag_Construction (before COD) | E13: flag | J13: =IF(J8<=Time!$F$11,1,0) | K13: =IF(K8<=Time!$F$11,1,0) | L13: =IF(L8<=Time!$F$11,1,0) | M13: =IF(M8<=Time!$F$11,1,0) | N13: =IF(N8<=Time!$F$11,1,0) | O13: =IF(O8<=Time!$F$11,1,0) | P13: =IF(P8<=Time!$F$11,1,0) | Q13: =IF(Q8<=Time!$F$11,1,0) | ... BJ13: =IF(BJ8<=Time!$F$11,1,0)
D14: Flag_FundingPeriod (to end of COD period) | E14: flag | J14: =IF(J8<=Time!$F$14,1,0) | K14: =IF(K8<=Time!$F$14,1,0) | L14: =IF(L8<=Time!$F$14,1,0) | M14: =IF(M8<=Time!$F$14,1,0) | N14: =IF(N8<=Time!$F$14,1,0) | O14: =IF(O8<=Time!$F$14,1,0) | P14: =IF(P8<=Time!$F$14,1,0) | Q14: =IF(Q8<=Time!$F$14,1,0) | ... BJ14: =IF(BJ8<=Time!$F$14,1,0)
D15: Flag_CODMonth | E15: flag | J15: =IF(J8=Time!$F$11+1,1,0) | K15: =IF(K8=Time!$F$11+1,1,0) | L15: =IF(L8=Time!$F$11+1,1,0) | M15: =IF(M8=Time!$F$11+1,1,0) | N15: =IF(N8=Time!$F$11+1,1,0) | O15: =IF(O8=Time!$F$11+1,1,0) | P15: =IF(P8=Time!$F$11+1,1,0) | Q15: =IF(Q8=Time!$F$11+1,1,0) | ... BJ15: =IF(BJ8=Time!$F$11+1,1,0)
D16: KCR per USD | E16: KCR/USD | J16: =IF(Inputs!$F$33=1,Inputs!$F$60*Time!$F$16^((J8-Inputs!$F$212)/12),INDEX(Operations!$J$11:$BN$11,1,J12)) | K16: =IF(Inputs!$F$33=1,Inputs!$F$60*Time!$F$16^((K8-Inputs!$F$212)/12),INDEX(Operations!$J$11:$BN$11,1,K12)) | L16: =IF(Inputs!$F$33=1,Inputs!$F$60*Time!$F$16^((L8-Inputs!$F$212)/12),INDEX(Operations!$J$11:$BN$11,1,L12)) | M16: =IF(Inputs!$F$33=1,Inputs!$F$60*Time!$F$16^((M8-Inputs!$F$212)/12),INDEX(Operations!$J$11:$BN$11,1,M12)) | N16: =IF(Inputs!$F$33=1,Inputs!$F$60*Time!$F$16^((N8-Inputs!$F$212)/12),INDEX(Operations!$J$11:$BN$11,1,N12)) | O16: =IF(Inputs!$F$33=1,Inputs!$F$60*Time!$F$16^((O8-Inputs!$F$212)/12),INDEX(Operations!$J$11:$BN$11,1,O12)) | P16: =IF(Inputs!$F$33=1,Inputs!$F$60*Time!$F$16^((P8-Inputs!$F$212)/12),INDEX(Operations!$J$11:$BN$11,1,P12)) | Q16: =IF(Inputs!$F$33=1,Inputs!$F$60*Time!$F$16^((Q8-Inputs!$F$212)/12),INDEX(Operations!$J$11:$BN$11,1,Q12)) | ... BJ16: =IF(Inputs!$F$33=1,Inputs!$F$60*Time!$F$16^((BJ8-Inputs!$F$212)/12),INDEX(Operations!$J$11:$BN$11,1,BJ12))
D17: Base rate (6M fixing for the half-year) | E17: % | J17: =INDEX(Operations!$J$8:$BN$8,1,J12) | K17: =INDEX(Operations!$J$8:$BN$8,1,K12) | L17: =INDEX(Operations!$J$8:$BN$8,1,L12) | M17: =INDEX(Operations!$J$8:$BN$8,1,M12) | N17: =INDEX(Operations!$J$8:$BN$8,1,N12) | O17: =INDEX(Operations!$J$8:$BN$8,1,O12) | P17: =INDEX(Operations!$J$8:$BN$8,1,P12) | Q17: =INDEX(Operations!$J$8:$BN$8,1,Q12) | ... BJ17: =INDEX(Operations!$J$8:$BN$8,1,BJ12)
D18: Kessara policy rate | E18: % | J18: =IF(Inputs!$F$33=1,Inputs!$F$73,INDEX(Inputs!$J$289:$AR$289,1,MATCH(YEAR(J9),Inputs!$J$282:$AR$282,0))) | K18: =IF(Inputs!$F$33=1,Inputs!$F$73,INDEX(Inputs!$J$289:$AR$289,1,MATCH(YEAR(K9),Inputs!$J$282:$AR$282,0))) | L18: =IF(Inputs!$F$33=1,Inputs!$F$73,INDEX(Inputs!$J$289:$AR$289,1,MATCH(YEAR(L9),Inputs!$J$282:$AR$282,0))) | M18: =IF(Inputs!$F$33=1,Inputs!$F$73,INDEX(Inputs!$J$289:$AR$289,1,MATCH(YEAR(M9),Inputs!$J$282:$AR$282,0))) | N18: =IF(Inputs!$F$33=1,Inputs!$F$73,INDEX(Inputs!$J$289:$AR$289,1,MATCH(YEAR(N9),Inputs!$J$282:$AR$282,0))) | O18: =IF(Inputs!$F$33=1,Inputs!$F$73,INDEX(Inputs!$J$289:$AR$289,1,MATCH(YEAR(O9),Inputs!$J$282:$AR$282,0))) | P18: =IF(Inputs!$F$33=1,Inputs!$F$73,INDEX(Inputs!$J$289:$AR$289,1,MATCH(YEAR(P9),Inputs!$J$282:$AR$282,0))) | Q18: =IF(Inputs!$F$33=1,Inputs!$F$73,INDEX(Inputs!$J$289:$AR$289,1,MATCH(YEAR(Q9),Inputs!$J$282:$AR$282,0))) | ... BJ18: =IF(Inputs!$F$33=1,Inputs!$F$73,INDEX(Inputs!$J$289:$AR$289,1,MATCH(YEAR(BJ9),Inputs!$J$282:$AR$282,0)))
B19: Uses before financing costs (USD m)
D20: EPC payment profile, selected | E20: % | J20: =IF(Inputs!$F$34<>1,Inputs!J306,Inputs!J305+IF(Inputs!$F$35>0,IF(J8=Inputs!$F$237,-Inputs!$F$238,0)+IF(J8=Inputs!$F$237+Inputs!$F$35,Inputs!$F$238,0),0)) | K20: =IF(Inputs!$F$34<>1,Inputs!K306,Inputs!K305+IF(Inputs!$F$35>0,IF(K8=Inputs!$F$237,-Inputs!$F$238,0)+IF(K8=Inputs!$F$237+Inputs!$F$35,Inputs!$F$238,0),0)) | L20: =IF(Inputs!$F$34<>1,Inputs!L306,Inputs!L305+IF(Inputs!$F$35>0,IF(L8=Inputs!$F$237,-Inputs!$F$238,0)+IF(L8=Inputs!$F$237+Inputs!$F$35,Inputs!$F$238,0),0)) | M20: =IF(Inputs!$F$34<>1,Inputs!M306,Inputs!M305+IF(Inputs!$F$35>0,IF(M8=Inputs!$F$237,-Inputs!$F$238,0)+IF(M8=Inputs!$F$237+Inputs!$F$35,Inputs!$F$238,0),0)) | N20: =IF(Inputs!$F$34<>1,Inputs!N306,Inputs!N305+IF(Inputs!$F$35>0,IF(N8=Inputs!$F$237,-Inputs!$F$238,0)+IF(N8=Inputs!$F$237+Inputs!$F$35,Inputs!$F$238,0),0)) | O20: =IF(Inputs!$F$34<>1,Inputs!O306,Inputs!O305+IF(Inputs!$F$35>0,IF(O8=Inputs!$F$237,-Inputs!$F$238,0)+IF(O8=Inputs!$F$237+Inputs!$F$35,Inputs!$F$238,0),0)) | P20: =IF(Inputs!$F$34<>1,Inputs!P306,Inputs!P305+IF(Inputs!$F$35>0,IF(P8=Inputs!$F$237,-Inputs!$F$238,0)+IF(P8=Inputs!$F$237+Inputs!$F$35,Inputs!$F$238,0),0)) | Q20: =IF(Inputs!$F$34<>1,Inputs!Q306,Inputs!Q305+IF(Inputs!$F$35>0,IF(Q8=Inputs!$F$237,-Inputs!$F$238,0)+IF(Q8=Inputs!$F$237+Inputs!$F$35,Inputs!$F$238,0),0)) | ... BJ20: =IF(Inputs!$F$34<>1,Inputs!BJ306,Inputs!BJ305+IF(Inputs!$F$35>0,IF(BJ8=Inputs!$F$237,-Inputs!$F$238,0)+IF(BJ8=Inputs!$F$237+Inputs!$F$35,Inputs!$F$238,0),0))
D21: EPC progress payments for contingency (FC) | E21: % | J21: =IF(J8=1,0,J20)-IF(J8=Time!$F$11,Inputs!$F$238,0) | K21: =IF(K8=1,0,K20)-IF(K8=Time!$F$11,Inputs!$F$238,0) | L21: =IF(L8=1,0,L20)-IF(L8=Time!$F$11,Inputs!$F$238,0) | M21: =IF(M8=1,0,M20)-IF(M8=Time!$F$11,Inputs!$F$238,0) | N21: =IF(N8=1,0,N20)-IF(N8=Time!$F$11,Inputs!$F$238,0) | O21: =IF(O8=1,0,O20)-IF(O8=Time!$F$11,Inputs!$F$238,0) | P21: =IF(P8=1,0,P20)-IF(P8=Time!$F$11,Inputs!$F$238,0) | Q21: =IF(Q8=1,0,Q20)-IF(Q8=Time!$F$11,Inputs!$F$238,0) | ... BJ21: =IF(BJ8=1,0,BJ20)-IF(BJ8=Time!$F$11,Inputs!$F$238,0)
D22: EPC payments | E22: USD m | G22: =SUM(J22:BJ22) | J22: =IF(Inputs!$F$34<>1,J20/100*Inputs!$F$58+J20/100*Inputs!$F$59*Inputs!$F$60/J16,Inputs!$F$57*Inputs!$F$36*J20/100) | K22: =IF(Inputs!$F$34<>1,K20/100*Inputs!$F$58+K20/100*Inputs!$F$59*Inputs!$F$60/K16,Inputs!$F$57*Inputs!$F$36*K20/100) | L22: =IF(Inputs!$F$34<>1,L20/100*Inputs!$F$58+L20/100*Inputs!$F$59*Inputs!$F$60/L16,Inputs!$F$57*Inputs!$F$36*L20/100) | M22: =IF(Inputs!$F$34<>1,M20/100*Inputs!$F$58+M20/100*Inputs!$F$59*Inputs!$F$60/M16,Inputs!$F$57*Inputs!$F$36*M20/100) | N22: =IF(Inputs!$F$34<>1,N20/100*Inputs!$F$58+N20/100*Inputs!$F$59*Inputs!$F$60/N16,Inputs!$F$57*Inputs!$F$36*N20/100) | O22: =IF(Inputs!$F$34<>1,O20/100*Inputs!$F$58+O20/100*Inputs!$F$59*Inputs!$F$60/O16,Inputs!$F$57*Inputs!$F$36*O20/100) | P22: =IF(Inputs!$F$34<>1,P20/100*Inputs!$F$58+P20/100*Inputs!$F$59*Inputs!$F$60/P16,Inputs!$F$57*Inputs!$F$36*P20/100) | Q22: =IF(Inputs!$F$34<>1,Q20/100*Inputs!$F$58+Q20/100*Inputs!$F$59*Inputs!$F$60/Q16,Inputs!$F$57*Inputs!$F$36*Q20/100) | ... BJ22: =IF(Inputs!$F$34<>1,BJ20/100*Inputs!$F$58+BJ20/100*Inputs!$F$59*Inputs!$F$60/BJ16,Inputs!$F$57*Inputs!$F$36*BJ20/100)
D23: Owner's costs | E23: USD m | G23: =SUM(J23:BJ23) | J23: =Inputs!$F$61*IF(Inputs!$F$34=1,Inputs!$F$36,1)*(Inputs!J307+IF(AND(Inputs!$F$34=1,J8>Inputs!$F$237,J8<=Time!$F$11),Inputs!$F$239,0))/100+IF(AND(Inputs!$F$34<>1,J8>=Inputs!$F$240,J8<=Inputs!$F$241),Inputs!$F$69/(Inputs!$F$241-Inputs!$F$240+1),0) | K23: =Inputs!$F$61*IF(Inputs!$F$34=1,Inputs!$F$36,1)*(Inputs!K307+IF(AND(Inputs!$F$34=1,K8>Inputs!$F$237,K8<=Time!$F$11),Inputs!$F$239,0))/100+IF(AND(Inputs!$F$34<>1,K8>=Inputs!$F$240,K8<=Inputs!$F$241),Inputs!$F$69/(Inputs!$F$241-Inputs!$F$240+1),0) | L23: =Inputs!$F$61*IF(Inputs!$F$34=1,Inputs!$F$36,1)*(Inputs!L307+IF(AND(Inputs!$F$34=1,L8>Inputs!$F$237,L8<=Time!$F$11),Inputs!$F$239,0))/100+IF(AND(Inputs!$F$34<>1,L8>=Inputs!$F$240,L8<=Inputs!$F$241),Inputs!$F$69/(Inputs!$F$241-Inputs!$F$240+1),0) | M23: =Inputs!$F$61*IF(Inputs!$F$34=1,Inputs!$F$36,1)*(Inputs!M307+IF(AND(Inputs!$F$34=1,M8>Inputs!$F$237,M8<=Time!$F$11),Inputs!$F$239,0))/100+IF(AND(Inputs!$F$34<>1,M8>=Inputs!$F$240,M8<=Inputs!$F$241),Inputs!$F$69/(Inputs!$F$241-Inputs!$F$240+1),0) | N23: =Inputs!$F$61*IF(Inputs!$F$34=1,Inputs!$F$36,1)*(Inputs!N307+IF(AND(Inputs!$F$34=1,N8>Inputs!$F$237,N8<=Time!$F$11),Inputs!$F$239,0))/100+IF(AND(Inputs!$F$34<>1,N8>=Inputs!$F$240,N8<=Inputs!$F$241),Inputs!$F$69/(Inputs!$F$241-Inputs!$F$240+1),0) | O23: =Inputs!$F$61*IF(Inputs!$F$34=1,Inputs!$F$36,1)*(Inputs!O307+IF(AND(Inputs!$F$34=1,O8>Inputs!$F$237,O8<=Time!$F$11),Inputs!$F$239,0))/100+IF(AND(Inputs!$F$34<>1,O8>=Inputs!$F$240,O8<=Inputs!$F$241),Inputs!$F$69/(Inputs!$F$241-Inputs!$F$240+1),0) | P23: =Inputs!$F$61*IF(Inputs!$F$34=1,Inputs!$F$36,1)*(Inputs!P307+IF(AND(Inputs!$F$34=1,P8>Inputs!$F$237,P8<=Time!$F$11),Inputs!$F$239,0))/100+IF(AND(Inputs!$F$34<>1,P8>=Inputs!$F$240,P8<=Inputs!$F$241),Inputs!$F$69/(Inputs!$F$241-Inputs!$F$240+1),0) | Q23: =Inputs!$F$61*IF(Inputs!$F$34=1,Inputs!$F$36,1)*(Inputs!Q307+IF(AND(Inputs!$F$34=1,Q8>Inputs!$F$237,Q8<=Time!$F$11),Inputs!$F$239,0))/100+IF(AND(Inputs!$F$34<>1,Q8>=Inputs!$F$240,Q8<=Inputs!$F$241),Inputs!$F$69/(Inputs!$F$241-Inputs!$F$240+1),0) | ... BJ23: =Inputs!$F$61*IF(Inputs!$F$34=1,Inputs!$F$36,1)*(Inputs!BJ307+IF(AND(Inputs!$F$34=1,BJ8>Inputs!$F$237,BJ8<=Time!$F$11),Inputs!$F$239,0))/100+IF(AND(Inputs!$F$34<>1,BJ8>=Inputs!$F$240,BJ8<=Inputs!$F$241),Inputs!$F$69/(Inputs!$F$241-Inputs!$F$240+1),0)
D24: Insurance during construction | E24: USD m | G24: =SUM(J24:BJ24) | J24: =Inputs!$F$62*Inputs!$F$36*(Inputs!$F$243*IF(J8=1,1,0)+(1-Inputs!$F$243)*IF(J8=Inputs!$F$242,1,0)) | K24: =Inputs!$F$62*Inputs!$F$36*(Inputs!$F$243*IF(K8=1,1,0)+(1-Inputs!$F$243)*IF(K8=Inputs!$F$242,1,0)) | L24: =Inputs!$F$62*Inputs!$F$36*(Inputs!$F$243*IF(L8=1,1,0)+(1-Inputs!$F$243)*IF(L8=Inputs!$F$242,1,0)) | M24: =Inputs!$F$62*Inputs!$F$36*(Inputs!$F$243*IF(M8=1,1,0)+(1-Inputs!$F$243)*IF(M8=Inputs!$F$242,1,0)) | N24: =Inputs!$F$62*Inputs!$F$36*(Inputs!$F$243*IF(N8=1,1,0)+(1-Inputs!$F$243)*IF(N8=Inputs!$F$242,1,0)) | O24: =Inputs!$F$62*Inputs!$F$36*(Inputs!$F$243*IF(O8=1,1,0)+(1-Inputs!$F$243)*IF(O8=Inputs!$F$242,1,0)) | P24: =Inputs!$F$62*Inputs!$F$36*(Inputs!$F$243*IF(P8=1,1,0)+(1-Inputs!$F$243)*IF(P8=Inputs!$F$242,1,0)) | Q24: =Inputs!$F$62*Inputs!$F$36*(Inputs!$F$243*IF(Q8=1,1,0)+(1-Inputs!$F$243)*IF(Q8=Inputs!$F$242,1,0)) | ... BJ24: =Inputs!$F$62*Inputs!$F$36*(Inputs!$F$243*IF(BJ8=1,1,0)+(1-Inputs!$F$243)*IF(BJ8=Inputs!$F$242,1,0))
D25: Development costs and fee | E25: USD m | G25: =SUM(J25:BJ25) | J25: =IF(J8=1,Inputs!$F$63+Inputs!$F$64,0) | K25: =IF(K8=1,Inputs!$F$63+Inputs!$F$64,0) | L25: =IF(L8=1,Inputs!$F$63+Inputs!$F$64,0) | M25: =IF(M8=1,Inputs!$F$63+Inputs!$F$64,0) | N25: =IF(N8=1,Inputs!$F$63+Inputs!$F$64,0) | O25: =IF(O8=1,Inputs!$F$63+Inputs!$F$64,0) | P25: =IF(P8=1,Inputs!$F$63+Inputs!$F$64,0) | Q25: =IF(Q8=1,Inputs!$F$63+Inputs!$F$64,0) | ... BJ25: =IF(BJ8=1,Inputs!$F$63+Inputs!$F$64,0)
D26: Lenders' advisors and legal | E26: USD m | G26: =SUM(J26:BJ26) | J26: =Inputs!$F$65*Inputs!$F$36*(Inputs!$F$244*IF(J8=1,1,0)+(1-Inputs!$F$244)/(Time!$F$11-1)*IF(AND(J8>1,J8<=Time!$F$11),1,0)) | K26: =Inputs!$F$65*Inputs!$F$36*(Inputs!$F$244*IF(K8=1,1,0)+(1-Inputs!$F$244)/(Time!$F$11-1)*IF(AND(K8>1,K8<=Time!$F$11),1,0)) | L26: =Inputs!$F$65*Inputs!$F$36*(Inputs!$F$244*IF(L8=1,1,0)+(1-Inputs!$F$244)/(Time!$F$11-1)*IF(AND(L8>1,L8<=Time!$F$11),1,0)) | M26: =Inputs!$F$65*Inputs!$F$36*(Inputs!$F$244*IF(M8=1,1,0)+(1-Inputs!$F$244)/(Time!$F$11-1)*IF(AND(M8>1,M8<=Time!$F$11),1,0)) | N26: =Inputs!$F$65*Inputs!$F$36*(Inputs!$F$244*IF(N8=1,1,0)+(1-Inputs!$F$244)/(Time!$F$11-1)*IF(AND(N8>1,N8<=Time!$F$11),1,0)) | O26: =Inputs!$F$65*Inputs!$F$36*(Inputs!$F$244*IF(O8=1,1,0)+(1-Inputs!$F$244)/(Time!$F$11-1)*IF(AND(O8>1,O8<=Time!$F$11),1,0)) | P26: =Inputs!$F$65*Inputs!$F$36*(Inputs!$F$244*IF(P8=1,1,0)+(1-Inputs!$F$244)/(Time!$F$11-1)*IF(AND(P8>1,P8<=Time!$F$11),1,0)) | Q26: =Inputs!$F$65*Inputs!$F$36*(Inputs!$F$244*IF(Q8=1,1,0)+(1-Inputs!$F$244)/(Time!$F$11-1)*IF(AND(Q8>1,Q8<=Time!$F$11),1,0)) | ... BJ26: =Inputs!$F$65*Inputs!$F$36*(Inputs!$F$244*IF(BJ8=1,1,0)+(1-Inputs!$F$244)/(Time!$F$11-1)*IF(AND(BJ8>1,BJ8<=Time!$F$11),1,0))
D27: Contingency (FC: pro rata with EPC progress payments) | E27: USD m | G27: =SUM(J27:BJ27) | J27: =IF(Inputs!$F$34=1,Inputs!$F$66*Inputs!$F$36*J21/SUM($J$21:$BJ$21),0) | K27: =IF(Inputs!$F$34=1,Inputs!$F$66*Inputs!$F$36*K21/SUM($J$21:$BJ$21),0) | L27: =IF(Inputs!$F$34=1,Inputs!$F$66*Inputs!$F$36*L21/SUM($J$21:$BJ$21),0) | M27: =IF(Inputs!$F$34=1,Inputs!$F$66*Inputs!$F$36*M21/SUM($J$21:$BJ$21),0) | N27: =IF(Inputs!$F$34=1,Inputs!$F$66*Inputs!$F$36*N21/SUM($J$21:$BJ$21),0) | O27: =IF(Inputs!$F$34=1,Inputs!$F$66*Inputs!$F$36*O21/SUM($J$21:$BJ$21),0) | P27: =IF(Inputs!$F$34=1,Inputs!$F$66*Inputs!$F$36*P21/SUM($J$21:$BJ$21),0) | Q27: =IF(Inputs!$F$34=1,Inputs!$F$66*Inputs!$F$36*Q21/SUM($J$21:$BJ$21),0) | ... BJ27: =IF(Inputs!$F$34=1,Inputs!$F$66*Inputs!$F$36*BJ21/SUM($J$21:$BJ$21),0)
D28: Initial working capital | E28: USD m | G28: =SUM(J28:BJ28) | J28: =IF(J8=Time!$F$11,Inputs!$F$67*Inputs!$F$36,0) | K28: =IF(K8=Time!$F$11,Inputs!$F$67*Inputs!$F$36,0) | L28: =IF(L8=Time!$F$11,Inputs!$F$67*Inputs!$F$36,0) | M28: =IF(M8=Time!$F$11,Inputs!$F$67*Inputs!$F$36,0) | N28: =IF(N8=Time!$F$11,Inputs!$F$67*Inputs!$F$36,0) | O28: =IF(O8=Time!$F$11,Inputs!$F$67*Inputs!$F$36,0) | P28: =IF(P8=Time!$F$11,Inputs!$F$67*Inputs!$F$36,0) | Q28: =IF(Q8=Time!$F$11,Inputs!$F$67*Inputs!$F$36,0) | ... BJ28: =IF(BJ8=Time!$F$11,Inputs!$F$67*Inputs!$F$36,0)
D29: Overrun items (actual) | E29: USD m | G29: =SUM(J29:BJ29) | J29: =IF(Inputs!$F$34<>1,Inputs!J308,0) | K29: =IF(Inputs!$F$34<>1,Inputs!K308,0) | L29: =IF(Inputs!$F$34<>1,Inputs!L308,0) | M29: =IF(Inputs!$F$34<>1,Inputs!M308,0) | N29: =IF(Inputs!$F$34<>1,Inputs!N308,0) | O29: =IF(Inputs!$F$34<>1,Inputs!O308,0) | P29: =IF(Inputs!$F$34<>1,Inputs!P308,0) | Q29: =IF(Inputs!$F$34<>1,Inputs!Q308,0) | ... BJ29: =IF(Inputs!$F$34<>1,Inputs!BJ308,0)
D30: KCR forward rate traded at financial close (covered interest parity) | E30: KCR/USD | J30: =Inputs!$F$60*((1+Inputs!$F$73/100)/(1+INDEX(Inputs!$J$291:$BN$291,1,J12)/100))^((J10-Inputs!$F$187)/Inputs!$F$248) | K30: =Inputs!$F$60*((1+Inputs!$F$73/100)/(1+INDEX(Inputs!$J$291:$BN$291,1,K12)/100))^((K10-Inputs!$F$187)/Inputs!$F$248) | L30: =Inputs!$F$60*((1+Inputs!$F$73/100)/(1+INDEX(Inputs!$J$291:$BN$291,1,L12)/100))^((L10-Inputs!$F$187)/Inputs!$F$248) | M30: =Inputs!$F$60*((1+Inputs!$F$73/100)/(1+INDEX(Inputs!$J$291:$BN$291,1,M12)/100))^((M10-Inputs!$F$187)/Inputs!$F$248) | N30: =Inputs!$F$60*((1+Inputs!$F$73/100)/(1+INDEX(Inputs!$J$291:$BN$291,1,N12)/100))^((N10-Inputs!$F$187)/Inputs!$F$248) | O30: =Inputs!$F$60*((1+Inputs!$F$73/100)/(1+INDEX(Inputs!$J$291:$BN$291,1,O12)/100))^((O10-Inputs!$F$187)/Inputs!$F$248) | P30: =Inputs!$F$60*((1+Inputs!$F$73/100)/(1+INDEX(Inputs!$J$291:$BN$291,1,P12)/100))^((P10-Inputs!$F$187)/Inputs!$F$248) | Q30: =Inputs!$F$60*((1+Inputs!$F$73/100)/(1+INDEX(Inputs!$J$291:$BN$291,1,Q12)/100))^((Q10-Inputs!$F$187)/Inputs!$F$248) | ... BJ30: =Inputs!$F$60*((1+Inputs!$F$73/100)/(1+INDEX(Inputs!$J$291:$BN$291,1,BJ12)/100))^((BJ10-Inputs!$F$187)/Inputs!$F$248)
D31: FX forward settlement on onshore EPC payments (gain to the project) | E31: USD m | G31: =SUM(J31:BJ31) | J31: =IF(Inputs!$F$34<>1,Inputs!$F$259*J34*(1/J16-1/J30),0) | K31: =IF(Inputs!$F$34<>1,Inputs!$F$259*K34*(1/K16-1/K30),0) | L31: =IF(Inputs!$F$34<>1,Inputs!$F$259*L34*(1/L16-1/L30),0) | M31: =IF(Inputs!$F$34<>1,Inputs!$F$259*M34*(1/M16-1/M30),0) | N31: =IF(Inputs!$F$34<>1,Inputs!$F$259*N34*(1/N16-1/N30),0) | O31: =IF(Inputs!$F$34<>1,Inputs!$F$259*O34*(1/O16-1/O30),0) | P31: =IF(Inputs!$F$34<>1,Inputs!$F$259*P34*(1/P16-1/P30),0) | Q31: =IF(Inputs!$F$34<>1,Inputs!$F$259*Q34*(1/Q16-1/Q30),0) | ... BJ31: =IF(Inputs!$F$34<>1,Inputs!$F$259*BJ34*(1/BJ16-1/BJ30),0)
D32: Uses before financing costs (net of FX hedge settlements) | E32: USD m | G32: =SUM(J32:BJ32) | J32: =J22+J23+J24+J25+J26+J27+J28+J29-J31 | K32: =K22+K23+K24+K25+K26+K27+K28+K29-K31 | L32: =L22+L23+L24+L25+L26+L27+L28+L29-L31 | M32: =M22+M23+M24+M25+M26+M27+M28+M29-M31 | N32: =N22+N23+N24+N25+N26+N27+N28+N29-N31 | O32: =O22+O23+O24+O25+O26+O27+O28+O29-O31 | P32: =P22+P23+P24+P25+P26+P27+P28+P29-P31 | Q32: =Q22+Q23+Q24+Q25+Q26+Q27+Q28+Q29-Q31 | ... BJ32: =BJ22+BJ23+BJ24+BJ25+BJ26+BJ27+BJ28+BJ29-BJ31
B33: VAT on onshore EPC (KCR m) and UBK VAT facility
D34: Onshore EPC payments | E34: KCR m | G34: =SUM(J34:BJ34) | J34: =J20/100*Inputs!$F$59*Inputs!$F$60*Inputs!$F$36 | K34: =K20/100*Inputs!$F$59*Inputs!$F$60*Inputs!$F$36 | L34: =L20/100*Inputs!$F$59*Inputs!$F$60*Inputs!$F$36 | M34: =M20/100*Inputs!$F$59*Inputs!$F$60*Inputs!$F$36 | N34: =N20/100*Inputs!$F$59*Inputs!$F$60*Inputs!$F$36 | O34: =O20/100*Inputs!$F$59*Inputs!$F$60*Inputs!$F$36 | P34: =P20/100*Inputs!$F$59*Inputs!$F$60*Inputs!$F$36 | Q34: =Q20/100*Inputs!$F$59*Inputs!$F$60*Inputs!$F$36 | ... BJ34: =BJ20/100*Inputs!$F$59*Inputs!$F$60*Inputs!$F$36
D38: VAT facility interest (provisional: pasted FC base values; replaced by formulas in Chapter 41) | E38: USD m | G38: =SUM(J38:BJ38) | J38: 0 | K38: 0.019445724 | L38: 0.020031042 | M38: 0.019521849 | N38: 0.020730431 | O38: 0.021886847 | P38: 0.021483009 | Q38: 0.026524861 | R38: 0.029193167 | S38: 0.03472798 | T38: 0.020173501 | U38: 0.027221871 | V38: 0.034171697 | W38: 0.040050802 | X38: 0.048562472 | Y38: 0.053634492 | Z38: 0.061715048 | AA38: 0.067224136 | AB38: 0.067139513 | AC38: 0.075210485 | AD38: 0.074945696 | AE38: 0.078407122 | AF38: 0.075558839 | AG38: 0.076471171 | AH38: 0.073642649 | AI38: 0.067436164 | AJ38: 0.064722764 | AK38: 0.057019429 | AL38: 0.05246833 | AM38: 0.045588345 | AN38: 0.03479697 | AO38: 0.031542811 | AP38: 0.02411303 | AQ38: 0.032090256 | AR38: 0.026017431 | AS38: 0.022569579 | AT38: 0.019139376 | AU38: 0.016021961 | AV38: 0.014747477 | AW38: 0.013168905 | AX38: 0.012998434 | AY38: 0.012751429 | AZ38: 0 | BA38: 0 | BB38: 0 | BC38: 0 | BD38: 0 | BE38: 0 | BF38: 0 | BG38: 0 | BH38: 0 | BI38: 0 | BJ38: 0

Sheet Operations
A1: Case P: Belanou Combined Cycle Power Project, Republic of Kessara
A2: Operations: macro paths, plant, revenue, operating costs, working capital
A3: Units in column E; constants in column F; row totals in column G; first period in column J. Inputs: blue on yellow. Links from other sheets: green.
D4: Label | E4: Unit | F4: Constant | G4: Total
D5: Period ending | J5: 2018H2 | K5: 2019H1 | L5: 2019H2 | M5: 2020H1 | N5: 2020H2 | O5: 2021H1 | P5: 2021H2 | Q5: 2022H1 | R5: 2022H2 | S5: 2023H1 | T5: 2023H2 | U5: 2024H1 | V5: 2024H2 | W5: 2025H1 | X5: 2025H2 | Y5: 2026H1 | Z5: 2026H2 | AA5: 2027H1 | AB5: 2027H2 | AC5: 2028H1 | AD5: 2028H2 | AE5: 2029H1 | AF5: 2029H2 | AG5: 2030H1 | AH5: 2030H2 | AI5: 2031H1 | AJ5: 2031H2 | AK5: 2032H1 | AL5: 2032H2 | AM5: 2033H1 | AN5: 2033H2 | AO5: 2034H1 | AP5: 2034H2 | AQ5: 2035H1 | AR5: 2035H2 | AS5: 2036H1 | AT5: 2036H2 | AU5: 2037H1 | AV5: 2037H2 | AW5: 2038H1 | AX5: 2038H2 | AY5: 2039H1 | AZ5: 2039H2 | BA5: 2040H1 | BB5: 2040H2 | BC5: 2041H1 | BD5: 2041H2 | BE5: 2042H1 | BF5: 2042H2 | BG5: 2043H1 | BH5: 2043H2 | BI5: 2044H1 | BJ5: 2044H2 | BK5: 2045H1 | BL5: 2045H2 | BM5: 2046H1 | BN5: 2046H2
B7: Macro paths
D8: Base rate before sensitivity shift | E8: % | J8: =CHOOSE(Inputs!$F$33,Inputs!J291,Inputs!J292,Inputs!J293) | K8: =CHOOSE(Inputs!$F$33,Inputs!K291,Inputs!K292,Inputs!K293) | L8: =CHOOSE(Inputs!$F$33,Inputs!L291,Inputs!L292,Inputs!L293) | M8: =CHOOSE(Inputs!$F$33,Inputs!M291,Inputs!M292,Inputs!M293) | N8: =CHOOSE(Inputs!$F$33,Inputs!N291,Inputs!N292,Inputs!N293) | O8: =CHOOSE(Inputs!$F$33,Inputs!O291,Inputs!O292,Inputs!O293) | P8: =CHOOSE(Inputs!$F$33,Inputs!P291,Inputs!P292,Inputs!P293) | Q8: =CHOOSE(Inputs!$F$33,Inputs!Q291,Inputs!Q292,Inputs!Q293) | ... BN8: =CHOOSE(Inputs!$F$33,Inputs!BN291,Inputs!BN292,Inputs!BN293)
D9: Base rate (6M LIBOR / Term SOFR + CAS) | E9: % | J9: =J8+Inputs!$F$42*Time!J39 | K9: =K8+Inputs!$F$42*Time!K39 | L9: =L8+Inputs!$F$42*Time!L39 | M9: =M8+Inputs!$F$42*Time!M39 | N9: =N8+Inputs!$F$42*Time!N39 | O9: =O8+Inputs!$F$42*Time!O39 | P9: =P8+Inputs!$F$42*Time!P39 | Q9: =Q8+Inputs!$F$42*Time!Q39 | ... BN9: =BN8+Inputs!$F$42*Time!BN39
D10: KCR per USD before devaluation sensitivity | E10: KCR/USD | J10: =CHOOSE(Inputs!$F$33,Inputs!$F$60*Time!$F$16^((Time!J20-Inputs!$F$212)*Time!J24),IF(Inputs!J294>0,Inputs!J294,I10*((1+J13/100)/(1+J12/100))^Time!J24),IF(Time!J54=0,Inputs!J294,I10*Time!$F$16^Time!J24)) | K10: =CHOOSE(Inputs!$F$33,Inputs!$F$60*Time!$F$16^((Time!K20-Inputs!$F$212)*Time!K24),IF(Inputs!K294>0,Inputs!K294,J10*((1+K13/100)/(1+K12/100))^Time!K24),IF(Time!K54=0,Inputs!K294,J10*Time!$F$16^Time!K24)) | L10: =CHOOSE(Inputs!$F$33,Inputs!$F$60*Time!$F$16^((Time!L20-Inputs!$F$212)*Time!L24),IF(Inputs!L294>0,Inputs!L294,K10*((1+L13/100)/(1+L12/100))^Time!L24),IF(Time!L54=0,Inputs!L294,K10*Time!$F$16^Time!L24)) | M10: =CHOOSE(Inputs!$F$33,Inputs!$F$60*Time!$F$16^((Time!M20-Inputs!$F$212)*Time!M24),IF(Inputs!M294>0,Inputs!M294,L10*((1+M13/100)/(1+M12/100))^Time!M24),IF(Time!M54=0,Inputs!M294,L10*Time!$F$16^Time!M24)) | N10: =CHOOSE(Inputs!$F$33,Inputs!$F$60*Time!$F$16^((Time!N20-Inputs!$F$212)*Time!N24),IF(Inputs!N294>0,Inputs!N294,M10*((1+N13/100)/(1+N12/100))^Time!N24),IF(Time!N54=0,Inputs!N294,M10*Time!$F$16^Time!N24)) | O10: =CHOOSE(Inputs!$F$33,Inputs!$F$60*Time!$F$16^((Time!O20-Inputs!$F$212)*Time!O24),IF(Inputs!O294>0,Inputs!O294,N10*((1+O13/100)/(1+O12/100))^Time!O24),IF(Time!O54=0,Inputs!O294,N10*Time!$F$16^Time!O24)) | P10: =CHOOSE(Inputs!$F$33,Inputs!$F$60*Time!$F$16^((Time!P20-Inputs!$F$212)*Time!P24),IF(Inputs!P294>0,Inputs!P294,O10*((1+P13/100)/(1+P12/100))^Time!P24),IF(Time!P54=0,Inputs!P294,O10*Time!$F$16^Time!P24)) | Q10: =CHOOSE(Inputs!$F$33,Inputs!$F$60*Time!$F$16^((Time!Q20-Inputs!$F$212)*Time!Q24),IF(Inputs!Q294>0,Inputs!Q294,P10*((1+Q13/100)/(1+Q12/100))^Time!Q24),IF(Time!Q54=0,Inputs!Q294,P10*Time!$F$16^Time!Q24)) | ... BN10: =CHOOSE(Inputs!$F$33,Inputs!$F$60*Time!$F$16^((Time!BN20-Inputs!$F$212)*Time!BN24),IF(Inputs!BN294>0,Inputs!BN294,BM10*((1+BN13/100)/(1+BN12/100))^Time!BN24),IF(Time!BN54=0,Inputs!BN294,BM10*Time!$F$16^Time!BN24))
D11: KCR per USD, period average | E11: KCR/USD | J11: =J10/(1-Inputs!$F$43*Time!J39) | K11: =K10/(1-Inputs!$F$43*Time!K39) | L11: =L10/(1-Inputs!$F$43*Time!L39) | M11: =M10/(1-Inputs!$F$43*Time!M39) | N11: =N10/(1-Inputs!$F$43*Time!N39) | O11: =O10/(1-Inputs!$F$43*Time!O39) | P11: =P10/(1-Inputs!$F$43*Time!P39) | Q11: =Q10/(1-Inputs!$F$43*Time!Q39) | ... BN11: =BN10/(1-Inputs!$F$43*Time!BN39)
D12: US CPI change, current year | E12: % | J12: =CHOOSE(Inputs!$F$33,INDEX(Inputs!$J$283:$AR$283,1,MATCH((Time!J26-0),Inputs!$J$282:$AR$282,0)),INDEX(Inputs!$J$285:$AR$285,1,MATCH((Time!J26-0),Inputs!$J$282:$AR$282,0)),INDEX(Inputs!$J$287:$AR$287,1,MATCH((Time!J26-0),Inputs!$J$282:$AR$282,0))) | K12: =CHOOSE(Inputs!$F$33,INDEX(Inputs!$J$283:$AR$283,1,MATCH((Time!K26-0),Inputs!$J$282:$AR$282,0)),INDEX(Inputs!$J$285:$AR$285,1,MATCH((Time!K26-0),Inputs!$J$282:$AR$282,0)),INDEX(Inputs!$J$287:$AR$287,1,MATCH((Time!K26-0),Inputs!$J$282:$AR$282,0))) | L12: =CHOOSE(Inputs!$F$33,INDEX(Inputs!$J$283:$AR$283,1,MATCH((Time!L26-0),Inputs!$J$282:$AR$282,0)),INDEX(Inputs!$J$285:$AR$285,1,MATCH((Time!L26-0),Inputs!$J$282:$AR$282,0)),INDEX(Inputs!$J$287:$AR$287,1,MATCH((Time!L26-0),Inputs!$J$282:$AR$282,0))) | M12: =CHOOSE(Inputs!$F$33,INDEX(Inputs!$J$283:$AR$283,1,MATCH((Time!M26-0),Inputs!$J$282:$AR$282,0)),INDEX(Inputs!$J$285:$AR$285,1,MATCH((Time!M26-0),Inputs!$J$282:$AR$282,0)),INDEX(Inputs!$J$287:$AR$287,1,MATCH((Time!M26-0),Inputs!$J$282:$AR$282,0))) | N12: =CHOOSE(Inputs!$F$33,INDEX(Inputs!$J$283:$AR$283,1,MATCH((Time!N26-0),Inputs!$J$282:$AR$282,0)),INDEX(Inputs!$J$285:$AR$285,1,MATCH((Time!N26-0),Inputs!$J$282:$AR$282,0)),INDEX(Inputs!$J$287:$AR$287,1,MATCH((Time!N26-0),Inputs!$J$282:$AR$282,0))) | O12: =CHOOSE(Inputs!$F$33,INDEX(Inputs!$J$283:$AR$283,1,MATCH((Time!O26-0),Inputs!$J$282:$AR$282,0)),INDEX(Inputs!$J$285:$AR$285,1,MATCH((Time!O26-0),Inputs!$J$282:$AR$282,0)),INDEX(Inputs!$J$287:$AR$287,1,MATCH((Time!O26-0),Inputs!$J$282:$AR$282,0))) | P12: =CHOOSE(Inputs!$F$33,INDEX(Inputs!$J$283:$AR$283,1,MATCH((Time!P26-0),Inputs!$J$282:$AR$282,0)),INDEX(Inputs!$J$285:$AR$285,1,MATCH((Time!P26-0),Inputs!$J$282:$AR$282,0)),INDEX(Inputs!$J$287:$AR$287,1,MATCH((Time!P26-0),Inputs!$J$282:$AR$282,0))) | Q12: =CHOOSE(Inputs!$F$33,INDEX(Inputs!$J$283:$AR$283,1,MATCH((Time!Q26-0),Inputs!$J$282:$AR$282,0)),INDEX(Inputs!$J$285:$AR$285,1,MATCH((Time!Q26-0),Inputs!$J$282:$AR$282,0)),INDEX(Inputs!$J$287:$AR$287,1,MATCH((Time!Q26-0),Inputs!$J$282:$AR$282,0))) | ... BN12: =CHOOSE(Inputs!$F$33,INDEX(Inputs!$J$283:$AR$283,1,MATCH((Time!BN26-0),Inputs!$J$282:$AR$282,0)),INDEX(Inputs!$J$285:$AR$285,1,MATCH((Time!BN26-0),Inputs!$J$282:$AR$282,0)),INDEX(Inputs!$J$287:$AR$287,1,MATCH((Time!BN26-0),Inputs!$J$282:$AR$282,0)))
D13: Kessara CPI change, current year | E13: % | J13: =CHOOSE(Inputs!$F$33,INDEX(Inputs!$J$284:$AR$284,1,MATCH((Time!J26-0),Inputs!$J$282:$AR$282,0)),INDEX(Inputs!$J$286:$AR$286,1,MATCH((Time!J26-0),Inputs!$J$282:$AR$282,0)),INDEX(Inputs!$J$288:$AR$288,1,MATCH((Time!J26-0),Inputs!$J$282:$AR$282,0))) | K13: =CHOOSE(Inputs!$F$33,INDEX(Inputs!$J$284:$AR$284,1,MATCH((Time!K26-0),Inputs!$J$282:$AR$282,0)),INDEX(Inputs!$J$286:$AR$286,1,MATCH((Time!K26-0),Inputs!$J$282:$AR$282,0)),INDEX(Inputs!$J$288:$AR$288,1,MATCH((Time!K26-0),Inputs!$J$282:$AR$282,0))) | L13: =CHOOSE(Inputs!$F$33,INDEX(Inputs!$J$284:$AR$284,1,MATCH((Time!L26-0),Inputs!$J$282:$AR$282,0)),INDEX(Inputs!$J$286:$AR$286,1,MATCH((Time!L26-0),Inputs!$J$282:$AR$282,0)),INDEX(Inputs!$J$288:$AR$288,1,MATCH((Time!L26-0),Inputs!$J$282:$AR$282,0))) | M13: =CHOOSE(Inputs!$F$33,INDEX(Inputs!$J$284:$AR$284,1,MATCH((Time!M26-0),Inputs!$J$282:$AR$282,0)),INDEX(Inputs!$J$286:$AR$286,1,MATCH((Time!M26-0),Inputs!$J$282:$AR$282,0)),INDEX(Inputs!$J$288:$AR$288,1,MATCH((Time!M26-0),Inputs!$J$282:$AR$282,0))) | N13: =CHOOSE(Inputs!$F$33,INDEX(Inputs!$J$284:$AR$284,1,MATCH((Time!N26-0),Inputs!$J$282:$AR$282,0)),INDEX(Inputs!$J$286:$AR$286,1,MATCH((Time!N26-0),Inputs!$J$282:$AR$282,0)),INDEX(Inputs!$J$288:$AR$288,1,MATCH((Time!N26-0),Inputs!$J$282:$AR$282,0))) | O13: =CHOOSE(Inputs!$F$33,INDEX(Inputs!$J$284:$AR$284,1,MATCH((Time!O26-0),Inputs!$J$282:$AR$282,0)),INDEX(Inputs!$J$286:$AR$286,1,MATCH((Time!O26-0),Inputs!$J$282:$AR$282,0)),INDEX(Inputs!$J$288:$AR$288,1,MATCH((Time!O26-0),Inputs!$J$282:$AR$282,0))) | P13: =CHOOSE(Inputs!$F$33,INDEX(Inputs!$J$284:$AR$284,1,MATCH((Time!P26-0),Inputs!$J$282:$AR$282,0)),INDEX(Inputs!$J$286:$AR$286,1,MATCH((Time!P26-0),Inputs!$J$282:$AR$282,0)),INDEX(Inputs!$J$288:$AR$288,1,MATCH((Time!P26-0),Inputs!$J$282:$AR$282,0))) | Q13: =CHOOSE(Inputs!$F$33,INDEX(Inputs!$J$284:$AR$284,1,MATCH((Time!Q26-0),Inputs!$J$282:$AR$282,0)),INDEX(Inputs!$J$286:$AR$286,1,MATCH((Time!Q26-0),Inputs!$J$282:$AR$282,0)),INDEX(Inputs!$J$288:$AR$288,1,MATCH((Time!Q26-0),Inputs!$J$282:$AR$282,0))) | ... BN13: =CHOOSE(Inputs!$F$33,INDEX(Inputs!$J$284:$AR$284,1,MATCH((Time!BN26-0),Inputs!$J$282:$AR$282,0)),INDEX(Inputs!$J$286:$AR$286,1,MATCH((Time!BN26-0),Inputs!$J$282:$AR$282,0)),INDEX(Inputs!$J$288:$AR$288,1,MATCH((Time!BN26-0),Inputs!$J$282:$AR$282,0)))
D14: US CPI change, prior year | E14: % | J14: =CHOOSE(Inputs!$F$33,INDEX(Inputs!$J$283:$AR$283,1,MATCH((Time!J26-1),Inputs!$J$282:$AR$282,0)),INDEX(Inputs!$J$285:$AR$285,1,MATCH((Time!J26-1),Inputs!$J$282:$AR$282,0)),INDEX(Inputs!$J$287:$AR$287,1,MATCH((Time!J26-1),Inputs!$J$282:$AR$282,0))) | K14: =CHOOSE(Inputs!$F$33,INDEX(Inputs!$J$283:$AR$283,1,MATCH((Time!K26-1),Inputs!$J$282:$AR$282,0)),INDEX(Inputs!$J$285:$AR$285,1,MATCH((Time!K26-1),Inputs!$J$282:$AR$282,0)),INDEX(Inputs!$J$287:$AR$287,1,MATCH((Time!K26-1),Inputs!$J$282:$AR$282,0))) | L14: =CHOOSE(Inputs!$F$33,INDEX(Inputs!$J$283:$AR$283,1,MATCH((Time!L26-1),Inputs!$J$282:$AR$282,0)),INDEX(Inputs!$J$285:$AR$285,1,MATCH((Time!L26-1),Inputs!$J$282:$AR$282,0)),INDEX(Inputs!$J$287:$AR$287,1,MATCH((Time!L26-1),Inputs!$J$282:$AR$282,0))) | M14: =CHOOSE(Inputs!$F$33,INDEX(Inputs!$J$283:$AR$283,1,MATCH((Time!M26-1),Inputs!$J$282:$AR$282,0)),INDEX(Inputs!$J$285:$AR$285,1,MATCH((Time!M26-1),Inputs!$J$282:$AR$282,0)),INDEX(Inputs!$J$287:$AR$287,1,MATCH((Time!M26-1),Inputs!$J$282:$AR$282,0))) | N14: =CHOOSE(Inputs!$F$33,INDEX(Inputs!$J$283:$AR$283,1,MATCH((Time!N26-1),Inputs!$J$282:$AR$282,0)),INDEX(Inputs!$J$285:$AR$285,1,MATCH((Time!N26-1),Inputs!$J$282:$AR$282,0)),INDEX(Inputs!$J$287:$AR$287,1,MATCH((Time!N26-1),Inputs!$J$282:$AR$282,0))) | O14: =CHOOSE(Inputs!$F$33,INDEX(Inputs!$J$283:$AR$283,1,MATCH((Time!O26-1),Inputs!$J$282:$AR$282,0)),INDEX(Inputs!$J$285:$AR$285,1,MATCH((Time!O26-1),Inputs!$J$282:$AR$282,0)),INDEX(Inputs!$J$287:$AR$287,1,MATCH((Time!O26-1),Inputs!$J$282:$AR$282,0))) | P14: =CHOOSE(Inputs!$F$33,INDEX(Inputs!$J$283:$AR$283,1,MATCH((Time!P26-1),Inputs!$J$282:$AR$282,0)),INDEX(Inputs!$J$285:$AR$285,1,MATCH((Time!P26-1),Inputs!$J$282:$AR$282,0)),INDEX(Inputs!$J$287:$AR$287,1,MATCH((Time!P26-1),Inputs!$J$282:$AR$282,0))) | Q14: =CHOOSE(Inputs!$F$33,INDEX(Inputs!$J$283:$AR$283,1,MATCH((Time!Q26-1),Inputs!$J$282:$AR$282,0)),INDEX(Inputs!$J$285:$AR$285,1,MATCH((Time!Q26-1),Inputs!$J$282:$AR$282,0)),INDEX(Inputs!$J$287:$AR$287,1,MATCH((Time!Q26-1),Inputs!$J$282:$AR$282,0))) | ... BN14: =CHOOSE(Inputs!$F$33,INDEX(Inputs!$J$283:$AR$283,1,MATCH((Time!BN26-1),Inputs!$J$282:$AR$282,0)),INDEX(Inputs!$J$285:$AR$285,1,MATCH((Time!BN26-1),Inputs!$J$282:$AR$282,0)),INDEX(Inputs!$J$287:$AR$287,1,MATCH((Time!BN26-1),Inputs!$J$282:$AR$282,0)))
D15: Kessara CPI change, prior year | E15: % | J15: =CHOOSE(Inputs!$F$33,INDEX(Inputs!$J$284:$AR$284,1,MATCH((Time!J26-1),Inputs!$J$282:$AR$282,0)),INDEX(Inputs!$J$286:$AR$286,1,MATCH((Time!J26-1),Inputs!$J$282:$AR$282,0)),INDEX(Inputs!$J$288:$AR$288,1,MATCH((Time!J26-1),Inputs!$J$282:$AR$282,0))) | K15: =CHOOSE(Inputs!$F$33,INDEX(Inputs!$J$284:$AR$284,1,MATCH((Time!K26-1),Inputs!$J$282:$AR$282,0)),INDEX(Inputs!$J$286:$AR$286,1,MATCH((Time!K26-1),Inputs!$J$282:$AR$282,0)),INDEX(Inputs!$J$288:$AR$288,1,MATCH((Time!K26-1),Inputs!$J$282:$AR$282,0))) | L15: =CHOOSE(Inputs!$F$33,INDEX(Inputs!$J$284:$AR$284,1,MATCH((Time!L26-1),Inputs!$J$282:$AR$282,0)),INDEX(Inputs!$J$286:$AR$286,1,MATCH((Time!L26-1),Inputs!$J$282:$AR$282,0)),INDEX(Inputs!$J$288:$AR$288,1,MATCH((Time!L26-1),Inputs!$J$282:$AR$282,0))) | M15: =CHOOSE(Inputs!$F$33,INDEX(Inputs!$J$284:$AR$284,1,MATCH((Time!M26-1),Inputs!$J$282:$AR$282,0)),INDEX(Inputs!$J$286:$AR$286,1,MATCH((Time!M26-1),Inputs!$J$282:$AR$282,0)),INDEX(Inputs!$J$288:$AR$288,1,MATCH((Time!M26-1),Inputs!$J$282:$AR$282,0))) | N15: =CHOOSE(Inputs!$F$33,INDEX(Inputs!$J$284:$AR$284,1,MATCH((Time!N26-1),Inputs!$J$282:$AR$282,0)),INDEX(Inputs!$J$286:$AR$286,1,MATCH((Time!N26-1),Inputs!$J$282:$AR$282,0)),INDEX(Inputs!$J$288:$AR$288,1,MATCH((Time!N26-1),Inputs!$J$282:$AR$282,0))) | O15: =CHOOSE(Inputs!$F$33,INDEX(Inputs!$J$284:$AR$284,1,MATCH((Time!O26-1),Inputs!$J$282:$AR$282,0)),INDEX(Inputs!$J$286:$AR$286,1,MATCH((Time!O26-1),Inputs!$J$282:$AR$282,0)),INDEX(Inputs!$J$288:$AR$288,1,MATCH((Time!O26-1),Inputs!$J$282:$AR$282,0))) | P15: =CHOOSE(Inputs!$F$33,INDEX(Inputs!$J$284:$AR$284,1,MATCH((Time!P26-1),Inputs!$J$282:$AR$282,0)),INDEX(Inputs!$J$286:$AR$286,1,MATCH((Time!P26-1),Inputs!$J$282:$AR$282,0)),INDEX(Inputs!$J$288:$AR$288,1,MATCH((Time!P26-1),Inputs!$J$282:$AR$282,0))) | Q15: =CHOOSE(Inputs!$F$33,INDEX(Inputs!$J$284:$AR$284,1,MATCH((Time!Q26-1),Inputs!$J$282:$AR$282,0)),INDEX(Inputs!$J$286:$AR$286,1,MATCH((Time!Q26-1),Inputs!$J$282:$AR$282,0)),INDEX(Inputs!$J$288:$AR$288,1,MATCH((Time!Q26-1),Inputs!$J$282:$AR$282,0))) | ... BN15: =CHOOSE(Inputs!$F$33,INDEX(Inputs!$J$284:$AR$284,1,MATCH((Time!BN26-1),Inputs!$J$282:$AR$282,0)),INDEX(Inputs!$J$286:$AR$286,1,MATCH((Time!BN26-1),Inputs!$J$282:$AR$282,0)),INDEX(Inputs!$J$288:$AR$288,1,MATCH((Time!BN26-1),Inputs!$J$282:$AR$282,0)))

Sheet Funding
A1: Case P: Belanou Combined Cycle Power Project, Republic of Kessara
A2: Funding: closed-form gross-up, drawdowns by tranche, IDC, fees, equity
A3: Units in column E; constants in column F; row totals in column G; first period in column J. Inputs: blue on yellow. Links from other sheets: green.
D4: Label | E4: Unit | F4: Constant | G4: Total
D5: Month | J5: 2018-08 | K5: 2018-09 | L5: 2018-10 | M5: 2018-11 | N5: 2018-12 | O5: 2019-01 | P5: 2019-02 | Q5: 2019-03 | R5: 2019-04 | S5: 2019-05 | T5: 2019-06 | U5: 2019-07 | V5: 2019-08 | W5: 2019-09 | X5: 2019-10 | Y5: 2019-11 | Z5: 2019-12 | AA5: 2020-01 | AB5: 2020-02 | AC5: 2020-03 | AD5: 2020-04 | AE5: 2020-05 | AF5: 2020-06 | AG5: 2020-07 | AH5: 2020-08 | AI5: 2020-09 | AJ5: 2020-10 | AK5: 2020-11 | AL5: 2020-12 | AM5: 2021-01 | AN5: 2021-02 | AO5: 2021-03 | AP5: 2021-04 | AQ5: 2021-05 | AR5: 2021-06 | AS5: 2021-07 | AT5: 2021-08 | AU5: 2021-09 | AV5: 2021-10 | AW5: 2021-11 | AX5: 2021-12 | AY5: 2022-01 | AZ5: 2022-02 | BA5: 2022-03 | BB5: 2022-04 | BC5: 2022-05 | BD5: 2022-06 | BE5: 2022-07 | BF5: 2022-08 | BG5: 2022-09 | BH5: 2022-10 | BI5: 2022-11 | BJ5: 2022-12
B7: Constants
D8: Contract debt share of funding g = D/(D+E) | E8: fraction | F8: =Inputs!$F$113/(Inputs!$F$113+Inputs!$F$114)
D9: Gearing used in the closed-form gross-up | E9: fraction | F9: =IF(Inputs!$F$51<>1,Funding!$F$8,Inputs!$F$105)
D10: ECA premium gross-up denominator 1 - prem x share x g | E10: factor | F10: =1-Inputs!$F$94/100*Inputs!$F$75*Funding!$F$9
D11: First installment share of remaining profile | E11: fraction | F11: =INDEX(Debt!$J$17:$BN$17,1,Time!$F$13)/INDEX(Debt!$J$18:$BN$18,1,Time!$F$13)
D12: DSRA coefficient per USD of E balance | E12: factor | F12: =$F$11+(INDEX(Operations!$J$9:$BN$9,1,Time!$F$13)+Inputs!$F$79)/100*INDEX(Time!$J$25:$BN$25,1,Time!$F$13)/Inputs!$F$247*1
D13: DSRA coefficient per USD of A balance | E13: factor | F13: =$F$11+(INDEX(Operations!$J$9:$BN$9,1,Time!$F$13)+Inputs!$F$80)/100*INDEX(Time!$J$25:$BN$25,1,Time!$F$13)/Inputs!$F$247*1
D14: DSRA coefficient per USD of B balance | E14: factor | F14: =$F$11+(INDEX(Operations!$J$9:$BN$9,1,Time!$F$13)+Inputs!$F$81)/100*INDEX(Time!$J$25:$BN$25,1,Time!$F$13)/Inputs!$F$247*1
D15: DSRA coefficient per USD of C balance | E15: factor | F15: =$F$11+(INDEX(Operations!$J$9:$BN$9,1,Time!$F$13)+INDEX(Debt!$J$8:$BN$8,1,Time!$F$13))/100*INDEX(Time!$J$25:$BN$25,1,Time!$F$13)/Inputs!$F$247*(1/(1-Inputs!$F$93/100))+(Inputs!$F$95/100*Inputs!$F$96/100)*INDEX(Time!$J$25:$BN$25,1,Time!$F$13)/Inputs!$F$248
D16: DSRA coefficient per USD of standby balance | E16: factor | F16: =$F$11+INDEX(Debt!$J$14:$BN$14,1,Time!$F$13)
D17: DSRA constant (swap net payment) | E17: USD m | F17: =INDEX(Inputs!$J$301:$BN$301,1,Time!$F$13)*(Inputs!$F$97/100*INDEX(Time!$J$24:$BN$24,1,Time!$F$13)-INDEX(Operations!$J$9:$BN$9,1,Time!$F$13)/100*INDEX(Time!$J$25:$BN$25,1,Time!$F$13)/Inputs!$F$247)
B18: Closed-form gross-up: debt balance = alpha + beta x T (FC-type cases)
D19: Blended loan rate per month (rho) | E19: factor | J19: =Inputs!$F$75*(Construction!J17+Inputs!$F$79)/100*Construction!J11/Inputs!$F$247*1+Inputs!$F$76*(Construction!J17+Inputs!$F$80)/100*Construction!J11/Inputs!$F$247*1+Inputs!$F$77*(Construction!J17+Inputs!$F$81)/100*Construction!J11/Inputs!$F$247*1+Inputs!$F$78*(Construction!J17+Inputs!$F$82)/100*Construction!J11/Inputs!$F$247*(1/(1-Inputs!$F$93/100))+Inputs!$F$78*(Inputs!$F$95/100*Inputs!$F$96/100)*Construction!J11/Inputs!$F$248 | K19: =Inputs!$F$75*(Construction!K17+Inputs!$F$79)/100*Construction!K11/Inputs!$F$247*1+Inputs!$F$76*(Construction!K17+Inputs!$F$80)/100*Construction!K11/Inputs!$F$247*1+Inputs!$F$77*(Construction!K17+Inputs!$F$81)/100*Construction!K11/Inputs!$F$247*1+Inputs!$F$78*(Construction!K17+Inputs!$F$82)/100*Construction!K11/Inputs!$F$247*(1/(1-Inputs!$F$93/100))+Inputs!$F$78*(Inputs!$F$95/100*Inputs!$F$96/100)*Construction!K11/Inputs!$F$248 | L19: =Inputs!$F$75*(Construction!L17+Inputs!$F$79)/100*Construction!L11/Inputs!$F$247*1+Inputs!$F$76*(Construction!L17+Inputs!$F$80)/100*Construction!L11/Inputs!$F$247*1+Inputs!$F$77*(Construction!L17+Inputs!$F$81)/100*Construction!L11/Inputs!$F$247*1+Inputs!$F$78*(Construction!L17+Inputs!$F$82)/100*Construction!L11/Inputs!$F$247*(1/(1-Inputs!$F$93/100))+Inputs!$F$78*(Inputs!$F$95/100*Inputs!$F$96/100)*Construction!L11/Inputs!$F$248 | M19: =Inputs!$F$75*(Construction!M17+Inputs!$F$79)/100*Construction!M11/Inputs!$F$247*1+Inputs!$F$76*(Construction!M17+Inputs!$F$80)/100*Construction!M11/Inputs!$F$247*1+Inputs!$F$77*(Construction!M17+Inputs!$F$81)/100*Construction!M11/Inputs!$F$247*1+Inputs!$F$78*(Construction!M17+Inputs!$F$82)/100*Construction!M11/Inputs!$F$247*(1/(1-Inputs!$F$93/100))+Inputs!$F$78*(Inputs!$F$95/100*Inputs!$F$96/100)*Construction!M11/Inputs!$F$248 | N19: =Inputs!$F$75*(Construction!N17+Inputs!$F$79)/100*Construction!N11/Inputs!$F$247*1+Inputs!$F$76*(Construction!N17+Inputs!$F$80)/100*Construction!N11/Inputs!$F$247*1+Inputs!$F$77*(Construction!N17+Inputs!$F$81)/100*Construction!N11/Inputs!$F$247*1+Inputs!$F$78*(Construction!N17+Inputs!$F$82)/100*Construction!N11/Inputs!$F$247*(1/(1-Inputs!$F$93/100))+Inputs!$F$78*(Inputs!$F$95/100*Inputs!$F$96/100)*Construction!N11/Inputs!$F$248 | O19: =Inputs!$F$75*(Construction!O17+Inputs!$F$79)/100*Construction!O11/Inputs!$F$247*1+Inputs!$F$76*(Construction!O17+Inputs!$F$80)/100*Construction!O11/Inputs!$F$247*1+Inputs!$F$77*(Construction!O17+Inputs!$F$81)/100*Construction!O11/Inputs!$F$247*1+Inputs!$F$78*(Construction!O17+Inputs!$F$82)/100*Construction!O11/Inputs!$F$247*(1/(1-Inputs!$F$93/100))+Inputs!$F$78*(Inputs!$F$95/100*Inputs!$F$96/100)*Construction!O11/Inputs!$F$248 | P19: =Inputs!$F$75*(Construction!P17+Inputs!$F$79)/100*Construction!P11/Inputs!$F$247*1+Inputs!$F$76*(Construction!P17+Inputs!$F$80)/100*Construction!P11/Inputs!$F$247*1+Inputs!$F$77*(Construction!P17+Inputs!$F$81)/100*Construction!P11/Inputs!$F$247*1+Inputs!$F$78*(Construction!P17+Inputs!$F$82)/100*Construction!P11/Inputs!$F$247*(1/(1-Inputs!$F$93/100))+Inputs!$F$78*(Inputs!$F$95/100*Inputs!$F$96/100)*Construction!P11/Inputs!$F$248 | Q19: =Inputs!$F$75*(Construction!Q17+Inputs!$F$79)/100*Construction!Q11/Inputs!$F$247*1+Inputs!$F$76*(Construction!Q17+Inputs!$F$80)/100*Construction!Q11/Inputs!$F$247*1+Inputs!$F$77*(Construction!Q17+Inputs!$F$81)/100*Construction!Q11/Inputs!$F$247*1+Inputs!$F$78*(Construction!Q17+Inputs!$F$82)/100*Construction!Q11/Inputs!$F$247*(1/(1-Inputs!$F$93/100))+Inputs!$F$78*(Inputs!$F$95/100*Inputs!$F$96/100)*Construction!Q11/Inputs!$F$248 | ... BJ19: =Inputs!$F$75*(Construction!BJ17+Inputs!$F$79)/100*Construction!BJ11/Inputs!$F$247*1+Inputs!$F$76*(Construction!BJ17+Inputs!$F$80)/100*Construction!BJ11/Inputs!$F$247*1+Inputs!$F$77*(Construction!BJ17+Inputs!$F$81)/100*Construction!BJ11/Inputs!$F$247*1+Inputs!$F$78*(Construction!BJ17+Inputs!$F$82)/100*Construction!BJ11/Inputs!$F$247*(1/(1-Inputs!$F$93/100))+Inputs!$F$78*(Inputs!$F$95/100*Inputs!$F$96/100)*Construction!BJ11/Inputs!$F$248
