Workbook
Name Scenario: Inputs!$F$8

Sheet Cover
A1: Case P: Belanou Combined Cycle Power Project, Republic of Kessara
A2: Case P companion model
A3: Units in column E; constants in column F; row totals in column G; first period in column J. Inputs: blue on yellow. Links from other sheets: green.
D4: Label | E4: Unit | F4: Constant | G4: Total
D5: Companion model for Chapters 39-45. Python mirror: model/case_p.py (source of truth).
D6: Select the scenario on the Inputs sheet (cell named Scenario):
D7: 1: FC base
D8: 2: FC banking
D9: 3: FC downside
D10: 4: Sens: availability -3 points
D11: 5: Sens: heat rate +2%
D12: 6: Sens: fixed opex +10%
D13: 7: Sens: capex +10% funded pro rata
D14: 8: Sens: COD delay 6 months, no LDs
D15: 9: Sens: base rate +200 bps (unhedged)
D16: 10: Sens: KCR devaluation 40%, 90-day lag
... D28: Sign convention: costs stored positive and subtracted explicitly.

Sheet Inputs
A1: Case P: Belanou Combined Cycle Power Project, Republic of Kessara
A2: Inputs: scenario selector, assumptions, contract terms
A3: Units in column E; constants in column F; row totals in column G; first period in column J. Inputs: blue on yellow. Links from other sheets: green.
D4: Label | E4: Unit | F4: Constant | G4: Total
D5: Scenario table: columns J-X = scenarios 1-15; semiannual rows: columns = periods; annual rows: columns = years 2015+ | J5: 2018H2 | K5: 2019H1 | L5: 2019H2 | M5: 2020H1 | N5: 2020H2 | O5: 2021H1 | P5: 2021H2 | Q5: 2022H1 | R5: 2022H2 | S5: 2023H1 | T5: 2023H2 | U5: 2024H1 | V5: 2024H2 | W5: 2025H1 | X5: 2025H2 | Y5: 2026H1 | Z5: 2026H2 | AA5: 2027H1 | AB5: 2027H2 | AC5: 2028H1 | AD5: 2028H2 | AE5: 2029H1 | AF5: 2029H2 | AG5: 2030H1 | AH5: 2030H2 | AI5: 2031H1 | AJ5: 2031H2 | AK5: 2032H1 | AL5: 2032H2 | AM5: 2033H1 | AN5: 2033H2 | AO5: 2034H1 | AP5: 2034H2 | AQ5: 2035H1 | AR5: 2035H2 | AS5: 2036H1 | AT5: 2036H2 | AU5: 2037H1 | AV5: 2037H2 | AW5: 2038H1 | AX5: 2038H2 | AY5: 2039H1 | AZ5: 2039H2 | BA5: 2040H1 | BB5: 2040H2 | BC5: 2041H1 | BD5: 2041H2 | BE5: 2042H1 | BF5: 2042H2 | BG5: 2043H1 | BH5: 2043H2 | BI5: 2044H1 | BJ5: 2044H2 | BK5: 2045H1 | BL5: 2045H2 | BM5: 2046H1 | BN5: 2046H2
B7: Scenario control
D8: Scenario selector (1-15, see table below) | E8: index | F8: 1
B9: Live scenario parameters (selected from the scenario table)
D10: Macro path (1 FC forward, 2 actual history, 3 COD re-forecast) [table] | E10: code | J10: 1 | K10: 1 | L10: 1 | M10: 1 | N10: 1 | O10: 1 | P10: 1 | Q10: 1 | R10: 1 | S10: 1 | T10: 1 | U10: 1 | V10: 1 | W10: 3 | X10: 2
D11: Construction case (1 FC budget, 2 actual) [table] | E11: code | J11: 1 | K11: 1 | L11: 1 | M11: 1 | N11: 1 | O11: 1 | P11: 1 | Q11: 1 | R11: 1 | S11: 1 | T11: 1 | U11: 1 | V11: 1 | W11: 2 | X11: 2
D12: COD delay (sensitivity) [table] | E12: months | J12: 0 | K12: 0 | L12: 0 | M12: 0 | N12: 0 | O12: 0 | P12: 0 | Q12: 6 | R12: 0 | S12: 0 | T12: 0 | U12: 0 | V12: 0 | W12: 0 | X12: 0
D13: Capex factor [table] | E13: factor | J13: 1 | K13: 1 | L13: 1 | M13: 1 | N13: 1 | O13: 1 | P13: 1.1 | Q13: 1 | R13: 1 | S13: 1 | T13: 1 | U13: 1 | V13: 1 | W13: 1 | X13: 1
D14: Availability adjustment [table] | E14: points | J14: 0 | K14: 0 | L14: -6.5 | M14: -3 | N14: 0 | O14: 0 | P14: 0 | Q14: 0 | R14: 0 | S14: 0 | T14: 0 | U14: 0 | V14: 0 | W14: 0 | X14: 0
D15: Dispatch factor when available [table] | E15: % | J15: 76.5 | K15: 72 | L15: 76.5 | M15: 76.5 | N15: 76.5 | O15: 76.5 | P15: 76.5 | Q15: 76.5 | R15: 76.5 | S15: 76.5 | T15: 76.5 | U15: 50 | V15: 76.5 | W15: 76.5 | X15: 76.5
D16: Plant heat rate factor [table] | E16: factor | J16: 1 | K16: 1 | L16: 1.015 | M16: 1 | N16: 1.02 | O16: 1 | P16: 1 | Q16: 1 | R16: 1 | S16: 1 | T16: 1 | U16: 1 | V16: 1 | W16: 1 | X16: 1
D17: Fixed opex factor [table] | E17: factor | J17: 1 | K17: 1 | L17: 1.1 | M17: 1 | N17: 1 | O17: 1.1 | P17: 1 | Q17: 1 | R17: 1 | S17: 1 | T17: 1 | U17: 1 | V17: 1 | W17: 1 | X17: 1
D18: Gas price factor [table] | E18: factor | J18: 1 | K18: 1 | L18: 1 | M18: 1 | N18: 1 | O18: 1 | P18: 1 | Q18: 1 | R18: 1 | S18: 1 | T18: 1 | U18: 1 | V18: 1.3 | W18: 1 | X18: 1
D19: Base rate shift from 2022H1 [table] | E19: % | J19: 0 | K19: 0 | L19: 0 | M19: 0 | N19: 0 | O19: 0 | P19: 0 | Q19: 0 | R19: 2 | S19: 0 | T19: 0 | U19: 0 | V19: 0 | W19: 0 | X19: 0
D20: KCR devaluation from 2022H1 [table] | E20: fraction | J20: 0 | K20: 0 | L20: 0 | M20: 0 | N20: 0 | O20: 0 | P20: 0 | Q20: 0 | R20: 0 | S20: 0.4 | T20: 0 | U20: 0 | V20: 0 | W20: 0 | X20: 0
D21: Extra days on SEKA capacity/VOM payments, 2022H1-2022H2 [table] | E21: days | J21: 0 | K21: 0 | L21: 0 | M21: 0 | N21: 0 | O21: 0 | P21: 0 | Q21: 0 | R21: 0 | S21: 90 | T21: 120 | U21: 0 | V21: 0 | W21: 0 | X21: 0
... D31: Capital charge factor [table] | E31: factor | J31: 1 | K31: 1 | L31: 1 | M31: 1 | N31: 1 | O31: 1 | P31: 1 | Q31: 1 | R31: 1 | S31: 1 | T31: 1 | U31: 1 | V31: 1 | W31: 1 | X31: 1
D32: Macro path (1 FC forward, 2 actual history, 3 COD re-forecast) | E32: code | F32: =INDEX($J$10:$X$10,1,Scenario)
D33: Construction case (1 FC budget, 2 actual) | E33: code | F33: =INDEX($J$11:$X$11,1,Scenario)
D34: COD delay (sensitivity) | E34: months | F34: =INDEX($J$12:$X$12,1,Scenario)
D35: Capex factor | E35: factor | F35: =INDEX($J$13:$X$13,1,Scenario)
D36: Availability adjustment | E36: points | F36: =INDEX($J$14:$X$14,1,Scenario)
D37: Dispatch factor when available | E37: % | F37: =INDEX($J$15:$X$15,1,Scenario)
D38: Plant heat rate factor | E38: factor | F38: =INDEX($J$16:$X$16,1,Scenario)
D39: Fixed opex factor | E39: factor | F39: =INDEX($J$17:$X$17,1,Scenario)
D40: Gas price factor | E40: factor | F40: =INDEX($J$18:$X$18,1,Scenario)
D41: Base rate shift from 2022H1 | E41: % | F41: =INDEX($J$19:$X$19,1,Scenario)
D42: KCR devaluation from 2022H1 | E42: fraction | F42: =INDEX($J$20:$X$20,1,Scenario)
D43: Extra days on SEKA capacity/VOM payments, 2022H1-2022H2 | E43: days | F43: =INDEX($J$21:$X$21,1,Scenario)
D44: Offtaker crisis events (1 = on) | E44: flag | F44: =INDEX($J$22:$X$22,1,Scenario)
D45: Insurance market step-up from 2022H2 (1 = on) | E45: flag | F45: =INDEX($J$23:$X$23,1,Scenario)
D46: Repayment profile (1 FC contract, 2 COD re-sculpted) | E46: code | F46: =INDEX($J$24:$X$24,1,Scenario)
D47: Performance LD prepayment June 2022 (1 = on) | E47: flag | F47: =INDEX($J$25:$X$25,1,Scenario)
D48: Waiver and amendment 2023 (1 = on) | E48: flag | F48: =INDEX($J$26:$X$26,1,Scenario)
D49: 2025 bond refinancing (1 = on) | E49: flag | F49: =INDEX($J$27:$X$27,1,Scenario)
D50: Funding mode (1 committed amounts, 2 re-grossed pro rata) | E50: code | F50: =INDEX($J$28:$X$28,1,Scenario)
...

Sheet Time
A1: Case P: Belanou Combined Cycle Power Project, Republic of Kessara
A2: Time: semiannual operating timeline (monthly timeline on the Construction sheet)
A3: Units in column E; constants in column F; row totals in column G; first period in column J. Inputs: blue on yellow. Links from other sheets: green.
D4: Label | E4: Unit | F4: Constant | G4: Total
D5: Period ending | J5: 2018H2 | K5: 2019H1 | L5: 2019H2 | M5: 2020H1 | N5: 2020H2 | O5: 2021H1 | P5: 2021H2 | Q5: 2022H1 | R5: 2022H2 | S5: 2023H1 | T5: 2023H2 | U5: 2024H1 | V5: 2024H2 | W5: 2025H1 | X5: 2025H2 | Y5: 2026H1 | Z5: 2026H2 | AA5: 2027H1 | AB5: 2027H2 | AC5: 2028H1 | AD5: 2028H2 | AE5: 2029H1 | AF5: 2029H2 | AG5: 2030H1 | AH5: 2030H2 | AI5: 2031H1 | AJ5: 2031H2 | AK5: 2032H1 | AL5: 2032H2 | AM5: 2033H1 | AN5: 2033H2 | AO5: 2034H1 | AP5: 2034H2 | AQ5: 2035H1 | AR5: 2035H2 | AS5: 2036H1 | AT5: 2036H2 | AU5: 2037H1 | AV5: 2037H2 | AW5: 2038H1 | AX5: 2038H2 | AY5: 2039H1 | AZ5: 2039H2 | BA5: 2040H1 | BB5: 2040H2 | BC5: 2041H1 | BD5: 2041H2 | BE5: 2042H1 | BF5: 2042H2 | BG5: 2043H1 | BH5: 2043H2 | BI5: 2044H1 | BJ5: 2044H2 | BK5: 2045H1 | BL5: 2045H2 | BM5: 2046H1 | BN5: 2046H2
B7: Key dates (scenario-dependent)
D8: Commercial operation date | E8: date | F8: =IF(Inputs!$F$33=2,DATE(2021,12,1),EDATE(DATE(2021,5,1),Inputs!$F$34))
D9: PPA expiry | E9: date | F9: =EDATE(Time!$F$8,300)-1
D10: Construction months (NTP to COD) | E10: months | F10: =(YEAR(Time!$F$8)-2018)*12+MONTH(Time!$F$8)-8
D11: Period containing COD (period number) | E11: index | F11: =(YEAR(Time!$F$8)-2018)*2+IF(MONTH(Time!$F$8)<=6,0,1)
D12: First debt service period | E12: index | F12: =Time!$F$11+1
D13: Last month of the funding period (month number) | E13: index | F13: =(YEAR(Time!$F$8)-2018)*12+IF(MONTH(Time!$F$8)<=6,6,12)-7
D14: Last operating period (period number) | E14: index | F14: =SUMPRODUCT($J$32:$BN$32,$J$17:$BN$17)
D15: FC FX drift (Kessara 7.5% / US 2.2%) | E15: factor | F15: =1.075/1.022
B16: Semiannual timeline
D17: Period number | E17: index | J17: =1 | K17: =2 | L17: =3 | M17: =4 | N17: =5 | O17: =6 | P17: =7 | Q17: =8 | R17: =9 | S17: =10 | T17: =11 | U17: =12 | V17: =13 | W17: =14 | X17: =15 | Y17: =16 | Z17: =17 | AA17: =18 | AB17: =19 | AC17: =20 | AD17: =21 | AE17: =22 | AF17: =23 | AG17: =24 | AH17: =25 | AI17: =26 | AJ17: =27 | AK17: =28 | AL17: =29 | AM17: =30 | AN17: =31 | AO17: =32 | AP17: =33 | AQ17: =34 | AR17: =35 | AS17: =36 | AT17: =37 | AU17: =38 | AV17: =39 | AW17: =40 | AX17: =41 | AY17: =42 | AZ17: =43 | BA17: =44 | BB17: =45 | BC17: =46 | BD17: =47 | BE17: =48 | BF17: =49 | BG17: =50 | BH17: =51 | BI17: =52 | BJ17: =53 | BK17: =54 | BL17: =55 | BM17: =56 | BN17: =57
D18: Period start | E18: date | J18: =DATE(2018,7,1) | K18: =EDATE(J18,6) | L18: =EDATE(K18,6) | M18: =EDATE(L18,6) | N18: =EDATE(M18,6) | O18: =EDATE(N18,6) | P18: =EDATE(O18,6) | Q18: =EDATE(P18,6) | R18: =EDATE(Q18,6) | ... BN18: =EDATE(BM18,6)
D19: Period end | E19: date | J19: =EOMONTH(J18,5) | K19: =EOMONTH(K18,5) | L19: =EOMONTH(L18,5) | M19: =EOMONTH(M18,5) | N19: =EOMONTH(N18,5) | O19: =EOMONTH(O18,5) | P19: =EOMONTH(P18,5) | Q19: =EOMONTH(Q18,5) | ... BN19: =EOMONTH(BN18,5)
D20: Days in period | E20: days | J20: =J19-J18+1 | K20: =K19-K18+1 | L20: =L19-L18+1 | M20: =M19-M18+1 | N20: =N19-N18+1 | O20: =O19-O18+1 | P20: =P19-P18+1 | Q20: =Q19-Q18+1 | ... BN20: =BN19-BN18+1
D21: Calendar year | E21: year | J21: =YEAR(J18) | K21: =YEAR(K18) | L21: =YEAR(L18) | M21: =YEAR(M18) | N21: =YEAR(N18) | O21: =YEAR(O18) | P21: =YEAR(P18) | Q21: =YEAR(Q18) | ... BN21: =YEAR(BN18)
D22: Half (1 = Jan-Jun) | E22: index | J22: =IF(MONTH(J18)=1,1,2) | K22: =IF(MONTH(K18)=1,1,2) | L22: =IF(MONTH(L18)=1,1,2) | M22: =IF(MONTH(M18)=1,1,2) | N22: =IF(MONTH(N18)=1,1,2) | O22: =IF(MONTH(O18)=1,1,2) | P22: =IF(MONTH(P18)=1,1,2) | Q22: =IF(MONTH(Q18)=1,1,2) | ... BN22: =IF(MONTH(BN18)=1,1,2)
D23: Operations start in period | E23: date | J23: =MAX(J18,$F$8) | K23: =MAX(K18,$F$8) | L23: =MAX(L18,$F$8) | M23: =MAX(M18,$F$8) | N23: =MAX(N18,$F$8) | O23: =MAX(O18,$F$8) | P23: =MAX(P18,$F$8) | Q23: =MAX(Q18,$F$8) | ... BN23: =MAX(BN18,$F$8)
D24: Operations end in period | E24: date | J24: =MIN(J19,$F$9) | K24: =MIN(K19,$F$9) | L24: =MIN(L19,$F$9) | M24: =MIN(M19,$F$9) | N24: =MIN(N19,$F$9) | O24: =MIN(O19,$F$9) | P24: =MIN(P19,$F$9) | Q24: =MIN(Q19,$F$9) | ... BN24: =MIN(BN19,$F$9)
D25: Operating months in period | E25: months | J25: =IF(J24>=J23,(YEAR(J24)-YEAR(J23))*12+MONTH(J24)-MONTH(J23)+1,0) | K25: =IF(K24>=K23,(YEAR(K24)-YEAR(K23))*12+MONTH(K24)-MONTH(K23)+1,0) | L25: =IF(L24>=L23,(YEAR(L24)-YEAR(L23))*12+MONTH(L24)-MONTH(L23)+1,0) | M25: =IF(M24>=M23,(YEAR(M24)-YEAR(M23))*12+MONTH(M24)-MONTH(M23)+1,0) | N25: =IF(N24>=N23,(YEAR(N24)-YEAR(N23))*12+MONTH(N24)-MONTH(N23)+1,0) | O25: =IF(O24>=O23,(YEAR(O24)-YEAR(O23))*12+MONTH(O24)-MONTH(O23)+1,0) | P25: =IF(P24>=P23,(YEAR(P24)-YEAR(P23))*12+MONTH(P24)-MONTH(P23)+1,0) | Q25: =IF(Q24>=Q23,(YEAR(Q24)-YEAR(Q23))*12+MONTH(Q24)-MONTH(Q23)+1,0) | ... BN25: =IF(BN24>=BN23,(YEAR(BN24)-YEAR(BN23))*12+MONTH(BN24)-MONTH(BN23)+1,0)
D26: Operating days in period | E26: days | J26: =IF(J24>=J23,J24-J23+1,0) | K26: =IF(K24>=K23,K24-K23+1,0) | L26: =IF(L24>=L23,L24-L23+1,0) | M26: =IF(M24>=M23,M24-M23+1,0) | N26: =IF(N24>=N23,N24-N23+1,0) | O26: =IF(O24>=O23,O24-O23+1,0) | P26: =IF(P24>=P23,P24-P23+1,0) | Q26: =IF(Q24>=Q23,Q24-Q23+1,0) | ... BN26: =IF(BN24>=BN23,BN24-BN23+1,0)
D27: Operating months elapsed at period start | E27: months | J27: =MIN(MAX((YEAR(J18)-YEAR($F$8))*12+MONTH(J18)-MONTH($F$8),0),300) | K27: =MIN(MAX((YEAR(K18)-YEAR($F$8))*12+MONTH(K18)-MONTH($F$8),0),300) | L27: =MIN(MAX((YEAR(L18)-YEAR($F$8))*12+MONTH(L18)-MONTH($F$8),0),300) | M27: =MIN(MAX((YEAR(M18)-YEAR($F$8))*12+MONTH(M18)-MONTH($F$8),0),300) | N27: =MIN(MAX((YEAR(N18)-YEAR($F$8))*12+MONTH(N18)-MONTH($F$8),0),300) | O27: =MIN(MAX((YEAR(O18)-YEAR($F$8))*12+MONTH(O18)-MONTH($F$8),0),300) | P27: =MIN(MAX((YEAR(P18)-YEAR($F$8))*12+MONTH(P18)-MONTH($F$8),0),300) | Q27: =MIN(MAX((YEAR(Q18)-YEAR($F$8))*12+MONTH(Q18)-MONTH($F$8),0),300) | ... BN27: =MIN(MAX((YEAR(BN18)-YEAR($F$8))*12+MONTH(BN18)-MONTH($F$8),0),300)
D28: Operating months elapsed at period end | E28: months | J28: =J27+J25 | K28: =K27+K25 | L28: =L27+L25 | M28: =M27+M25 | N28: =N27+N25 | O28: =O27+O25 | P28: =P27+P25 | Q28: =Q27+Q25 | ... BN28: =BN27+BN25
D29: Flag_CODPeriod | E29: flag | J29: =IF(J17=$F$11,1,0) | K29: =IF(K17=$F$11,1,0) | L29: =IF(L17=$F$11,1,0) | M29: =IF(M17=$F$11,1,0) | N29: =IF(N17=$F$11,1,0) | O29: =IF(O17=$F$11,1,0) | P29: =IF(P17=$F$11,1,0) | Q29: =IF(Q17=$F$11,1,0) | ... BN29: =IF(BN17=$F$11,1,0)
D30: Flag_DebtService (after COD period) | E30: flag | J30: =IF(J17>$F$11,1,0) | K30: =IF(K17>$F$11,1,0) | L30: =IF(L17>$F$11,1,0) | M30: =IF(M17>$F$11,1,0) | N30: =IF(N17>$F$11,1,0) | O30: =IF(O17>$F$11,1,0) | P30: =IF(P17>$F$11,1,0) | Q30: =IF(Q17>$F$11,1,0) | ... BN30: =IF(BN17>$F$11,1,0)
D31: Flag_Operations | E31: flag | J31: =IF(J25>0,1,0) | K31: =IF(K25>0,1,0) | L31: =IF(L25>0,1,0) | M31: =IF(M25>0,1,0) | N31: =IF(N25>0,1,0) | O31: =IF(O25>0,1,0) | P31: =IF(P25>0,1,0) | Q31: =IF(Q25>0,1,0) | ... BN31: =IF(BN25>0,1,0)
D32: Flag_LastOperatingPeriod | E32: flag | J32: =IF(AND(J25>0,K25=0),1,0) | K32: =IF(AND(K25>0,L25=0),1,0) | L32: =IF(AND(L25>0,M25=0),1,0) | M32: =IF(AND(M25>0,N25=0),1,0) | N32: =IF(AND(N25>0,O25=0),1,0) | O32: =IF(AND(O25>0,P25=0),1,0) | P32: =IF(AND(P25>0,Q25=0),1,0) | Q32: =IF(AND(Q25>0,R25=0),1,0) | ... BM32: =IF(AND(BM25>0,BN25=0),1,0) | BN32: =IF(AND(BN25>0,0=0),1,0)
D33: Flag_ShockPeriods (2022H1-2022H2) | E33: flag | J33: =IF(AND(J17>=8,J17<=9),1,0) | K33: =IF(AND(K17>=8,K17<=9),1,0) | L33: =IF(AND(L17>=8,L17<=9),1,0) | M33: =IF(AND(M17>=8,M17<=9),1,0) | N33: =IF(AND(N17>=8,N17<=9),1,0) | O33: =IF(AND(O17>=8,O17<=9),1,0) | P33: =IF(AND(P17>=8,P17<=9),1,0) | Q33: =IF(AND(Q17>=8,Q17<=9),1,0) | ... BN33: =IF(AND(BN17>=8,BN17<=9),1,0)
D34: Flag from 2022H1 | E34: flag | J34: =IF(J17>=8,1,0) | K34: =IF(K17>=8,1,0) | L34: =IF(L17>=8,1,0) | M34: =IF(M17>=8,1,0) | N34: =IF(N17>=8,1,0) | O34: =IF(O17>=8,1,0) | P34: =IF(P17>=8,1,0) | Q34: =IF(Q17>=8,1,0) | ... BN34: =IF(BN17>=8,1,0)

Sheet Construction
A1: Case P: Belanou Combined Cycle Power Project, Republic of Kessara
A2: Construction: monthly uses of funds before financing costs, VAT
A3: Units in column E; constants in column F; row totals in column G; first period in column J. Inputs: blue on yellow. Links from other sheets: green.
D4: Label | E4: Unit | F4: Constant | G4: Total
D5: Month | J5: 2018-08 | K5: 2018-09 | L5: 2018-10 | M5: 2018-11 | N5: 2018-12 | O5: 2019-01 | P5: 2019-02 | Q5: 2019-03 | R5: 2019-04 | S5: 2019-05 | T5: 2019-06 | U5: 2019-07 | V5: 2019-08 | W5: 2019-09 | X5: 2019-10 | Y5: 2019-11 | Z5: 2019-12 | AA5: 2020-01 | AB5: 2020-02 | AC5: 2020-03 | AD5: 2020-04 | AE5: 2020-05 | AF5: 2020-06 | AG5: 2020-07 | AH5: 2020-08 | AI5: 2020-09 | AJ5: 2020-10 | AK5: 2020-11 | AL5: 2020-12 | AM5: 2021-01 | AN5: 2021-02 | AO5: 2021-03 | AP5: 2021-04 | AQ5: 2021-05 | AR5: 2021-06 | AS5: 2021-07 | AT5: 2021-08 | AU5: 2021-09 | AV5: 2021-10 | AW5: 2021-11 | AX5: 2021-12 | AY5: 2022-01 | AZ5: 2022-02 | BA5: 2022-03 | BB5: 2022-04 | BC5: 2022-05 | BD5: 2022-06 | BE5: 2022-07 | BF5: 2022-08 | BG5: 2022-09 | BH5: 2022-10 | BI5: 2022-11 | BJ5: 2022-12
B7: Monthly timeline (column J = August 2018)
D8: Month number | E8: index | J8: =1 | K8: =2 | L8: =3 | M8: =4 | N8: =5 | O8: =6 | P8: =7 | Q8: =8 | R8: =9 | S8: =10 | T8: =11 | U8: =12 | V8: =13 | W8: =14 | X8: =15 | Y8: =16 | Z8: =17 | AA8: =18 | AB8: =19 | AC8: =20 | AD8: =21 | AE8: =22 | AF8: =23 | AG8: =24 | AH8: =25 | AI8: =26 | AJ8: =27 | AK8: =28 | AL8: =29 | AM8: =30 | AN8: =31 | AO8: =32 | AP8: =33 | AQ8: =34 | AR8: =35 | AS8: =36 | AT8: =37 | AU8: =38 | AV8: =39 | AW8: =40 | AX8: =41 | AY8: =42 | AZ8: =43 | BA8: =44 | BB8: =45 | BC8: =46 | BD8: =47 | BE8: =48 | BF8: =49 | BG8: =50 | BH8: =51 | BI8: =52 | BJ8: =53
D9: Month start | E9: date | J9: =DATE(2018,8,1) | K9: =EDATE(J9,1) | L9: =EDATE(K9,1) | M9: =EDATE(L9,1) | N9: =EDATE(M9,1) | O9: =EDATE(N9,1) | P9: =EDATE(O9,1) | Q9: =EDATE(P9,1) | R9: =EDATE(Q9,1) | ... BJ9: =EDATE(BI9,1)
D10: Month end | E10: date | J10: =EOMONTH(J9,0) | K10: =EOMONTH(K9,0) | L10: =EOMONTH(L9,0) | M10: =EOMONTH(M9,0) | N10: =EOMONTH(N9,0) | O10: =EOMONTH(O9,0) | P10: =EOMONTH(P9,0) | Q10: =EOMONTH(Q9,0) | ... BJ10: =EOMONTH(BJ9,0)
D11: Days | E11: days | J11: =J10-J9+1 | K11: =K10-K9+1 | L11: =L10-L9+1 | M11: =M10-M9+1 | N11: =N10-N9+1 | O11: =O10-O9+1 | P11: =P10-P9+1 | Q11: =Q10-Q9+1 | ... BJ11: =BJ10-BJ9+1
D12: Semiannual period number | E12: index | J12: =(YEAR(J9)-2018)*2+IF(MONTH(J9)<=6,0,1) | K12: =(YEAR(K9)-2018)*2+IF(MONTH(K9)<=6,0,1) | L12: =(YEAR(L9)-2018)*2+IF(MONTH(L9)<=6,0,1) | M12: =(YEAR(M9)-2018)*2+IF(MONTH(M9)<=6,0,1) | N12: =(YEAR(N9)-2018)*2+IF(MONTH(N9)<=6,0,1) | O12: =(YEAR(O9)-2018)*2+IF(MONTH(O9)<=6,0,1) | P12: =(YEAR(P9)-2018)*2+IF(MONTH(P9)<=6,0,1) | Q12: =(YEAR(Q9)-2018)*2+IF(MONTH(Q9)<=6,0,1) | ... BJ12: =(YEAR(BJ9)-2018)*2+IF(MONTH(BJ9)<=6,0,1)
D13: Flag_Construction (before COD) | E13: flag | J13: =IF(J8<=Time!$F$10,1,0) | K13: =IF(K8<=Time!$F$10,1,0) | L13: =IF(L8<=Time!$F$10,1,0) | M13: =IF(M8<=Time!$F$10,1,0) | N13: =IF(N8<=Time!$F$10,1,0) | O13: =IF(O8<=Time!$F$10,1,0) | P13: =IF(P8<=Time!$F$10,1,0) | Q13: =IF(Q8<=Time!$F$10,1,0) | ... BJ13: =IF(BJ8<=Time!$F$10,1,0)
D14: Flag_FundingPeriod (to end of COD period) | E14: flag | J14: =IF(J8<=Time!$F$13,1,0) | K14: =IF(K8<=Time!$F$13,1,0) | L14: =IF(L8<=Time!$F$13,1,0) | M14: =IF(M8<=Time!$F$13,1,0) | N14: =IF(N8<=Time!$F$13,1,0) | O14: =IF(O8<=Time!$F$13,1,0) | P14: =IF(P8<=Time!$F$13,1,0) | Q14: =IF(Q8<=Time!$F$13,1,0) | ... BJ14: =IF(BJ8<=Time!$F$13,1,0)
D15: Flag_CODMonth | E15: flag | J15: =IF(J8=Time!$F$10+1,1,0) | K15: =IF(K8=Time!$F$10+1,1,0) | L15: =IF(L8=Time!$F$10+1,1,0) | M15: =IF(M8=Time!$F$10+1,1,0) | N15: =IF(N8=Time!$F$10+1,1,0) | O15: =IF(O8=Time!$F$10+1,1,0) | P15: =IF(P8=Time!$F$10+1,1,0) | Q15: =IF(Q8=Time!$F$10+1,1,0) | ... BJ15: =IF(BJ8=Time!$F$10+1,1,0)
D16: KCR per USD | E16: KCR/USD | J16: =IF(Inputs!$F$32=1,Inputs!$F$58*Time!$F$15^((J8-0.5)/12),INDEX(Operations!$J$11:$BN$11,1,J12)) | K16: =IF(Inputs!$F$32=1,Inputs!$F$58*Time!$F$15^((K8-0.5)/12),INDEX(Operations!$J$11:$BN$11,1,K12)) | L16: =IF(Inputs!$F$32=1,Inputs!$F$58*Time!$F$15^((L8-0.5)/12),INDEX(Operations!$J$11:$BN$11,1,L12)) | M16: =IF(Inputs!$F$32=1,Inputs!$F$58*Time!$F$15^((M8-0.5)/12),INDEX(Operations!$J$11:$BN$11,1,M12)) | N16: =IF(Inputs!$F$32=1,Inputs!$F$58*Time!$F$15^((N8-0.5)/12),INDEX(Operations!$J$11:$BN$11,1,N12)) | O16: =IF(Inputs!$F$32=1,Inputs!$F$58*Time!$F$15^((O8-0.5)/12),INDEX(Operations!$J$11:$BN$11,1,O12)) | P16: =IF(Inputs!$F$32=1,Inputs!$F$58*Time!$F$15^((P8-0.5)/12),INDEX(Operations!$J$11:$BN$11,1,P12)) | Q16: =IF(Inputs!$F$32=1,Inputs!$F$58*Time!$F$15^((Q8-0.5)/12),INDEX(Operations!$J$11:$BN$11,1,Q12)) | ... BJ16: =IF(Inputs!$F$32=1,Inputs!$F$58*Time!$F$15^((BJ8-0.5)/12),INDEX(Operations!$J$11:$BN$11,1,BJ12))
D17: Base rate (6M fixing for the half-year) | E17: % | J17: =INDEX(Operations!$J$8:$BN$8,1,J12) | K17: =INDEX(Operations!$J$8:$BN$8,1,K12) | L17: =INDEX(Operations!$J$8:$BN$8,1,L12) | M17: =INDEX(Operations!$J$8:$BN$8,1,M12) | N17: =INDEX(Operations!$J$8:$BN$8,1,N12) | O17: =INDEX(Operations!$J$8:$BN$8,1,O12) | P17: =INDEX(Operations!$J$8:$BN$8,1,P12) | Q17: =INDEX(Operations!$J$8:$BN$8,1,Q12) | ... BJ17: =INDEX(Operations!$J$8:$BN$8,1,BJ12)
D18: Kessara policy rate | E18: % | J18: =IF(Inputs!$F$32=1,Inputs!$F$71,INDEX(Inputs!$J$210:$AR$210,1,YEAR(J9)-2014)) | K18: =IF(Inputs!$F$32=1,Inputs!$F$71,INDEX(Inputs!$J$210:$AR$210,1,YEAR(K9)-2014)) | L18: =IF(Inputs!$F$32=1,Inputs!$F$71,INDEX(Inputs!$J$210:$AR$210,1,YEAR(L9)-2014)) | M18: =IF(Inputs!$F$32=1,Inputs!$F$71,INDEX(Inputs!$J$210:$AR$210,1,YEAR(M9)-2014)) | N18: =IF(Inputs!$F$32=1,Inputs!$F$71,INDEX(Inputs!$J$210:$AR$210,1,YEAR(N9)-2014)) | O18: =IF(Inputs!$F$32=1,Inputs!$F$71,INDEX(Inputs!$J$210:$AR$210,1,YEAR(O9)-2014)) | P18: =IF(Inputs!$F$32=1,Inputs!$F$71,INDEX(Inputs!$J$210:$AR$210,1,YEAR(P9)-2014)) | Q18: =IF(Inputs!$F$32=1,Inputs!$F$71,INDEX(Inputs!$J$210:$AR$210,1,YEAR(Q9)-2014)) | ... BJ18: =IF(Inputs!$F$32=1,Inputs!$F$71,INDEX(Inputs!$J$210:$AR$210,1,YEAR(BJ9)-2014))
B19: Uses before financing costs (USD m)
D20: EPC payment profile, selected | E20: % | J20: =IF(Inputs!$F$33=2,Inputs!J226,Inputs!J225+IF(Inputs!$F$34>0,IF(J8=33,-7.5,0)+IF(J8=33+Inputs!$F$34,7.5,0),0)) | K20: =IF(Inputs!$F$33=2,Inputs!K226,Inputs!K225+IF(Inputs!$F$34>0,IF(K8=33,-7.5,0)+IF(K8=33+Inputs!$F$34,7.5,0),0)) | L20: =IF(Inputs!$F$33=2,Inputs!L226,Inputs!L225+IF(Inputs!$F$34>0,IF(L8=33,-7.5,0)+IF(L8=33+Inputs!$F$34,7.5,0),0)) | M20: =IF(Inputs!$F$33=2,Inputs!M226,Inputs!M225+IF(Inputs!$F$34>0,IF(M8=33,-7.5,0)+IF(M8=33+Inputs!$F$34,7.5,0),0)) | N20: =IF(Inputs!$F$33=2,Inputs!N226,Inputs!N225+IF(Inputs!$F$34>0,IF(N8=33,-7.5,0)+IF(N8=33+Inputs!$F$34,7.5,0),0)) | O20: =IF(Inputs!$F$33=2,Inputs!O226,Inputs!O225+IF(Inputs!$F$34>0,IF(O8=33,-7.5,0)+IF(O8=33+Inputs!$F$34,7.5,0),0)) | P20: =IF(Inputs!$F$33=2,Inputs!P226,Inputs!P225+IF(Inputs!$F$34>0,IF(P8=33,-7.5,0)+IF(P8=33+Inputs!$F$34,7.5,0),0)) | Q20: =IF(Inputs!$F$33=2,Inputs!Q226,Inputs!Q225+IF(Inputs!$F$34>0,IF(Q8=33,-7.5,0)+IF(Q8=33+Inputs!$F$34,7.5,0),0)) | ... BJ20: =IF(Inputs!$F$33=2,Inputs!BJ226,Inputs!BJ225+IF(Inputs!$F$34>0,IF(BJ8=33,-7.5,0)+IF(BJ8=33+Inputs!$F$34,7.5,0),0))
D21: EPC progress payments for contingency (FC) | E21: % | J21: =IF(J8=1,0,J20)-IF(J8=Time!$F$10,7.5,0) | K21: =IF(K8=1,0,K20)-IF(K8=Time!$F$10,7.5,0) | L21: =IF(L8=1,0,L20)-IF(L8=Time!$F$10,7.5,0) | M21: =IF(M8=1,0,M20)-IF(M8=Time!$F$10,7.5,0) | N21: =IF(N8=1,0,N20)-IF(N8=Time!$F$10,7.5,0) | O21: =IF(O8=1,0,O20)-IF(O8=Time!$F$10,7.5,0) | P21: =IF(P8=1,0,P20)-IF(P8=Time!$F$10,7.5,0) | Q21: =IF(Q8=1,0,Q20)-IF(Q8=Time!$F$10,7.5,0) | ... BJ21: =IF(BJ8=1,0,BJ20)-IF(BJ8=Time!$F$10,7.5,0)
D22: EPC payments | E22: USD m | G22: =SUM(J22:BJ22) | J22: =IF(Inputs!$F$33=2,J20/100*Inputs!$F$56+J20/100*Inputs!$F$57*Inputs!$F$58/J16,Inputs!$F$55*Inputs!$F$35*J20/100) | K22: =IF(Inputs!$F$33=2,K20/100*Inputs!$F$56+K20/100*Inputs!$F$57*Inputs!$F$58/K16,Inputs!$F$55*Inputs!$F$35*K20/100) | L22: =IF(Inputs!$F$33=2,L20/100*Inputs!$F$56+L20/100*Inputs!$F$57*Inputs!$F$58/L16,Inputs!$F$55*Inputs!$F$35*L20/100) | M22: =IF(Inputs!$F$33=2,M20/100*Inputs!$F$56+M20/100*Inputs!$F$57*Inputs!$F$58/M16,Inputs!$F$55*Inputs!$F$35*M20/100) | N22: =IF(Inputs!$F$33=2,N20/100*Inputs!$F$56+N20/100*Inputs!$F$57*Inputs!$F$58/N16,Inputs!$F$55*Inputs!$F$35*N20/100) | O22: =IF(Inputs!$F$33=2,O20/100*Inputs!$F$56+O20/100*Inputs!$F$57*Inputs!$F$58/O16,Inputs!$F$55*Inputs!$F$35*O20/100) | P22: =IF(Inputs!$F$33=2,P20/100*Inputs!$F$56+P20/100*Inputs!$F$57*Inputs!$F$58/P16,Inputs!$F$55*Inputs!$F$35*P20/100) | Q22: =IF(Inputs!$F$33=2,Q20/100*Inputs!$F$56+Q20/100*Inputs!$F$57*Inputs!$F$58/Q16,Inputs!$F$55*Inputs!$F$35*Q20/100) | ... BJ22: =IF(Inputs!$F$33=2,BJ20/100*Inputs!$F$56+BJ20/100*Inputs!$F$57*Inputs!$F$58/BJ16,Inputs!$F$55*Inputs!$F$35*BJ20/100)
D23: Owner's costs | E23: USD m | G23: =SUM(J23:BJ23) | J23: =Inputs!$F$59*IF(Inputs!$F$33=1,Inputs!$F$35,1)*(Inputs!J227+IF(AND(Inputs!$F$33=1,J8>33,J8<=Time!$F$10),2.75,0))/100+IF(AND(Inputs!$F$33=2,J8>=34,J8<=40),Inputs!$F$67/7,0) | K23: =Inputs!$F$59*IF(Inputs!$F$33=1,Inputs!$F$35,1)*(Inputs!K227+IF(AND(Inputs!$F$33=1,K8>33,K8<=Time!$F$10),2.75,0))/100+IF(AND(Inputs!$F$33=2,K8>=34,K8<=40),Inputs!$F$67/7,0) | L23: =Inputs!$F$59*IF(Inputs!$F$33=1,Inputs!$F$35,1)*(Inputs!L227+IF(AND(Inputs!$F$33=1,L8>33,L8<=Time!$F$10),2.75,0))/100+IF(AND(Inputs!$F$33=2,L8>=34,L8<=40),Inputs!$F$67/7,0) | M23: =Inputs!$F$59*IF(Inputs!$F$33=1,Inputs!$F$35,1)*(Inputs!M227+IF(AND(Inputs!$F$33=1,M8>33,M8<=Time!$F$10),2.75,0))/100+IF(AND(Inputs!$F$33=2,M8>=34,M8<=40),Inputs!$F$67/7,0) | N23: =Inputs!$F$59*IF(Inputs!$F$33=1,Inputs!$F$35,1)*(Inputs!N227+IF(AND(Inputs!$F$33=1,N8>33,N8<=Time!$F$10),2.75,0))/100+IF(AND(Inputs!$F$33=2,N8>=34,N8<=40),Inputs!$F$67/7,0) | O23: =Inputs!$F$59*IF(Inputs!$F$33=1,Inputs!$F$35,1)*(Inputs!O227+IF(AND(Inputs!$F$33=1,O8>33,O8<=Time!$F$10),2.75,0))/100+IF(AND(Inputs!$F$33=2,O8>=34,O8<=40),Inputs!$F$67/7,0) | P23: =Inputs!$F$59*IF(Inputs!$F$33=1,Inputs!$F$35,1)*(Inputs!P227+IF(AND(Inputs!$F$33=1,P8>33,P8<=Time!$F$10),2.75,0))/100+IF(AND(Inputs!$F$33=2,P8>=34,P8<=40),Inputs!$F$67/7,0) | Q23: =Inputs!$F$59*IF(Inputs!$F$33=1,Inputs!$F$35,1)*(Inputs!Q227+IF(AND(Inputs!$F$33=1,Q8>33,Q8<=Time!$F$10),2.75,0))/100+IF(AND(Inputs!$F$33=2,Q8>=34,Q8<=40),Inputs!$F$67/7,0) | ... BJ23: =Inputs!$F$59*IF(Inputs!$F$33=1,Inputs!$F$35,1)*(Inputs!BJ227+IF(AND(Inputs!$F$33=1,BJ8>33,BJ8<=Time!$F$10),2.75,0))/100+IF(AND(Inputs!$F$33=2,BJ8>=34,BJ8<=40),Inputs!$F$67/7,0)
D24: Insurance during construction | E24: USD m | G24: =SUM(J24:BJ24) | J24: =Inputs!$F$60*Inputs!$F$35*(0.85*IF(J8=1,1,0)+0.15*IF(J8=18,1,0)) | K24: =Inputs!$F$60*Inputs!$F$35*(0.85*IF(K8=1,1,0)+0.15*IF(K8=18,1,0)) | L24: =Inputs!$F$60*Inputs!$F$35*(0.85*IF(L8=1,1,0)+0.15*IF(L8=18,1,0)) | M24: =Inputs!$F$60*Inputs!$F$35*(0.85*IF(M8=1,1,0)+0.15*IF(M8=18,1,0)) | N24: =Inputs!$F$60*Inputs!$F$35*(0.85*IF(N8=1,1,0)+0.15*IF(N8=18,1,0)) | O24: =Inputs!$F$60*Inputs!$F$35*(0.85*IF(O8=1,1,0)+0.15*IF(O8=18,1,0)) | P24: =Inputs!$F$60*Inputs!$F$35*(0.85*IF(P8=1,1,0)+0.15*IF(P8=18,1,0)) | Q24: =Inputs!$F$60*Inputs!$F$35*(0.85*IF(Q8=1,1,0)+0.15*IF(Q8=18,1,0)) | ... BJ24: =Inputs!$F$60*Inputs!$F$35*(0.85*IF(BJ8=1,1,0)+0.15*IF(BJ8=18,1,0))
D25: Development costs and fee | E25: USD m | G25: =SUM(J25:BJ25) | J25: =IF(J8=1,Inputs!$F$61+Inputs!$F$62,0) | K25: =IF(K8=1,Inputs!$F$61+Inputs!$F$62,0) | L25: =IF(L8=1,Inputs!$F$61+Inputs!$F$62,0) | M25: =IF(M8=1,Inputs!$F$61+Inputs!$F$62,0) | N25: =IF(N8=1,Inputs!$F$61+Inputs!$F$62,0) | O25: =IF(O8=1,Inputs!$F$61+Inputs!$F$62,0) | P25: =IF(P8=1,Inputs!$F$61+Inputs!$F$62,0) | Q25: =IF(Q8=1,Inputs!$F$61+Inputs!$F$62,0) | ... BJ25: =IF(BJ8=1,Inputs!$F$61+Inputs!$F$62,0)
D26: Lenders' advisors and legal | E26: USD m | G26: =SUM(J26:BJ26) | J26: =Inputs!$F$63*Inputs!$F$35*(0.7*IF(J8=1,1,0)+0.3/(Time!$F$10-1)*IF(AND(J8>=2,J8<=Time!$F$10),1,0)) | K26: =Inputs!$F$63*Inputs!$F$35*(0.7*IF(K8=1,1,0)+0.3/(Time!$F$10-1)*IF(AND(K8>=2,K8<=Time!$F$10),1,0)) | L26: =Inputs!$F$63*Inputs!$F$35*(0.7*IF(L8=1,1,0)+0.3/(Time!$F$10-1)*IF(AND(L8>=2,L8<=Time!$F$10),1,0)) | M26: =Inputs!$F$63*Inputs!$F$35*(0.7*IF(M8=1,1,0)+0.3/(Time!$F$10-1)*IF(AND(M8>=2,M8<=Time!$F$10),1,0)) | N26: =Inputs!$F$63*Inputs!$F$35*(0.7*IF(N8=1,1,0)+0.3/(Time!$F$10-1)*IF(AND(N8>=2,N8<=Time!$F$10),1,0)) | O26: =Inputs!$F$63*Inputs!$F$35*(0.7*IF(O8=1,1,0)+0.3/(Time!$F$10-1)*IF(AND(O8>=2,O8<=Time!$F$10),1,0)) | P26: =Inputs!$F$63*Inputs!$F$35*(0.7*IF(P8=1,1,0)+0.3/(Time!$F$10-1)*IF(AND(P8>=2,P8<=Time!$F$10),1,0)) | Q26: =Inputs!$F$63*Inputs!$F$35*(0.7*IF(Q8=1,1,0)+0.3/(Time!$F$10-1)*IF(AND(Q8>=2,Q8<=Time!$F$10),1,0)) | ... BJ26: =Inputs!$F$63*Inputs!$F$35*(0.7*IF(BJ8=1,1,0)+0.3/(Time!$F$10-1)*IF(AND(BJ8>=2,BJ8<=Time!$F$10),1,0))
D27: Contingency (FC: pro rata with EPC progress payments) | E27: USD m | G27: =SUM(J27:BJ27) | J27: =IF(Inputs!$F$33=1,Inputs!$F$64*Inputs!$F$35*J21/SUM($J$21:$BJ$21),0) | K27: =IF(Inputs!$F$33=1,Inputs!$F$64*Inputs!$F$35*K21/SUM($J$21:$BJ$21),0) | L27: =IF(Inputs!$F$33=1,Inputs!$F$64*Inputs!$F$35*L21/SUM($J$21:$BJ$21),0) | M27: =IF(Inputs!$F$33=1,Inputs!$F$64*Inputs!$F$35*M21/SUM($J$21:$BJ$21),0) | N27: =IF(Inputs!$F$33=1,Inputs!$F$64*Inputs!$F$35*N21/SUM($J$21:$BJ$21),0) | O27: =IF(Inputs!$F$33=1,Inputs!$F$64*Inputs!$F$35*O21/SUM($J$21:$BJ$21),0) | P27: =IF(Inputs!$F$33=1,Inputs!$F$64*Inputs!$F$35*P21/SUM($J$21:$BJ$21),0) | Q27: =IF(Inputs!$F$33=1,Inputs!$F$64*Inputs!$F$35*Q21/SUM($J$21:$BJ$21),0) | ... BJ27: =IF(Inputs!$F$33=1,Inputs!$F$64*Inputs!$F$35*BJ21/SUM($J$21:$BJ$21),0)
D28: Initial working capital | E28: USD m | G28: =SUM(J28:BJ28) | J28: =IF(J8=Time!$F$10,Inputs!$F$65*Inputs!$F$35,0) | K28: =IF(K8=Time!$F$10,Inputs!$F$65*Inputs!$F$35,0) | L28: =IF(L8=Time!$F$10,Inputs!$F$65*Inputs!$F$35,0) | M28: =IF(M8=Time!$F$10,Inputs!$F$65*Inputs!$F$35,0) | N28: =IF(N8=Time!$F$10,Inputs!$F$65*Inputs!$F$35,0) | O28: =IF(O8=Time!$F$10,Inputs!$F$65*Inputs!$F$35,0) | P28: =IF(P8=Time!$F$10,Inputs!$F$65*Inputs!$F$35,0) | Q28: =IF(Q8=Time!$F$10,Inputs!$F$65*Inputs!$F$35,0) | ... BJ28: =IF(BJ8=Time!$F$10,Inputs!$F$65*Inputs!$F$35,0)
D29: Overrun items (actual) | E29: USD m | G29: =SUM(J29:BJ29) | J29: =IF(Inputs!$F$33=2,Inputs!J228,0) | K29: =IF(Inputs!$F$33=2,Inputs!K228,0) | L29: =IF(Inputs!$F$33=2,Inputs!L228,0) | M29: =IF(Inputs!$F$33=2,Inputs!M228,0) | N29: =IF(Inputs!$F$33=2,Inputs!N228,0) | O29: =IF(Inputs!$F$33=2,Inputs!O228,0) | P29: =IF(Inputs!$F$33=2,Inputs!P228,0) | Q29: =IF(Inputs!$F$33=2,Inputs!Q228,0) | ... BJ29: =IF(Inputs!$F$33=2,Inputs!BJ228,0)
D30: Uses before financing costs | E30: USD m | G30: =SUM(J30:BJ30) | J30: =J22+J23+J24+J25+J26+J27+J28+J29 | K30: =K22+K23+K24+K25+K26+K27+K28+K29 | L30: =L22+L23+L24+L25+L26+L27+L28+L29 | M30: =M22+M23+M24+M25+M26+M27+M28+M29 | N30: =N22+N23+N24+N25+N26+N27+N28+N29 | O30: =O22+O23+O24+O25+O26+O27+O28+O29 | P30: =P22+P23+P24+P25+P26+P27+P28+P29 | Q30: =Q22+Q23+Q24+Q25+Q26+Q27+Q28+Q29 | ... BJ30: =BJ22+BJ23+BJ24+BJ25+BJ26+BJ27+BJ28+BJ29
B31: VAT on onshore EPC (KCR m) and UBK VAT facility
D32: Onshore EPC payments | E32: KCR m | G32: =SUM(J32:BJ32) | J32: =J20/100*Inputs!$F$57*Inputs!$F$58*Inputs!$F$35 | K32: =K20/100*Inputs!$F$57*Inputs!$F$58*Inputs!$F$35 | L32: =L20/100*Inputs!$F$57*Inputs!$F$58*Inputs!$F$35 | M32: =M20/100*Inputs!$F$57*Inputs!$F$58*Inputs!$F$35 | N32: =N20/100*Inputs!$F$57*Inputs!$F$58*Inputs!$F$35 | O32: =O20/100*Inputs!$F$57*Inputs!$F$58*Inputs!$F$35 | P32: =P20/100*Inputs!$F$57*Inputs!$F$58*Inputs!$F$35 | Q32: =Q20/100*Inputs!$F$57*Inputs!$F$58*Inputs!$F$35 | ... BJ32: =BJ20/100*Inputs!$F$57*Inputs!$F$58*Inputs!$F$35
D33: VAT paid (drawn on the VAT facility) | E33: KCR m | G33: =SUM(J33:BJ33) | J33: =Inputs!$F$68/100*J32 | K33: =Inputs!$F$68/100*K32 | L33: =Inputs!$F$68/100*L32 | M33: =Inputs!$F$68/100*M32 | N33: =Inputs!$F$68/100*N32 | O33: =Inputs!$F$68/100*O32 | P33: =Inputs!$F$68/100*P32 | Q33: =Inputs!$F$68/100*Q32 | ... BJ33: =Inputs!$F$68/100*BJ32
D34: VAT refunds (9-month lag) repaying the facility | E34: KCR m | G34: =SUM(J34:BJ34) | J34: =0 | K34: =0 | L34: =0 | M34: =0 | N34: =0 | O34: =0 | P34: =0 | Q34: =0 | R34: =0 | S34: =J33 | T34: =K33 | U34: =L33 | V34: =M33 | W34: =N33 | X34: =O33 | Y34: =P33 | Z34: =Q33 | ... BJ34: =BA33
D35: VAT facility balance | E35: KCR m | J35: =0+J33-J34 | K35: =J35+K33-K34 | L35: =K35+L33-L34 | M35: =L35+M33-M34 | N35: =M35+N33-N34 | O35: =N35+O33-O34 | P35: =O35+P33-P34 | Q35: =P35+Q33-Q34 | R35: =Q35+R33-R34 | ... BJ35: =BI35+BJ33-BJ34
D36: VAT facility interest | E36: USD m | G36: =SUM(J36:BJ36) | J36: =0*(J18+Inputs!$F$69)/100*J11/365/J16 | K36: =J35*(K18+Inputs!$F$69)/100*K11/365/K16 | L36: =K35*(L18+Inputs!$F$69)/100*L11/365/L16 | M36: =L35*(M18+Inputs!$F$69)/100*M11/365/M16 | N36: =M35*(N18+Inputs!$F$69)/100*N11/365/N16 | O36: =N35*(O18+Inputs!$F$69)/100*O11/365/O16 | P36: =O35*(P18+Inputs!$F$69)/100*P11/365/P16 | Q36: =P35*(Q18+Inputs!$F$69)/100*Q11/365/Q16 | R36: =Q35*(R18+Inputs!$F$69)/100*R11/365/R16 | ... BJ36: =BI35*(BJ18+Inputs!$F$69)/100*BJ11/365/BJ16

Sheet Operations
A1: Case P: Belanou Combined Cycle Power Project, Republic of Kessara
A2: Operations: macro paths, plant, revenue, operating costs, working capital
A3: Units in column E; constants in column F; row totals in column G; first period in column J. Inputs: blue on yellow. Links from other sheets: green.
D4: Label | E4: Unit | F4: Constant | G4: Total
D5: Period ending | J5: 2018H2 | K5: 2019H1 | L5: 2019H2 | M5: 2020H1 | N5: 2020H2 | O5: 2021H1 | P5: 2021H2 | Q5: 2022H1 | R5: 2022H2 | S5: 2023H1 | T5: 2023H2 | U5: 2024H1 | V5: 2024H2 | W5: 2025H1 | X5: 2025H2 | Y5: 2026H1 | Z5: 2026H2 | AA5: 2027H1 | AB5: 2027H2 | AC5: 2028H1 | AD5: 2028H2 | AE5: 2029H1 | AF5: 2029H2 | AG5: 2030H1 | AH5: 2030H2 | AI5: 2031H1 | AJ5: 2031H2 | AK5: 2032H1 | AL5: 2032H2 | AM5: 2033H1 | AN5: 2033H2 | AO5: 2034H1 | AP5: 2034H2 | AQ5: 2035H1 | AR5: 2035H2 | AS5: 2036H1 | AT5: 2036H2 | AU5: 2037H1 | AV5: 2037H2 | AW5: 2038H1 | AX5: 2038H2 | AY5: 2039H1 | AZ5: 2039H2 | BA5: 2040H1 | BB5: 2040H2 | BC5: 2041H1 | BD5: 2041H2 | BE5: 2042H1 | BF5: 2042H2 | BG5: 2043H1 | BH5: 2043H2 | BI5: 2044H1 | BJ5: 2044H2 | BK5: 2045H1 | BL5: 2045H2 | BM5: 2046H1 | BN5: 2046H2
B7: Macro paths
D8: Base rate before sensitivity shift | E8: % | J8: =CHOOSE(Inputs!$F$32,Inputs!J212,Inputs!J213,Inputs!J214) | K8: =CHOOSE(Inputs!$F$32,Inputs!K212,Inputs!K213,Inputs!K214) | L8: =CHOOSE(Inputs!$F$32,Inputs!L212,Inputs!L213,Inputs!L214) | M8: =CHOOSE(Inputs!$F$32,Inputs!M212,Inputs!M213,Inputs!M214) | N8: =CHOOSE(Inputs!$F$32,Inputs!N212,Inputs!N213,Inputs!N214) | O8: =CHOOSE(Inputs!$F$32,Inputs!O212,Inputs!O213,Inputs!O214) | P8: =CHOOSE(Inputs!$F$32,Inputs!P212,Inputs!P213,Inputs!P214) | Q8: =CHOOSE(Inputs!$F$32,Inputs!Q212,Inputs!Q213,Inputs!Q214) | ... BN8: =CHOOSE(Inputs!$F$32,Inputs!BN212,Inputs!BN213,Inputs!BN214)
D9: Base rate (6M LIBOR / Term SOFR + CAS) | E9: % | J9: =J8+Inputs!$F$41*Time!J34 | K9: =K8+Inputs!$F$41*Time!K34 | L9: =L8+Inputs!$F$41*Time!L34 | M9: =M8+Inputs!$F$41*Time!M34 | N9: =N8+Inputs!$F$41*Time!N34 | O9: =O8+Inputs!$F$41*Time!O34 | P9: =P8+Inputs!$F$41*Time!P34 | Q9: =Q8+Inputs!$F$41*Time!Q34 | ... BN9: =BN8+Inputs!$F$41*Time!BN34
D10: KCR per USD before devaluation sensitivity | E10: KCR/USD | J10: =CHOOSE(Inputs!$F$32,Inputs!$F$58*Time!$F$15^((Time!J17-0.5)/2),Inputs!J215,Inputs!J215) | K10: =CHOOSE(Inputs!$F$32,Inputs!$F$58*Time!$F$15^((Time!K17-0.5)/2),Inputs!K215,Inputs!K215) | L10: =CHOOSE(Inputs!$F$32,Inputs!$F$58*Time!$F$15^((Time!L17-0.5)/2),Inputs!L215,Inputs!L215) | M10: =CHOOSE(Inputs!$F$32,Inputs!$F$58*Time!$F$15^((Time!M17-0.5)/2),Inputs!M215,Inputs!M215) | N10: =CHOOSE(Inputs!$F$32,Inputs!$F$58*Time!$F$15^((Time!N17-0.5)/2),Inputs!N215,Inputs!N215) | O10: =CHOOSE(Inputs!$F$32,Inputs!$F$58*Time!$F$15^((Time!O17-0.5)/2),Inputs!O215,Inputs!O215) | P10: =CHOOSE(Inputs!$F$32,Inputs!$F$58*Time!$F$15^((Time!P17-0.5)/2),Inputs!P215,Inputs!P215) | Q10: =CHOOSE(Inputs!$F$32,Inputs!$F$58*Time!$F$15^((Time!Q17-0.5)/2),Inputs!Q215,P10*Time!$F$15^0.5) | R10: =CHOOSE(Inputs!$F$32,Inputs!$F$58*Time!$F$15^((Time!R17-0.5)/2),Inputs!R215,Q10*Time!$F$15^0.5) | S10: =CHOOSE(Inputs!$F$32,Inputs!$F$58*Time!$F$15^((Time!S17-0.5)/2),Inputs!S215,R10*Time!$F$15^0.5) | T10: =CHOOSE(Inputs!$F$32,Inputs!$F$58*Time!$F$15^((Time!T17-0.5)/2),Inputs!T215,S10*Time!$F$15^0.5) | U10: =CHOOSE(Inputs!$F$32,Inputs!$F$58*Time!$F$15^((Time!U17-0.5)/2),Inputs!U215,T10*Time!$F$15^0.5) | V10: =CHOOSE(Inputs!$F$32,Inputs!$F$58*Time!$F$15^((Time!V17-0.5)/2),Inputs!V215,U10*Time!$F$15^0.5) | W10: =CHOOSE(Inputs!$F$32,Inputs!$F$58*Time!$F$15^((Time!W17-0.5)/2),Inputs!W215,V10*Time!$F$15^0.5) | X10: =CHOOSE(Inputs!$F$32,Inputs!$F$58*Time!$F$15^((Time!X17-0.5)/2),Inputs!X215,W10*Time!$F$15^0.5) | ... Z10: =CHOOSE(Inputs!$F$32,Inputs!$F$58*Time!$F$15^((Time!Z17-0.5)/2),Inputs!Z215,Y10*Time!$F$15^0.5) | AA10: =CHOOSE(Inputs!$F$32,Inputs!$F$58*Time!$F$15^((Time!AA17-0.5)/2),Z10*((1+AA13/100)/(1+AA12/100))^0.5,Z10*Time!$F$15^0.5) | AB10: =CHOOSE(Inputs!$F$32,Inputs!$F$58*Time!$F$15^((Time!AB17-0.5)/2),AA10*((1+AB13/100)/(1+AB12/100))^0.5,AA10*Time!$F$15^0.5) | AC10: =CHOOSE(Inputs!$F$32,Inputs!$F$58*Time!$F$15^((Time!AC17-0.5)/2),AB10*((1+AC13/100)/(1+AC12/100))^0.5,AB10*Time!$F$15^0.5) | AD10: =CHOOSE(Inputs!$F$32,Inputs!$F$58*Time!$F$15^((Time!AD17-0.5)/2),AC10*((1+AD13/100)/(1+AD12/100))^0.5,AC10*Time!$F$15^0.5) | AE10: =CHOOSE(Inputs!$F$32,Inputs!$F$58*Time!$F$15^((Time!AE17-0.5)/2),AD10*((1+AE13/100)/(1+AE12/100))^0.5,AD10*Time!$F$15^0.5) | AF10: =CHOOSE(Inputs!$F$32,Inputs!$F$58*Time!$F$15^((Time!AF17-0.5)/2),AE10*((1+AF13/100)/(1+AF12/100))^0.5,AE10*Time!$F$15^0.5) | AG10: =CHOOSE(Inputs!$F$32,Inputs!$F$58*Time!$F$15^((Time!AG17-0.5)/2),AF10*((1+AG13/100)/(1+AG12/100))^0.5,AF10*Time!$F$15^0.5) | AH10: =CHOOSE(Inputs!$F$32,Inputs!$F$58*Time!$F$15^((Time!AH17-0.5)/2),AG10*((1+AH13/100)/(1+AH12/100))^0.5,AG10*Time!$F$15^0.5) | ... BN10: =CHOOSE(Inputs!$F$32,Inputs!$F$58*Time!$F$15^((Time!BN17-0.5)/2),BM10*((1+BN13/100)/(1+BN12/100))^0.5,BM10*Time!$F$15^0.5)
D11: KCR per USD, period average | E11: KCR/USD | J11: =J10/(1-Inputs!$F$42*Time!J34) | K11: =K10/(1-Inputs!$F$42*Time!K34) | L11: =L10/(1-Inputs!$F$42*Time!L34) | M11: =M10/(1-Inputs!$F$42*Time!M34) | N11: =N10/(1-Inputs!$F$42*Time!N34) | O11: =O10/(1-Inputs!$F$42*Time!O34) | P11: =P10/(1-Inputs!$F$42*Time!P34) | Q11: =Q10/(1-Inputs!$F$42*Time!Q34) | ... BN11: =BN10/(1-Inputs!$F$42*Time!BN34)
D12: US CPI change, current year | E12: % | J12: =CHOOSE(Inputs!$F$32,INDEX(Inputs!$J$204:$AR$204,1,(Time!J21-0)-2014),INDEX(Inputs!$J$206:$AR$206,1,(Time!J21-0)-2014),INDEX(Inputs!$J$208:$AR$208,1,(Time!J21-0)-2014)) | K12: =CHOOSE(Inputs!$F$32,INDEX(Inputs!$J$204:$AR$204,1,(Time!K21-0)-2014),INDEX(Inputs!$J$206:$AR$206,1,(Time!K21-0)-2014),INDEX(Inputs!$J$208:$AR$208,1,(Time!K21-0)-2014)) | L12: =CHOOSE(Inputs!$F$32,INDEX(Inputs!$J$204:$AR$204,1,(Time!L21-0)-2014),INDEX(Inputs!$J$206:$AR$206,1,(Time!L21-0)-2014),INDEX(Inputs!$J$208:$AR$208,1,(Time!L21-0)-2014)) | M12: =CHOOSE(Inputs!$F$32,INDEX(Inputs!$J$204:$AR$204,1,(Time!M21-0)-2014),INDEX(Inputs!$J$206:$AR$206,1,(Time!M21-0)-2014),INDEX(Inputs!$J$208:$AR$208,1,(Time!M21-0)-2014)) | N12: =CHOOSE(Inputs!$F$32,INDEX(Inputs!$J$204:$AR$204,1,(Time!N21-0)-2014),INDEX(Inputs!$J$206:$AR$206,1,(Time!N21-0)-2014),INDEX(Inputs!$J$208:$AR$208,1,(Time!N21-0)-2014)) | O12: =CHOOSE(Inputs!$F$32,INDEX(Inputs!$J$204:$AR$204,1,(Time!O21-0)-2014),INDEX(Inputs!$J$206:$AR$206,1,(Time!O21-0)-2014),INDEX(Inputs!$J$208:$AR$208,1,(Time!O21-0)-2014)) | P12: =CHOOSE(Inputs!$F$32,INDEX(Inputs!$J$204:$AR$204,1,(Time!P21-0)-2014),INDEX(Inputs!$J$206:$AR$206,1,(Time!P21-0)-2014),INDEX(Inputs!$J$208:$AR$208,1,(Time!P21-0)-2014)) | Q12: =CHOOSE(Inputs!$F$32,INDEX(Inputs!$J$204:$AR$204,1,(Time!Q21-0)-2014),INDEX(Inputs!$J$206:$AR$206,1,(Time!Q21-0)-2014),INDEX(Inputs!$J$208:$AR$208,1,(Time!Q21-0)-2014)) | ... BN12: =CHOOSE(Inputs!$F$32,INDEX(Inputs!$J$204:$AR$204,1,(Time!BN21-0)-2014),INDEX(Inputs!$J$206:$AR$206,1,(Time!BN21-0)-2014),INDEX(Inputs!$J$208:$AR$208,1,(Time!BN21-0)-2014))
D13: Kessara CPI change, current year | E13: % | J13: =CHOOSE(Inputs!$F$32,INDEX(Inputs!$J$205:$AR$205,1,(Time!J21-0)-2014),INDEX(Inputs!$J$207:$AR$207,1,(Time!J21-0)-2014),INDEX(Inputs!$J$209:$AR$209,1,(Time!J21-0)-2014)) | K13: =CHOOSE(Inputs!$F$32,INDEX(Inputs!$J$205:$AR$205,1,(Time!K21-0)-2014),INDEX(Inputs!$J$207:$AR$207,1,(Time!K21-0)-2014),INDEX(Inputs!$J$209:$AR$209,1,(Time!K21-0)-2014)) | L13: =CHOOSE(Inputs!$F$32,INDEX(Inputs!$J$205:$AR$205,1,(Time!L21-0)-2014),INDEX(Inputs!$J$207:$AR$207,1,(Time!L21-0)-2014),INDEX(Inputs!$J$209:$AR$209,1,(Time!L21-0)-2014)) | M13: =CHOOSE(Inputs!$F$32,INDEX(Inputs!$J$205:$AR$205,1,(Time!M21-0)-2014),INDEX(Inputs!$J$207:$AR$207,1,(Time!M21-0)-2014),INDEX(Inputs!$J$209:$AR$209,1,(Time!M21-0)-2014)) | N13: =CHOOSE(Inputs!$F$32,INDEX(Inputs!$J$205:$AR$205,1,(Time!N21-0)-2014),INDEX(Inputs!$J$207:$AR$207,1,(Time!N21-0)-2014),INDEX(Inputs!$J$209:$AR$209,1,(Time!N21-0)-2014)) | O13: =CHOOSE(Inputs!$F$32,INDEX(Inputs!$J$205:$AR$205,1,(Time!O21-0)-2014),INDEX(Inputs!$J$207:$AR$207,1,(Time!O21-0)-2014),INDEX(Inputs!$J$209:$AR$209,1,(Time!O21-0)-2014)) | P13: =CHOOSE(Inputs!$F$32,INDEX(Inputs!$J$205:$AR$205,1,(Time!P21-0)-2014),INDEX(Inputs!$J$207:$AR$207,1,(Time!P21-0)-2014),INDEX(Inputs!$J$209:$AR$209,1,(Time!P21-0)-2014)) | Q13: =CHOOSE(Inputs!$F$32,INDEX(Inputs!$J$205:$AR$205,1,(Time!Q21-0)-2014),INDEX(Inputs!$J$207:$AR$207,1,(Time!Q21-0)-2014),INDEX(Inputs!$J$209:$AR$209,1,(Time!Q21-0)-2014)) | ... BN13: =CHOOSE(Inputs!$F$32,INDEX(Inputs!$J$205:$AR$205,1,(Time!BN21-0)-2014),INDEX(Inputs!$J$207:$AR$207,1,(Time!BN21-0)-2014),INDEX(Inputs!$J$209:$AR$209,1,(Time!BN21-0)-2014))
D14: US CPI change, prior year | E14: % | J14: =CHOOSE(Inputs!$F$32,INDEX(Inputs!$J$204:$AR$204,1,(Time!J21-1)-2014),INDEX(Inputs!$J$206:$AR$206,1,(Time!J21-1)-2014),INDEX(Inputs!$J$208:$AR$208,1,(Time!J21-1)-2014)) | K14: =CHOOSE(Inputs!$F$32,INDEX(Inputs!$J$204:$AR$204,1,(Time!K21-1)-2014),INDEX(Inputs!$J$206:$AR$206,1,(Time!K21-1)-2014),INDEX(Inputs!$J$208:$AR$208,1,(Time!K21-1)-2014)) | L14: =CHOOSE(Inputs!$F$32,INDEX(Inputs!$J$204:$AR$204,1,(Time!L21-1)-2014),INDEX(Inputs!$J$206:$AR$206,1,(Time!L21-1)-2014),INDEX(Inputs!$J$208:$AR$208,1,(Time!L21-1)-2014)) | M14: =CHOOSE(Inputs!$F$32,INDEX(Inputs!$J$204:$AR$204,1,(Time!M21-1)-2014),INDEX(Inputs!$J$206:$AR$206,1,(Time!M21-1)-2014),INDEX(Inputs!$J$208:$AR$208,1,(Time!M21-1)-2014)) | N14: =CHOOSE(Inputs!$F$32,INDEX(Inputs!$J$204:$AR$204,1,(Time!N21-1)-2014),INDEX(Inputs!$J$206:$AR$206,1,(Time!N21-1)-2014),INDEX(Inputs!$J$208:$AR$208,1,(Time!N21-1)-2014)) | O14: =CHOOSE(Inputs!$F$32,INDEX(Inputs!$J$204:$AR$204,1,(Time!O21-1)-2014),INDEX(Inputs!$J$206:$AR$206,1,(Time!O21-1)-2014),INDEX(Inputs!$J$208:$AR$208,1,(Time!O21-1)-2014)) | P14: =CHOOSE(Inputs!$F$32,INDEX(Inputs!$J$204:$AR$204,1,(Time!P21-1)-2014),INDEX(Inputs!$J$206:$AR$206,1,(Time!P21-1)-2014),INDEX(Inputs!$J$208:$AR$208,1,(Time!P21-1)-2014)) | Q14: =CHOOSE(Inputs!$F$32,INDEX(Inputs!$J$204:$AR$204,1,(Time!Q21-1)-2014),INDEX(Inputs!$J$206:$AR$206,1,(Time!Q21-1)-2014),INDEX(Inputs!$J$208:$AR$208,1,(Time!Q21-1)-2014)) | ... BN14: =CHOOSE(Inputs!$F$32,INDEX(Inputs!$J$204:$AR$204,1,(Time!BN21-1)-2014),INDEX(Inputs!$J$206:$AR$206,1,(Time!BN21-1)-2014),INDEX(Inputs!$J$208:$AR$208,1,(Time!BN21-1)-2014))
D15: Kessara CPI change, prior year | E15: % | J15: =CHOOSE(Inputs!$F$32,INDEX(Inputs!$J$205:$AR$205,1,(Time!J21-1)-2014),INDEX(Inputs!$J$207:$AR$207,1,(Time!J21-1)-2014),INDEX(Inputs!$J$209:$AR$209,1,(Time!J21-1)-2014)) | K15: =CHOOSE(Inputs!$F$32,INDEX(Inputs!$J$205:$AR$205,1,(Time!K21-1)-2014),INDEX(Inputs!$J$207:$AR$207,1,(Time!K21-1)-2014),INDEX(Inputs!$J$209:$AR$209,1,(Time!K21-1)-2014)) | L15: =CHOOSE(Inputs!$F$32,INDEX(Inputs!$J$205:$AR$205,1,(Time!L21-1)-2014),INDEX(Inputs!$J$207:$AR$207,1,(Time!L21-1)-2014),INDEX(Inputs!$J$209:$AR$209,1,(Time!L21-1)-2014)) | M15: =CHOOSE(Inputs!$F$32,INDEX(Inputs!$J$205:$AR$205,1,(Time!M21-1)-2014),INDEX(Inputs!$J$207:$AR$207,1,(Time!M21-1)-2014),INDEX(Inputs!$J$209:$AR$209,1,(Time!M21-1)-2014)) | N15: =CHOOSE(Inputs!$F$32,INDEX(Inputs!$J$205:$AR$205,1,(Time!N21-1)-2014),INDEX(Inputs!$J$207:$AR$207,1,(Time!N21-1)-2014),INDEX(Inputs!$J$209:$AR$209,1,(Time!N21-1)-2014)) | O15: =CHOOSE(Inputs!$F$32,INDEX(Inputs!$J$205:$AR$205,1,(Time!O21-1)-2014),INDEX(Inputs!$J$207:$AR$207,1,(Time!O21-1)-2014),INDEX(Inputs!$J$209:$AR$209,1,(Time!O21-1)-2014)) | P15: =CHOOSE(Inputs!$F$32,INDEX(Inputs!$J$205:$AR$205,1,(Time!P21-1)-2014),INDEX(Inputs!$J$207:$AR$207,1,(Time!P21-1)-2014),INDEX(Inputs!$J$209:$AR$209,1,(Time!P21-1)-2014)) | Q15: =CHOOSE(Inputs!$F$32,INDEX(Inputs!$J$205:$AR$205,1,(Time!Q21-1)-2014),INDEX(Inputs!$J$207:$AR$207,1,(Time!Q21-1)-2014),INDEX(Inputs!$J$209:$AR$209,1,(Time!Q21-1)-2014)) | ... BN15: =CHOOSE(Inputs!$F$32,INDEX(Inputs!$J$205:$AR$205,1,(Time!BN21-1)-2014),INDEX(Inputs!$J$207:$AR$207,1,(Time!BN21-1)-2014),INDEX(Inputs!$J$209:$AR$209,1,(Time!BN21-1)-2014))
D16: US index, June 2018 (2018 price base) | E16: index | F16: =100*(1+CHOOSE(Inputs!$F$32,INDEX(Inputs!$J$204:$AR$204,1,2016-2014),INDEX(Inputs!$J$206:$AR$206,1,2016-2014),INDEX(Inputs!$J$208:$AR$208,1,2016-2014))/100)^(1/12)*(1+CHOOSE(Inputs!$F$32,INDEX(Inputs!$J$204:$AR$204,1,2017-2014),INDEX(Inputs!$J$206:$AR$206,1,2017-2014),INDEX(Inputs!$J$208:$AR$208,1,2017-2014))/100)*(1+CHOOSE(Inputs!$F$32,INDEX(Inputs!$J$204:$AR$204,1,2018-2014),INDEX(Inputs!$J$206:$AR$206,1,2018-2014),INDEX(Inputs!$J$208:$AR$208,1,2018-2014))/100)^(6/12)
D17: US CPI index, cost reading (Mar/Sep), Nov 2016 = 100 | E17: index | J17: =100*(1+CHOOSE(Inputs!$F$32,INDEX(Inputs!$J$204:$AR$204,1,2016-2014),INDEX(Inputs!$J$206:$AR$206,1,2016-2014),INDEX(Inputs!$J$208:$AR$208,1,2016-2014))/100)^(1/12)*(1+CHOOSE(Inputs!$F$32,INDEX(Inputs!$J$204:$AR$204,1,2017-2014),INDEX(Inputs!$J$206:$AR$206,1,2017-2014),INDEX(Inputs!$J$208:$AR$208,1,2017-2014))/100)*(1+CHOOSE(Inputs!$F$32,INDEX(Inputs!$J$204:$AR$204,1,2018-2014),INDEX(Inputs!$J$206:$AR$206,1,2018-2014),INDEX(Inputs!$J$208:$AR$208,1,2018-2014))/100)^(9/12) | K17: =J17*IF(Time!K22=1,(1+K14/100)^0.25*(1+K12/100)^0.25,(1+K12/100)^0.5) | L17: =K17*IF(Time!L22=1,(1+L14/100)^0.25*(1+L12/100)^0.25,(1+L12/100)^0.5) | M17: =L17*IF(Time!M22=1,(1+M14/100)^0.25*(1+M12/100)^0.25,(1+M12/100)^0.5) | N17: =M17*IF(Time!N22=1,(1+N14/100)^0.25*(1+N12/100)^0.25,(1+N12/100)^0.5) | O17: =N17*IF(Time!O22=1,(1+O14/100)^0.25*(1+O12/100)^0.25,(1+O12/100)^0.5) | P17: =O17*IF(Time!P22=1,(1+P14/100)^0.25*(1+P12/100)^0.25,(1+P12/100)^0.5) | Q17: =P17*IF(Time!Q22=1,(1+Q14/100)^0.25*(1+Q12/100)^0.25,(1+Q12/100)^0.5) | R17: =Q17*IF(Time!R22=1,(1+R14/100)^0.25*(1+R12/100)^0.25,(1+R12/100)^0.5) | ... BN17: =BM17*IF(Time!BN22=1,(1+BN14/100)^0.25*(1+BN12/100)^0.25,(1+BN12/100)^0.5)
D18: US CPI index, tariff reading (3-month lag) | E18: index | J18: =J17*(1+J12/100)^0.25 | K18: =K17*(1+K12/100)^0.25 | L18: =L17*(1+L12/100)^0.25 | M18: =M17*(1+M12/100)^0.25 | N18: =N17*(1+N12/100)^0.25 | O18: =O17*(1+O12/100)^0.25 | P18: =P17*(1+P12/100)^0.25 | Q18: =Q17*(1+Q12/100)^0.25 | ... BN18: =BN17*(1+BN12/100)^0.25
D19: US cost indexation factor vs 2018 prices | E19: factor | J19: =J17/$F$16 | K19: =K17/$F$16 | L19: =L17/$F$16 | M19: =M17/$F$16 | N19: =N17/$F$16 | O19: =O17/$F$16 | P19: =P17/$F$16 | Q19: =Q17/$F$16 | ... BN19: =BN17/$F$16
D20: KC index, June 2018 (2018 price base) | E20: index | F20: =100*(1+CHOOSE(Inputs!$F$32,INDEX(Inputs!$J$205:$AR$205,1,2016-2014),INDEX(Inputs!$J$207:$AR$207,1,2016-2014),INDEX(Inputs!$J$209:$AR$209,1,2016-2014))/100)^(1/12)*(1+CHOOSE(Inputs!$F$32,INDEX(Inputs!$J$205:$AR$205,1,2017-2014),INDEX(Inputs!$J$207:$AR$207,1,2017-2014),INDEX(Inputs!$J$209:$AR$209,1,2017-2014))/100)*(1+CHOOSE(Inputs!$F$32,INDEX(Inputs!$J$205:$AR$205,1,2018-2014),INDEX(Inputs!$J$207:$AR$207,1,2018-2014),INDEX(Inputs!$J$209:$AR$209,1,2018-2014))/100)^(6/12)
D21: Kessara CPI index, cost reading (Mar/Sep), Nov 2016 = 100 | E21: index | J21: =100*(1+CHOOSE(Inputs!$F$32,INDEX(Inputs!$J$205:$AR$205,1,2016-2014),INDEX(Inputs!$J$207:$AR$207,1,2016-2014),INDEX(Inputs!$J$209:$AR$209,1,2016-2014))/100)^(1/12)*(1+CHOOSE(Inputs!$F$32,INDEX(Inputs!$J$205:$AR$205,1,2017-2014),INDEX(Inputs!$J$207:$AR$207,1,2017-2014),INDEX(Inputs!$J$209:$AR$209,1,2017-2014))/100)*(1+CHOOSE(Inputs!$F$32,INDEX(Inputs!$J$205:$AR$205,1,2018-2014),INDEX(Inputs!$J$207:$AR$207,1,2018-2014),INDEX(Inputs!$J$209:$AR$209,1,2018-2014))/100)^(9/12) | K21: =J21*IF(Time!K22=1,(1+K15/100)^0.25*(1+K13/100)^0.25,(1+K13/100)^0.5) | L21: =K21*IF(Time!L22=1,(1+L15/100)^0.25*(1+L13/100)^0.25,(1+L13/100)^0.5) | M21: =L21*IF(Time!M22=1,(1+M15/100)^0.25*(1+M13/100)^0.25,(1+M13/100)^0.5) | N21: =M21*IF(Time!N22=1,(1+N15/100)^0.25*(1+N13/100)^0.25,(1+N13/100)^0.5) | O21: =N21*IF(Time!O22=1,(1+O15/100)^0.25*(1+O13/100)^0.25,(1+O13/100)^0.5) | P21: =O21*IF(Time!P22=1,(1+P15/100)^0.25*(1+P13/100)^0.25,(1+P13/100)^0.5) | Q21: =P21*IF(Time!Q22=1,(1+Q15/100)^0.25*(1+Q13/100)^0.25,(1+Q13/100)^0.5) | R21: =Q21*IF(Time!R22=1,(1+R15/100)^0.25*(1+R13/100)^0.25,(1+R13/100)^0.5) | ... BN21: =BM21*IF(Time!BN22=1,(1+BN15/100)^0.25*(1+BN13/100)^0.25,(1+BN13/100)^0.5)
D22: Kessara CPI index, tariff reading (3-month lag) | E22: index | J22: =J21*(1+J13/100)^0.25 | K22: =K21*(1+K13/100)^0.25 | L22: =L21*(1+L13/100)^0.25 | M22: =M21*(1+M13/100)^0.25 | N22: =N21*(1+N13/100)^0.25 | O22: =O21*(1+O13/100)^0.25 | P22: =P21*(1+P13/100)^0.25 | Q22: =Q21*(1+Q13/100)^0.25 | ... BN22: =BN21*(1+BN13/100)^0.25
D23: Kessara cost indexation factor vs 2018 prices | E23: factor | J23: =J21/$F$20 | K23: =K21/$F$20 | L23: =L21/$F$20 | M23: =M21/$F$20 | N23: =N21/$F$20 | O23: =O21/$F$20 | P23: =P21/$F$20 | Q23: =Q21/$F$20 | ... BN23: =BN21/$F$20
B24: Plant
D25: Operating year at period start | E25: OY | J25: =INT(Time!J27/12)+1 | K25: =INT(Time!K27/12)+1 | L25: =INT(Time!L27/12)+1 | M25: =INT(Time!M27/12)+1 | N25: =INT(Time!N27/12)+1 | O25: =INT(Time!O27/12)+1 | P25: =INT(Time!P27/12)+1 | Q25: =INT(Time!Q27/12)+1 | ... BN25: =INT(Time!BN27/12)+1
D26: Months in that operating year | E26: months | J26: =MIN(Time!J28,J25*12)-Time!J27 | K26: =MIN(Time!K28,K25*12)-Time!K27 | L26: =MIN(Time!L28,L25*12)-Time!L27 | M26: =MIN(Time!M28,M25*12)-Time!M27 | N26: =MIN(Time!N28,N25*12)-Time!N27 | O26: =MIN(Time!O28,O25*12)-Time!O27 | P26: =MIN(Time!P28,P25*12)-Time!P27 | Q26: =MIN(Time!Q28,Q25*12)-Time!Q27 | ... BN26: =MIN(Time!BN28,BN25*12)-Time!BN27
D27: Availability, profile (month-weighted) | E27: % | J27: =IF(Time!J25>0,(J26*INDEX(Inputs!$J$223:$Q$223,1,MOD(J25-1,8)+1)+(Time!J25-J26)*INDEX(Inputs!$J$223:$Q$223,1,MOD(J25,8)+1))/Time!J25,0) | K27: =IF(Time!K25>0,(K26*INDEX(Inputs!$J$223:$Q$223,1,MOD(K25-1,8)+1)+(Time!K25-K26)*INDEX(Inputs!$J$223:$Q$223,1,MOD(K25,8)+1))/Time!K25,0) | L27: =IF(Time!L25>0,(L26*INDEX(Inputs!$J$223:$Q$223,1,MOD(L25-1,8)+1)+(Time!L25-L26)*INDEX(Inputs!$J$223:$Q$223,1,MOD(L25,8)+1))/Time!L25,0) | M27: =IF(Time!M25>0,(M26*INDEX(Inputs!$J$223:$Q$223,1,MOD(M25-1,8)+1)+(Time!M25-M26)*INDEX(Inputs!$J$223:$Q$223,1,MOD(M25,8)+1))/Time!M25,0) | N27: =IF(Time!N25>0,(N26*INDEX(Inputs!$J$223:$Q$223,1,MOD(N25-1,8)+1)+(Time!N25-N26)*INDEX(Inputs!$J$223:$Q$223,1,MOD(N25,8)+1))/Time!N25,0) | O27: =IF(Time!O25>0,(O26*INDEX(Inputs!$J$223:$Q$223,1,MOD(O25-1,8)+1)+(Time!O25-O26)*INDEX(Inputs!$J$223:$Q$223,1,MOD(O25,8)+1))/Time!O25,0) | P27: =IF(Time!P25>0,(P26*INDEX(Inputs!$J$223:$Q$223,1,MOD(P25-1,8)+1)+(Time!P25-P26)*INDEX(Inputs!$J$223:$Q$223,1,MOD(P25,8)+1))/Time!P25,0) | Q27: =IF(Time!Q25>0,(Q26*INDEX(Inputs!$J$223:$Q$223,1,MOD(Q25-1,8)+1)+(Time!Q25-Q26)*INDEX(Inputs!$J$223:$Q$223,1,MOD(Q25,8)+1))/Time!Q25,0) | ... BN27: =IF(Time!BN25>0,(BN26*INDEX(Inputs!$J$223:$Q$223,1,MOD(BN25-1,8)+1)+(Time!BN25-BN26)*INDEX(Inputs!$J$223:$Q$223,1,MOD(BN25,8)+1))/Time!BN25,0)
D28: Availability | E28: % | J28: =IF(Time!J25>0,J27+Inputs!$F$36,0) | K28: =IF(Time!K25>0,K27+Inputs!$F$36,0) | L28: =IF(Time!L25>0,L27+Inputs!$F$36,0) | M28: =IF(Time!M25>0,M27+Inputs!$F$36,0) | N28: =IF(Time!N25>0,N27+Inputs!$F$36,0) | O28: =IF(Time!O25>0,O27+Inputs!$F$36,0) | P28: =IF(Time!P25>0,P27+Inputs!$F$36,0) | Q28: =IF(Time!Q25>0,Q27+Inputs!$F$36,0) | ... BN28: =IF(Time!BN25>0,BN27+Inputs!$F$36,0)
D29: Years since COD (period mid-point) | E29: years | J29: =IF(Time!J25>0,(Time!J27+Time!J28)/24,0) | K29: =IF(Time!K25>0,(Time!K27+Time!K28)/24,0) | L29: =IF(Time!L25>0,(Time!L27+Time!L28)/24,0) | M29: =IF(Time!M25>0,(Time!M27+Time!M28)/24,0) | N29: =IF(Time!N25>0,(Time!N27+Time!N28)/24,0) | O29: =IF(Time!O25>0,(Time!O27+Time!O28)/24,0) | P29: =IF(Time!P25>0,(Time!P27+Time!P28)/24,0) | Q29: =IF(Time!Q25>0,(Time!Q27+Time!Q28)/24,0) | ... BN29: =IF(Time!BN25>0,(Time!BN27+Time!BN28)/24,0)
D30: Contracted capacity | E30: MW | F30: =IF(Inputs!$F$33=2,Inputs!$F$115,Inputs!$F$114)
D31: Plant net heat rate, new and clean | E31: kJ/kWh | F31: =IF(Inputs!$F$33=2,Inputs!$F$117,Inputs!$F$116)
D32: Output degradation factor | E32: factor | J32: =(1-Inputs!$F$123/100*J29)*(1-Inputs!$F$124/100) | K32: =(1-Inputs!$F$123/100*K29)*(1-Inputs!$F$124/100) | L32: =(1-Inputs!$F$123/100*L29)*(1-Inputs!$F$124/100) | M32: =(1-Inputs!$F$123/100*M29)*(1-Inputs!$F$124/100) | N32: =(1-Inputs!$F$123/100*N29)*(1-Inputs!$F$124/100) | O32: =(1-Inputs!$F$123/100*O29)*(1-Inputs!$F$124/100) | P32: =(1-Inputs!$F$123/100*P29)*(1-Inputs!$F$124/100) | Q32: =(1-Inputs!$F$123/100*Q29)*(1-Inputs!$F$124/100) | ... BN32: =(1-Inputs!$F$123/100*BN29)*(1-Inputs!$F$124/100)
D33: Net energy delivered | E33: MWh | J33: =$F$30*730*Time!J25*J28/100*Inputs!$F$37/100*J32 | K33: =$F$30*730*Time!K25*K28/100*Inputs!$F$37/100*K32 | L33: =$F$30*730*Time!L25*L28/100*Inputs!$F$37/100*L32 | M33: =$F$30*730*Time!M25*M28/100*Inputs!$F$37/100*M32 | N33: =$F$30*730*Time!N25*N28/100*Inputs!$F$37/100*N32 | O33: =$F$30*730*Time!O25*O28/100*Inputs!$F$37/100*O32 | P33: =$F$30*730*Time!P25*P28/100*Inputs!$F$37/100*P32 | Q33: =$F$30*730*Time!Q25*Q28/100*Inputs!$F$37/100*Q32 | ... BN33: =$F$30*730*Time!BN25*BN28/100*Inputs!$F$37/100*BN32
D34: Plant net heat rate | E34: kJ/kWh | J34: =$F$31*(1+Inputs!$F$125/100*J29)*(1+Inputs!$F$126/100)*(1+Inputs!$F$120/100)*Inputs!$F$38 | K34: =$F$31*(1+Inputs!$F$125/100*K29)*(1+Inputs!$F$126/100)*(1+Inputs!$F$120/100)*Inputs!$F$38 | L34: =$F$31*(1+Inputs!$F$125/100*L29)*(1+Inputs!$F$126/100)*(1+Inputs!$F$120/100)*Inputs!$F$38 | M34: =$F$31*(1+Inputs!$F$125/100*M29)*(1+Inputs!$F$126/100)*(1+Inputs!$F$120/100)*Inputs!$F$38 | N34: =$F$31*(1+Inputs!$F$125/100*N29)*(1+Inputs!$F$126/100)*(1+Inputs!$F$120/100)*Inputs!$F$38 | O34: =$F$31*(1+Inputs!$F$125/100*O29)*(1+Inputs!$F$126/100)*(1+Inputs!$F$120/100)*Inputs!$F$38 | P34: =$F$31*(1+Inputs!$F$125/100*P29)*(1+Inputs!$F$126/100)*(1+Inputs!$F$120/100)*Inputs!$F$38 | Q34: =$F$31*(1+Inputs!$F$125/100*Q29)*(1+Inputs!$F$126/100)*(1+Inputs!$F$120/100)*Inputs!$F$38 | ... BN34: =$F$31*(1+Inputs!$F$125/100*BN29)*(1+Inputs!$F$126/100)*(1+Inputs!$F$120/100)*Inputs!$F$38
D35: Contracted heat rate at dispatched load | E35: kJ/kWh | J35: =Inputs!$F$118*(1+Inputs!$F$119/100*J29)*(1+Inputs!$F$120/100) | K35: =Inputs!$F$118*(1+Inputs!$F$119/100*K29)*(1+Inputs!$F$120/100) | L35: =Inputs!$F$118*(1+Inputs!$F$119/100*L29)*(1+Inputs!$F$120/100) | M35: =Inputs!$F$118*(1+Inputs!$F$119/100*M29)*(1+Inputs!$F$120/100) | N35: =Inputs!$F$118*(1+Inputs!$F$119/100*N29)*(1+Inputs!$F$120/100) | O35: =Inputs!$F$118*(1+Inputs!$F$119/100*O29)*(1+Inputs!$F$120/100) | P35: =Inputs!$F$118*(1+Inputs!$F$119/100*P29)*(1+Inputs!$F$120/100) | Q35: =Inputs!$F$118*(1+Inputs!$F$119/100*Q29)*(1+Inputs!$F$120/100) | ... BN35: =Inputs!$F$118*(1+Inputs!$F$119/100*BN29)*(1+Inputs!$F$120/100)
D36: Gas price (GCV) | E36: USD/MMBtu | J36: =Inputs!$F$139*(1+Inputs!$F$140/100)^(Time!J21-2018)*Inputs!$F$40 | K36: =Inputs!$F$139*(1+Inputs!$F$140/100)^(Time!K21-2018)*Inputs!$F$40 | L36: =Inputs!$F$139*(1+Inputs!$F$140/100)^(Time!L21-2018)*Inputs!$F$40 | M36: =Inputs!$F$139*(1+Inputs!$F$140/100)^(Time!M21-2018)*Inputs!$F$40 | N36: =Inputs!$F$139*(1+Inputs!$F$140/100)^(Time!N21-2018)*Inputs!$F$40 | O36: =Inputs!$F$139*(1+Inputs!$F$140/100)^(Time!O21-2018)*Inputs!$F$40 | P36: =Inputs!$F$139*(1+Inputs!$F$140/100)^(Time!P21-2018)*Inputs!$F$40 | Q36: =Inputs!$F$139*(1+Inputs!$F$140/100)^(Time!Q21-2018)*Inputs!$F$40 | ... BN36: =Inputs!$F$139*(1+Inputs!$F$140/100)^(Time!BN21-2018)*Inputs!$F$40
D37: Gas burned | E37: MMBtu | J37: =J33*J34*(1000*Inputs!$F$121/Inputs!$F$122) | K37: =K33*K34*(1000*Inputs!$F$121/Inputs!$F$122) | L37: =L33*L34*(1000*Inputs!$F$121/Inputs!$F$122) | M37: =M33*M34*(1000*Inputs!$F$121/Inputs!$F$122) | N37: =N33*N34*(1000*Inputs!$F$121/Inputs!$F$122) | O37: =O33*O34*(1000*Inputs!$F$121/Inputs!$F$122) | P37: =P33*P34*(1000*Inputs!$F$121/Inputs!$F$122) | Q37: =Q33*Q34*(1000*Inputs!$F$121/Inputs!$F$122) | ... BN37: =BN33*BN34*(1000*Inputs!$F$121/Inputs!$F$122)
D38: Take-or-pay quantity | E38: MMBtu | J38: =Inputs!$F$142*Inputs!$F$141*Time!J26 | K38: =Inputs!$F$142*Inputs!$F$141*Time!K26 | L38: =Inputs!$F$142*Inputs!$F$141*Time!L26 | M38: =Inputs!$F$142*Inputs!$F$141*Time!M26 | N38: =Inputs!$F$142*Inputs!$F$141*Time!N26 | O38: =Inputs!$F$142*Inputs!$F$141*Time!O26 | P38: =Inputs!$F$142*Inputs!$F$141*Time!P26 | Q38: =Inputs!$F$142*Inputs!$F$141*Time!Q26 | ... BN38: =Inputs!$F$142*Inputs!$F$141*Time!BN26
B39: Revenue (USD m)
D40: Capital charge, indexed | E40: USD/kW-month | J40: =Inputs!$F$131*Inputs!$F$53*(1-Inputs!$F$132+Inputs!$F$132*J18/100) | K40: =Inputs!$F$131*Inputs!$F$53*(1-Inputs!$F$132+Inputs!$F$132*K18/100) | L40: =Inputs!$F$131*Inputs!$F$53*(1-Inputs!$F$132+Inputs!$F$132*L18/100) | M40: =Inputs!$F$131*Inputs!$F$53*(1-Inputs!$F$132+Inputs!$F$132*M18/100) | N40: =Inputs!$F$131*Inputs!$F$53*(1-Inputs!$F$132+Inputs!$F$132*N18/100) | O40: =Inputs!$F$131*Inputs!$F$53*(1-Inputs!$F$132+Inputs!$F$132*O18/100) | P40: =Inputs!$F$131*Inputs!$F$53*(1-Inputs!$F$132+Inputs!$F$132*P18/100) | Q40: =Inputs!$F$131*Inputs!$F$53*(1-Inputs!$F$132+Inputs!$F$132*Q18/100) | ... BN40: =Inputs!$F$131*Inputs!$F$53*(1-Inputs!$F$132+Inputs!$F$132*BN18/100)
D41: Fixed O&M charge, indexed | E41: USD/kW-month | J41: =Inputs!$F$133*(Inputs!$F$134*J18/100+(1-Inputs!$F$134)*J22/100*Inputs!$F$135/J11) | K41: =Inputs!$F$133*(Inputs!$F$134*K18/100+(1-Inputs!$F$134)*K22/100*Inputs!$F$135/K11) | L41: =Inputs!$F$133*(Inputs!$F$134*L18/100+(1-Inputs!$F$134)*L22/100*Inputs!$F$135/L11) | M41: =Inputs!$F$133*(Inputs!$F$134*M18/100+(1-Inputs!$F$134)*M22/100*Inputs!$F$135/M11) | N41: =Inputs!$F$133*(Inputs!$F$134*N18/100+(1-Inputs!$F$134)*N22/100*Inputs!$F$135/N11) | O41: =Inputs!$F$133*(Inputs!$F$134*O18/100+(1-Inputs!$F$134)*O22/100*Inputs!$F$135/O11) | P41: =Inputs!$F$133*(Inputs!$F$134*P18/100+(1-Inputs!$F$134)*P22/100*Inputs!$F$135/P11) | Q41: =Inputs!$F$133*(Inputs!$F$134*Q18/100+(1-Inputs!$F$134)*Q22/100*Inputs!$F$135/Q11) | ... BN41: =Inputs!$F$133*(Inputs!$F$134*BN18/100+(1-Inputs!$F$134)*BN22/100*Inputs!$F$135/BN11)
...

Sheet Tax
A1: Case P: Belanou Combined Cycle Power Project, Republic of Kessara
A2: Tax: holiday, deferred depreciation, thin capitalization, minimum turnover tax
A3: Units in column E; constants in column F; row totals in column G; first period in column J. Inputs: blue on yellow. Links from other sheets: green.
D4: Label | E4: Unit | F4: Constant | G4: Total
D5: Period ending | J5: 2018H2 | K5: 2019H1 | L5: 2019H2 | M5: 2020H1 | N5: 2020H2 | O5: 2021H1 | P5: 2021H2 | Q5: 2022H1 | R5: 2022H2 | S5: 2023H1 | T5: 2023H2 | U5: 2024H1 | V5: 2024H2 | W5: 2025H1 | X5: 2025H2 | Y5: 2026H1 | Z5: 2026H2 | AA5: 2027H1 | AB5: 2027H2 | AC5: 2028H1 | AD5: 2028H2 | AE5: 2029H1 | AF5: 2029H2 | AG5: 2030H1 | AH5: 2030H2 | AI5: 2031H1 | AJ5: 2031H2 | AK5: 2032H1 | AL5: 2032H2 | AM5: 2033H1 | AN5: 2033H2 | AO5: 2034H1 | AP5: 2034H2 | AQ5: 2035H1 | AR5: 2035H2 | AS5: 2036H1 | AT5: 2036H2 | AU5: 2037H1 | AV5: 2037H2 | AW5: 2038H1 | AX5: 2038H2 | AY5: 2039H1 | AZ5: 2039H2 | BA5: 2040H1 | BB5: 2040H2 | BC5: 2041H1 | BD5: 2041H2 | BE5: 2042H1 | BF5: 2042H2 | BG5: 2043H1 | BH5: 2043H2 | BI5: 2044H1 | BJ5: 2044H2 | BK5: 2045H1 | BL5: 2045H2 | BM5: 2046H1 | BN5: 2046H2
D7: Holiday months (OY1-OY5) | E7: months | J7: =MAX(0,MIN(Time!J28,96)-MIN(Time!J27,96)) | K7: =MAX(0,MIN(Time!K28,96)-MIN(Time!K27,96)) | L7: =MAX(0,MIN(Time!L28,96)-MIN(Time!L27,96)) | M7: =MAX(0,MIN(Time!M28,96)-MIN(Time!M27,96)) | N7: =MAX(0,MIN(Time!N28,96)-MIN(Time!N27,96)) | O7: =MAX(0,MIN(Time!O28,96)-MIN(Time!O27,96)) | P7: =MAX(0,MIN(Time!P28,96)-MIN(Time!P27,96)) | Q7: =MAX(0,MIN(Time!Q28,96)-MIN(Time!Q27,96)) | ... BN7: =MAX(0,MIN(Time!BN28,96)-MIN(Time!BN27,96))
D8: Reduced-rate months (OY6-OY8) | E8: months | J8: =MAX(0,MIN(Time!J28,96)-MIN(MAX(Time!J27,96),96)) | K8: =MAX(0,MIN(Time!K28,96)-MIN(MAX(Time!K27,96),96)) | L8: =MAX(0,MIN(Time!L28,96)-MIN(MAX(Time!L27,96),96)) | M8: =MAX(0,MIN(Time!M28,96)-MIN(MAX(Time!M27,96),96)) | N8: =MAX(0,MIN(Time!N28,96)-MIN(MAX(Time!N27,96),96)) | O8: =MAX(0,MIN(Time!O28,96)-MIN(MAX(Time!O27,96),96)) | P8: =MAX(0,MIN(Time!P28,96)-MIN(MAX(Time!P27,96),96)) | Q8: =MAX(0,MIN(Time!Q28,96)-MIN(MAX(Time!Q27,96),96)) | ... BN8: =MAX(0,MIN(Time!BN28,96)-MIN(MAX(Time!BN27,96),96))
