Workbook

Sheet Cover
D1: Case T: Merrick Link toll road PPP | Cover
D3: Case T reference model: the Merrick Link toll road PPP, State of Brannock, Commonwealth of Ardmore.
D4: Model version 1.0; story as of October 3, 2026. Currency: Ardmore dollar (ARD), millions, nominal.
D5: Python mirror: model/case_t.py (source of truth); verification: model/case_t_verification.md.
D7: How to use: choose the scenario in Inputs!F (named range Scenario):
D8: 1 = Bid base (Pellow traffic), locked financing
D9: 2 = Banking case (Ridgeway traffic), live debt sizing
D10: 3 = Downside traffic, locked financing
D11: 4 = Actual history to 2026H1, then Ridgeway 2023 case; restructuring at 2023-12-31
D12: 5 = Restructuring case: actual history to 2023H2, Ridgeway 2023 case from 2024 (live notes sculpting)
D13: 6 = Retender valuation at 2022-06-30 (actual to 2022H1, retender traffic case after)
D14: 7 = Sensitivity: traffic -10%
... D39: subtracted; tables show negatives in parentheses.

Sheet Inputs
D1: Case T: Merrick Link toll road PPP | Inputs
D2: Units: ARD millions unless stated. Inputs blue on yellow; links green; calculations black.
D3: Period end | E3: date | J3: =Time!J8 -> 42185 | K3: =Time!K8 -> 42277 | L3: =Time!L8 -> 42369 | M3: =Time!M8 -> 42460 | N3: =Time!N8 -> 42551 | O3: =Time!O8 -> 42643 | P3: =Time!P8 -> 42735 | Q3: =Time!Q8 -> 42825 | ... DB3: =Time!DB8 -> 58256
D5: Switches
D6: Scenario (1-13, see Cover) | E6: # | F6: 4
D7: Contribution option (1 = bid, 2 = solved for 11.4% on banking) | E7: # | F7: 1
D8: Circuit breaker (1 = live circular links, 0 = cut) | E8: flag | F8: 1
D9: Test tolerance | E9: ARD m | F9: 1e-06
D10: Large number for MIN helper rows | E10: # | F10: 1000000000000
D12: Dates
D13: Financial close | E13: date | F13: 42151
D14: End of first model period | E14: date | F14: 42185
D15: Scheduled completion and end of construction funding | E15: date | F15: 43555
D16: Scheduled opening | E16: date | F16: 43555
D17: Actual opening | E17: date | F17: 43591
D18: Concession expiry (original) | E18: date | F18: 56030
D19: Concession expiry (extended 2023) | E19: date | F19: 58221
D20: Restructuring (model date) | E20: date | F20: 45291
D21: Senior first repayment | E21: date | F21: 44377
D22: Senior final repayment | E22: date | F22: 54423
D23: Bank margin step-up date | E23: date | F23: 43978
D24: Bank mini-perm maturity (refinancing or A&E date) | E24: date | F24: 44708
... D42: PSC: contribution payment date | E42: date | F42: 43555
D44: Conventions
D45: Days per year (ACT/365) | E45: days | F45: 365
D46: Days per year (30/360) | E46: days | F46: 360
D47: Average days per month (period length in months) | E47: days | F47: 30.4
D48: Defects period | E48: months | F48: 24
D49: Handback funding window | E49: months | F49: 60
D50: Bridge draws: last construction months | E50: months | F50: 18
D51: Toll escalation month (July 1) | E51: # | F51: 7
D52: Toll rounding (decimal places) | E52: # | F52: 4
D53: Last year of the 3% escalation floor (July 1) | E53: year | F53: 2029
D54: CPI-only escalation from (restructured) | E54: year | F54: 2024
D55: Traffic growth band 1 ends | E55: year | F55: 2030
D56: Traffic growth band 2 ends | E56: year | F56: 2040
... D65: ARD per ARD million | E65: # | F65: 1000000
D67: Construction costs
D68: D&C contract price (lump sum) | E68: ARD m | F68: 1684.3
D69: Retention released at completion | E69: % | F69: 0.025
...

Sheet Time
D1: Case T: Merrick Link toll road PPP | Time
D2: Units: ARD millions unless stated. Inputs blue on yellow; links green; calculations black.
D3: Period end | E3: date | J3: =J8 -> 42185 | K3: =K8 -> 42277 | L3: =L8 -> 42369 | M3: =M8 -> 42460 | N3: =N8 -> 42551 | O3: =O8 -> 42643 | P3: =P8 -> 42735 | Q3: =Q8 -> 42825 | ... DB3: =DB8 -> 58256
D5: Timeline
D6: Period number | E6: # | J6: =I6+1 -> 1 | K6: =J6+1 -> 2 | L6: =K6+1 -> 3 | M6: =L6+1 -> 4 | N6: =M6+1 -> 5 | O6: =N6+1 -> 6 | P6: =O6+1 -> 7 | Q6: =P6+1 -> 8 | ... DB6: =DA6+1 -> 97
D7: Period start | E7: date | J7: =IF(J6=1,Inputs!$F$13,I8) -> 42151 | K7: =IF(K6=1,Inputs!$F$13,J8) -> 42185 | L7: =IF(L6=1,Inputs!$F$13,K8) -> 42277 | M7: =IF(M6=1,Inputs!$F$13,L8) -> 42369 | N7: =IF(N6=1,Inputs!$F$13,M8) -> 42460 | O7: =IF(O6=1,Inputs!$F$13,N8) -> 42551 | P7: =IF(P6=1,Inputs!$F$13,O8) -> 42643 | Q7: =IF(Q6=1,Inputs!$F$13,P8) -> 42735 | ... DB7: =IF(DB6=1,Inputs!$F$13,DA8) -> 58075
D8: Period end | E8: date | J8: =IF(J6=1,Inputs!$F$14,EOMONTH(I8,IF(I8<=Inputs!$F$15,3,6))) -> 42185 | K8: =IF(K6=1,Inputs!$F$14,EOMONTH(J8,IF(J8<=Inputs!$F$15,3,6))) -> 42277 | L8: =IF(L6=1,Inputs!$F$14,EOMONTH(K8,IF(K8<=Inputs!$F$15,3,6))) -> 42369 | M8: =IF(M6=1,Inputs!$F$14,EOMONTH(L8,IF(L8<=Inputs!$F$15,3,6))) -> 42460 | N8: =IF(N6=1,Inputs!$F$14,EOMONTH(M8,IF(M8<=Inputs!$F$15,3,6))) -> 42551 | O8: =IF(O6=1,Inputs!$F$14,EOMONTH(N8,IF(N8<=Inputs!$F$15,3,6))) -> 42643 | P8: =IF(P6=1,Inputs!$F$14,EOMONTH(O8,IF(O8<=Inputs!$F$15,3,6))) -> 42735 | Q8: =IF(Q6=1,Inputs!$F$14,EOMONTH(P8,IF(P8<=Inputs!$F$15,3,6))) -> 42825 | ... DB8: =IF(DB6=1,Inputs!$F$14,EOMONTH(DA8,IF(DA8<=Inputs!$F$15,3,6))) -> 58256
D9: Days in period | E9: days | J9: =J8-J7 -> 34 | K9: =K8-K7 -> 92 | L9: =L8-L7 -> 92 | M9: =M8-M7 -> 91 | N9: =N8-N7 -> 91 | O9: =O8-O7 -> 92 | P9: =P8-P7 -> 92 | Q9: =Q8-Q7 -> 90 | ... DB9: =DB8-DB7 -> 181
D10: Days in period (30/360) | E10: days | J10: =Inputs!$F$46*(YEAR(J8)-YEAR(J7))+30*(MONTH(J8)-MONTH(J7))+MIN(DAY(J8),30)-MIN(DAY(J7),30) -> 33 | K10: =Inputs!$F$46*(YEAR(K8)-YEAR(K7))+30*(MONTH(K8)-MONTH(K7))+MIN(DAY(K8),30)-MIN(DAY(K7),30) -> 90 | L10: =Inputs!$F$46*(YEAR(L8)-YEAR(L7))+30*(MONTH(L8)-MONTH(L7))+MIN(DAY(L8),30)-MIN(DAY(L7),30) -> 90 | M10: =Inputs!$F$46*(YEAR(M8)-YEAR(M7))+30*(MONTH(M8)-MONTH(M7))+MIN(DAY(M8),30)-MIN(DAY(M7),30) -> 90 | N10: =Inputs!$F$46*(YEAR(N8)-YEAR(N7))+30*(MONTH(N8)-MONTH(N7))+MIN(DAY(N8),30)-MIN(DAY(N7),30) -> 90 | O10: =Inputs!$F$46*(YEAR(O8)-YEAR(O7))+30*(MONTH(O8)-MONTH(O7))+MIN(DAY(O8),30)-MIN(DAY(O7),30) -> 90 | P10: =Inputs!$F$46*(YEAR(P8)-YEAR(P7))+30*(MONTH(P8)-MONTH(P7))+MIN(DAY(P8),30)-MIN(DAY(P7),30) -> 90 | Q10: =Inputs!$F$46*(YEAR(Q8)-YEAR(Q7))+30*(MONTH(Q8)-MONTH(Q7))+MIN(DAY(Q8),30)-MIN(DAY(Q7),30) -> 90 | ... DB10: =Inputs!$F$46*(YEAR(DB8)-YEAR(DB7))+30*(MONTH(DB8)-MONTH(DB7))+MIN(DAY(DB8),30)-MIN(DAY(DB7),30) -> 180
D11: Calendar year | E11: year | J11: =YEAR(J8) -> 2015 | K11: =YEAR(K8) -> 2015 | L11: =YEAR(L8) -> 2015 | M11: =YEAR(M8) -> 2016 | N11: =YEAR(N8) -> 2016 | O11: =YEAR(O8) -> 2016 | P11: =YEAR(P8) -> 2016 | Q11: =YEAR(Q8) -> 2017 | ... DB11: =YEAR(DB8) -> 2059
D12: Half (1 = Jan-Jun, 2 = Jul-Dec) | E12: # | J12: =IF(MONTH(J8)<=6,1,2) -> 1 | K12: =IF(MONTH(K8)<=6,1,2) -> 2 | L12: =IF(MONTH(L8)<=6,1,2) -> 2 | M12: =IF(MONTH(M8)<=6,1,2) -> 1 | N12: =IF(MONTH(N8)<=6,1,2) -> 1 | O12: =IF(MONTH(O8)<=6,1,2) -> 2 | P12: =IF(MONTH(P8)<=6,1,2) -> 2 | Q12: =IF(MONTH(Q8)<=6,1,2) -> 1 | ... DB12: =IF(MONTH(DB8)<=6,1,2) -> 1
D13: Half-year code | E13: code | J13: =J11*Inputs!$F$63+J12 -> 20151 | K13: =K11*Inputs!$F$63+K12 -> 20152 | L13: =L11*Inputs!$F$63+L12 -> 20152 | M13: =M11*Inputs!$F$63+M12 -> 20161 | N13: =N11*Inputs!$F$63+N12 -> 20161 | O13: =O11*Inputs!$F$63+O12 -> 20162 | P13: =P11*Inputs!$F$63+P12 -> 20162 | Q13: =Q11*Inputs!$F$63+Q12 -> 20171 | ... DB13: =DB11*Inputs!$F$63+DB12 -> 20591
D14: Months in period | E14: # | J14: =ROUND(J9/Inputs!$F$47,0) -> 1 | K14: =ROUND(K9/Inputs!$F$47,0) -> 3 | L14: =ROUND(L9/Inputs!$F$47,0) -> 3 | M14: =ROUND(M9/Inputs!$F$47,0) -> 3 | N14: =ROUND(N9/Inputs!$F$47,0) -> 3 | O14: =ROUND(O9/Inputs!$F$47,0) -> 3 | P14: =ROUND(P9/Inputs!$F$47,0) -> 3 | Q14: =ROUND(Q9/Inputs!$F$47,0) -> 3 | ... DB14: =ROUND(DB9/Inputs!$F$47,0) -> 6
D15: Key dates for the selected scenario
D16: Opening date | E16: date | F16: =IF(Inputs!$F$213=1,Inputs!$F$17,Inputs!$F$16) -> 43591
D17: Concession expiry | E17: date | F17: =IF(Inputs!$F$215=1,Inputs!$F$19,Inputs!$F$18) -> 58221
D18: Construction days (close to scheduled completion) | E18: days | F18: =Inputs!$F$15-Inputs!$F$13 -> 1404
D19: Flags
D20: Flag_Construction | E20: flag | J20: =IF(J8<=Inputs!$F$15,1,0) -> 1 | K20: =IF(K8<=Inputs!$F$15,1,0) -> 1 | L20: =IF(L8<=Inputs!$F$15,1,0) -> 1 | M20: =IF(M8<=Inputs!$F$15,1,0) -> 1 | N20: =IF(N8<=Inputs!$F$15,1,0) -> 1 | O20: =IF(O8<=Inputs!$F$15,1,0) -> 1 | P20: =IF(P8<=Inputs!$F$15,1,0) -> 1 | Q20: =IF(Q8<=Inputs!$F$15,1,0) -> 1 | ... DB20: =IF(DB8<=Inputs!$F$15,1,0) -> 0
D21: Flag_FirstPostConstruction | E21: flag | J21: =IF(AND(I20=1,J20=0),1,0) -> 0 | K21: =IF(AND(J20=1,K20=0),1,0) -> 0 | L21: =IF(AND(K20=1,L20=0),1,0) -> 0 | M21: =IF(AND(L20=1,M20=0),1,0) -> 0 | N21: =IF(AND(M20=1,N20=0),1,0) -> 0 | O21: =IF(AND(N20=1,O20=0),1,0) -> 0 | P21: =IF(AND(O20=1,P20=0),1,0) -> 0 | Q21: =IF(AND(P20=1,Q20=0),1,0) -> 0 | ... DB21: =IF(AND(DA20=1,DB20=0),1,0) -> 0
D22: Flag_BridgeDraw (last six construction quarters) | E22: flag | J22: =IF(AND(J20=1,J8>EDATE(Inputs!$F$15,-Inputs!$F$50)),1,0) -> 0 | K22: =IF(AND(K20=1,K8>EDATE(Inputs!$F$15,-Inputs!$F$50)),1,0) -> 0 | L22: =IF(AND(L20=1,L8>EDATE(Inputs!$F$15,-Inputs!$F$50)),1,0) -> 0 | M22: =IF(AND(M20=1,M8>EDATE(Inputs!$F$15,-Inputs!$F$50)),1,0) -> 0 | N22: =IF(AND(N20=1,N8>EDATE(Inputs!$F$15,-Inputs!$F$50)),1,0) -> 0 | O22: =IF(AND(O20=1,O8>EDATE(Inputs!$F$15,-Inputs!$F$50)),1,0) -> 0 | P22: =IF(AND(P20=1,P8>EDATE(Inputs!$F$15,-Inputs!$F$50)),1,0) -> 0 | Q22: =IF(AND(Q20=1,Q8>EDATE(Inputs!$F$15,-Inputs!$F$50)),1,0) -> 0 | ... DB22: =IF(AND(DB20=1,DB8>EDATE(Inputs!$F$15,-Inputs!$F$50)),1,0) -> 0
D23: Flag_PostRestructuring | E23: flag | J23: =IF(AND(Inputs!$F$215=1,J8>Inputs!$F$20),1,0) -> 0 | K23: =IF(AND(Inputs!$F$215=1,K8>Inputs!$F$20),1,0) -> 0 | L23: =IF(AND(Inputs!$F$215=1,L8>Inputs!$F$20),1,0) -> 0 | M23: =IF(AND(Inputs!$F$215=1,M8>Inputs!$F$20),1,0) -> 0 | N23: =IF(AND(Inputs!$F$215=1,N8>Inputs!$F$20),1,0) -> 0 | O23: =IF(AND(Inputs!$F$215=1,O8>Inputs!$F$20),1,0) -> 0 | P23: =IF(AND(Inputs!$F$215=1,P8>Inputs!$F$20),1,0) -> 0 | Q23: =IF(AND(Inputs!$F$215=1,Q8>Inputs!$F$20),1,0) -> 0 | ... DB23: =IF(AND(Inputs!$F$215=1,DB8>Inputs!$F$20),1,0) -> 1
D24: Applicable concession expiry | E24: date | J24: =IF(J23=1,Inputs!$F$19,Inputs!$F$18) -> 56030 | K24: =IF(K23=1,Inputs!$F$19,Inputs!$F$18) -> 56030 | L24: =IF(L23=1,Inputs!$F$19,Inputs!$F$18) -> 56030 | M24: =IF(M23=1,Inputs!$F$19,Inputs!$F$18) -> 56030 | N24: =IF(N23=1,Inputs!$F$19,Inputs!$F$18) -> 56030 | O24: =IF(O23=1,Inputs!$F$19,Inputs!$F$18) -> 56030 | P24: =IF(P23=1,Inputs!$F$19,Inputs!$F$18) -> 56030 | Q24: =IF(Q23=1,Inputs!$F$19,Inputs!$F$18) -> 56030 | ... DB24: =IF(DB23=1,Inputs!$F$19,Inputs!$F$18) -> 58221
D25: Operating days | E25: days | J25: =MAX(0,MIN(J8,$F$17)-MAX(J7,$F$16)) -> 0 | K25: =MAX(0,MIN(K8,$F$17)-MAX(K7,$F$16)) -> 0 | L25: =MAX(0,MIN(L8,$F$17)-MAX(L7,$F$16)) -> 0 | M25: =MAX(0,MIN(M8,$F$17)-MAX(M7,$F$16)) -> 0 | N25: =MAX(0,MIN(N8,$F$17)-MAX(N7,$F$16)) -> 0 | O25: =MAX(0,MIN(O8,$F$17)-MAX(O7,$F$16)) -> 0 | P25: =MAX(0,MIN(P8,$F$17)-MAX(P7,$F$16)) -> 0 | Q25: =MAX(0,MIN(Q8,$F$17)-MAX(Q7,$F$16)) -> 0 | ... DB25: =MAX(0,MIN(DB8,$F$17)-MAX(DB7,$F$16)) -> 146
D26: Flag_Operations | E26: flag | J26: =IF(J25>0,1,0) -> 0 | K26: =IF(K25>0,1,0) -> 0 | L26: =IF(L25>0,1,0) -> 0 | M26: =IF(M25>0,1,0) -> 0 | N26: =IF(N25>0,1,0) -> 0 | O26: =IF(O25>0,1,0) -> 0 | P26: =IF(P25>0,1,0) -> 0 | Q26: =IF(Q25>0,1,0) -> 0 | ... DB26: =IF(DB25>0,1,0) -> 1
D27: Flag_OpeningPeriod | E27: flag | J27: =IF(AND(J7<$F$16,$F$16<=J8),1,0) -> 0 | K27: =IF(AND(K7<$F$16,$F$16<=K8),1,0) -> 0 | L27: =IF(AND(L7<$F$16,$F$16<=L8),1,0) -> 0 | M27: =IF(AND(M7<$F$16,$F$16<=M8),1,0) -> 0 | N27: =IF(AND(N7<$F$16,$F$16<=N8),1,0) -> 0 | O27: =IF(AND(O7<$F$16,$F$16<=O8),1,0) -> 0 | P27: =IF(AND(P7<$F$16,$F$16<=P8),1,0) -> 0 | Q27: =IF(AND(Q7<$F$16,$F$16<=Q8),1,0) -> 0 | ... DB27: =IF(AND(DB7<$F$16,$F$16<=DB8),1,0) -> 0
D28: Flag_FinalPeriod (concession expiry) | E28: flag | J28: =IF(AND(J7<$F$17,$F$17<=J8),1,0) -> 0 | K28: =IF(AND(K7<$F$17,$F$17<=K8),1,0) -> 0 | L28: =IF(AND(L7<$F$17,$F$17<=L8),1,0) -> 0 | M28: =IF(AND(M7<$F$17,$F$17<=M8),1,0) -> 0 | N28: =IF(AND(N7<$F$17,$F$17<=N8),1,0) -> 0 | O28: =IF(AND(O7<$F$17,$F$17<=O8),1,0) -> 0 | P28: =IF(AND(P7<$F$17,$F$17<=P8),1,0) -> 0 | Q28: =IF(AND(Q7<$F$17,$F$17<=Q8),1,0) -> 0 | ... DB28: =IF(AND(DB7<$F$17,$F$17<=DB8),1,0) -> 1
D29: Remaining concession days from period start | E29: days | J29: =MAX(0,J24-MAX(J7,$F$16)) -> 12439 | K29: =MAX(0,K24-MAX(K7,$F$16)) -> 12439 | L29: =MAX(0,L24-MAX(L7,$F$16)) -> 12439 | M29: =MAX(0,M24-MAX(M7,$F$16)) -> 12439 | N29: =MAX(0,N24-MAX(N7,$F$16)) -> 12439 | O29: =MAX(0,O24-MAX(O7,$F$16)) -> 12439 | P29: =MAX(0,P24-MAX(P7,$F$16)) -> 12439 | Q29: =MAX(0,Q24-MAX(Q7,$F$16)) -> 12439 | ... DB29: =MAX(0,DB24-MAX(DB7,$F$16)) -> 146
D30: Flag_Repayment (senior, original) | E30: flag | J30: =IF(AND(J8>=Inputs!$F$21,J8<=Inputs!$F$22),1,0) -> 0 | K30: =IF(AND(K8>=Inputs!$F$21,K8<=Inputs!$F$22),1,0) -> 0 | L30: =IF(AND(L8>=Inputs!$F$21,L8<=Inputs!$F$22),1,0) -> 0 | M30: =IF(AND(M8>=Inputs!$F$21,M8<=Inputs!$F$22),1,0) -> 0 | N30: =IF(AND(N8>=Inputs!$F$21,N8<=Inputs!$F$22),1,0) -> 0 | O30: =IF(AND(O8>=Inputs!$F$21,O8<=Inputs!$F$22),1,0) -> 0 | P30: =IF(AND(P8>=Inputs!$F$21,P8<=Inputs!$F$22),1,0) -> 0 | Q30: =IF(AND(Q8>=Inputs!$F$21,Q8<=Inputs!$F$22),1,0) -> 0 | ... DB30: =IF(AND(DB8>=Inputs!$F$21,DB8<=Inputs!$F$22),1,0) -> 0
D31: Flag_FirstRepayment | E31: flag | J31: =IF(AND(J30=1,I30=0),1,0) -> 0 | K31: =IF(AND(K30=1,J30=0),1,0) -> 0 | L31: =IF(AND(L30=1,K30=0),1,0) -> 0 | M31: =IF(AND(M30=1,L30=0),1,0) -> 0 | N31: =IF(AND(N30=1,M30=0),1,0) -> 0 | O31: =IF(AND(O30=1,N30=0),1,0) -> 0 | P31: =IF(AND(P30=1,O30=0),1,0) -> 0 | Q31: =IF(AND(Q30=1,P30=0),1,0) -> 0 | ... DB31: =IF(AND(DB30=1,DA30=0),1,0) -> 0
D32: Flag_RampUp (operations before first repayment) | E32: flag | J32: =IF(AND(J26=1,J8<Inputs!$F$21),1,0) -> 0 | K32: =IF(AND(K26=1,K8<Inputs!$F$21),1,0) -> 0 | L32: =IF(AND(L26=1,L8<Inputs!$F$21),1,0) -> 0 | M32: =IF(AND(M26=1,M8<Inputs!$F$21),1,0) -> 0 | N32: =IF(AND(N26=1,N8<Inputs!$F$21),1,0) -> 0 | O32: =IF(AND(O26=1,O8<Inputs!$F$21),1,0) -> 0 | P32: =IF(AND(P26=1,P8<Inputs!$F$21),1,0) -> 0 | Q32: =IF(AND(Q26=1,Q8<Inputs!$F$21),1,0) -> 0 | ... DB32: =IF(AND(DB26=1,DB8<Inputs!$F$21),1,0) -> 0
D33: Flag_BeforeFirstRepayment | E33: flag | J33: =IF(J8<Inputs!$F$21,1,0) -> 1 | K33: =IF(K8<Inputs!$F$21,1,0) -> 1 | L33: =IF(L8<Inputs!$F$21,1,0) -> 1 | M33: =IF(M8<Inputs!$F$21,1,0) -> 1 | N33: =IF(N8<Inputs!$F$21,1,0) -> 1 | O33: =IF(O8<Inputs!$F$21,1,0) -> 1 | P33: =IF(P8<Inputs!$F$21,1,0) -> 1 | Q33: =IF(Q8<Inputs!$F$21,1,0) -> 1 | ... DB33: =IF(DB8<Inputs!$F$21,1,0) -> 0
D34: Flag_Standstill | E34: flag | J34: =IF(AND(Inputs!$F$213=1,J8>=Inputs!$F$21,J8<=Inputs!$F$20),1,0) -> 0 | K34: =IF(AND(Inputs!$F$213=1,K8>=Inputs!$F$21,K8<=Inputs!$F$20),1,0) -> 0 | L34: =IF(AND(Inputs!$F$213=1,L8>=Inputs!$F$21,L8<=Inputs!$F$20),1,0) -> 0 | M34: =IF(AND(Inputs!$F$213=1,M8>=Inputs!$F$21,M8<=Inputs!$F$20),1,0) -> 0 | N34: =IF(AND(Inputs!$F$213=1,N8>=Inputs!$F$21,N8<=Inputs!$F$20),1,0) -> 0 | O34: =IF(AND(Inputs!$F$213=1,O8>=Inputs!$F$21,O8<=Inputs!$F$20),1,0) -> 0 | P34: =IF(AND(Inputs!$F$213=1,P8>=Inputs!$F$21,P8<=Inputs!$F$20),1,0) -> 0 | Q34: =IF(AND(Inputs!$F$213=1,Q8>=Inputs!$F$21,Q8<=Inputs!$F$20),1,0) -> 0 | ... DB34: =IF(AND(Inputs!$F$213=1,DB8>=Inputs!$F$21,DB8<=Inputs!$F$20),1,0) -> 0
D35: Flag_Restructuring | E35: flag | J35: =IF(AND(Inputs!$F$215=1,J8=Inputs!$F$20),1,0) -> 0 | K35: =IF(AND(Inputs!$F$215=1,K8=Inputs!$F$20),1,0) -> 0 | L35: =IF(AND(Inputs!$F$215=1,L8=Inputs!$F$20),1,0) -> 0 | M35: =IF(AND(Inputs!$F$215=1,M8=Inputs!$F$20),1,0) -> 0 | N35: =IF(AND(Inputs!$F$215=1,N8=Inputs!$F$20),1,0) -> 0 | O35: =IF(AND(Inputs!$F$215=1,O8=Inputs!$F$20),1,0) -> 0 | P35: =IF(AND(Inputs!$F$215=1,P8=Inputs!$F$20),1,0) -> 0 | Q35: =IF(AND(Inputs!$F$215=1,Q8=Inputs!$F$20),1,0) -> 0 | ... DB35: =IF(AND(Inputs!$F$215=1,DB8=Inputs!$F$20),1,0) -> 0
D36: Flag_FirstNotesPeriod | E36: flag | J36: =IF(AND(J23=1,I35=1),1,0) -> 0 | K36: =IF(AND(K23=1,J35=1),1,0) -> 0 | L36: =IF(AND(L23=1,K35=1),1,0) -> 0 | M36: =IF(AND(M23=1,L35=1),1,0) -> 0 | N36: =IF(AND(N23=1,M35=1),1,0) -> 0 | O36: =IF(AND(O23=1,N35=1),1,0) -> 0 | P36: =IF(AND(P23=1,O35=1),1,0) -> 0 | Q36: =IF(AND(Q23=1,P35=1),1,0) -> 0 | ... DB36: =IF(AND(DB23=1,DA35=1),1,0) -> 0
D37: Flag_NotesRepayment | E37: flag | J37: =IF(AND(J23=1,J8<=Inputs!$F$32),1,0) -> 0 | K37: =IF(AND(K23=1,K8<=Inputs!$F$32),1,0) -> 0 | L37: =IF(AND(L23=1,L8<=Inputs!$F$32),1,0) -> 0 | M37: =IF(AND(M23=1,M8<=Inputs!$F$32),1,0) -> 0 | N37: =IF(AND(N23=1,N8<=Inputs!$F$32),1,0) -> 0 | O37: =IF(AND(O23=1,O8<=Inputs!$F$32),1,0) -> 0 | P37: =IF(AND(P23=1,P8<=Inputs!$F$32),1,0) -> 0 | Q37: =IF(AND(Q23=1,Q8<=Inputs!$F$32),1,0) -> 0 | ... DB37: =IF(AND(DB23=1,DB8<=Inputs!$F$32),1,0) -> 0
D38: Flag_NotesSweep | E38: flag | J38: =IF(AND(J23=1,J8<=Inputs!$F$33),1,0) -> 0 | K38: =IF(AND(K23=1,K8<=Inputs!$F$33),1,0) -> 0 | L38: =IF(AND(L23=1,L8<=Inputs!$F$33),1,0) -> 0 | M38: =IF(AND(M23=1,M8<=Inputs!$F$33),1,0) -> 0 | N38: =IF(AND(N23=1,N8<=Inputs!$F$33),1,0) -> 0 | O38: =IF(AND(O23=1,O8<=Inputs!$F$33),1,0) -> 0 | P38: =IF(AND(P23=1,P8<=Inputs!$F$33),1,0) -> 0 | Q38: =IF(AND(Q23=1,Q8<=Inputs!$F$33),1,0) -> 0 | ... DB38: =IF(AND(DB23=1,DB8<=Inputs!$F$33),1,0) -> 0
D39: Flag_ActualTraffic | E39: flag | J39: =IF(AND(Inputs!$F$213=1,J26=1,J8<=Inputs!$F$214),1,0) -> 0 | K39: =IF(AND(Inputs!$F$213=1,K26=1,K8<=Inputs!$F$214),1,0) -> 0 | L39: =IF(AND(Inputs!$F$213=1,L26=1,L8<=Inputs!$F$214),1,0) -> 0 | M39: =IF(AND(Inputs!$F$213=1,M26=1,M8<=Inputs!$F$214),1,0) -> 0 | N39: =IF(AND(Inputs!$F$213=1,N26=1,N8<=Inputs!$F$214),1,0) -> 0 | O39: =IF(AND(Inputs!$F$213=1,O26=1,O8<=Inputs!$F$214),1,0) -> 0 | P39: =IF(AND(Inputs!$F$213=1,P26=1,P8<=Inputs!$F$214),1,0) -> 0 | Q39: =IF(AND(Inputs!$F$213=1,Q26=1,Q8<=Inputs!$F$214),1,0) -> 0 | ... DB39: =IF(AND(Inputs!$F$213=1,DB26=1,DB8<=Inputs!$F$214),1,0) -> 0
D40: Share of period before margin step | E40: factor | J40: =MIN(1,MAX(0,(MIN(J8,Inputs!$F$23)-J7)/J9)) -> 1 | K40: =MIN(1,MAX(0,(MIN(K8,Inputs!$F$23)-K7)/K9)) -> 1 | L40: =MIN(1,MAX(0,(MIN(L8,Inputs!$F$23)-L7)/L9)) -> 1 | M40: =MIN(1,MAX(0,(MIN(M8,Inputs!$F$23)-M7)/M9)) -> 1 | N40: =MIN(1,MAX(0,(MIN(N8,Inputs!$F$23)-N7)/N9)) -> 1 | O40: =MIN(1,MAX(0,(MIN(O8,Inputs!$F$23)-O7)/O9)) -> 1 | P40: =MIN(1,MAX(0,(MIN(P8,Inputs!$F$23)-P7)/P9)) -> 1 | Q40: =MIN(1,MAX(0,(MIN(Q8,Inputs!$F$23)-Q7)/Q9)) -> 1 | ... DB40: =MIN(1,MAX(0,(MIN(DB8,Inputs!$F$23)-DB7)/DB9)) -> 0
D41: Share of period before mini-perm maturity | E41: factor | J41: =MIN(1,MAX(0,(MIN(J8,Inputs!$F$24)-J7)/J9)) -> 1 | K41: =MIN(1,MAX(0,(MIN(K8,Inputs!$F$24)-K7)/K9)) -> 1 | L41: =MIN(1,MAX(0,(MIN(L8,Inputs!$F$24)-L7)/L9)) -> 1 | M41: =MIN(1,MAX(0,(MIN(M8,Inputs!$F$24)-M7)/M9)) -> 1 | N41: =MIN(1,MAX(0,(MIN(N8,Inputs!$F$24)-N7)/N9)) -> 1 | O41: =MIN(1,MAX(0,(MIN(O8,Inputs!$F$24)-O7)/O9)) -> 1 | P41: =MIN(1,MAX(0,(MIN(P8,Inputs!$F$24)-P7)/P9)) -> 1 | Q41: =MIN(1,MAX(0,(MIN(Q8,Inputs!$F$24)-Q7)/Q9)) -> 1 | ... DB41: =MIN(1,MAX(0,(MIN(DB8,Inputs!$F$24)-DB7)/DB9)) -> 0
...

Sheet Construction
D1: Case T: Merrick Link toll road PPP | Construction
D2: Units: ARD millions unless stated. Inputs blue on yellow; links green; calculations black.
D3: Period end | E3: date | J3: =Time!J8 -> 42185 | K3: =Time!K8 -> 42277 | L3: =Time!L8 -> 42369 | M3: =Time!M8 -> 42460 | N3: =Time!N8 -> 42551 | O3: =Time!O8 -> 42643 | P3: =Time!P8 -> 42735 | Q3: =Time!Q8 -> 42825 | ... DB3: =Time!DB8 -> 58256
D5: Construction costs (paid at period end)
D6: D&C contract payments (incl. 5% retention at completion) | E6: ARD m | G6: =SUM(J6:DB6) -> 1684.3 | J6: =Inputs!$F$68*Inputs!J267+IF(Time!J8=Inputs!$F$15,Inputs!$F$68*(Inputs!$F$69+Inputs!$F$70),0) -> 2.7487776 | K6: =Inputs!$F$68*Inputs!K267+IF(Time!K8=Inputs!$F$15,Inputs!$F$68*(Inputs!$F$69+Inputs!$F$70),0) -> 21.656729 | L6: =Inputs!$F$68*Inputs!L267+IF(Time!L8=Inputs!$F$15,Inputs!$F$68*(Inputs!$F$69+Inputs!$F$70),0) -> 52.144244 | M6: =Inputs!$F$68*Inputs!M267+IF(Time!M8=Inputs!$F$15,Inputs!$F$68*(Inputs!$F$69+Inputs!$F$70),0) -> 87.622339 | N6: =Inputs!$F$68*Inputs!N267+IF(Time!N8=Inputs!$F$15,Inputs!$F$68*(Inputs!$F$69+Inputs!$F$70),0) -> 122.59683 | O6: =Inputs!$F$68*Inputs!O267+IF(Time!O8=Inputs!$F$15,Inputs!$F$68*(Inputs!$F$69+Inputs!$F$70),0) -> 152.67337 | P6: =Inputs!$F$68*Inputs!P267+IF(Time!P8=Inputs!$F$15,Inputs!$F$68*(Inputs!$F$69+Inputs!$F$70),0) -> 174.5558 | Q6: =Inputs!$F$68*Inputs!Q267+IF(Time!Q8=Inputs!$F$15,Inputs!$F$68*(Inputs!$F$69+Inputs!$F$70),0) -> 186.04609 | ... DB6: =Inputs!$F$68*Inputs!DB267+IF(Time!DB8=Inputs!$F$15,Inputs!$F$68*(Inputs!$F$69+Inputs!$F$70),0) -> 0
D7: Development and bid costs | E7: ARD m | G7: =SUM(J7:DB7) -> 41.2 | J7: =IF(Time!J6=1,Inputs!$F$71,0) -> 41.2 | K7: =IF(Time!K6=1,Inputs!$F$71,0) -> 0 | L7: =IF(Time!L6=1,Inputs!$F$71,0) -> 0 | M7: =IF(Time!M6=1,Inputs!$F$71,0) -> 0 | N7: =IF(Time!N6=1,Inputs!$F$71,0) -> 0 | O7: =IF(Time!O6=1,Inputs!$F$71,0) -> 0 | P7: =IF(Time!P6=1,Inputs!$F$71,0) -> 0 | Q7: =IF(Time!Q6=1,Inputs!$F$71,0) -> 0 | ... DB7: =IF(Time!DB6=1,Inputs!$F$71,0) -> 0
D8: Project company costs | E8: ARD m | G8: =SUM(J8:DB8) -> 37.8 | J8: =Inputs!$F$72*Time!J9/Time!$F$18*Time!J20 -> 0.91538462 | K8: =Inputs!$F$72*Time!K9/Time!$F$18*Time!K20 -> 2.4769231 | L8: =Inputs!$F$72*Time!L9/Time!$F$18*Time!L20 -> 2.4769231 | M8: =Inputs!$F$72*Time!M9/Time!$F$18*Time!M20 -> 2.45 | N8: =Inputs!$F$72*Time!N9/Time!$F$18*Time!N20 -> 2.45 | O8: =Inputs!$F$72*Time!O9/Time!$F$18*Time!O20 -> 2.4769231 | P8: =Inputs!$F$72*Time!P9/Time!$F$18*Time!P20 -> 2.4769231 | Q8: =Inputs!$F$72*Time!Q9/Time!$F$18*Time!Q20 -> 2.4230769 | ... DB8: =Inputs!$F$72*Time!DB9/Time!$F$18*Time!DB20 -> 0
D9: Insurance during construction | E9: ARD m | G9: =SUM(J9:DB9) -> 12.6 | J9: =IF(Time!J6=1,Inputs!$F$73*Inputs!$F$74,IF(Time!J8=Inputs!$F$37,Inputs!$F$73*(1-Inputs!$F$74),0)) -> 10.08 | K9: =IF(Time!K6=1,Inputs!$F$73*Inputs!$F$74,IF(Time!K8=Inputs!$F$37,Inputs!$F$73*(1-Inputs!$F$74),0)) -> 0 | L9: =IF(Time!L6=1,Inputs!$F$73*Inputs!$F$74,IF(Time!L8=Inputs!$F$37,Inputs!$F$73*(1-Inputs!$F$74),0)) -> 0 | M9: =IF(Time!M6=1,Inputs!$F$73*Inputs!$F$74,IF(Time!M8=Inputs!$F$37,Inputs!$F$73*(1-Inputs!$F$74),0)) -> 0 | N9: =IF(Time!N6=1,Inputs!$F$73*Inputs!$F$74,IF(Time!N8=Inputs!$F$37,Inputs!$F$73*(1-Inputs!$F$74),0)) -> 0 | O9: =IF(Time!O6=1,Inputs!$F$73*Inputs!$F$74,IF(Time!O8=Inputs!$F$37,Inputs!$F$73*(1-Inputs!$F$74),0)) -> 0 | P9: =IF(Time!P6=1,Inputs!$F$73*Inputs!$F$74,IF(Time!P8=Inputs!$F$37,Inputs!$F$73*(1-Inputs!$F$74),0)) -> 0 | Q9: =IF(Time!Q6=1,Inputs!$F$73*Inputs!$F$74,IF(Time!Q8=Inputs!$F$37,Inputs!$F$73*(1-Inputs!$F$74),0)) -> 0 | ... DB9: =IF(Time!DB6=1,Inputs!$F$73*Inputs!$F$74,IF(Time!DB8=Inputs!$F$37,Inputs!$F$73*(1-Inputs!$F$74),0)) -> 0
D10: Independent certifier | E10: ARD m | G10: =SUM(J10:DB10) -> 3.4 | J10: =Inputs!$F$75*Time!J9/Time!$F$18*Time!J20 -> 0.082336182 | K10: =Inputs!$F$75*Time!K9/Time!$F$18*Time!K20 -> 0.22279202 | L10: =Inputs!$F$75*Time!L9/Time!$F$18*Time!L20 -> 0.22279202 | M10: =Inputs!$F$75*Time!M9/Time!$F$18*Time!M20 -> 0.22037037 | N10: =Inputs!$F$75*Time!N9/Time!$F$18*Time!N20 -> 0.22037037 | O10: =Inputs!$F$75*Time!O9/Time!$F$18*Time!O20 -> 0.22279202 | P10: =Inputs!$F$75*Time!P9/Time!$F$18*Time!P20 -> 0.22279202 | Q10: =Inputs!$F$75*Time!Q9/Time!$F$18*Time!Q20 -> 0.21794872 | ... DB10: =Inputs!$F$75*Time!DB9/Time!$F$18*Time!DB20 -> 0
D11: Lenders' advisors and legal | E11: ARD m | G11: =SUM(J11:DB11) -> 9.7 | J11: =Inputs!$F$76*Time!J9/Time!$F$18*Time!J20 -> 0.23490028 | K11: =Inputs!$F$76*Time!K9/Time!$F$18*Time!K20 -> 0.63561254 | L11: =Inputs!$F$76*Time!L9/Time!$F$18*Time!L20 -> 0.63561254 | M11: =Inputs!$F$76*Time!M9/Time!$F$18*Time!M20 -> 0.6287037 | N11: =Inputs!$F$76*Time!N9/Time!$F$18*Time!N20 -> 0.6287037 | O11: =Inputs!$F$76*Time!O9/Time!$F$18*Time!O20 -> 0.63561254 | P11: =Inputs!$F$76*Time!P9/Time!$F$18*Time!P20 -> 0.63561254 | Q11: =Inputs!$F$76*Time!Q9/Time!$F$18*Time!Q20 -> 0.62179487 | ... DB11: =Inputs!$F$76*Time!DB9/Time!$F$18*Time!DB20 -> 0
D12: Contingency | E12: ARD m | G12: =SUM(J12:DB12) -> 52.4 | J12: =Inputs!$F$77*Inputs!J267/SUM(Inputs!$J$267:$DB$267) -> 0.090017684 | K12: =Inputs!$F$77*Inputs!K267/SUM(Inputs!$J$267:$DB$267) -> 0.70922021 | L12: =Inputs!$F$77*Inputs!L267/SUM(Inputs!$J$267:$DB$267) -> 1.7076333 | M12: =Inputs!$F$77*Inputs!M267/SUM(Inputs!$J$267:$DB$267) -> 2.8694792 | N12: =Inputs!$F$77*Inputs!N267/SUM(Inputs!$J$267:$DB$267) -> 4.0148328 | O12: =Inputs!$F$77*Inputs!O267/SUM(Inputs!$J$267:$DB$267) -> 4.9997874 | P12: =Inputs!$F$77*Inputs!P267/SUM(Inputs!$J$267:$DB$267) -> 5.7163987 | Q12: =Inputs!$F$77*Inputs!Q267/SUM(Inputs!$J$267:$DB$267) -> 6.0926859 | ... DB12: =Inputs!$F$77*Inputs!DB267/SUM(Inputs!$J$267:$DB$267) -> 0
D13: Total construction costs before financing | E13: ARD m | G13: =SUM(J13:DB13) -> 1841.4 | J13: =J6+J7+J8+J9+J10+J11+J12 -> 55.351416 | K13: =K6+K7+K8+K9+K10+K11+K12 -> 25.701277 | L13: =L6+L7+L8+L9+L10+L11+L12 -> 57.187205 | M13: =M6+M7+M8+M9+M10+M11+M12 -> 93.790892 | N13: =N6+N7+N8+N9+N10+N11+N12 -> 129.91074 | O13: =O6+O7+O8+O9+O10+O11+O12 -> 161.00849 | P13: =P6+P7+P8+P9+P10+P11+P12 -> 183.60753 | Q13: =Q6+Q7+Q8+Q9+Q10+Q11+Q12 -> 195.4016 | ... DB13: =DB6+DB7+DB8+DB9+DB10+DB11+DB12 -> 0
D14: Retention deposited at completion (released after defects period) | E14: ARD m | G14: =SUM(J14:DB14) -> 42.1075 | J14: =IF(Time!J8=Inputs!$F$15,Inputs!$F$68*Inputs!$F$70,0) -> 0 | K14: =IF(Time!K8=Inputs!$F$15,Inputs!$F$68*Inputs!$F$70,0) -> 0 | L14: =IF(Time!L8=Inputs!$F$15,Inputs!$F$68*Inputs!$F$70,0) -> 0 | M14: =IF(Time!M8=Inputs!$F$15,Inputs!$F$68*Inputs!$F$70,0) -> 0 | N14: =IF(Time!N8=Inputs!$F$15,Inputs!$F$68*Inputs!$F$70,0) -> 0 | O14: =IF(Time!O8=Inputs!$F$15,Inputs!$F$68*Inputs!$F$70,0) -> 0 | P14: =IF(Time!P8=Inputs!$F$15,Inputs!$F$68*Inputs!$F$70,0) -> 0 | Q14: =IF(Time!Q8=Inputs!$F$15,Inputs!$F$68*Inputs!$F$70,0) -> 0 | ... DB14: =IF(Time!DB8=Inputs!$F$15,Inputs!$F$68*Inputs!$F$70,0) -> 0

Sheet Operations
D1: Case T: Merrick Link toll road PPP | Operations
D2: Units: ARD millions unless stated. Inputs blue on yellow; links green; calculations black.
D3: Period end | E3: date | J3: =Time!J8 -> 42185 | K3: =Time!K8 -> 42277 | L3: =Time!L8 -> 42369 | M3: =Time!M8 -> 42460 | N3: =Time!N8 -> 42551 | O3: =Time!O8 -> 42643 | P3: =Time!P8 -> 42735 | Q3: =Time!Q8 -> 42825 | ... DB3: =Time!DB8 -> 58256
D5: Traffic
D6: Growth rate for the year | E6: %pa | J6: =IF(Time!J11<=Inputs!$F$55,Inputs!$F$243,IF(Time!J11<=Inputs!$F$56,Inputs!$F$244,Inputs!$F$245)) -> 2.6 | K6: =IF(Time!K11<=Inputs!$F$55,Inputs!$F$243,IF(Time!K11<=Inputs!$F$56,Inputs!$F$244,Inputs!$F$245)) -> 2.6 | L6: =IF(Time!L11<=Inputs!$F$55,Inputs!$F$243,IF(Time!L11<=Inputs!$F$56,Inputs!$F$244,Inputs!$F$245)) -> 2.6 | M6: =IF(Time!M11<=Inputs!$F$55,Inputs!$F$243,IF(Time!M11<=Inputs!$F$56,Inputs!$F$244,Inputs!$F$245)) -> 2.6 | N6: =IF(Time!N11<=Inputs!$F$55,Inputs!$F$243,IF(Time!N11<=Inputs!$F$56,Inputs!$F$244,Inputs!$F$245)) -> 2.6 | O6: =IF(Time!O11<=Inputs!$F$55,Inputs!$F$243,IF(Time!O11<=Inputs!$F$56,Inputs!$F$244,Inputs!$F$245)) -> 2.6 | P6: =IF(Time!P11<=Inputs!$F$55,Inputs!$F$243,IF(Time!P11<=Inputs!$F$56,Inputs!$F$244,Inputs!$F$245)) -> 2.6 | Q6: =IF(Time!Q11<=Inputs!$F$55,Inputs!$F$243,IF(Time!Q11<=Inputs!$F$56,Inputs!$F$244,Inputs!$F$245)) -> 2.6 | ... DB6: =IF(Time!DB11<=Inputs!$F$55,Inputs!$F$243,IF(Time!DB11<=Inputs!$F$56,Inputs!$F$244,Inputs!$F$245)) -> 0.9
D7: Underlying traffic level | E7: k/day | J7: =IF(Time!J11<=Inputs!$F$242,Inputs!$F$241/(1+Inputs!$F$243/100)^(Inputs!$F$242-Time!J11),I7*IF(Time!J11>Time!I11,1+J6/100,1)) -> 34.69211 | K7: =IF(Time!K11<=Inputs!$F$242,Inputs!$F$241/(1+Inputs!$F$243/100)^(Inputs!$F$242-Time!K11),J7*IF(Time!K11>Time!J11,1+K6/100,1)) -> 34.69211 | L7: =IF(Time!L11<=Inputs!$F$242,Inputs!$F$241/(1+Inputs!$F$243/100)^(Inputs!$F$242-Time!L11),K7*IF(Time!L11>Time!K11,1+L6/100,1)) -> 34.69211 | M7: =IF(Time!M11<=Inputs!$F$242,Inputs!$F$241/(1+Inputs!$F$243/100)^(Inputs!$F$242-Time!M11),L7*IF(Time!M11>Time!L11,1+M6/100,1)) -> 35.594105 | N7: =IF(Time!N11<=Inputs!$F$242,Inputs!$F$241/(1+Inputs!$F$243/100)^(Inputs!$F$242-Time!N11),M7*IF(Time!N11>Time!M11,1+N6/100,1)) -> 35.594105 | O7: =IF(Time!O11<=Inputs!$F$242,Inputs!$F$241/(1+Inputs!$F$243/100)^(Inputs!$F$242-Time!O11),N7*IF(Time!O11>Time!N11,1+O6/100,1)) -> 35.594105 | P7: =IF(Time!P11<=Inputs!$F$242,Inputs!$F$241/(1+Inputs!$F$243/100)^(Inputs!$F$242-Time!P11),O7*IF(Time!P11>Time!O11,1+P6/100,1)) -> 35.594105 | Q7: =IF(Time!Q11<=Inputs!$F$242,Inputs!$F$241/(1+Inputs!$F$243/100)^(Inputs!$F$242-Time!Q11),P7*IF(Time!Q11>Time!P11,1+Q6/100,1)) -> 36.519551 | ... DB7: =IF(Time!DB11<=Inputs!$F$242,Inputs!$F$241/(1+Inputs!$F$243/100)^(Inputs!$F$242-Time!DB11),DA7*IF(Time!DB11>Time!DA11,1+DB6/100,1)) -> 72.252198
D8: Ramp-up table year | E8: year | J8: =MAX(Inputs!$F$57,MIN(Inputs!$F$58,Time!J11-Inputs!$F$219)) -> 2019 | K8: =MAX(Inputs!$F$57,MIN(Inputs!$F$58,Time!K11-Inputs!$F$219)) -> 2019 | L8: =MAX(Inputs!$F$57,MIN(Inputs!$F$58,Time!L11-Inputs!$F$219)) -> 2019 | M8: =MAX(Inputs!$F$57,MIN(Inputs!$F$58,Time!M11-Inputs!$F$219)) -> 2019 | N8: =MAX(Inputs!$F$57,MIN(Inputs!$F$58,Time!N11-Inputs!$F$219)) -> 2019 | O8: =MAX(Inputs!$F$57,MIN(Inputs!$F$58,Time!O11-Inputs!$F$219)) -> 2019 | P8: =MAX(Inputs!$F$57,MIN(Inputs!$F$58,Time!P11-Inputs!$F$219)) -> 2019 | Q8: =MAX(Inputs!$F$57,MIN(Inputs!$F$58,Time!Q11-Inputs!$F$219)) -> 2019 | ... DB8: =MAX(Inputs!$F$57,MIN(Inputs!$F$58,Time!DB11-Inputs!$F$219)) -> 2023
D9: Ramp-up factor | E9: factor | J9: =CHOOSE(J8-Inputs!$F$57+1,Inputs!$F$248,Inputs!$F$249,Inputs!$F$250,Inputs!$F$251,Inputs!$F$252) -> 1 | K9: =CHOOSE(K8-Inputs!$F$57+1,Inputs!$F$248,Inputs!$F$249,Inputs!$F$250,Inputs!$F$251,Inputs!$F$252) -> 1 | L9: =CHOOSE(L8-Inputs!$F$57+1,Inputs!$F$248,Inputs!$F$249,Inputs!$F$250,Inputs!$F$251,Inputs!$F$252) -> 1 | M9: =CHOOSE(M8-Inputs!$F$57+1,Inputs!$F$248,Inputs!$F$249,Inputs!$F$250,Inputs!$F$251,Inputs!$F$252) -> 1 | N9: =CHOOSE(N8-Inputs!$F$57+1,Inputs!$F$248,Inputs!$F$249,Inputs!$F$250,Inputs!$F$251,Inputs!$F$252) -> 1 | O9: =CHOOSE(O8-Inputs!$F$57+1,Inputs!$F$248,Inputs!$F$249,Inputs!$F$250,Inputs!$F$251,Inputs!$F$252) -> 1 | P9: =CHOOSE(P8-Inputs!$F$57+1,Inputs!$F$248,Inputs!$F$249,Inputs!$F$250,Inputs!$F$251,Inputs!$F$252) -> 1 | Q9: =CHOOSE(Q8-Inputs!$F$57+1,Inputs!$F$248,Inputs!$F$249,Inputs!$F$250,Inputs!$F$251,Inputs!$F$252) -> 1 | ... DB9: =CHOOSE(DB8-Inputs!$F$57+1,Inputs!$F$248,Inputs!$F$249,Inputs!$F$250,Inputs!$F$251,Inputs!$F$252) -> 1
D10: Heavy-vehicle uplift factor | E10: factor | J10: =IF(Time!J11>=Inputs!$F$59,1+Inputs!$F$246/100,1) -> 1 | K10: =IF(Time!K11>=Inputs!$F$59,1+Inputs!$F$246/100,1) -> 1 | L10: =IF(Time!L11>=Inputs!$F$59,1+Inputs!$F$246/100,1) -> 1 | M10: =IF(Time!M11>=Inputs!$F$59,1+Inputs!$F$246/100,1) -> 1 | N10: =IF(Time!N11>=Inputs!$F$59,1+Inputs!$F$246/100,1) -> 1 | O10: =IF(Time!O11>=Inputs!$F$59,1+Inputs!$F$246/100,1) -> 1 | P10: =IF(Time!P11>=Inputs!$F$59,1+Inputs!$F$246/100,1) -> 1 | Q10: =IF(Time!Q11>=Inputs!$F$59,1+Inputs!$F$246/100,1) -> 1 | ... DB10: =IF(Time!DB11>=Inputs!$F$59,1+Inputs!$F$246/100,1) -> 1.024
D11: Forecast traffic | E11: k/day | J11: =J7*J9*J10*Inputs!$F$218 -> 34.69211 | K11: =K7*K9*K10*Inputs!$F$218 -> 34.69211 | L11: =L7*L9*L10*Inputs!$F$218 -> 34.69211 | M11: =M7*M9*M10*Inputs!$F$218 -> 35.594105 | N11: =N7*N9*N10*Inputs!$F$218 -> 35.594105 | O11: =O7*O9*O10*Inputs!$F$218 -> 35.594105 | P11: =P7*P9*P10*Inputs!$F$218 -> 35.594105 | Q11: =Q7*Q9*Q10*Inputs!$F$218 -> 36.519551 | ... DB11: =DB7*DB9*DB10*Inputs!$F$218 -> 73.986251
D12: Actual traffic | E12: k/day | J12: =IFERROR(INDEX(Inputs!$J$262:$X$262,MATCH(Time!J13,Inputs!$J$261:$X$261,0)),0) -> 0 | K12: =IFERROR(INDEX(Inputs!$J$262:$X$262,MATCH(Time!K13,Inputs!$J$261:$X$261,0)),0) -> 0 | L12: =IFERROR(INDEX(Inputs!$J$262:$X$262,MATCH(Time!L13,Inputs!$J$261:$X$261,0)),0) -> 0 | M12: =IFERROR(INDEX(Inputs!$J$262:$X$262,MATCH(Time!M13,Inputs!$J$261:$X$261,0)),0) -> 0 | N12: =IFERROR(INDEX(Inputs!$J$262:$X$262,MATCH(Time!N13,Inputs!$J$261:$X$261,0)),0) -> 0 | O12: =IFERROR(INDEX(Inputs!$J$262:$X$262,MATCH(Time!O13,Inputs!$J$261:$X$261,0)),0) -> 0 | P12: =IFERROR(INDEX(Inputs!$J$262:$X$262,MATCH(Time!P13,Inputs!$J$261:$X$261,0)),0) -> 0 | Q12: =IFERROR(INDEX(Inputs!$J$262:$X$262,MATCH(Time!Q13,Inputs!$J$261:$X$261,0)),0) -> 0 | ... DB12: =IFERROR(INDEX(Inputs!$J$262:$X$262,MATCH(Time!DB13,Inputs!$J$261:$X$261,0)),0) -> 0
D13: Traffic used (average daily trips) | E13: k/day | J13: =IF(Time!J39=1,J12,J11)*Time!J26 -> 0 | K13: =IF(Time!K39=1,K12,K11)*Time!K26 -> 0 | L13: =IF(Time!L39=1,L12,L11)*Time!L26 -> 0 | M13: =IF(Time!M39=1,M12,M11)*Time!M26 -> 0 | N13: =IF(Time!N39=1,N12,N11)*Time!N26 -> 0 | O13: =IF(Time!O39=1,O12,O11)*Time!O26 -> 0 | P13: =IF(Time!P39=1,P12,P11)*Time!P26 -> 0 | Q13: =IF(Time!Q39=1,Q12,Q11)*Time!Q26 -> 0 | ... DB13: =IF(Time!DB39=1,DB12,DB11)*Time!DB26 -> 73.986251
D14: Toll revenue
D15: Weighted class multiplier, original | E15: factor | F15: =((Inputs!$F$129-Inputs!$F$224)*Inputs!$F$138+Inputs!$F$130*Inputs!$F$135+(Inputs!$F$131+Inputs!$F$224)*Inputs!$F$136)/100 -> 1.2686
D16: Weighted class multiplier, from 2024 (restructured) | E16: factor | F16: =(Inputs!$F$132*Inputs!$F$138+Inputs!$F$133*Inputs!$F$135+Inputs!$F$134*Inputs!$F$137)/100 -> 1.2448
D17: Weighted class multiplier | E17: factor | J17: =IF(Time!J23=1,$F$16,$F$15) -> 1.2686 | K17: =IF(Time!K23=1,$F$16,$F$15) -> 1.2686 | L17: =IF(Time!L23=1,$F$16,$F$15) -> 1.2686 | M17: =IF(Time!M23=1,$F$16,$F$15) -> 1.2686 | N17: =IF(Time!N23=1,$F$16,$F$15) -> 1.2686 | O17: =IF(Time!O23=1,$F$16,$F$15) -> 1.2686 | P17: =IF(Time!P23=1,$F$16,$F$15) -> 1.2686 | Q17: =IF(Time!Q23=1,$F$16,$F$15) -> 1.2686 | ... DB17: =IF(Time!DB23=1,$F$16,$F$15) -> 1.2448
D18: Gross toll revenue | E18: ARD m | G18: =SUM(J18:DB18) -> 8675.2587 | J18: =J13*Inputs!$F$64*Time!J25*Inputs!$F$127*Time!J60*J17/Inputs!$F$65 -> 0 | K18: =K13*Inputs!$F$64*Time!K25*Inputs!$F$127*Time!K60*K17/Inputs!$F$65 -> 0 | L18: =L13*Inputs!$F$64*Time!L25*Inputs!$F$127*Time!L60*L17/Inputs!$F$65 -> 0 | M18: =M13*Inputs!$F$64*Time!M25*Inputs!$F$127*Time!M60*M17/Inputs!$F$65 -> 0 | N18: =N13*Inputs!$F$64*Time!N25*Inputs!$F$127*Time!N60*N17/Inputs!$F$65 -> 0 | O18: =O13*Inputs!$F$64*Time!O25*Inputs!$F$127*Time!O60*O17/Inputs!$F$65 -> 0 | P18: =P13*Inputs!$F$64*Time!P25*Inputs!$F$127*Time!P60*P17/Inputs!$F$65 -> 0 | Q18: =Q13*Inputs!$F$64*Time!Q25*Inputs!$F$127*Time!Q60*Q17/Inputs!$F$65 -> 0 | ... DB18: =DB13*Inputs!$F$64*Time!DB25*Inputs!$F$127*Time!DB60*DB17/Inputs!$F$65 -> 163.27544
D19: Revenue leakage | E19: ARD m | G19: =SUM(J19:DB19) -> 156.15466 | J19: =J18*Inputs!$F$128 -> 0 | K19: =K18*Inputs!$F$128 -> 0 | L19: =L18*Inputs!$F$128 -> 0 | M19: =M18*Inputs!$F$128 -> 0 | N19: =N18*Inputs!$F$128 -> 0 | O19: =O18*Inputs!$F$128 -> 0 | P19: =P18*Inputs!$F$128 -> 0 | Q19: =Q18*Inputs!$F$128 -> 0 | ... DB19: =DB18*Inputs!$F$128 -> 2.9389579
D20: Net toll revenue | E20: ARD m | G20: =SUM(J20:DB20) -> 8519.1041 | J20: =J18-J19 -> 0 | K20: =K18-K19 -> 0 | L20: =L18-L19 -> 0 | M20: =M18-M19 -> 0 | N20: =N18-N19 -> 0 | O20: =O18-O19 -> 0 | P20: =P18-P19 -> 0 | Q20: =Q18-Q19 -> 0 | ... DB20: =DB18-DB19 -> 160.33648
D21: Delay liquidated damages received | E21: ARD m | G21: =SUM(J21:DB21) -> 10.26 | J21: =IF(AND(Inputs!$F$213=1,Time!J27=1),Inputs!$F$78,0) -> 0 | K21: =IF(AND(Inputs!$F$213=1,Time!K27=1),Inputs!$F$78,0) -> 0 | L21: =IF(AND(Inputs!$F$213=1,Time!L27=1),Inputs!$F$78,0) -> 0 | M21: =IF(AND(Inputs!$F$213=1,Time!M27=1),Inputs!$F$78,0) -> 0 | N21: =IF(AND(Inputs!$F$213=1,Time!N27=1),Inputs!$F$78,0) -> 0 | O21: =IF(AND(Inputs!$F$213=1,Time!O27=1),Inputs!$F$78,0) -> 0 | P21: =IF(AND(Inputs!$F$213=1,Time!P27=1),Inputs!$F$78,0) -> 0 | Q21: =IF(AND(Inputs!$F$213=1,Time!Q27=1),Inputs!$F$78,0) -> 0 | ... DB21: =IF(AND(Inputs!$F$213=1,Time!DB27=1),Inputs!$F$78,0) -> 0
D22: Operating costs
D23: Cost factor (CPI x operating days / 365 x opex factor) | E23: factor | J23: =Time!J56*Time!J25/Inputs!$F$45*Inputs!$F$221 -> 0 | K23: =Time!K56*Time!K25/Inputs!$F$45*Inputs!$F$221 -> 0 | L23: =Time!L56*Time!L25/Inputs!$F$45*Inputs!$F$221 -> 0 | M23: =Time!M56*Time!M25/Inputs!$F$45*Inputs!$F$221 -> 0 | N23: =Time!N56*Time!N25/Inputs!$F$45*Inputs!$F$221 -> 0 | O23: =Time!O56*Time!O25/Inputs!$F$45*Inputs!$F$221 -> 0 | P23: =Time!P56*Time!P25/Inputs!$F$45*Inputs!$F$221 -> 0 | Q23: =Time!Q56*Time!Q25/Inputs!$F$45*Inputs!$F$221 -> 0 | ... DB23: =Time!DB56*Time!DB25/Inputs!$F$45*Inputs!$F$221 -> 1.2390462
D24: Corvus fixed O&M | E24: ARD m | G24: =SUM(J24:DB24) -> 858.3272 | J24: =Inputs!$F$141*J23*IF(Time!J23=1,1-Inputs!$F$142,1) -> 0 | K24: =Inputs!$F$141*K23*IF(Time!K23=1,1-Inputs!$F$142,1) -> 0 | L24: =Inputs!$F$141*L23*IF(Time!L23=1,1-Inputs!$F$142,1) -> 0 | M24: =Inputs!$F$141*M23*IF(Time!M23=1,1-Inputs!$F$142,1) -> 0 | N24: =Inputs!$F$141*N23*IF(Time!N23=1,1-Inputs!$F$142,1) -> 0 | O24: =Inputs!$F$141*O23*IF(Time!O23=1,1-Inputs!$F$142,1) -> 0 | P24: =Inputs!$F$141*P23*IF(Time!P23=1,1-Inputs!$F$142,1) -> 0 | Q24: =Inputs!$F$141*Q23*IF(Time!Q23=1,1-Inputs!$F$142,1) -> 0 | ... DB24: =Inputs!$F$141*DB23*IF(Time!DB23=1,1-Inputs!$F$142,1) -> 13.496682
D25: Tolling back office, fixed | E25: ARD m | G25: =SUM(J25:DB25) -> 168.41401 | J25: =Inputs!$F$144*J23 -> 0 | K25: =Inputs!$F$144*K23 -> 0 | L25: =Inputs!$F$144*L23 -> 0 | M25: =Inputs!$F$144*M23 -> 0 | N25: =Inputs!$F$144*N23 -> 0 | O25: =Inputs!$F$144*O23 -> 0 | P25: =Inputs!$F$144*P23 -> 0 | Q25: =Inputs!$F$144*Q23 -> 0 | ... DB25: =Inputs!$F$144*DB23 -> 2.6639493
D26: Tolling back office, variable | E26: ARD m | G26: =SUM(J26:DB26) -> 528.18445 | J26: =Inputs!$F$143*J20*Inputs!$F$221 -> 0 | K26: =Inputs!$F$143*K20*Inputs!$F$221 -> 0 | L26: =Inputs!$F$143*L20*Inputs!$F$221 -> 0 | M26: =Inputs!$F$143*M20*Inputs!$F$221 -> 0 | N26: =Inputs!$F$143*N20*Inputs!$F$221 -> 0 | O26: =Inputs!$F$143*O20*Inputs!$F$221 -> 0 | P26: =Inputs!$F$143*P20*Inputs!$F$221 -> 0 | Q26: =Inputs!$F$143*Q20*Inputs!$F$221 -> 0 | ... DB26: =Inputs!$F$143*DB20*Inputs!$F$221 -> 9.940862
D27: Insurance | E27: ARD m | G27: =SUM(J27:DB27) -> 263.19584 | J27: =Inputs!$F$145*J23 -> 0 | K27: =Inputs!$F$145*K23 -> 0 | L27: =Inputs!$F$145*L23 -> 0 | M27: =Inputs!$F$145*M23 -> 0 | N27: =Inputs!$F$145*N23 -> 0 | O27: =Inputs!$F$145*O23 -> 0 | P27: =Inputs!$F$145*P23 -> 0 | Q27: =Inputs!$F$145*Q23 -> 0 | ... DB27: =Inputs!$F$145*DB23 -> 4.1631952
D28: Project company costs | E28: ARD m | G28: =SUM(J28:DB28) -> 212.27998 | J28: =Inputs!$F$146*J23 -> 0 | K28: =Inputs!$F$146*K23 -> 0 | L28: =Inputs!$F$146*L23 -> 0 | M28: =Inputs!$F$146*M23 -> 0 | N28: =Inputs!$F$146*N23 -> 0 | O28: =Inputs!$F$146*O23 -> 0 | P28: =Inputs!$F$146*P23 -> 0 | Q28: =Inputs!$F$146*Q23 -> 0 | ... DB28: =Inputs!$F$146*DB23 -> 3.3578151
D29: Total operating costs | E29: ARD m | G29: =SUM(J29:DB29) -> 2030.4015 | J29: =J24+J25+J26+J27+J28 -> 0 | K29: =K24+K25+K26+K27+K28 -> 0 | L29: =L24+L25+L26+L27+L28 -> 0 | M29: =M24+M25+M26+M27+M28 -> 0 | N29: =N24+N25+N26+N27+N28 -> 0 | O29: =O24+O25+O26+O27+O28 -> 0 | P29: =P24+P25+P26+P27+P28 -> 0 | Q29: =Q24+Q25+Q26+Q27+Q28 -> 0 | ... DB29: =DB24+DB25+DB26+DB27+DB28 -> 33.622504
D30: State revenue share | E30: ARD m | G30: =SUM(J30:DB30) -> 0 | J30: =IF(Time!J23=1,Inputs!$F$176*MAX(0,J20-Inputs!$F$177*Time!J56/Time!$F$57*Time!J25/Inputs!$F$45),0) -> 0 | K30: =IF(Time!K23=1,Inputs!$F$176*MAX(0,K20-Inputs!$F$177*Time!K56/Time!$F$57*Time!K25/Inputs!$F$45),0) -> 0 | L30: =IF(Time!L23=1,Inputs!$F$176*MAX(0,L20-Inputs!$F$177*Time!L56/Time!$F$57*Time!L25/Inputs!$F$45),0) -> 0 | M30: =IF(Time!M23=1,Inputs!$F$176*MAX(0,M20-Inputs!$F$177*Time!M56/Time!$F$57*Time!M25/Inputs!$F$45),0) -> 0 | N30: =IF(Time!N23=1,Inputs!$F$176*MAX(0,N20-Inputs!$F$177*Time!N56/Time!$F$57*Time!N25/Inputs!$F$45),0) -> 0 | O30: =IF(Time!O23=1,Inputs!$F$176*MAX(0,O20-Inputs!$F$177*Time!O56/Time!$F$57*Time!O25/Inputs!$F$45),0) -> 0 | P30: =IF(Time!P23=1,Inputs!$F$176*MAX(0,P20-Inputs!$F$177*Time!P56/Time!$F$57*Time!P25/Inputs!$F$45),0) -> 0 | Q30: =IF(Time!Q23=1,Inputs!$F$176*MAX(0,Q20-Inputs!$F$177*Time!Q56/Time!$F$57*Time!Q25/Inputs!$F$45),0) -> 0 | ... DB30: =IF(Time!DB23=1,Inputs!$F$176*MAX(0,DB20-Inputs!$F$177*Time!DB56/Time!$F$57*Time!DB25/Inputs!$F$45),0) -> 0
D31: Restructuring costs | E31: ARD m | G31: =SUM(J31:DB31) -> 21.6 | J31: =IF(AND(Time!J39=1,Time!J8>=Inputs!$F$38,Time!J8<=Inputs!$F$20),Inputs!$F$161/Inputs!$F$162,0) -> 0 | K31: =IF(AND(Time!K39=1,Time!K8>=Inputs!$F$38,Time!K8<=Inputs!$F$20),Inputs!$F$161/Inputs!$F$162,0) -> 0 | L31: =IF(AND(Time!L39=1,Time!L8>=Inputs!$F$38,Time!L8<=Inputs!$F$20),Inputs!$F$161/Inputs!$F$162,0) -> 0 | M31: =IF(AND(Time!M39=1,Time!M8>=Inputs!$F$38,Time!M8<=Inputs!$F$20),Inputs!$F$161/Inputs!$F$162,0) -> 0 | N31: =IF(AND(Time!N39=1,Time!N8>=Inputs!$F$38,Time!N8<=Inputs!$F$20),Inputs!$F$161/Inputs!$F$162,0) -> 0 | O31: =IF(AND(Time!O39=1,Time!O8>=Inputs!$F$38,Time!O8<=Inputs!$F$20),Inputs!$F$161/Inputs!$F$162,0) -> 0 | P31: =IF(AND(Time!P39=1,Time!P8>=Inputs!$F$38,Time!P8<=Inputs!$F$20),Inputs!$F$161/Inputs!$F$162,0) -> 0 | Q31: =IF(AND(Time!Q39=1,Time!Q8>=Inputs!$F$38,Time!Q8<=Inputs!$F$20),Inputs!$F$161/Inputs!$F$162,0) -> 0 | ... DB31: =IF(AND(Time!DB39=1,Time!DB8>=Inputs!$F$38,Time!DB8<=Inputs!$F$20),Inputs!$F$161/Inputs!$F$162,0) -> 0
D32: EBITDA | E32: ARD m | G32: =SUM(J32:DB32) -> 6477.3626 | J32: =J20+J21-J29-J30-J31 -> 0 | K32: =K20+K21-K29-K30-K31 -> 0 | L32: =L20+L21-L29-L30-L31 -> 0 | M32: =M20+M21-M29-M30-M31 -> 0 | N32: =N20+N21-N29-N30-N31 -> 0 | O32: =O20+O21-O29-O30-O31 -> 0 | P32: =P20+P21-P29-P30-P31 -> 0 | Q32: =Q20+Q21-Q29-Q30-Q31 -> 0 | ... DB32: =DB20+DB21-DB29-DB30-DB31 -> 126.71398
D33: Lifecycle and handback
D34: Operating year (H2 periods) | E34: # | J34: =IF(AND(Time!J12=2,Time!J26=1,Time!J8<=Time!$F$17),Time!J11-Inputs!$F$60,0) -> 0 | K34: =IF(AND(Time!K12=2,Time!K26=1,Time!K8<=Time!$F$17),Time!K11-Inputs!$F$60,0) -> 0 | L34: =IF(AND(Time!L12=2,Time!L26=1,Time!L8<=Time!$F$17),Time!L11-Inputs!$F$60,0) -> 0 | M34: =IF(AND(Time!M12=2,Time!M26=1,Time!M8<=Time!$F$17),Time!M11-Inputs!$F$60,0) -> 0 | N34: =IF(AND(Time!N12=2,Time!N26=1,Time!N8<=Time!$F$17),Time!N11-Inputs!$F$60,0) -> 0 | O34: =IF(AND(Time!O12=2,Time!O26=1,Time!O8<=Time!$F$17),Time!O11-Inputs!$F$60,0) -> 0 | P34: =IF(AND(Time!P12=2,Time!P26=1,Time!P8<=Time!$F$17),Time!P11-Inputs!$F$60,0) -> 0 | Q34: =IF(AND(Time!Q12=2,Time!Q26=1,Time!Q8<=Time!$F$17),Time!Q11-Inputs!$F$60,0) -> 0 | ... DB34: =IF(AND(Time!DB12=2,Time!DB26=1,Time!DB8<=Time!$F$17),Time!DB11-Inputs!$F$60,0) -> 0
D35: Lifecycle works (2015 prices) | E35: ARD m | G35: =SUM(J35:DB35) -> 265.1 | J35: =IF(J34>0,Inputs!$F$147*IF(MOD(J34,Inputs!$F$148)=0,1,0)+Inputs!$F$149*IF(MOD(J34,Inputs!$F$150)=0,1,0)+Inputs!$F$151*IF(MOD(J34,Inputs!$F$152)=0,1,0),0) -> 0 | K35: =IF(K34>0,Inputs!$F$147*IF(MOD(K34,Inputs!$F$148)=0,1,0)+Inputs!$F$149*IF(MOD(K34,Inputs!$F$150)=0,1,0)+Inputs!$F$151*IF(MOD(K34,Inputs!$F$152)=0,1,0),0) -> 0 | L35: =IF(L34>0,Inputs!$F$147*IF(MOD(L34,Inputs!$F$148)=0,1,0)+Inputs!$F$149*IF(MOD(L34,Inputs!$F$150)=0,1,0)+Inputs!$F$151*IF(MOD(L34,Inputs!$F$152)=0,1,0),0) -> 0 | M35: =IF(M34>0,Inputs!$F$147*IF(MOD(M34,Inputs!$F$148)=0,1,0)+Inputs!$F$149*IF(MOD(M34,Inputs!$F$150)=0,1,0)+Inputs!$F$151*IF(MOD(M34,Inputs!$F$152)=0,1,0),0) -> 0 | N35: =IF(N34>0,Inputs!$F$147*IF(MOD(N34,Inputs!$F$148)=0,1,0)+Inputs!$F$149*IF(MOD(N34,Inputs!$F$150)=0,1,0)+Inputs!$F$151*IF(MOD(N34,Inputs!$F$152)=0,1,0),0) -> 0 | O35: =IF(O34>0,Inputs!$F$147*IF(MOD(O34,Inputs!$F$148)=0,1,0)+Inputs!$F$149*IF(MOD(O34,Inputs!$F$150)=0,1,0)+Inputs!$F$151*IF(MOD(O34,Inputs!$F$152)=0,1,0),0) -> 0 | P35: =IF(P34>0,Inputs!$F$147*IF(MOD(P34,Inputs!$F$148)=0,1,0)+Inputs!$F$149*IF(MOD(P34,Inputs!$F$150)=0,1,0)+Inputs!$F$151*IF(MOD(P34,Inputs!$F$152)=0,1,0),0) -> 0 | Q35: =IF(Q34>0,Inputs!$F$147*IF(MOD(Q34,Inputs!$F$148)=0,1,0)+Inputs!$F$149*IF(MOD(Q34,Inputs!$F$150)=0,1,0)+Inputs!$F$151*IF(MOD(Q34,Inputs!$F$152)=0,1,0),0) -> 0 | ... DB35: =IF(DB34>0,Inputs!$F$147*IF(MOD(DB34,Inputs!$F$148)=0,1,0)+Inputs!$F$149*IF(MOD(DB34,Inputs!$F$150)=0,1,0)+Inputs!$F$151*IF(MOD(DB34,Inputs!$F$152)=0,1,0),0) -> 0
D36: Lifecycle works (nominal), paid from the MMRA | E36: ARD m | G36: =SUM(J36:DB36) -> 550.67763 | J36: =J35*Time!J56*Inputs!$F$222 -> 0 | K36: =K35*Time!K56*Inputs!$F$222 -> 0 | L36: =L35*Time!L56*Inputs!$F$222 -> 0 | M36: =M35*Time!M56*Inputs!$F$222 -> 0 | N36: =N35*Time!N56*Inputs!$F$222 -> 0 | O36: =O35*Time!O56*Inputs!$F$222 -> 0 | P36: =P35*Time!P56*Inputs!$F$222 -> 0 | Q36: =Q35*Time!Q56*Inputs!$F$222 -> 0 | ... DB36: =DB35*Time!DB56*Inputs!$F$222 -> 0
D37: Lifecycle reserve contribution (next six periods / 6) | E37: ARD m | G37: =SUM(J37:DB37) -> 550.67763 | J37: =SUM(K36:P36)/Inputs!$F$153 -> 0 | K37: =SUM(L36:Q36)/Inputs!$F$153 -> 0 | L37: =SUM(M36:R36)/Inputs!$F$153 -> 0 | M37: =SUM(N36:S36)/Inputs!$F$153 -> 0 | N37: =SUM(O36:T36)/Inputs!$F$153 -> 0 | O37: =SUM(P36:U36)/Inputs!$F$153 -> 0 | P37: =SUM(Q36:V36)/Inputs!$F$153 -> 0 | Q37: =SUM(R36:W36)/Inputs!$F$153 -> 0 | ... DB37: =SUM(DC36:DH36)/Inputs!$F$153 -> 0
D38: Flag_HandbackFunding | E38: flag | J38: =IF(AND(Time!J26=1,Time!J7>=EDATE(Time!$F$17,-Inputs!$F$49)),1,0) -> 0 | K38: =IF(AND(Time!K26=1,Time!K7>=EDATE(Time!$F$17,-Inputs!$F$49)),1,0) -> 0 | L38: =IF(AND(Time!L26=1,Time!L7>=EDATE(Time!$F$17,-Inputs!$F$49)),1,0) -> 0 | M38: =IF(AND(Time!M26=1,Time!M7>=EDATE(Time!$F$17,-Inputs!$F$49)),1,0) -> 0 | N38: =IF(AND(Time!N26=1,Time!N7>=EDATE(Time!$F$17,-Inputs!$F$49)),1,0) -> 0 | O38: =IF(AND(Time!O26=1,Time!O7>=EDATE(Time!$F$17,-Inputs!$F$49)),1,0) -> 0 | P38: =IF(AND(Time!P26=1,Time!P7>=EDATE(Time!$F$17,-Inputs!$F$49)),1,0) -> 0 | Q38: =IF(AND(Time!Q26=1,Time!Q7>=EDATE(Time!$F$17,-Inputs!$F$49)),1,0) -> 0 | ... DB38: =IF(AND(Time!DB26=1,Time!DB7>=EDATE(Time!$F$17,-Inputs!$F$49)),1,0) -> 1
D39: Handback reserve contribution | E39: ARD m | G39: =SUM(J39:DB39) -> 124.14388 | J39: =Inputs!$F$154*Time!J56*Inputs!$F$222/Inputs!$F$155*J38 -> 0 | K39: =Inputs!$F$154*Time!K56*Inputs!$F$222/Inputs!$F$155*K38 -> 0 | L39: =Inputs!$F$154*Time!L56*Inputs!$F$222/Inputs!$F$155*L38 -> 0 | M39: =Inputs!$F$154*Time!M56*Inputs!$F$222/Inputs!$F$155*M38 -> 0 | N39: =Inputs!$F$154*Time!N56*Inputs!$F$222/Inputs!$F$155*N38 -> 0 | O39: =Inputs!$F$154*Time!O56*Inputs!$F$222/Inputs!$F$155*O38 -> 0 | P39: =Inputs!$F$154*Time!P56*Inputs!$F$222/Inputs!$F$155*P38 -> 0 | Q39: =Inputs!$F$154*Time!Q56*Inputs!$F$222/Inputs!$F$155*Q38 -> 0 | ... DB39: =Inputs!$F$154*Time!DB56*Inputs!$F$222/Inputs!$F$155*DB38 -> 13.195842
D40: Working capital
D41: Toll receivables | E41: ARD m | J41: =IF(AND(Time!J26=1,Time!J28=0),J20/Time!J25*Inputs!$F$156,0) -> 0 | K41: =IF(AND(Time!K26=1,Time!K28=0),K20/Time!K25*Inputs!$F$156,0) -> 0 | L41: =IF(AND(Time!L26=1,Time!L28=0),L20/Time!L25*Inputs!$F$156,0) -> 0 | M41: =IF(AND(Time!M26=1,Time!M28=0),M20/Time!M25*Inputs!$F$156,0) -> 0 | N41: =IF(AND(Time!N26=1,Time!N28=0),N20/Time!N25*Inputs!$F$156,0) -> 0 | O41: =IF(AND(Time!O26=1,Time!O28=0),O20/Time!O25*Inputs!$F$156,0) -> 0 | P41: =IF(AND(Time!P26=1,Time!P28=0),P20/Time!P25*Inputs!$F$156,0) -> 0 | Q41: =IF(AND(Time!Q26=1,Time!Q28=0),Q20/Time!Q25*Inputs!$F$156,0) -> 0 | ... DB41: =IF(AND(Time!DB26=1,Time!DB28=0),DB20/Time!DB25*Inputs!$F$156,0) -> 0
...

Sheet Tax
D1: Case T: Merrick Link toll road PPP | Tax
D2: Units: ARD millions unless stated. Inputs blue on yellow; links green; calculations black.
D3: Period end | E3: date | J3: =Time!J8 -> 42185 | K3: =Time!K8 -> 42277 | L3: =Time!L8 -> 42369 | M3: =Time!M8 -> 42460 | N3: =Time!N8 -> 42551 | O3: =Time!O8 -> 42643 | P3: =Time!P8 -> 42735 | Q3: =Time!Q8 -> 42825 | ... DB3: =Time!DB8 -> 58256
D5: Tax cost base of the concession asset
D6: Opening tax written-down value | E6: ARD m | J6: =I11 -> 0 | K6: =J11 -> 73.414541 | L6: =K11 -> 104.99317 | M6: =L11 -> 168.75744 | N6: =M11 -> 270.51178 | O6: =N11 -> 410.61034 | P6: =O11 -> 584.71411 | Q6: =P11 -> 782.99668 | ... DB6: =DA11 -> 16.083795
D7: Additions (capitalized cost less contribution plus upgrade) | E7: ARD m | G7: =SUM(J7:DB7) -> 1915.5053 | J7: =Funding!J41-Funding!J39+Operations!J45 -> 73.414541 | K7: =Funding!K41-Funding!K39+Operations!K45 -> 31.578625 | L7: =Funding!L41-Funding!L39+Operations!L45 -> 63.764276 | M7: =Funding!M41-Funding!M39+Operations!M45 -> 101.75434 | N7: =Funding!N41-Funding!N39+Operations!N45 -> 140.09856 | O7: =Funding!O41-Funding!O39+Operations!O45 -> 174.10377 | P7: =Funding!P41-Funding!P39+Operations!P45 -> 198.28257 | Q7: =Funding!Q41-Funding!Q39+Operations!Q45 -> 211.6284 | ... DB7: =Funding!DB41-Funding!DB39+Operations!DB45 -> 0
D8: Tax amortization (straight line over remaining term) | E8: ARD m | G8: =SUM(J8:DB8) -> 1673.7071 | J8: =IF(Time!J29>0,J6*Time!J25/Time!J29,0) -> 0 | K8: =IF(Time!K29>0,K6*Time!K25/Time!K29,0) -> 0 | L8: =IF(Time!L29>0,L6*Time!L25/Time!L29,0) -> 0 | M8: =IF(Time!M29>0,M6*Time!M25/Time!M29,0) -> 0 | N8: =IF(Time!N29>0,N6*Time!N25/Time!N29,0) -> 0 | O8: =IF(Time!O29>0,O6*Time!O25/Time!O29,0) -> 0 | P8: =IF(Time!P29>0,P6*Time!P25/Time!P29,0) -> 0 | Q8: =IF(Time!Q29>0,Q6*Time!Q25/Time!Q29,0) -> 0 | ... DB8: =IF(Time!DB29>0,DB6*Time!DB25/Time!DB29,0) -> 16.083795
D9: Value before forgiveness | E9: ARD m | J9: =J6+J7-J8 -> 73.414541 | K9: =K6+K7-K8 -> 104.99317 | L9: =L6+L7-L8 -> 168.75744 | M9: =M6+M7-M8 -> 270.51178 | N9: =N6+N7-N8 -> 410.61034 | O9: =O6+O7-O8 -> 584.71411 | P9: =P6+P7-P8 -> 782.99668 | Q9: =Q6+Q7-Q8 -> 994.62508 | ... DB9: =DB6+DB7-DB8 -> 0
D10: Debt forgiveness applied to cost base | E10: ARD m | G10: =SUM(J10:DB10) -> 241.79816 | J10: =MIN(J19-J20,J9) -> 0 | K10: =MIN(K19-K20,K9) -> 0 | L10: =MIN(L19-L20,L9) -> 0 | M10: =MIN(M19-M20,M9) -> 0 | N10: =MIN(N19-N20,N9) -> 0 | O10: =MIN(O19-O20,O9) -> 0 | P10: =MIN(P19-P20,P9) -> 0 | Q10: =MIN(Q19-Q20,Q9) -> 0 | ... DB10: =MIN(DB19-DB20,DB9) -> 0
D11: Closing tax written-down value | E11: ARD m | J11: =J9-J10 -> 73.414541 | K11: =K9-K10 -> 104.99317 | L11: =L9-L10 -> 168.75744 | M11: =M9-M10 -> 270.51178 | N11: =N9-N10 -> 410.61034 | O11: =O9-O10 -> 584.71411 | P11: =P9-P10 -> 782.99668 | Q11: =Q9-Q10 -> 994.62508 | ... DB11: =DB9-DB10 -> 0
D12: Taxable income
D13: NILO interest accrued (deductible) | E13: ARD m | G13: =SUM(J13:DB13) -> 503.83999 | J13: =Debt!J97*(1-Time!J20) -> 0 | K13: =Debt!K97*(1-Time!K20) -> 0 | L13: =Debt!L97*(1-Time!L20) -> 0 | M13: =Debt!M97*(1-Time!M20) -> 0 | N13: =Debt!N97*(1-Time!N20) -> 0 | O13: =Debt!O97*(1-Time!O20) -> 0 | P13: =Debt!P97*(1-Time!P20) -> 0 | Q13: =Debt!Q97*(1-Time!Q20) -> 0 | ... DB13: =Debt!DB97*(1-Time!DB20) -> 5.0901589e-13
D14: Shareholder loan interest accrued (deductible) | E14: ARD m | G14: =SUM(J14:DB14) -> 281.98031 | J14: =Waterfall!J54*(1-Time!J20) -> 0 | K14: =Waterfall!K54*(1-Time!K20) -> 0 | L14: =Waterfall!L54*(1-Time!L20) -> 0 | M14: =Waterfall!M54*(1-Time!M20) -> 0 | N14: =Waterfall!N54*(1-Time!N20) -> 0 | O14: =Waterfall!O54*(1-Time!O20) -> 0 | P14: =Waterfall!P54*(1-Time!P20) -> 0 | Q14: =Waterfall!Q54*(1-Time!Q20) -> 0 | ... DB14: =Waterfall!DB54*(1-Time!DB20) -> 0
D15: Taxable income before losses | E15: ARD m | G15: =SUM(J15:DB15) -> 2623.282 | J15: =(Operations!J32-Operations!J36-Reserves!J22-J8-Debt!J64-J13-J14-Debt!J65)*(1-Time!J20) -> 0 | K15: =(Operations!K32-Operations!K36-Reserves!K22-K8-Debt!K64-K13-K14-Debt!K65)*(1-Time!K20) -> 0 | L15: =(Operations!L32-Operations!L36-Reserves!L22-L8-Debt!L64-L13-L14-Debt!L65)*(1-Time!L20) -> 0 | M15: =(Operations!M32-Operations!M36-Reserves!M22-M8-Debt!M64-M13-M14-Debt!M65)*(1-Time!M20) -> 0 | N15: =(Operations!N32-Operations!N36-Reserves!N22-N8-Debt!N64-N13-N14-Debt!N65)*(1-Time!N20) -> 0 | O15: =(Operations!O32-Operations!O36-Reserves!O22-O8-Debt!O64-O13-O14-Debt!O65)*(1-Time!O20) -> 0 | P15: =(Operations!P32-Operations!P36-Reserves!P22-P8-Debt!P64-P13-P14-Debt!P65)*(1-Time!P20) -> 0 | Q15: =(Operations!Q32-Operations!Q36-Reserves!Q22-Q8-Debt!Q64-Q13-Q14-Debt!Q65)*(1-Time!Q20) -> 0 | ... DB15: =(Operations!DB32-Operations!DB36-Reserves!DB22-DB8-Debt!DB64-DB13-DB14-Debt!DB65)*(1-Time!DB20) -> -13.513692
D16: Tax losses brought forward | E16: ARD m | J16: =I21 -> 0 | K16: =J21 -> 0 | L16: =K21 -> 0 | M16: =L21 -> 0 | N16: =M21 -> 0 | O16: =N21 -> 0 | P16: =O21 -> 0 | Q16: =P21 -> 0 | ... DB16: =DA21 -> 0
D17: Losses used | E17: ARD m | G17: =SUM(J17:DB17) -> 167.51578 | J17: =MIN(J16,MAX(0,J15)) -> 0 | K17: =MIN(K16,MAX(0,K15)) -> 0 | L17: =MIN(L16,MAX(0,L15)) -> 0 | M17: =MIN(M16,MAX(0,M15)) -> 0 | N17: =MIN(N16,MAX(0,N15)) -> 0 | O17: =MIN(O16,MAX(0,O15)) -> 0 | P17: =MIN(P16,MAX(0,P15)) -> 0 | Q17: =MIN(Q16,MAX(0,Q15)) -> 0 | ... DB17: =MIN(DB16,MAX(0,DB15)) -> 0
D18: Losses added | E18: ARD m | G18: =SUM(J18:DB18) -> 823.69926 | J18: =MAX(0,-J15) -> 0 | K18: =MAX(0,-K15) -> 0 | L18: =MAX(0,-L15) -> 0 | M18: =MAX(0,-M15) -> 0 | N18: =MAX(0,-N15) -> 0 | O18: =MAX(0,-O15) -> 0 | P18: =MAX(0,-P15) -> 0 | Q18: =MAX(0,-Q15) -> 0 | ... DB18: =MAX(0,-DB15) -> 13.513692
D19: Forgiven commercial debt (cancelled claims plus shareholder loans) | E19: ARD m | G19: =SUM(J19:DB19) -> 884.46795 | J19: =Time!J35*(Debt!J79+Debt!J80) -> 0 | K19: =Time!K35*(Debt!K79+Debt!K80) -> 0 | L19: =Time!L35*(Debt!L79+Debt!L80) -> 0 | M19: =Time!M35*(Debt!M79+Debt!M80) -> 0 | N19: =Time!N35*(Debt!N79+Debt!N80) -> 0 | O19: =Time!O35*(Debt!O79+Debt!O80) -> 0 | P19: =Time!P35*(Debt!P79+Debt!P80) -> 0 | Q19: =Time!Q35*(Debt!Q79+Debt!Q80) -> 0 | ... DB19: =Time!DB35*(Debt!DB79+Debt!DB80) -> 0
D20: Forgiveness applied to losses | E20: ARD m | G20: =SUM(J20:DB20) -> 642.66979 | J20: =MIN(J19,J16-J17+J18) -> 0 | K20: =MIN(K19,K16-K17+K18) -> 0 | L20: =MIN(L19,L16-L17+L18) -> 0 | M20: =MIN(M19,M16-M17+M18) -> 0 | N20: =MIN(N19,N16-N17+N18) -> 0 | O20: =MIN(O19,O16-O17+O18) -> 0 | P20: =MIN(P19,P16-P17+P18) -> 0 | Q20: =MIN(Q19,Q16-Q17+Q18) -> 0 | ... DB20: =MIN(DB19,DB16-DB17+DB18) -> 0
D21: Tax losses carried forward | E21: ARD m | J21: =J16-J17+J18-J20 -> 0 | K21: =K16-K17+K18-K20 -> 0 | L21: =L16-L17+L18-L20 -> 0 | M21: =M16-M17+M18-M20 -> 0 | N21: =N16-N17+N18-N20 -> 0 | O21: =O16-O17+O18-O20 -> 0 | P21: =P16-P17+P18-P20 -> 0 | Q21: =Q16-Q17+Q18-Q20 -> 0 | ... DB21: =DB16-DB17+DB18-DB20 -> 13.513692
D22: Taxable income after losses | E22: ARD m | G22: =SUM(J22:DB22) -> 3279.4655 | J22: =MAX(0,J15)-J17 -> 0 | K22: =MAX(0,K15)-K17 -> 0 | L22: =MAX(0,L15)-L17 -> 0 | M22: =MAX(0,M15)-M17 -> 0 | N22: =MAX(0,N15)-N17 -> 0 | O22: =MAX(0,O15)-O17 -> 0 | P22: =MAX(0,P15)-P17 -> 0 | Q22: =MAX(0,Q15)-Q17 -> 0 | ... DB22: =MAX(0,DB15)-DB17 -> 0
D23: Tax paid | E23: ARD m | G23: =SUM(J23:DB23) -> 983.83964 | J23: =Inputs!$F$158*J22 -> 0 | K23: =Inputs!$F$158*K22 -> 0 | L23: =Inputs!$F$158*L22 -> 0 | M23: =Inputs!$F$158*M22 -> 0 | N23: =Inputs!$F$158*N22 -> 0 | O23: =Inputs!$F$158*O22 -> 0 | P23: =Inputs!$F$158*P22 -> 0 | Q23: =Inputs!$F$158*Q22 -> 0 | ... DB23: =Inputs!$F$158*DB22 -> 0

Sheet Funding
D1: Case T: Merrick Link toll road PPP | Funding
D2: Units: ARD millions unless stated. Inputs blue on yellow; links green; calculations black.
D3: Period end | E3: date | J3: =Time!J8 -> 42185 | K3: =Time!K8 -> 42277 | L3: =Time!L8 -> 42369 | M3: =Time!M8 -> 42460 | N3: =Time!N8 -> 42551 | O3: =Time!O8 -> 42643 | P3: =Time!P8 -> 42735 | Q3: =Time!Q8 -> 42825 | ... DB3: =Time!DB8 -> 58256
D5: Commitments
D6: Bank mini-perm commitment | E6: ARD m | F6: =Inputs!$F$96*Debt!$F$26 -> 396.95858
D7: Bond face value (fully funded at close into escrow) | E7: ARD m | F7: =Inputs!$F$97*Debt!$F$26 -> 485.17159
D8: Uses of funds
D9: Construction costs | E9: ARD m | G9: =SUM(J9:DB9) -> 1841.4 | J9: =Construction!J13 -> 55.351416 | K9: =Construction!K13 -> 25.701277 | L9: =Construction!L13 -> 57.187205 | M9: =Construction!M13 -> 93.790892 | N9: =Construction!N13 -> 129.91074 | O9: =Construction!O13 -> 161.00849 | P9: =Construction!P13 -> 183.60753 | Q9: =Construction!Q13 -> 195.4016 | ... DB9: =Construction!DB13 -> 0
D10: Upfront fees (bank, bond issue, NILO, bridge) | E10: ARD m | G10: =SUM(J10:DB10) -> 16.503927 | J10: =IF(Time!J6=1,Inputs!$F$108*$F$6+Inputs!$F$112*$F$7+Inputs!$F$121*Debt!$F$28+Inputs!$F$84*Inputs!$F$227,0) -> 16.503927 | K10: =IF(Time!K6=1,Inputs!$F$108*$F$6+Inputs!$F$112*$F$7+Inputs!$F$121*Debt!$F$28+Inputs!$F$84*Inputs!$F$227,0) -> 0 | L10: =IF(Time!L6=1,Inputs!$F$108*$F$6+Inputs!$F$112*$F$7+Inputs!$F$121*Debt!$F$28+Inputs!$F$84*Inputs!$F$227,0) -> 0 | M10: =IF(Time!M6=1,Inputs!$F$108*$F$6+Inputs!$F$112*$F$7+Inputs!$F$121*Debt!$F$28+Inputs!$F$84*Inputs!$F$227,0) -> 0 | N10: =IF(Time!N6=1,Inputs!$F$108*$F$6+Inputs!$F$112*$F$7+Inputs!$F$121*Debt!$F$28+Inputs!$F$84*Inputs!$F$227,0) -> 0 | O10: =IF(Time!O6=1,Inputs!$F$108*$F$6+Inputs!$F$112*$F$7+Inputs!$F$121*Debt!$F$28+Inputs!$F$84*Inputs!$F$227,0) -> 0 | P10: =IF(Time!P6=1,Inputs!$F$108*$F$6+Inputs!$F$112*$F$7+Inputs!$F$121*Debt!$F$28+Inputs!$F$84*Inputs!$F$227,0) -> 0 | Q10: =IF(Time!Q6=1,Inputs!$F$108*$F$6+Inputs!$F$112*$F$7+Inputs!$F$121*Debt!$F$28+Inputs!$F$84*Inputs!$F$227,0) -> 0 | ... DB10: =IF(Time!DB6=1,Inputs!$F$108*$F$6+Inputs!$F$112*$F$7+Inputs!$F$121*Debt!$F$28+Inputs!$F$84*Inputs!$F$227,0) -> 0
D11: Bank interest during construction | E11: ARD m | G11: =SUM(J11:DB11) -> 37.9294 | J11: =Debt!J43*Time!J20 -> 0 | K11: =Debt!K43*Time!K20 -> 0 | L11: =Debt!L43*Time!L20 -> 0 | M11: =Debt!M43*Time!M20 -> 0 | N11: =Debt!N43*Time!N20 -> 0 | O11: =Debt!O43*Time!O20 -> 0.075326408 | P11: =Debt!P43*Time!P20 -> 0.79185685 | Q11: =Debt!Q43*Time!Q20 -> 1.5752662 | ... DB11: =Debt!DB43*Time!DB20 -> 0
D12: Bank commitment fee | E12: ARD m | G12: =SUM(J12:DB12) -> 8.3252397 | J12: =Inputs!$F$109*($F$6-Debt!J42)*Time!J9/Inputs!$F$45*Time!J20 -> 0.35128115 | K12: =Inputs!$F$109*($F$6-Debt!K42)*Time!K9/Inputs!$F$45*Time!K20 -> 0.95052547 | L12: =Inputs!$F$109*($F$6-Debt!L42)*Time!L9/Inputs!$F$45*Time!L20 -> 0.95052547 | M12: =Inputs!$F$109*($F$6-Debt!M42)*Time!M9/Inputs!$F$45*Time!M20 -> 0.94019367 | N12: =Inputs!$F$109*($F$6-Debt!N42)*Time!N9/Inputs!$F$45*Time!N20 -> 0.94019367 | O12: =Inputs!$F$109*($F$6-Debt!O42)*Time!O9/Inputs!$F$45*Time!O20 -> 0.93825101 | P12: =Inputs!$F$109*($F$6-Debt!P42)*Time!P9/Inputs!$F$45*Time!P20 -> 0.82149219 | Q12: =Inputs!$F$109*($F$6-Debt!Q42)*Time!Q9/Inputs!$F$45*Time!Q20 -> 0.67317183 | ... DB12: =Inputs!$F$109*($F$6-Debt!DB42)*Time!DB9/Inputs!$F$45*Time!DB20 -> 0
D13: Bond interest during construction | E13: ARD m | G13: =SUM(J13:DB13) -> 90.397576 | J13: =Debt!J50*Time!J20 -> 2.156992 | K13: =Debt!K50*Time!K20 -> 5.8827056 | L13: =Debt!L50*Time!L20 -> 5.8827056 | M13: =Debt!M50*Time!M20 -> 5.8827056 | N13: =Debt!N50*Time!N20 -> 5.8827056 | O13: =Debt!O50*Time!O20 -> 5.8827056 | P13: =Debt!P50*Time!P20 -> 5.8827056 | Q13: =Debt!Q50*Time!Q20 -> 5.8827056 | ... DB13: =Debt!DB50*Time!DB20 -> 0
D14: Bond escrow: opening | E14: ARD m | J14: =IF(Time!J6=1,$F$7,I16) -> 485.17159 | K14: =IF(Time!K6=1,$F$7,J16) -> 485.17159 | L14: =IF(Time!L6=1,$F$7,K16) -> 485.17159 | M14: =IF(Time!M6=1,$F$7,L16) -> 485.17159 | N14: =IF(Time!N6=1,$F$7,M16) -> 485.17159 | O14: =IF(Time!O6=1,$F$7,N16) -> 478.90641 | P14: =IF(Time!P6=1,$F$7,O16) -> 419.30983 | Q14: =IF(Time!Q6=1,$F$7,P16) -> 351.2391 | ... DB14: =IF(Time!DB6=1,$F$7,DA16) -> 0
D15: Bond escrow earnings (deducted) | E15: ARD m | G15: =SUM(J15:DB15) -> 22.492753 | J15: =J14*Inputs!$F$111*Time!J9/Inputs!$F$45*Time!J20 -> 0.94907539 | K15: =K14*Inputs!$F$111*Time!K9/Inputs!$F$45*Time!K20 -> 2.5680863 | L15: =L14*Inputs!$F$111*Time!L9/Inputs!$F$45*Time!L20 -> 2.5680863 | M15: =M14*Inputs!$F$111*Time!M9/Inputs!$F$45*Time!M20 -> 2.5401724 | N15: =N14*Inputs!$F$111*Time!N9/Inputs!$F$45*Time!N20 -> 2.5401724 | O15: =O14*Inputs!$F$111*Time!O9/Inputs!$F$45*Time!O20 -> 2.5349238 | P15: =P14*Inputs!$F$111*Time!P9/Inputs!$F$45*Time!P20 -> 2.2194701 | Q15: =Q14*Inputs!$F$111*Time!Q9/Inputs!$F$45*Time!Q20 -> 1.8187449 | ... DB15: =DB14*Inputs!$F$111*Time!DB9/Inputs!$F$45*Time!DB20 -> 0
D16: Bond escrow: closing | E16: ARD m | J16: =J14-J36 -> 485.17159 | K16: =K14-K36 -> 485.17159 | L16: =L14-L36 -> 485.17159 | M16: =M14-M36 -> 485.17159 | N16: =N14-N36 -> 478.90641 | O16: =O14-O36 -> 419.30983 | P16: =P14-P36 -> 351.2391 | Q16: =Q14-Q36 -> 278.54469 | ... DB16: =DB14-DB36 -> 0
