Workbook
Name Scenario: Inputs!$F$8

Sheet Cover
A1: Cactus Ridge Solar and Storage (fictional; Illustrative): Exercise 43.17 solution
A2: Cover: purpose, layout, method and answers
A3: Column D label, E unit, F constant or scalar, G row total; first period in column J. Inputs: blue on yellow. Links from other sheets: green. Checks: 0 when passing.
D4: Label | E4: Unit | F4: Constant | G4: Total
D6: Solution workbook for Exercise 43.17 (Part VII capstone, guided by Exhibit 43.8). Macro-free; no circular reference; iterative calculation off.
D7: Sheets: Cover, Inputs, Construction (monthly, January to December 2027), Operations, Tax, Debt, Waterfall (half-years 2028H1 to 2047H2), Returns, Checks.
D8: Case selector: Inputs F8 (named Scenario): 1 base (P50), 2 sizing (one-year P90), 3 downside (P90 and opex +10%). The debt is locked at the sizing profile in every case.
D9: Circularity: the committed debt (Inputs F33), equity (F34) and principal profile (row 57) are the converged sizing-case values (ex43_17_mirror.py, 12 passes);
D10: Construction recomputes total funding live and Debt rows 15 to 19 recompute the sculpted profile live; Checks F9 to F11 show they are the fixed point.
D11: Python mirror: ex43_17_mirror.py (same answers; interpretations listed there and in model/exercises/README.md).
D13: Master check (0 = all pass) | F13: =Checks!$F$20
D15: Answers for the selected case (live; Returns sheet)
D16: Equity IRR (XIRR) | E16: % | F16: =Returns!$F$10
D17: Minimum DSCR (repayment half-years) | E17: x | F17: =Returns!$F$11
D18: Average DSCR (CFADS / debt service over the repayment half-years) | E18: x | F18: =Returns!$F$12
D19: Number of lock-ups | E19: count | F19: =Returns!$F$13
D20: Hard costs | E20: USD m | F20: =Returns!$F$14
D21: Interest during construction | E21: USD m | F21: =Returns!$F$15
D22: Commitment fees | E22: USD m | F22: =Returns!$F$16
D23: Upfront fee | E23: USD m | F23: =Returns!$F$17
D24: DSRA initial funding | E24: USD m | F24: =Returns!$F$18
D25: Total funding requirement | E25: USD m | F25: =Returns!$F$19
D26: Senior debt | E26: USD m | F26: =Returns!$F$20
D27: Senior debt at the gearing cap | E27: USD m | F27: =Returns!$F$21
D28: Gearing | E28: % | F28: =Returns!$F$22
D29: Equity | E29: USD m | F29: =Returns!$F$23
D30: First half-year debt service | E30: USD m | F30: =Returns!$F$24

Sheet Inputs
A1: Cactus Ridge Solar and Storage (fictional; Illustrative): Exercise 43.17 solution
A2: Inputs: case control, costs, financing, operations, tax, timing, contract terms (Exhibit 43.8)
A3: Column D label, E unit, F constant or scalar, G row total; first period in column J. Inputs: blue on yellow. Links from other sheets: green. Checks: 0 when passing.
D4: Label | E4: Unit | F4: Constant | G4: Total
D5: Case table: columns J to L = cases 1 to 3; monthly rows: J to U = Jan to Dec 2027; half-year rows: J to AW = 2028H1 to 2047H2
B7: Case control
D8: Scenario (1 base P50, 2 sizing one-year P90, 3 downside P90 and opex +10%) | E8: index | F8: 1
B9: Case table (columns J to L = cases 1 to 3) and live values (column F)
D10: Energy factor applied to P50 [table] | E10: factor | J10: 1 | K10: 0.917 | L10: 0.917
D11: Operating cost factor [table] | E11: factor | J11: 1 | K11: 1 | L11: 1.1
D12: Energy factor (live) | E12: factor | F12: =INDEX($J$10:$L$10,1,Scenario)
D13: Operating cost factor (live) | E13: factor | F13: =INDEX($J$11:$L$11,1,Scenario)
B14: Construction costs (USD m)
D15: PV EPC price | E15: USD m | F15: 168.4
D16: Battery supply price | E16: USD m | F16: 61.7
D17: Battery share paid at the first payment | E17: % | F17: 20
D18: Battery share paid at the second payment | E18: % | F18: 80
D19: Battery first payment month (January 2027 = 1) | E19: month | F19: 1
D20: Battery second payment month (October 2027) | E20: month | F20: 10
D21: Development and owner's costs (paid in month 1) | E21: USD m | F21: 12.9
D22: Contingency (pro rata with PV EPC payments, months 2 to 12) | E22: USD m | F22: 9.6
B23: Monthly PV EPC payment profile
D24: PV EPC payment profile (columns J to U = January to December 2027) | E24: % | G24: =SUM(J24:U24) | J24: 10 | K24: 4.5 | L24: 6 | M24: 8.5 | N24: 10.5 | O24: 12 | P24: 12.5 | Q24: 11 | R24: 9 | S24: 7 | T24: 5 | U24: 4
B25: Financing
D26: Senior loan all-in fixed rate (swapped) | E26: % pa | F26: 7.25
D27: Months per year | E27: months | F27: 12
D28: Upfront fee (of the commitment, month 1) | E28: % | F28: 1.75
D29: Commitment fee on the undrawn commitment | E29: % pa | F29: 0.7
D30: Gearing cap (share of total funding requirement) | E30: % | F30: 75
D31: Sizing DSCR (sizing case) | E31: x | F31: 1.3
D32: Distribution test: historic 12-month DSCR at least | E32: x | F32: 1.15
D33: Senior debt commitment (contract; converged sizing) | E33: USD m | F33: 185.42498
D34: Equity commitment (contract; converged sizing) | E34: USD m | F34: 87.746229
D35: Number of repayment half-years (2028H1 to 2042H2) | E35: count | F35: 30
B36: Operations
D37: Solar P50 energy, operating year 1 | E37: GWh | F37: 512.8
D38: Share of annual energy in H1 (Jan-Jun) | E38: % | F38: 52
D39: Degradation (compounding, from operating year 2) | E39: % pa | F39: 0.4
D40: PPA price in the price base year | E40: USD/MWh | F40: 49.8
D41: Escalation of PPA price and battery payment (each January 1) | E41: % pa | F41: 1.5
...

Sheet Construction
A1: Cactus Ridge Solar and Storage (fictional; Illustrative): Exercise 43.17 solution
A2: Construction: monthly uses and pro rata funding (January to December 2027)
A3: Column D label, E unit, F constant or scalar, G row total; first period in column J. Inputs: blue on yellow. Links from other sheets: green. Checks: 0 when passing.
D4: Label | E4: Unit | F4: Constant | G4: Total
J5: 2027-01 | K5: 2027-02 | L5: 2027-03 | M5: 2027-04 | N5: 2027-05 | O5: 2027-06 | P5: 2027-07 | Q5: 2027-08 | R5: 2027-09 | S5: 2027-10 | T5: 2027-11 | U5: 2027-12
B7: Monthly timeline
D8: Month number | E8: index | J8: =I8+1 | K8: =J8+1 | L8: =K8+1 | M8: =L8+1 | N8: =M8+1 | O8: =N8+1 | P8: =O8+1 | Q8: =P8+1 | ... U8: =T8+1
D9: Month start | E9: date | J9: =IF(J8=1,Inputs!$F$53,EDATE(I9,1)) | K9: =IF(K8=1,Inputs!$F$53,EDATE(J9,1)) | L9: =IF(L8=1,Inputs!$F$53,EDATE(K9,1)) | M9: =IF(M8=1,Inputs!$F$53,EDATE(L9,1)) | N9: =IF(N8=1,Inputs!$F$53,EDATE(M9,1)) | O9: =IF(O8=1,Inputs!$F$53,EDATE(N9,1)) | P9: =IF(P8=1,Inputs!$F$53,EDATE(O9,1)) | Q9: =IF(Q8=1,Inputs!$F$53,EDATE(P9,1)) | ... U9: =IF(U8=1,Inputs!$F$53,EDATE(T9,1))
D10: Month end (cash flow date) | E10: date | J10: =EOMONTH(J9,0) | K10: =EOMONTH(K9,0) | L10: =EOMONTH(L9,0) | M10: =EOMONTH(M9,0) | N10: =EOMONTH(N9,0) | O10: =EOMONTH(O9,0) | P10: =EOMONTH(P9,0) | Q10: =EOMONTH(Q9,0) | ... U10: =EOMONTH(U9,0)
B11: Uses (USD m)
D12: PV EPC payments | E12: USD m | G12: =SUM(J12:U12) | J12: =Inputs!$F$15*Inputs!J24/100 | K12: =Inputs!$F$15*Inputs!K24/100 | L12: =Inputs!$F$15*Inputs!L24/100 | M12: =Inputs!$F$15*Inputs!M24/100 | N12: =Inputs!$F$15*Inputs!N24/100 | O12: =Inputs!$F$15*Inputs!O24/100 | P12: =Inputs!$F$15*Inputs!P24/100 | Q12: =Inputs!$F$15*Inputs!Q24/100 | ... U12: =Inputs!$F$15*Inputs!U24/100
D13: Battery supply payments | E13: USD m | G13: =SUM(J13:U13) | J13: =Inputs!$F$16*(IF(J8=Inputs!$F$19,Inputs!$F$17,0)+IF(J8=Inputs!$F$20,Inputs!$F$18,0))/100 | K13: =Inputs!$F$16*(IF(K8=Inputs!$F$19,Inputs!$F$17,0)+IF(K8=Inputs!$F$20,Inputs!$F$18,0))/100 | L13: =Inputs!$F$16*(IF(L8=Inputs!$F$19,Inputs!$F$17,0)+IF(L8=Inputs!$F$20,Inputs!$F$18,0))/100 | M13: =Inputs!$F$16*(IF(M8=Inputs!$F$19,Inputs!$F$17,0)+IF(M8=Inputs!$F$20,Inputs!$F$18,0))/100 | N13: =Inputs!$F$16*(IF(N8=Inputs!$F$19,Inputs!$F$17,0)+IF(N8=Inputs!$F$20,Inputs!$F$18,0))/100 | O13: =Inputs!$F$16*(IF(O8=Inputs!$F$19,Inputs!$F$17,0)+IF(O8=Inputs!$F$20,Inputs!$F$18,0))/100 | P13: =Inputs!$F$16*(IF(P8=Inputs!$F$19,Inputs!$F$17,0)+IF(P8=Inputs!$F$20,Inputs!$F$18,0))/100 | Q13: =Inputs!$F$16*(IF(Q8=Inputs!$F$19,Inputs!$F$17,0)+IF(Q8=Inputs!$F$20,Inputs!$F$18,0))/100 | ... U13: =Inputs!$F$16*(IF(U8=Inputs!$F$19,Inputs!$F$17,0)+IF(U8=Inputs!$F$20,Inputs!$F$18,0))/100
D14: Development and owner's costs | E14: USD m | G14: =SUM(J14:U14) | J14: =IF(J8=1,Inputs!$F$21,0) | K14: =IF(K8=1,Inputs!$F$21,0) | L14: =IF(L8=1,Inputs!$F$21,0) | M14: =IF(M8=1,Inputs!$F$21,0) | N14: =IF(N8=1,Inputs!$F$21,0) | O14: =IF(O8=1,Inputs!$F$21,0) | P14: =IF(P8=1,Inputs!$F$21,0) | Q14: =IF(Q8=1,Inputs!$F$21,0) | ... U14: =IF(U8=1,Inputs!$F$21,0)
D15: Contingency (pro rata with PV EPC payments, months 2 to 12) | E15: USD m | G15: =SUM(J15:U15) | J15: =IF(J8>1,Inputs!$F$22*Inputs!J24/SUMIFS(Inputs!$J$24:$U$24,$J$8:$U$8,">1"),0) | K15: =IF(K8>1,Inputs!$F$22*Inputs!K24/SUMIFS(Inputs!$J$24:$U$24,$J$8:$U$8,">1"),0) | L15: =IF(L8>1,Inputs!$F$22*Inputs!L24/SUMIFS(Inputs!$J$24:$U$24,$J$8:$U$8,">1"),0) | M15: =IF(M8>1,Inputs!$F$22*Inputs!M24/SUMIFS(Inputs!$J$24:$U$24,$J$8:$U$8,">1"),0) | N15: =IF(N8>1,Inputs!$F$22*Inputs!N24/SUMIFS(Inputs!$J$24:$U$24,$J$8:$U$8,">1"),0) | O15: =IF(O8>1,Inputs!$F$22*Inputs!O24/SUMIFS(Inputs!$J$24:$U$24,$J$8:$U$8,">1"),0) | P15: =IF(P8>1,Inputs!$F$22*Inputs!P24/SUMIFS(Inputs!$J$24:$U$24,$J$8:$U$8,">1"),0) | Q15: =IF(Q8>1,Inputs!$F$22*Inputs!Q24/SUMIFS(Inputs!$J$24:$U$24,$J$8:$U$8,">1"),0) | ... U15: =IF(U8>1,Inputs!$F$22*Inputs!U24/SUMIFS(Inputs!$J$24:$U$24,$J$8:$U$8,">1"),0)
D16: Hard costs | E16: USD m | G16: =SUM(J16:U16) | J16: =SUM(J12:J15) | K16: =SUM(K12:K15) | L16: =SUM(L12:L15) | M16: =SUM(M12:M15) | N16: =SUM(N12:N15) | O16: =SUM(O12:O15) | P16: =SUM(P12:P15) | Q16: =SUM(Q12:Q15) | ... U16: =SUM(U12:U15)
D17: Senior loan: opening balance | E17: USD m | J17: =I24 | K17: =J24 | L17: =K24 | M17: =L24 | N17: =M24 | O17: =N24 | P17: =O24 | Q17: =P24 | ... U17: =T24
D18: Interest during construction (rate / 12 on the opening balance) | E18: USD m | G18: =SUM(J18:U18) | J18: =J17*Inputs!$F$26/100/Inputs!$F$27 | K18: =K17*Inputs!$F$26/100/Inputs!$F$27 | L18: =L17*Inputs!$F$26/100/Inputs!$F$27 | M18: =M17*Inputs!$F$26/100/Inputs!$F$27 | N18: =N17*Inputs!$F$26/100/Inputs!$F$27 | O18: =O17*Inputs!$F$26/100/Inputs!$F$27 | P18: =P17*Inputs!$F$26/100/Inputs!$F$27 | Q18: =Q17*Inputs!$F$26/100/Inputs!$F$27 | ... U18: =U17*Inputs!$F$26/100/Inputs!$F$27
D19: Commitment fee (on the undrawn commitment at month start) | E19: USD m | G19: =SUM(J19:U19) | J19: =(Inputs!$F$33-J17)*Inputs!$F$29/100/Inputs!$F$27 | K19: =(Inputs!$F$33-K17)*Inputs!$F$29/100/Inputs!$F$27 | L19: =(Inputs!$F$33-L17)*Inputs!$F$29/100/Inputs!$F$27 | M19: =(Inputs!$F$33-M17)*Inputs!$F$29/100/Inputs!$F$27 | N19: =(Inputs!$F$33-N17)*Inputs!$F$29/100/Inputs!$F$27 | O19: =(Inputs!$F$33-O17)*Inputs!$F$29/100/Inputs!$F$27 | P19: =(Inputs!$F$33-P17)*Inputs!$F$29/100/Inputs!$F$27 | Q19: =(Inputs!$F$33-Q17)*Inputs!$F$29/100/Inputs!$F$27 | ... U19: =(Inputs!$F$33-U17)*Inputs!$F$29/100/Inputs!$F$27
D20: Upfront fee (month 1) | E20: USD m | G20: =SUM(J20:U20) | J20: =IF(J8=1,Inputs!$F$28/100*Inputs!$F$33,0) | K20: =IF(K8=1,Inputs!$F$28/100*Inputs!$F$33,0) | L20: =IF(L8=1,Inputs!$F$28/100*Inputs!$F$33,0) | M20: =IF(M8=1,Inputs!$F$28/100*Inputs!$F$33,0) | N20: =IF(N8=1,Inputs!$F$28/100*Inputs!$F$33,0) | O20: =IF(O8=1,Inputs!$F$28/100*Inputs!$F$33,0) | P20: =IF(P8=1,Inputs!$F$28/100*Inputs!$F$33,0) | Q20: =IF(Q8=1,Inputs!$F$28/100*Inputs!$F$33,0) | ... U20: =IF(U8=1,Inputs!$F$28/100*Inputs!$F$33,0)
D21: DSRA initial funding (first half-year debt service, month before COD) | E21: USD m | G21: =SUM(J21:U21) | J21: =IF(J10=EOMONTH(Inputs!$F$54,-1),Debt!$F$13,0) | K21: =IF(K10=EOMONTH(Inputs!$F$54,-1),Debt!$F$13,0) | L21: =IF(L10=EOMONTH(Inputs!$F$54,-1),Debt!$F$13,0) | M21: =IF(M10=EOMONTH(Inputs!$F$54,-1),Debt!$F$13,0) | N21: =IF(N10=EOMONTH(Inputs!$F$54,-1),Debt!$F$13,0) | O21: =IF(O10=EOMONTH(Inputs!$F$54,-1),Debt!$F$13,0) | P21: =IF(P10=EOMONTH(Inputs!$F$54,-1),Debt!$F$13,0) | Q21: =IF(Q10=EOMONTH(Inputs!$F$54,-1),Debt!$F$13,0) | ... U21: =IF(U10=EOMONTH(Inputs!$F$54,-1),Debt!$F$13,0)
D22: Total uses | E22: USD m | G22: =SUM(J22:U22) | J22: =J16+J18+J19+J20+J21 | K22: =K16+K18+K19+K20+K21 | L22: =L16+L18+L19+L20+L21 | M22: =M16+M18+M19+M20+M21 | N22: =N16+N18+N19+N20+N21 | O22: =O16+O18+O19+O20+O21 | P22: =P16+P18+P19+P20+P21 | Q22: =Q16+Q18+Q19+Q20+Q21 | ... U22: =U16+U18+U19+U20+U21
D23: Senior loan drawdown (debt share g of uses) | E23: USD m | G23: =SUM(J23:U23) | J23: =$F$26*J22 | K23: =$F$26*K22 | L23: =$F$26*L22 | M23: =$F$26*M22 | N23: =$F$26*N22 | O23: =$F$26*O22 | P23: =$F$26*P22 | Q23: =$F$26*Q22 | ... U23: =$F$26*U22
D24: Senior loan: closing balance | E24: USD m | J24: =J17+J23 | K24: =K17+K23 | L24: =L17+L23 | M24: =M17+M23 | N24: =N17+N23 | O24: =O17+O23 | P24: =P17+P23 | Q24: =Q17+Q23 | ... U24: =U17+U23
D25: Equity contribution | E25: USD m | G25: =SUM(J25:U25) | J25: =J22-J23 | K25: =K22-K23 | L25: =L22-L23 | M25: =M22-M23 | N25: =N22-N23 | O25: =O22-O23 | P25: =P22-P23 | Q25: =Q22-Q23 | ... U25: =U22-U23
D26: Debt share of funding g = D / (D + E) | E26: fraction | F26: =Inputs!$F$33/(Inputs!$F$33+Inputs!$F$34)
D27: Total funding requirement T (sum of uses) | E27: USD m | F27: =SUM(J22:U22)
D28: Capitalized cost for tax (total uses less DSRA) | E28: USD m | F28: =F27-SUM(J21:U21)
D29: Gearing (senior debt / total funding) | E29: % | F29: =SUM(J23:U23)/F27*100
D30: Senior debt at the gearing cap | E30: USD m | F30: =Inputs!$F$30/100*F27

Sheet Operations
A1: Cactus Ridge Solar and Storage (fictional; Illustrative): Exercise 43.17 solution
A2: Operations: timeline, energy, revenue, operating costs (half-years 2028H1 to 2047H2)
A3: Column D label, E unit, F constant or scalar, G row total; first period in column J. Inputs: blue on yellow. Links from other sheets: green. Checks: 0 when passing.
D4: Label | E4: Unit | F4: Constant | G4: Total
J5: 2028H1 | K5: 2028H2 | L5: 2029H1 | M5: 2029H2 | N5: 2030H1 | O5: 2030H2 | P5: 2031H1 | Q5: 2031H2 | R5: 2032H1 | S5: 2032H2 | T5: 2033H1 | U5: 2033H2 | V5: 2034H1 | W5: 2034H2 | X5: 2035H1 | Y5: 2035H2 | Z5: 2036H1 | AA5: 2036H2 | AB5: 2037H1 | AC5: 2037H2 | AD5: 2038H1 | AE5: 2038H2 | AF5: 2039H1 | AG5: 2039H2 | AH5: 2040H1 | AI5: 2040H2 | AJ5: 2041H1 | AK5: 2041H2 | AL5: 2042H1 | AM5: 2042H2 | AN5: 2043H1 | AO5: 2043H2 | AP5: 2044H1 | AQ5: 2044H2 | AR5: 2045H1 | AS5: 2045H2 | AT5: 2046H1 | AU5: 2046H2 | AV5: 2047H1 | AW5: 2047H2
B7: Semiannual timeline
D8: Period number | E8: index | J8: =I8+1 | K8: =J8+1 | L8: =K8+1 | M8: =L8+1 | N8: =M8+1 | O8: =N8+1 | P8: =O8+1 | Q8: =P8+1 | ... AW8: =AV8+1
D9: Period start | E9: date | J9: =IF(J8=1,Inputs!$F$54,EDATE(I9,Inputs!$F$55)) | K9: =IF(K8=1,Inputs!$F$54,EDATE(J9,Inputs!$F$55)) | L9: =IF(L8=1,Inputs!$F$54,EDATE(K9,Inputs!$F$55)) | M9: =IF(M8=1,Inputs!$F$54,EDATE(L9,Inputs!$F$55)) | N9: =IF(N8=1,Inputs!$F$54,EDATE(M9,Inputs!$F$55)) | O9: =IF(O8=1,Inputs!$F$54,EDATE(N9,Inputs!$F$55)) | P9: =IF(P8=1,Inputs!$F$54,EDATE(O9,Inputs!$F$55)) | Q9: =IF(Q8=1,Inputs!$F$54,EDATE(P9,Inputs!$F$55)) | ... AW9: =IF(AW8=1,Inputs!$F$54,EDATE(AV9,Inputs!$F$55))
D10: Period end (cash flow date) | E10: date | J10: =EOMONTH(J9,Inputs!$F$55-1) | K10: =EOMONTH(K9,Inputs!$F$55-1) | L10: =EOMONTH(L9,Inputs!$F$55-1) | M10: =EOMONTH(M9,Inputs!$F$55-1) | N10: =EOMONTH(N9,Inputs!$F$55-1) | O10: =EOMONTH(O9,Inputs!$F$55-1) | P10: =EOMONTH(P9,Inputs!$F$55-1) | Q10: =EOMONTH(Q9,Inputs!$F$55-1) | ... AW10: =EOMONTH(AW9,Inputs!$F$55-1)
D11: Calendar year | E11: year | J11: =YEAR(J9) | K11: =YEAR(K9) | L11: =YEAR(L9) | M11: =YEAR(M9) | N11: =YEAR(N9) | O11: =YEAR(O9) | P11: =YEAR(P9) | Q11: =YEAR(Q9) | ... AW11: =YEAR(AW9)
D12: Operating year | E12: OY | J12: =J11-YEAR(Inputs!$F$54)+1 | K12: =K11-YEAR(Inputs!$F$54)+1 | L12: =L11-YEAR(Inputs!$F$54)+1 | M12: =M11-YEAR(Inputs!$F$54)+1 | N12: =N11-YEAR(Inputs!$F$54)+1 | O12: =O11-YEAR(Inputs!$F$54)+1 | P12: =P11-YEAR(Inputs!$F$54)+1 | Q12: =Q11-YEAR(Inputs!$F$54)+1 | ... AW12: =AW11-YEAR(Inputs!$F$54)+1
D13: Flag_FirstHalf (Jan-Jun) | E13: flag | J13: =IF(MONTH(J9)=1,1,0) | K13: =IF(MONTH(K9)=1,1,0) | L13: =IF(MONTH(L9)=1,1,0) | M13: =IF(MONTH(M9)=1,1,0) | N13: =IF(MONTH(N9)=1,1,0) | O13: =IF(MONTH(O9)=1,1,0) | P13: =IF(MONTH(P9)=1,1,0) | Q13: =IF(MONTH(Q9)=1,1,0) | ... AW13: =IF(MONTH(AW9)=1,1,0)
D14: Flag_TaxHoliday | E14: flag | J14: =IF(J11<=Inputs!$F$50,1,0) | K14: =IF(K11<=Inputs!$F$50,1,0) | L14: =IF(L11<=Inputs!$F$50,1,0) | M14: =IF(M11<=Inputs!$F$50,1,0) | N14: =IF(N11<=Inputs!$F$50,1,0) | O14: =IF(O11<=Inputs!$F$50,1,0) | P14: =IF(P11<=Inputs!$F$50,1,0) | Q14: =IF(Q11<=Inputs!$F$50,1,0) | ... AW14: =IF(AW11<=Inputs!$F$50,1,0)
D15: Flag_Repayment (2028H1 to 2042H2) | E15: flag | J15: =IF(J8<=Inputs!$F$35,1,0) | K15: =IF(K8<=Inputs!$F$35,1,0) | L15: =IF(L8<=Inputs!$F$35,1,0) | M15: =IF(M8<=Inputs!$F$35,1,0) | N15: =IF(N8<=Inputs!$F$35,1,0) | O15: =IF(O8<=Inputs!$F$35,1,0) | P15: =IF(P8<=Inputs!$F$35,1,0) | Q15: =IF(Q8<=Inputs!$F$35,1,0) | ... AW15: =IF(AW8<=Inputs!$F$35,1,0)
B16: Revenue (USD m)
D17: Solar energy (case factor applied) | E17: GWh | G17: =SUM(J17:AW17) | J17: =Inputs!$F$37*(1-Inputs!$F$39/100)^(J12-1)*IF(J13=1,Inputs!$F$38/100,1-Inputs!$F$38/100)*Inputs!$F$12 | K17: =Inputs!$F$37*(1-Inputs!$F$39/100)^(K12-1)*IF(K13=1,Inputs!$F$38/100,1-Inputs!$F$38/100)*Inputs!$F$12 | L17: =Inputs!$F$37*(1-Inputs!$F$39/100)^(L12-1)*IF(L13=1,Inputs!$F$38/100,1-Inputs!$F$38/100)*Inputs!$F$12 | M17: =Inputs!$F$37*(1-Inputs!$F$39/100)^(M12-1)*IF(M13=1,Inputs!$F$38/100,1-Inputs!$F$38/100)*Inputs!$F$12 | N17: =Inputs!$F$37*(1-Inputs!$F$39/100)^(N12-1)*IF(N13=1,Inputs!$F$38/100,1-Inputs!$F$38/100)*Inputs!$F$12 | O17: =Inputs!$F$37*(1-Inputs!$F$39/100)^(O12-1)*IF(O13=1,Inputs!$F$38/100,1-Inputs!$F$38/100)*Inputs!$F$12 | P17: =Inputs!$F$37*(1-Inputs!$F$39/100)^(P12-1)*IF(P13=1,Inputs!$F$38/100,1-Inputs!$F$38/100)*Inputs!$F$12 | Q17: =Inputs!$F$37*(1-Inputs!$F$39/100)^(Q12-1)*IF(Q13=1,Inputs!$F$38/100,1-Inputs!$F$38/100)*Inputs!$F$12 | ... AW17: =Inputs!$F$37*(1-Inputs!$F$39/100)^(AW12-1)*IF(AW13=1,Inputs!$F$38/100,1-Inputs!$F$38/100)*Inputs!$F$12
D18: PPA price | E18: USD/MWh | J18: =Inputs!$F$40*(1+Inputs!$F$41/100)^(J11-Inputs!$F$47) | K18: =Inputs!$F$40*(1+Inputs!$F$41/100)^(K11-Inputs!$F$47) | L18: =Inputs!$F$40*(1+Inputs!$F$41/100)^(L11-Inputs!$F$47) | M18: =Inputs!$F$40*(1+Inputs!$F$41/100)^(M11-Inputs!$F$47) | N18: =Inputs!$F$40*(1+Inputs!$F$41/100)^(N11-Inputs!$F$47) | O18: =Inputs!$F$40*(1+Inputs!$F$41/100)^(O11-Inputs!$F$47) | P18: =Inputs!$F$40*(1+Inputs!$F$41/100)^(P11-Inputs!$F$47) | Q18: =Inputs!$F$40*(1+Inputs!$F$41/100)^(Q11-Inputs!$F$47) | ... AW18: =Inputs!$F$40*(1+Inputs!$F$41/100)^(AW11-Inputs!$F$47)
D19: Energy revenue | E19: USD m | G19: =SUM(J19:AW19) | J19: =J17*J18/1000 | K19: =K17*K18/1000 | L19: =L17*L18/1000 | M19: =M17*M18/1000 | N19: =N17*N18/1000 | O19: =O17*O18/1000 | P19: =P17*P18/1000 | Q19: =Q17*Q18/1000 | ... AW19: =AW17*AW18/1000
D20: Battery capacity payment | E20: USD m | G20: =SUM(J20:AW20) | J20: =Inputs!$F$42*1000*Inputs!$F$43*(1+Inputs!$F$41/100)^(J11-Inputs!$F$47)*Inputs!$F$55/1000000 | K20: =Inputs!$F$42*1000*Inputs!$F$43*(1+Inputs!$F$41/100)^(K11-Inputs!$F$47)*Inputs!$F$55/1000000 | L20: =Inputs!$F$42*1000*Inputs!$F$43*(1+Inputs!$F$41/100)^(L11-Inputs!$F$47)*Inputs!$F$55/1000000 | M20: =Inputs!$F$42*1000*Inputs!$F$43*(1+Inputs!$F$41/100)^(M11-Inputs!$F$47)*Inputs!$F$55/1000000 | N20: =Inputs!$F$42*1000*Inputs!$F$43*(1+Inputs!$F$41/100)^(N11-Inputs!$F$47)*Inputs!$F$55/1000000 | O20: =Inputs!$F$42*1000*Inputs!$F$43*(1+Inputs!$F$41/100)^(O11-Inputs!$F$47)*Inputs!$F$55/1000000 | P20: =Inputs!$F$42*1000*Inputs!$F$43*(1+Inputs!$F$41/100)^(P11-Inputs!$F$47)*Inputs!$F$55/1000000 | Q20: =Inputs!$F$42*1000*Inputs!$F$43*(1+Inputs!$F$41/100)^(Q11-Inputs!$F$47)*Inputs!$F$55/1000000 | ... AW20: =Inputs!$F$42*1000*Inputs!$F$43*(1+Inputs!$F$41/100)^(AW11-Inputs!$F$47)*Inputs!$F$55/1000000
D21: Total revenue | E21: USD m | G21: =SUM(J21:AW21) | J21: =J19+J20 | K21: =K19+K20 | L21: =L19+L20 | M21: =M19+M20 | N21: =N19+N20 | O21: =O19+O20 | P21: =P19+P20 | Q21: =Q19+Q20 | ... AW21: =AW19+AW20
B22: Operating costs (USD m)
D23: Fixed operating cost (equal halves) | E23: USD m | G23: =SUM(J23:AW23) | J23: =Inputs!$F$44*(1+Inputs!$F$45/100)^(J11-Inputs!$F$47)*Inputs!$F$55/Inputs!$F$27*Inputs!$F$13 | K23: =Inputs!$F$44*(1+Inputs!$F$45/100)^(K11-Inputs!$F$47)*Inputs!$F$55/Inputs!$F$27*Inputs!$F$13 | L23: =Inputs!$F$44*(1+Inputs!$F$45/100)^(L11-Inputs!$F$47)*Inputs!$F$55/Inputs!$F$27*Inputs!$F$13 | M23: =Inputs!$F$44*(1+Inputs!$F$45/100)^(M11-Inputs!$F$47)*Inputs!$F$55/Inputs!$F$27*Inputs!$F$13 | N23: =Inputs!$F$44*(1+Inputs!$F$45/100)^(N11-Inputs!$F$47)*Inputs!$F$55/Inputs!$F$27*Inputs!$F$13 | O23: =Inputs!$F$44*(1+Inputs!$F$45/100)^(O11-Inputs!$F$47)*Inputs!$F$55/Inputs!$F$27*Inputs!$F$13 | P23: =Inputs!$F$44*(1+Inputs!$F$45/100)^(P11-Inputs!$F$47)*Inputs!$F$55/Inputs!$F$27*Inputs!$F$13 | Q23: =Inputs!$F$44*(1+Inputs!$F$45/100)^(Q11-Inputs!$F$47)*Inputs!$F$55/Inputs!$F$27*Inputs!$F$13 | ... AW23: =Inputs!$F$44*(1+Inputs!$F$45/100)^(AW11-Inputs!$F$47)*Inputs!$F$55/Inputs!$F$27*Inputs!$F$13
D24: Variable operating cost | E24: USD m | G24: =SUM(J24:AW24) | J24: =J17*Inputs!$F$46/1000*Inputs!$F$13 | K24: =K17*Inputs!$F$46/1000*Inputs!$F$13 | L24: =L17*Inputs!$F$46/1000*Inputs!$F$13 | M24: =M17*Inputs!$F$46/1000*Inputs!$F$13 | N24: =N17*Inputs!$F$46/1000*Inputs!$F$13 | O24: =O17*Inputs!$F$46/1000*Inputs!$F$13 | P24: =P17*Inputs!$F$46/1000*Inputs!$F$13 | Q24: =Q17*Inputs!$F$46/1000*Inputs!$F$13 | ... AW24: =AW17*Inputs!$F$46/1000*Inputs!$F$13
D25: Total operating costs | E25: USD m | G25: =SUM(J25:AW25) | J25: =J23+J24 | K25: =K23+K24 | L25: =L23+L24 | M25: =M23+M24 | N25: =N23+N24 | O25: =O23+O24 | P25: =P23+P24 | Q25: =Q23+Q24 | ... AW25: =AW23+AW24
D26: EBITDA | E26: USD m | G26: =SUM(J26:AW26) | J26: =J21-J25 | K26: =K21-K25 | L26: =L21-L25 | M26: =M21-M25 | N26: =N21-N25 | O26: =O21-O25 | P26: =P21-P25 | Q26: =Q21-Q25 | ... AW26: =AW21-AW25

Sheet Tax
A1: Cactus Ridge Solar and Storage (fictional; Illustrative): Exercise 43.17 solution
A2: Tax: holiday 2028 to 2030 (losses lost), straight-line depreciation, losses carried forward
A3: Column D label, E unit, F constant or scalar, G row total; first period in column J. Inputs: blue on yellow. Links from other sheets: green. Checks: 0 when passing.
D4: Label | E4: Unit | F4: Constant | G4: Total
J5: 2028H1 | K5: 2028H2 | L5: 2029H1 | M5: 2029H2 | N5: 2030H1 | O5: 2030H2 | P5: 2031H1 | Q5: 2031H2 | R5: 2032H1 | S5: 2032H2 | T5: 2033H1 | U5: 2033H2 | V5: 2034H1 | W5: 2034H2 | X5: 2035H1 | Y5: 2035H2 | Z5: 2036H1 | AA5: 2036H2 | AB5: 2037H1 | AC5: 2037H2 | AD5: 2038H1 | AE5: 2038H2 | AF5: 2039H1 | AG5: 2039H2 | AH5: 2040H1 | AI5: 2040H2 | AJ5: 2041H1 | AK5: 2041H2 | AL5: 2042H1 | AM5: 2042H2 | AN5: 2043H1 | AO5: 2043H2 | AP5: 2044H1 | AQ5: 2044H2 | AR5: 2045H1 | AS5: 2045H2 | AT5: 2046H1 | AU5: 2046H2 | AV5: 2047H1 | AW5: 2047H2
D7: Depreciation (straight line over 40 half-years) | E7: USD m | G7: =SUM(J7:AW7) | J7: =Construction!$F$28/Inputs!$F$51*IF(Operations!J8<=Inputs!$F$51,1,0) | K7: =Construction!$F$28/Inputs!$F$51*IF(Operations!K8<=Inputs!$F$51,1,0) | L7: =Construction!$F$28/Inputs!$F$51*IF(Operations!L8<=Inputs!$F$51,1,0) | M7: =Construction!$F$28/Inputs!$F$51*IF(Operations!M8<=Inputs!$F$51,1,0) | N7: =Construction!$F$28/Inputs!$F$51*IF(Operations!N8<=Inputs!$F$51,1,0) | O7: =Construction!$F$28/Inputs!$F$51*IF(Operations!O8<=Inputs!$F$51,1,0) | P7: =Construction!$F$28/Inputs!$F$51*IF(Operations!P8<=Inputs!$F$51,1,0) | Q7: =Construction!$F$28/Inputs!$F$51*IF(Operations!Q8<=Inputs!$F$51,1,0) | ... AW7: =Construction!$F$28/Inputs!$F$51*IF(Operations!AW8<=Inputs!$F$51,1,0)
D8: Senior interest (deductible) | E8: USD m | G8: =SUM(J8:AW8) | J8: =Debt!J9 | K8: =Debt!K9 | L8: =Debt!L9 | M8: =Debt!M9 | N8: =Debt!N9 | O8: =Debt!O9 | P8: =Debt!P9 | Q8: =Debt!Q9 | ... AW8: =Debt!AW9
D9: Taxable income before losses | E9: USD m | G9: =SUM(J9:AW9) | J9: =Operations!J26-J8-J7 | K9: =Operations!K26-K8-K7 | L9: =Operations!L26-L8-L7 | M9: =Operations!M26-M8-M7 | N9: =Operations!N26-N8-N7 | O9: =Operations!O26-O8-O7 | P9: =Operations!P26-P8-P7 | Q9: =Operations!Q26-Q8-Q7 | ... AW9: =Operations!AW26-AW8-AW7
D10: Tax losses used | E10: USD m | G10: =SUM(J10:AW10) | J10: =IF(Operations!J14=1,0,MIN(I12,MAX(0,J9))) | K10: =IF(Operations!K14=1,0,MIN(J12,MAX(0,K9))) | L10: =IF(Operations!L14=1,0,MIN(K12,MAX(0,L9))) | M10: =IF(Operations!M14=1,0,MIN(L12,MAX(0,M9))) | N10: =IF(Operations!N14=1,0,MIN(M12,MAX(0,N9))) | O10: =IF(Operations!O14=1,0,MIN(N12,MAX(0,O9))) | P10: =IF(Operations!P14=1,0,MIN(O12,MAX(0,P9))) | Q10: =IF(Operations!Q14=1,0,MIN(P12,MAX(0,Q9))) | ... AW10: =IF(Operations!AW14=1,0,MIN(AV12,MAX(0,AW9)))
D11: Tax losses arising (holiday losses lost) | E11: USD m | G11: =SUM(J11:AW11) | J11: =IF(Operations!J14=1,0,MAX(0,-J9)) | K11: =IF(Operations!K14=1,0,MAX(0,-K9)) | L11: =IF(Operations!L14=1,0,MAX(0,-L9)) | M11: =IF(Operations!M14=1,0,MAX(0,-M9)) | N11: =IF(Operations!N14=1,0,MAX(0,-N9)) | O11: =IF(Operations!O14=1,0,MAX(0,-O9)) | P11: =IF(Operations!P14=1,0,MAX(0,-P9)) | Q11: =IF(Operations!Q14=1,0,MAX(0,-Q9)) | ... AW11: =IF(Operations!AW14=1,0,MAX(0,-AW9))
D12: Tax losses carried forward, closing | E12: USD m | J12: =I12-J10+J11 | K12: =J12-K10+K11 | L12: =K12-L10+L11 | M12: =L12-M10+M11 | N12: =M12-N10+N11 | O12: =N12-O10+O11 | P12: =O12-P10+P11 | Q12: =P12-Q10+Q11 | ... AW12: =AV12-AW10+AW11
D13: Taxable income | E13: USD m | G13: =SUM(J13:AW13) | J13: =IF(Operations!J14=1,0,MAX(0,J9-J10)) | K13: =IF(Operations!K14=1,0,MAX(0,K9-K10)) | L13: =IF(Operations!L14=1,0,MAX(0,L9-L10)) | M13: =IF(Operations!M14=1,0,MAX(0,M9-M10)) | N13: =IF(Operations!N14=1,0,MAX(0,N9-N10)) | O13: =IF(Operations!O14=1,0,MAX(0,O9-O10)) | P13: =IF(Operations!P14=1,0,MAX(0,P9-P10)) | Q13: =IF(Operations!Q14=1,0,MAX(0,Q9-Q10)) | ... AW13: =IF(Operations!AW14=1,0,MAX(0,AW9-AW10))
D14: Tax paid | E14: USD m | G14: =SUM(J14:AW14) | J14: =J13*Inputs!$F$49/100 | K14: =K13*Inputs!$F$49/100 | L14: =L13*Inputs!$F$49/100 | M14: =M13*Inputs!$F$49/100 | N14: =N13*Inputs!$F$49/100 | O14: =O13*Inputs!$F$49/100 | P14: =P13*Inputs!$F$49/100 | Q14: =Q13*Inputs!$F$49/100 | ... AW14: =AW13*Inputs!$F$49/100

Sheet Debt
A1: Cactus Ridge Solar and Storage (fictional; Illustrative): Exercise 43.17 solution
A2: Debt: senior loan on the contract profile; live sculpting check (sizing case)
A3: Column D label, E unit, F constant or scalar, G row total; first period in column J. Inputs: blue on yellow. Links from other sheets: green. Checks: 0 when passing.
D4: Label | E4: Unit | F4: Constant | G4: Total
J5: 2028H1 | K5: 2028H2 | L5: 2029H1 | M5: 2029H2 | N5: 2030H1 | O5: 2030H2 | P5: 2031H1 | Q5: 2031H2 | R5: 2032H1 | S5: 2032H2 | T5: 2033H1 | U5: 2033H2 | V5: 2034H1 | W5: 2034H2 | X5: 2035H1 | Y5: 2035H2 | Z5: 2036H1 | AA5: 2036H2 | AB5: 2037H1 | AC5: 2037H2 | AD5: 2038H1 | AE5: 2038H2 | AF5: 2039H1 | AG5: 2039H2 | AH5: 2040H1 | AI5: 2040H2 | AJ5: 2041H1 | AK5: 2041H2 | AL5: 2042H1 | AM5: 2042H2 | AN5: 2043H1 | AO5: 2043H2 | AP5: 2044H1 | AQ5: 2044H2 | AR5: 2045H1 | AS5: 2045H2 | AT5: 2046H1 | AU5: 2046H2 | AV5: 2047H1 | AW5: 2047H2
B7: Senior loan (USD m)
D8: Opening balance | E8: USD m | J8: =IF(Operations!J8=1,Inputs!$F$33,I12) | K8: =IF(Operations!K8=1,Inputs!$F$33,J12) | L8: =IF(Operations!L8=1,Inputs!$F$33,K12) | M8: =IF(Operations!M8=1,Inputs!$F$33,L12) | N8: =IF(Operations!N8=1,Inputs!$F$33,M12) | O8: =IF(Operations!O8=1,Inputs!$F$33,N12) | P8: =IF(Operations!P8=1,Inputs!$F$33,O12) | Q8: =IF(Operations!Q8=1,Inputs!$F$33,P12) | ... AW8: =IF(Operations!AW8=1,Inputs!$F$33,AV12)
D9: Interest (rate x months / 12 on the opening balance) | E9: USD m | G9: =SUM(J9:AW9) | J9: =J8*Inputs!$F$26/100*Inputs!$F$55/Inputs!$F$27 | K9: =K8*Inputs!$F$26/100*Inputs!$F$55/Inputs!$F$27 | L9: =L8*Inputs!$F$26/100*Inputs!$F$55/Inputs!$F$27 | M9: =M8*Inputs!$F$26/100*Inputs!$F$55/Inputs!$F$27 | N9: =N8*Inputs!$F$26/100*Inputs!$F$55/Inputs!$F$27 | O9: =O8*Inputs!$F$26/100*Inputs!$F$55/Inputs!$F$27 | P9: =P8*Inputs!$F$26/100*Inputs!$F$55/Inputs!$F$27 | Q9: =Q8*Inputs!$F$26/100*Inputs!$F$55/Inputs!$F$27 | ... AW9: =AW8*Inputs!$F$26/100*Inputs!$F$55/Inputs!$F$27
D10: Principal (contract profile) | E10: USD m | G10: =SUM(J10:AW10) | J10: =Inputs!J57 | K10: =Inputs!K57 | L10: =Inputs!L57 | M10: =Inputs!M57 | N10: =Inputs!N57 | O10: =Inputs!O57 | P10: =Inputs!P57 | Q10: =Inputs!Q57 | ... AW10: =Inputs!AW57
D11: Debt service | E11: USD m | G11: =SUM(J11:AW11) | J11: =J9+J10 | K11: =K9+K10 | L11: =L9+L10 | M11: =M9+M10 | N11: =N9+N10 | O11: =O9+O10 | P11: =P9+P10 | Q11: =Q9+Q10 | ... AW11: =AW9+AW10
D12: Closing balance | E12: USD m | J12: =J8-J10 | K12: =K8-K10 | L12: =L8-L10 | M12: =M8-M10 | N12: =N8-N10 | O12: =O8-O10 | P12: =P8-P10 | Q12: =Q8-Q10 | ... AW12: =AW8-AW10
D13: First half-year debt service (DSRA initial funding) | E13: USD m | F13: =J11
B14: Live sculpting check (meaningful in the sizing case, Scenario 2)
D15: Sculpted debt service = CFADS / sizing DSCR | E15: USD m | G15: =SUM(J15:AW15) | J15: =Operations!J15*Waterfall!J7/Inputs!$F$31 | K15: =Operations!K15*Waterfall!K7/Inputs!$F$31 | L15: =Operations!L15*Waterfall!L7/Inputs!$F$31 | M15: =Operations!M15*Waterfall!M7/Inputs!$F$31 | N15: =Operations!N15*Waterfall!N7/Inputs!$F$31 | O15: =Operations!O15*Waterfall!O7/Inputs!$F$31 | P15: =Operations!P15*Waterfall!P7/Inputs!$F$31 | Q15: =Operations!Q15*Waterfall!Q7/Inputs!$F$31 | ... AW15: =Operations!AW15*Waterfall!AW7/Inputs!$F$31
D16: PV of sculpted debt service at the loan rate (backward recursion) | E16: USD m | J16: =IF(Operations!J15=1,(J15+K16)/(1+Inputs!$F$26/100*Inputs!$F$55/Inputs!$F$27),0) | K16: =IF(Operations!K15=1,(K15+L16)/(1+Inputs!$F$26/100*Inputs!$F$55/Inputs!$F$27),0) | L16: =IF(Operations!L15=1,(L15+M16)/(1+Inputs!$F$26/100*Inputs!$F$55/Inputs!$F$27),0) | M16: =IF(Operations!M15=1,(M15+N16)/(1+Inputs!$F$26/100*Inputs!$F$55/Inputs!$F$27),0) | N16: =IF(Operations!N15=1,(N15+O16)/(1+Inputs!$F$26/100*Inputs!$F$55/Inputs!$F$27),0) | O16: =IF(Operations!O15=1,(O15+P16)/(1+Inputs!$F$26/100*Inputs!$F$55/Inputs!$F$27),0) | P16: =IF(Operations!P15=1,(P15+Q16)/(1+Inputs!$F$26/100*Inputs!$F$55/Inputs!$F$27),0) | Q16: =IF(Operations!Q15=1,(Q15+R16)/(1+Inputs!$F$26/100*Inputs!$F$55/Inputs!$F$27),0) | ... AW16: =IF(Operations!AW15=1,(AW15+AX16)/(1+Inputs!$F$26/100*Inputs!$F$55/Inputs!$F$27),0)
D17: Debt capacity at the sizing DSCR | E17: USD m | F17: =J16
D18: Sculpted principal | E18: USD m | G18: =SUM(J18:AW18) | J18: =J15-J8*Inputs!$F$26/100*Inputs!$F$55/Inputs!$F$27 | K18: =K15-K8*Inputs!$F$26/100*Inputs!$F$55/Inputs!$F$27 | L18: =L15-L8*Inputs!$F$26/100*Inputs!$F$55/Inputs!$F$27 | M18: =M15-M8*Inputs!$F$26/100*Inputs!$F$55/Inputs!$F$27 | N18: =N15-N8*Inputs!$F$26/100*Inputs!$F$55/Inputs!$F$27 | O18: =O15-O8*Inputs!$F$26/100*Inputs!$F$55/Inputs!$F$27 | P18: =P15-P8*Inputs!$F$26/100*Inputs!$F$55/Inputs!$F$27 | Q18: =Q15-Q8*Inputs!$F$26/100*Inputs!$F$55/Inputs!$F$27 | ... AW18: =AW15-AW8*Inputs!$F$26/100*Inputs!$F$55/Inputs!$F$27
D19: Sculpted principal less contract principal | E19: USD m | J19: =J18-J10 | K19: =K18-K10 | L19: =L18-L10 | M19: =M18-M10 | N19: =N18-N10 | O19: =O18-O10 | P19: =P18-P10 | Q19: =Q18-Q10 | ... AW19: =AW18-AW10

Sheet Waterfall
A1: Cactus Ridge Solar and Storage (fictional; Illustrative): Exercise 43.17 solution
A2: Waterfall: CFADS, debt service, DSRA, distribution test, distributions
A3: Column D label, E unit, F constant or scalar, G row total; first period in column J. Inputs: blue on yellow. Links from other sheets: green. Checks: 0 when passing.
D4: Label | E4: Unit | F4: Constant | G4: Total
J5: 2028H1 | K5: 2028H2 | L5: 2029H1 | M5: 2029H2 | N5: 2030H1 | O5: 2030H2 | P5: 2031H1 | Q5: 2031H2 | R5: 2032H1 | S5: 2032H2 | T5: 2033H1 | U5: 2033H2 | V5: 2034H1 | W5: 2034H2 | X5: 2035H1 | Y5: 2035H2 | Z5: 2036H1 | AA5: 2036H2 | AB5: 2037H1 | AC5: 2037H2 | AD5: 2038H1 | AE5: 2038H2 | AF5: 2039H1 | AG5: 2039H2 | AH5: 2040H1 | AI5: 2040H2 | AJ5: 2041H1 | AK5: 2041H2 | AL5: 2042H1 | AM5: 2042H2 | AN5: 2043H1 | AO5: 2043H2 | AP5: 2044H1 | AQ5: 2044H2 | AR5: 2045H1 | AS5: 2045H2 | AT5: 2046H1 | AU5: 2046H2 | AV5: 2047H1 | AW5: 2047H2
D7: CFADS (EBITDA less tax) | E7: USD m | G7: =SUM(J7:AW7) | J7: =Operations!J26-Tax!J14 | K7: =Operations!K26-Tax!K14 | L7: =Operations!L26-Tax!L14 | M7: =Operations!M26-Tax!M14 | N7: =Operations!N26-Tax!N14 | O7: =Operations!O26-Tax!O14 | P7: =Operations!P26-Tax!P14 | Q7: =Operations!Q26-Tax!Q14 | ... AW7: =Operations!AW26-Tax!AW14
D8: Senior debt service | E8: USD m | G8: =SUM(J8:AW8) | J8: =Debt!J11 | K8: =Debt!K11 | L8: =Debt!L11 | M8: =Debt!M11 | N8: =Debt!N11 | O8: =Debt!O11 | P8: =Debt!P11 | Q8: =Debt!Q11 | ... AW8: =Debt!AW11
D9: DSCR, period | E9: x | J9: =IF(J8>Inputs!$F$58,J7/J8,0) | K9: =IF(K8>Inputs!$F$58,K7/K8,0) | L9: =IF(L8>Inputs!$F$58,L7/L8,0) | M9: =IF(M8>Inputs!$F$58,M7/M8,0) | N9: =IF(N8>Inputs!$F$58,N7/N8,0) | O9: =IF(O8>Inputs!$F$58,O7/O8,0) | P9: =IF(P8>Inputs!$F$58,P7/P8,0) | Q9: =IF(Q8>Inputs!$F$58,Q7/Q8,0) | ... AW9: =IF(AW8>Inputs!$F$58,AW7/AW8,0)
D10: DSCR, historic 12 months (this and the previous half-year) | E10: x | J10: =IF(J8>Inputs!$F$58,(J7+I7)/(J8+I8),0) | K10: =IF(K8>Inputs!$F$58,(K7+J7)/(K8+J8),0) | L10: =IF(L8>Inputs!$F$58,(L7+K7)/(L8+K8),0) | M10: =IF(M8>Inputs!$F$58,(M7+L7)/(M8+L8),0) | N10: =IF(N8>Inputs!$F$58,(N7+M7)/(N8+M8),0) | O10: =IF(O8>Inputs!$F$58,(O7+N7)/(O8+N8),0) | P10: =IF(P8>Inputs!$F$58,(P7+O7)/(P8+O8),0) | Q10: =IF(Q8>Inputs!$F$58,(Q7+P7)/(Q8+P8),0) | ... AW10: =IF(AW8>Inputs!$F$58,(AW7+AV7)/(AW8+AV8),0)
D11: DSRA opening | E11: USD m | J11: =IF(Operations!J8=1,SUM(Construction!$J$21:$U$21),I14) | K11: =IF(Operations!K8=1,SUM(Construction!$J$21:$U$21),J14) | L11: =IF(Operations!L8=1,SUM(Construction!$J$21:$U$21),K14) | M11: =IF(Operations!M8=1,SUM(Construction!$J$21:$U$21),L14) | N11: =IF(Operations!N8=1,SUM(Construction!$J$21:$U$21),M14) | O11: =IF(Operations!O8=1,SUM(Construction!$J$21:$U$21),N14) | P11: =IF(Operations!P8=1,SUM(Construction!$J$21:$U$21),O14) | Q11: =IF(Operations!Q8=1,SUM(Construction!$J$21:$U$21),P14) | ... AW11: =IF(Operations!AW8=1,SUM(Construction!$J$21:$U$21),AV14)
D12: DSRA target (next half-year debt service; nil after final maturity) | E12: USD m | J12: =K8 | K12: =L8 | L12: =M8 | M12: =N8 | N12: =O8 | O12: =P8 | P12: =Q8 | Q12: =R8 | ... AW12: =AX8
D13: DSRA release (+) or top-up (-) | E13: USD m | G13: =SUM(J13:AW13) | J13: =J11-J12 | K13: =K11-K12 | L13: =L11-L12 | M13: =M11-M12 | N13: =N11-N12 | O13: =O11-O12 | P13: =P11-P12 | Q13: =Q11-Q12 | ... AW13: =AW11-AW12
D14: DSRA closing | E14: USD m | J14: =J12 | K14: =K12 | L14: =L12 | M14: =M12 | N14: =N12 | O14: =O12 | P14: =P12 | Q14: =Q12 | ... AW14: =AW12
D15: Cash available for distribution (incl. locked-up cash brought forward) | E15: USD m | J15: =J7-J8+J13+I18 | K15: =K7-K8+K13+J18 | L15: =L7-L8+L13+K18 | M15: =M7-M8+M13+L18 | N15: =N7-N8+N13+M18 | O15: =O7-O8+O13+N18 | P15: =P7-P8+P13+O18 | Q15: =Q7-Q8+Q13+P18 | ... AW15: =AW7-AW8+AW13+AV18
D16: Distribution test passed (historic DSCR at least 1.15x, or no debt service) | E16: flag | J16: =IF(OR(J8<=Inputs!$F$58,J10>=Inputs!$F$32),1,0) | K16: =IF(OR(K8<=Inputs!$F$58,K10>=Inputs!$F$32),1,0) | L16: =IF(OR(L8<=Inputs!$F$58,L10>=Inputs!$F$32),1,0) | M16: =IF(OR(M8<=Inputs!$F$58,M10>=Inputs!$F$32),1,0) | N16: =IF(OR(N8<=Inputs!$F$58,N10>=Inputs!$F$32),1,0) | O16: =IF(OR(O8<=Inputs!$F$58,O10>=Inputs!$F$32),1,0) | P16: =IF(OR(P8<=Inputs!$F$58,P10>=Inputs!$F$32),1,0) | Q16: =IF(OR(Q8<=Inputs!$F$58,Q10>=Inputs!$F$32),1,0) | ... AW16: =IF(OR(AW8<=Inputs!$F$58,AW10>=Inputs!$F$32),1,0)
D17: Distributions to equity | E17: USD m | G17: =SUM(J17:AW17) | J17: =J15*J16 | K17: =K15*K16 | L17: =L15*L16 | M17: =M15*M16 | N17: =N15*N16 | O17: =O15*O16 | P17: =P15*P16 | Q17: =Q15*Q16 | ... AW17: =AW15*AW16
D18: Locked-up cash, closing | E18: USD m | J18: =J15-J17 | K18: =K15-K17 | L18: =L15-L17 | M18: =M15-M17 | N18: =N15-N17 | O18: =O15-O17 | P18: =P15-P17 | Q18: =Q15-Q17 | ... AW18: =AW15-AW17
D19: Lock-up (1 = distribution blocked) | E19: flag | G19: =SUM(J19:AW19) | J19: =1-J16 | K19: =1-K16 | L19: =1-L16 | M19: =1-M16 | N19: =1-N16 | O19: =1-O16 | P19: =1-P16 | Q19: =1-Q16 | ... AW19: =1-AW16

Sheet Returns
A1: Cactus Ridge Solar and Storage (fictional; Illustrative): Exercise 43.17 solution
A2: Returns: dated equity cash flows (12 month ends, then 40 half-year ends) and summary outputs
A3: Column D label, E unit, F constant or scalar, G row total; first period in column J. Inputs: blue on yellow. Links from other sheets: green. Checks: 0 when passing.
D4: Label | E4: Unit | F4: Constant | G4: Total
J5: 2027-01 | K5: 2027-02 | L5: 2027-03 | M5: 2027-04 | N5: 2027-05 | O5: 2027-06 | P5: 2027-07 | Q5: 2027-08 | R5: 2027-09 | S5: 2027-10 | T5: 2027-11 | U5: 2027-12 | V5: 2028H1 | W5: 2028H2 | X5: 2029H1 | Y5: 2029H2 | Z5: 2030H1 | AA5: 2030H2 | AB5: 2031H1 | AC5: 2031H2 | AD5: 2032H1 | AE5: 2032H2 | AF5: 2033H1 | AG5: 2033H2 | AH5: 2034H1 | AI5: 2034H2 | AJ5: 2035H1 | AK5: 2035H2 | AL5: 2036H1 | AM5: 2036H2 | AN5: 2037H1 | AO5: 2037H2 | AP5: 2038H1 | AQ5: 2038H2 | AR5: 2039H1 | AS5: 2039H2 | AT5: 2040H1 | AU5: 2040H2 | AV5: 2041H1 | AW5: 2041H2 | AX5: 2042H1 | AY5: 2042H2 | AZ5: 2043H1 | BA5: 2043H2 | BB5: 2044H1 | BC5: 2044H2 | BD5: 2045H1 | BE5: 2045H2 | BF5: 2046H1 | BG5: 2046H2 | BH5: 2047H1 | BI5: 2047H2
D7: Cash flow date | E7: date | J7: =Construction!J10 | K7: =Construction!K10 | L7: =Construction!L10 | M7: =Construction!M10 | N7: =Construction!N10 | O7: =Construction!O10 | P7: =Construction!P10 | Q7: =Construction!Q10 | ... U7: =Construction!U10 | V7: =Operations!J10 | W7: =Operations!K10 | X7: =Operations!L10 | Y7: =Operations!M10 | Z7: =Operations!N10 | AA7: =Operations!O10 | AB7: =Operations!P10 | AC7: =Operations!Q10 | ... BI7: =Operations!AW10
D8: Equity cash flow (contributions negative) | E8: USD m | G8: =SUM(J8:BI8) | J8: =-Construction!J25 | K8: =-Construction!K25 | L8: =-Construction!L25 | M8: =-Construction!M25 | N8: =-Construction!N25 | O8: =-Construction!O25 | P8: =-Construction!P25 | Q8: =-Construction!Q25 | ... U8: =-Construction!U25 | V8: =Waterfall!J17 | W8: =Waterfall!K17 | X8: =Waterfall!L17 | Y8: =Waterfall!M17 | Z8: =Waterfall!N17 | AA8: =Waterfall!O17 | AB8: =Waterfall!P17 | AC8: =Waterfall!Q17 | ... BI8: =Waterfall!AW17
B9: Summary outputs (selected case)
D10: Equity IRR (XIRR) | E10: % | F10: =XIRR(J8:BI8,J7:BI7)*100
D11: Minimum DSCR (repayment half-years) | E11: x | F11: =_xlfn.MINIFS(Waterfall!J9:AW9,Waterfall!J8:AW8,">"&Inputs!$F$58)
D12: Average DSCR (CFADS / debt service over the repayment half-years) | E12: x | F12: =SUMIFS(Waterfall!J7:AW7,Waterfall!J8:AW8,">"&Inputs!$F$58)/SUM(Waterfall!J8:AW8)
D13: Number of lock-ups | E13: count | F13: =SUM(Waterfall!J19:AW19)
D14: Hard costs | E14: USD m | F14: =Construction!$G$16
D15: Interest during construction | E15: USD m | F15: =Construction!$G$18
D16: Commitment fees | E16: USD m | F16: =Construction!$G$19
D17: Upfront fee | E17: USD m | F17: =Construction!$G$20
D18: DSRA initial funding | E18: USD m | F18: =Construction!$G$21
D19: Total funding requirement | E19: USD m | F19: =Construction!$F$27
D20: Senior debt | E20: USD m | F20: =Construction!$G$23
D21: Senior debt at the gearing cap | E21: USD m | F21: =Construction!$F$30
D22: Gearing | E22: % | F22: =Construction!$F$29
D23: Equity | E23: USD m | F23: =Construction!$G$25
D24: First half-year debt service | E24: USD m | F24: =Debt!$F$13

Sheet Checks
A1: Cactus Ridge Solar and Storage (fictional; Illustrative): Exercise 43.17 solution
A2: Checks: every check shows 0 when passing
A3: Column D label, E unit, F constant or scalar, G row total; first period in column J. Inputs: blue on yellow. Links from other sheets: green. Checks: 0 when passing.
D4: Label | E4: Unit | F4: Constant | G4: Total
D7: Sources less uses (construction) | E7: check | F7: =IF(ABS(Construction!$G$23+Construction!$G$25-Construction!$F$27)<=Inputs!$F$59,0,Construction!$G$23+Construction!$G$25-Construction!$F$27)
D8: PV EPC profile sums to 100% | E8: check | F8: =IF(ABS(Inputs!$G$24-100)<=Inputs!$F$59,0,Inputs!$G$24-100)
D9: Committed debt drawn in full (debt drawn less commitment) | E9: check | F9: =IF(ABS(Construction!$G$23-Inputs!$F$33)<=Inputs!$F$59,0,Construction!$G$23-Inputs!$F$33)
D10: Sizing case: live debt capacity at 1.30x equals the commitment | E10: check | F10: =IF(Scenario=2,IF(ABS(Debt!$F$17-Inputs!$F$33)<=Inputs!$F$59,0,Debt!$F$17-Inputs!$F$33),0)
D11: Sizing case: live sculpted principal equals the contract profile (max abs) | E11: check | F11: =IF(Scenario=2,IF(MAX(MAX(Debt!J19:AW19),-MIN(Debt!J19:AW19))<=Inputs!$F$59,0,MAX(MAX(Debt!J19:AW19),-MIN(Debt!J19:AW19))),0)
D12: Debt not above the gearing cap | E12: check | F12: =IF(Inputs!$F$33<=Construction!$F$30,0,1)
D13: Debt repaid by final maturity (closing balance in the last repayment half-year) | E13: check | F13: =IF(ABS(INDEX(Debt!J12:AW12,1,Inputs!$F$35))<=Inputs!$F$59,0,INDEX(Debt!J12:AW12,1,Inputs!$F$35))
D14: Contract profile sums to the commitment | E14: check | F14: =IF(ABS(Inputs!$G$57-Inputs!$F$33)<=Inputs!$F$59,0,Inputs!$G$57-Inputs!$F$33)
D15: No negative cash after debt service and DSRA (min, if below 0) | E15: check | F15: =IF(MIN(Waterfall!J15:AW15)>=-Inputs!$F$59,0,MIN(Waterfall!J15:AW15))
D16: DSRA released at final maturity (closing DSRA in the last repayment half-year) | E16: check | F16: =IF(ABS(INDEX(Waterfall!J14:AW14,1,Inputs!$F$35))<=Inputs!$F$59,0,1)
D17: Energy shares H1 + H2 = 100% (operating year 1) | E17: check | F17: =IF(ABS(Operations!J17+Operations!K17-Inputs!$F$37*Inputs!$F$12)<=Inputs!$F$59,0,1)
D18: Equity flows: contributions equal the equity commitment | E18: check | F18: =IF(ABS(-SUMIF(Returns!J8:BI8,"<0")-Inputs!$F$34)<=Inputs!$F$59,0,1)
D20: Sum of checks (0 = all pass) | E20: check | F20: =ABS(F7)+ABS(F8)+ABS(F9)+ABS(F10)+ABS(F11)+ABS(F12)+ABS(F13)+ABS(F14)+ABS(F15)+ABS(F16)+ABS(F17)+ABS(F18)
