Workbook
Name Scenario: Inputs!$F$8

Sheet Inputs
A1: Quebracho Alto (fictional; Illustrative): Chapter 13 practice files
A2: Inputs: every number the workbook uses, with units (Examples 13.2 to 13.9)
A3: Column D label, E unit, F value or scalar, G row total; first period in column J. Inputs: blue on yellow. Links: green. Checks: 0 when passing.
B5: Check and macro settings
D6: Check tolerance | E6: USD m | F6: 0.001
B7: Scenario control (Example 13.4)
D8: Scenario (1 Base, 2 Low, 3 High; cell named Scenario) | E8: index | F8: 1
B9: Escalation factors by operating year (columns F to Y = years 1 to 20; Example 13.5)
D10: Escalation factor (tariff escalation 2.4% a year) | F10: 1 | G10: 1.024 | H10: 1.048576 | I10: 1.0737418 | J10: 1.0995116 | K10: 1.1258999 | L10: 1.1529215 | M10: 1.1805916 | N10: 1.2089258 | O10: 1.23794 | P10: 1.2676506 | Q10: 1.2980742 | R10: 1.329228 | S10: 1.3611295 | T10: 1.3937966 | U10: 1.4272477 | V10: 1.4615016 | W10: 1.4965777 | X10: 1.5324955 | Y10: 1.5692754
B11: Timing (Example 13.2)
D12: Notice to proceed | E12: date | F12: 46447
D13: Construction months | E13: months | F13: 26
D14: Commercial operation date | E14: date | F14: 47239
D15: Operating years | E15: years | F15: 20
D16: Months per operating period | E16: months | F16: 6
B17: Operations and revenue (Examples 13.5 to 13.7)
D18: Annual energy (no degradation in these examples) | E18: GWh | F18: 551.4
D19: Base tariff (year 1) | E19: USD/MWh | F19: 63.4
D20: Tariff escalation (Example 13.5; factors in row 10) | E20: % pa | F20: 0.024
D21: Operating cost | E21: USD m pa | F21: 7.94
D22: Discount rate (base) | E22: % pa | F22: 0.0875
B23: Delay LDs (Example 13.3)
D24: Delay LD rate | E24: USD/day | F24: 39500
D25: Delay LD cap | E25: USD | F25: 9620000
D26: Days in each delay month (columns J to Q = delay months 1 to 8) | E26: days | J26: 31 | K26: 30 | L26: 31 | M26: 31 | N26: 30 | O26: 31 | P26: 30 | Q26: 31
B27: Funding (Example 13.8)
D28: Gearing (debt share of total funding) | E28: % | F28: 0.72
D29: IDC as a share of total debt (whole construction period; simplification) | E29: % | F29: 0.0874 | H29: Base | I29: Low | J29: High
D30: Costs before financing: scenario table H30:J30 (Base, Low, High); live value in F30 | E30: USD m | F30: =INDEX(H30:J30,Scenario) | H30: 248.6 | I30: 231.7 | J30: 271.9
D31: Macro tolerance (optional Converge macro, ssec:13.8.5) | E31: USD m | F31: 0.001
D32: Macro pass limit | E32: passes | F32: 50
B33: Goal seek (Example 13.7)
D34: Breakeven tariff at the base rate, pasted from Goal Seek (NPV = 0 by changing the tariff) | E34: USD/MWh | F34: 62.912218
D35: Breakeven test rate, low (Example 13.7) | E35: % pa | F35: 0.0775
D36: Breakeven test rate, high (Example 13.7) | E36: % pa | F36: 0.0975

Sheet Time
A1: Quebracho Alto (fictional; Illustrative): Chapter 13 practice files
A2: Time: monthly construction timeline (rows 4 to 12) and semiannual operations timeline (rows 18 to 24)
A3: Column D label, E unit, F value or scalar, G row total; first period in column J. Inputs: blue on yellow. Links: green. Checks: 0 when passing.
D4: Month counter | E4: index | J4: =I4+1 | K4: =J4+1 | L4: =K4+1 | M4: =L4+1 | N4: =M4+1 | O4: =N4+1 | P4: =O4+1 | Q4: =P4+1 | ... AM4: =AL4+1
J5: 2027-03 | K5: 2027-04 | L5: 2027-05 | M5: 2027-06 | N5: 2027-07 | O5: 2027-08 | P5: 2027-09 | Q5: 2027-10 | R5: 2027-11 | S5: 2027-12 | T5: 2028-01 | U5: 2028-02 | V5: 2028-03 | W5: 2028-04 | X5: 2028-05 | Y5: 2028-06 | Z5: 2028-07 | AA5: 2028-08 | AB5: 2028-09 | AC5: 2028-10 | AD5: 2028-11 | AE5: 2028-12 | AF5: 2029-01 | AG5: 2029-02 | AH5: 2029-03 | AI5: 2029-04 | AJ5: 2029-05 | AK5: 2029-06 | AL5: 2029-07 | AM5: 2029-08
D7: Days in month | E7: days | J7: =J10-J9+1 | K7: =K10-K9+1 | L7: =L10-L9+1 | M7: =M10-M9+1 | N7: =N10-N9+1 | O7: =O10-O9+1 | P7: =P10-P9+1 | Q7: =Q10-Q9+1 | ... AM7: =AM10-AM9+1
D9: Month start | E9: date | J9: =IF(J4=1,$F$14,I10+1) | K9: =IF(K4=1,$F$14,J10+1) | L9: =IF(L4=1,$F$14,K10+1) | M9: =IF(M4=1,$F$14,L10+1) | N9: =IF(N4=1,$F$14,M10+1) | O9: =IF(O4=1,$F$14,N10+1) | P9: =IF(P4=1,$F$14,O10+1) | Q9: =IF(Q4=1,$F$14,P10+1) | ... AM9: =IF(AM4=1,$F$14,AL10+1)
D10: Month end | E10: date | J10: =IF(J4=1,EOMONTH($F$14,0),EOMONTH(I10,1)) | K10: =IF(K4=1,EOMONTH($F$14,0),EOMONTH(J10,1)) | L10: =IF(L4=1,EOMONTH($F$14,0),EOMONTH(K10,1)) | M10: =IF(M4=1,EOMONTH($F$14,0),EOMONTH(L10,1)) | N10: =IF(N4=1,EOMONTH($F$14,0),EOMONTH(M10,1)) | O10: =IF(O4=1,EOMONTH($F$14,0),EOMONTH(N10,1)) | P10: =IF(P4=1,EOMONTH($F$14,0),EOMONTH(O10,1)) | Q10: =IF(Q4=1,EOMONTH($F$14,0),EOMONTH(P10,1)) | ... AM10: =IF(AM4=1,EOMONTH($F$14,0),EOMONTH(AL10,1))
D12: Flag_Construction | E12: flag | G12: =SUM(J12:AM12) | J12: =(J10<=$F$15)*(J9>=$F$14) | K12: =(K10<=$F$15)*(K9>=$F$14) | L12: =(L10<=$F$15)*(L9>=$F$14) | M12: =(M10<=$F$15)*(M9>=$F$14) | N12: =(N10<=$F$15)*(N9>=$F$14) | O12: =(O10<=$F$15)*(O9>=$F$14) | P12: =(P10<=$F$15)*(P9>=$F$14) | Q12: =(Q10<=$F$15)*(Q9>=$F$14) | ... AM12: =(AM10<=$F$15)*(AM9>=$F$14)
B13: Key dates (column F)
D14: Start of construction (notice to proceed) | E14: date | F14: =Inputs!$F$12
D15: End of construction (last day of the last construction month) | E15: date | F15: =EOMONTH(EDATE(F14,Inputs!$F$13-1),0)
D16: Commercial operation date | E16: date | F16: =Inputs!$F$14
D17: End of operations | E17: date | F17: =EDATE(F16,12*Inputs!$F$15)-1
D18: Half-year counter (operations timeline) | E18: index | J18: =I18+1 | K18: =J18+1 | L18: =K18+1 | M18: =L18+1 | N18: =M18+1 | O18: =N18+1 | P18: =O18+1 | Q18: =P18+1 | ... AX18: =AW18+1
D19: Half-year start | E19: date | J19: =IF(J18=1,DATE(YEAR($F$16),1+Inputs!$F$16*INT((MONTH($F$16)-1)/Inputs!$F$16),1),I20+1) | K19: =IF(K18=1,DATE(YEAR($F$16),1+Inputs!$F$16*INT((MONTH($F$16)-1)/Inputs!$F$16),1),J20+1) | L19: =IF(L18=1,DATE(YEAR($F$16),1+Inputs!$F$16*INT((MONTH($F$16)-1)/Inputs!$F$16),1),K20+1) | M19: =IF(M18=1,DATE(YEAR($F$16),1+Inputs!$F$16*INT((MONTH($F$16)-1)/Inputs!$F$16),1),L20+1) | N19: =IF(N18=1,DATE(YEAR($F$16),1+Inputs!$F$16*INT((MONTH($F$16)-1)/Inputs!$F$16),1),M20+1) | O19: =IF(O18=1,DATE(YEAR($F$16),1+Inputs!$F$16*INT((MONTH($F$16)-1)/Inputs!$F$16),1),N20+1) | P19: =IF(P18=1,DATE(YEAR($F$16),1+Inputs!$F$16*INT((MONTH($F$16)-1)/Inputs!$F$16),1),O20+1) | Q19: =IF(Q18=1,DATE(YEAR($F$16),1+Inputs!$F$16*INT((MONTH($F$16)-1)/Inputs!$F$16),1),P20+1) | ... AX19: =IF(AX18=1,DATE(YEAR($F$16),1+Inputs!$F$16*INT((MONTH($F$16)-1)/Inputs!$F$16),1),AW20+1)
D20: Half-year end | E20: date | J20: =EOMONTH(J19,Inputs!$F$16-1) | K20: =EOMONTH(K19,Inputs!$F$16-1) | L20: =EOMONTH(L19,Inputs!$F$16-1) | M20: =EOMONTH(M19,Inputs!$F$16-1) | N20: =EOMONTH(N19,Inputs!$F$16-1) | O20: =EOMONTH(O19,Inputs!$F$16-1) | P20: =EOMONTH(P19,Inputs!$F$16-1) | Q20: =EOMONTH(Q19,Inputs!$F$16-1) | ... AX20: =EOMONTH(AX19,Inputs!$F$16-1)
D21: Days in half-year | E21: days | J21: =J20-J19+1 | K21: =K20-K19+1 | L21: =L20-L19+1 | M21: =M20-M19+1 | N21: =N20-N19+1 | O21: =O20-O19+1 | P21: =P20-P19+1 | Q21: =Q20-Q19+1 | ... AX21: =AX20-AX19+1
D22: Flag_Operations | E22: flag | J22: =IF(AND(J20>=$F$16,J19<=$F$17),1,0) | K22: =IF(AND(K20>=$F$16,K19<=$F$17),1,0) | L22: =IF(AND(L20>=$F$16,L19<=$F$17),1,0) | M22: =IF(AND(M20>=$F$16,M19<=$F$17),1,0) | N22: =IF(AND(N20>=$F$16,N19<=$F$17),1,0) | O22: =IF(AND(O20>=$F$16,O19<=$F$17),1,0) | P22: =IF(AND(P20>=$F$16,P19<=$F$17),1,0) | Q22: =IF(AND(Q20>=$F$16,Q19<=$F$17),1,0) | ... AX22: =IF(AND(AX20>=$F$16,AX19<=$F$17),1,0)
D23: Flag_FirstOperationsPeriod | E23: flag | J23: =IF(AND(J22=1,I22=0),1,0) | K23: =IF(AND(K22=1,J22=0),1,0) | L23: =IF(AND(L22=1,K22=0),1,0) | M23: =IF(AND(M22=1,L22=0),1,0) | N23: =IF(AND(N22=1,M22=0),1,0) | O23: =IF(AND(O22=1,N22=0),1,0) | P23: =IF(AND(P22=1,O22=0),1,0) | Q23: =IF(AND(Q22=1,P22=0),1,0) | ... AX23: =IF(AND(AX22=1,AW22=0),1,0)
D24: Operations fraction of the period (actual days) | E24: fraction | J24: =MAX(0,MIN(J20,$F$17)-MAX(J19,$F$16)+1)/(J20-J19+1) | K24: =MAX(0,MIN(K20,$F$17)-MAX(K19,$F$16)+1)/(K20-K19+1) | L24: =MAX(0,MIN(L20,$F$17)-MAX(L19,$F$16)+1)/(L20-L19+1) | M24: =MAX(0,MIN(M20,$F$17)-MAX(M19,$F$16)+1)/(M20-M19+1) | N24: =MAX(0,MIN(N20,$F$17)-MAX(N19,$F$16)+1)/(N20-N19+1) | O24: =MAX(0,MIN(O20,$F$17)-MAX(O19,$F$16)+1)/(O20-O19+1) | P24: =MAX(0,MIN(P20,$F$17)-MAX(P19,$F$16)+1)/(P20-P19+1) | Q24: =MAX(0,MIN(Q20,$F$17)-MAX(Q19,$F$16)+1)/(Q20-Q19+1) | ... AX24: =MAX(0,MIN(AX20,$F$17)-MAX(AX19,$F$16)+1)/(AX20-AX19+1)
D25: Operations fraction in the first operating period | E25: fraction | F25: =SUMPRODUCT(J23:AX23,J24:AX24)

Sheet Calc
A1: Quebracho Alto (fictional; Illustrative): Chapter 13 practice files
A2: Calc: LD cap (Ex 13.3), revenue and NPV rows (Ex 13.5, 13.6), data table, goal seek (Ex 13.7), IDC closed form and iteration (Ex 13.8), sources and uses (Ex 13.9)
A3: Column D label, E unit, F value or scalar, G row total; first period in column J. Inputs: blue on yellow. Links: green. Checks: 0 when passing.
D4: Operating year counter (revenue and NPV rows, columns J to AC) | E4: index | J4: =I4+1 | K4: =J4+1 | L4: =K4+1 | M4: =L4+1 | N4: =M4+1 | O4: =N4+1 | P4: =O4+1 | Q4: =P4+1 | ... AC4: =AB4+1
B6: Example 13.3: delay LDs with a cumulative cap (columns J to Q = delay months 1 to 8)
D7: Days in the delay month | E7: days | J7: =Inputs!J26 | K7: =Inputs!K26 | L7: =Inputs!L26 | M7: =Inputs!M26 | N7: =Inputs!N26 | O7: =Inputs!O26 | P7: =Inputs!P26 | Q7: =Inputs!Q26
D20: Delay LD rate | E20: USD/day | F20: =Inputs!$F$24
D21: Delay LD cap | E21: USD | F21: =Inputs!$F$25
D22: Delay LD accrual (capped) | E22: USD | G22: =SUM(J22:Q22) | J22: =MAX(0,MIN($F$20*J$7,$F$21-I23)) | K22: =MAX(0,MIN($F$20*K$7,$F$21-J23)) | L22: =MAX(0,MIN($F$20*L$7,$F$21-K23)) | M22: =MAX(0,MIN($F$20*M$7,$F$21-L23)) | N22: =MAX(0,MIN($F$20*N$7,$F$21-M23)) | O22: =MAX(0,MIN($F$20*O$7,$F$21-N23)) | P22: =MAX(0,MIN($F$20*P$7,$F$21-O23)) | Q22: =MAX(0,MIN($F$20*Q$7,$F$21-P23))
D23: Delay LDs, cumulative | E23: USD | J23: =I23+J22 | K23: =J23+K22 | L23: =K23+L22 | M23: =L23+M22 | N23: =M23+N22 | O23: =N23+O22 | P23: =O23+P22 | Q23: =P23+Q22
D24: Days to reach the cap | E24: days | F24: =F21/F20
B25: Examples 13.5 and 13.6: 20-year revenue and NPV rows (columns J to AC = operating years 1 to 20)
D26: Escalation factor (INDEX on the Inputs factor row; Example 13.5 replacement for OFFSET) | E26: factor | J26: =INDEX(Inputs!$F$10:$Y$10,J$4) | K26: =INDEX(Inputs!$F$10:$Y$10,K$4) | L26: =INDEX(Inputs!$F$10:$Y$10,L$4) | M26: =INDEX(Inputs!$F$10:$Y$10,M$4) | N26: =INDEX(Inputs!$F$10:$Y$10,N$4) | O26: =INDEX(Inputs!$F$10:$Y$10,O$4) | P26: =INDEX(Inputs!$F$10:$Y$10,P$4) | Q26: =INDEX(Inputs!$F$10:$Y$10,Q$4) | ... AC26: =INDEX(Inputs!$F$10:$Y$10,AC$4)
D27: Revenue with escalation (Example 13.5) | E27: USD m | G27: =SUM(J27:AC27) | J27: =Inputs!$F$18*Inputs!$F$19*J26/1000 | K27: =Inputs!$F$18*Inputs!$F$19*K26/1000 | L27: =Inputs!$F$18*Inputs!$F$19*L26/1000 | M27: =Inputs!$F$18*Inputs!$F$19*M26/1000 | N27: =Inputs!$F$18*Inputs!$F$19*N26/1000 | O27: =Inputs!$F$18*Inputs!$F$19*O26/1000 | P27: =Inputs!$F$18*Inputs!$F$19*P26/1000 | Q27: =Inputs!$F$18*Inputs!$F$19*Q26/1000 | ... AC27: =Inputs!$F$18*Inputs!$F$19*AC26/1000
D28: Discount factor at the base rate (end of year) | E28: factor | J28: =1/(1+Inputs!$F$22)^J$4 | K28: =1/(1+Inputs!$F$22)^K$4 | L28: =1/(1+Inputs!$F$22)^L$4 | M28: =1/(1+Inputs!$F$22)^M$4 | N28: =1/(1+Inputs!$F$22)^N$4 | O28: =1/(1+Inputs!$F$22)^O$4 | P28: =1/(1+Inputs!$F$22)^P$4 | Q28: =1/(1+Inputs!$F$22)^Q$4 | ... AC28: =1/(1+Inputs!$F$22)^AC$4
D29: PV of revenue with escalation at the base rate | E29: USD m | F29: =SUMPRODUCT(J27:AC27,J28:AC28)
D30: Data-table input cell: flat tariff (row input; must sit on this sheet) | E30: USD/MWh | F30: 62
D31: Data-table input cell: discount rate (column input; must sit on this sheet) | E31: % pa | F31: 0.0875
D32: Revenue at the flat tariff (Example 13.6: no escalation) | E32: USD m | G32: =SUM(J32:AC32) | J32: =Inputs!$F$18*$F$30/1000 | K32: =Inputs!$F$18*$F$30/1000 | L32: =Inputs!$F$18*$F$30/1000 | M32: =Inputs!$F$18*$F$30/1000 | N32: =Inputs!$F$18*$F$30/1000 | O32: =Inputs!$F$18*$F$30/1000 | P32: =Inputs!$F$18*$F$30/1000 | Q32: =Inputs!$F$18*$F$30/1000 | ... AC32: =Inputs!$F$18*$F$30/1000
D33: Operating cost | E33: USD m | G33: =SUM(J33:AC33) | J33: =Inputs!$F$21 | K33: =Inputs!$F$21 | L33: =Inputs!$F$21 | M33: =Inputs!$F$21 | N33: =Inputs!$F$21 | O33: =Inputs!$F$21 | P33: =Inputs!$F$21 | Q33: =Inputs!$F$21 | ... AC33: =Inputs!$F$21
D34: Net cash flow | E34: USD m | G34: =SUM(J34:AC34) | J34: =J32-J33 | K34: =K32-K33 | L34: =L32-L33 | M34: =M32-M33 | N34: =N32-N33 | O34: =O32-O33 | P34: =P32-P33 | Q34: =Q32-Q33 | ... AC34: =AC32-AC33
D35: Discount factor at the data-table rate | E35: factor | J35: =1/(1+$F$31)^J$4 | K35: =1/(1+$F$31)^K$4 | L35: =1/(1+$F$31)^L$4 | M35: =1/(1+$F$31)^M$4 | N35: =1/(1+$F$31)^N$4 | O35: =1/(1+$F$31)^O$4 | P35: =1/(1+$F$31)^P$4 | Q35: =1/(1+$F$31)^Q$4 | ... AC35: =1/(1+$F$31)^AC$4
D36: Present value of net cash flow | E36: USD m | G36: =SUM(J36:AC36) | J36: =J34*J35 | K36: =K34*K35 | L36: =L34*L35 | M36: =M34*M35 | N36: =N34*N35 | O36: =O34*O35 | P36: =P34*P35 | Q36: =Q34*Q35 | ... AC36: =AC34*AC35
D37: NPV = -capex + sum of present values (feeds the data table) | E37: USD m | F37: =-Inputs!$F$30+G36
D38: NPV, annuity form (Example 13.6 Excel form) | E38: USD m | F38: =-Inputs!$F$30+PV(F31,Inputs!$F$15,-(Inputs!$F$18*F30/1000-Inputs!$F$21))
B39: Example 13.8: IDC circularity (C, g, r_c from Inputs)
D40: Senior debt, closed form D = gC / (1 - g r_c) | E40: USD m | F40: =Inputs!$F$28*Inputs!$F$30/(1-Inputs!$F$28*Inputs!$F$29)
D41: Pasted debt (written by the optional Converge macro; 0 = not run) | E41: USD m | F41: 0
D42: Debt computed from the pasted debt: g x (C + r_c x pasted) | E42: USD m | F42: =Inputs!$F$28*(Inputs!$F$30+Inputs!$F$29*F41)
D43: Convergence residual (computed less pasted) | E43: USD m | F43: =F42-F41
D44: Iteration D0 = g x C | E44: USD m | F44: =Inputs!$F$28*Inputs!$F$30
D45: Iteration D1 = g x (C + r_c x D0) | E45: USD m | F45: =Inputs!$F$28*(Inputs!$F$30+Inputs!$F$29*F44)
D46: Iteration D2 = g x (C + r_c x D1) | E46: USD m | F46: =Inputs!$F$28*(Inputs!$F$30+Inputs!$F$29*F45)
D47: Iteration D3 = g x (C + r_c x D2) | E47: USD m | F47: =Inputs!$F$28*(Inputs!$F$30+Inputs!$F$29*F46)
D48: Iteration D4 = g x (C + r_c x D3) | E48: USD m | F48: =Inputs!$F$28*(Inputs!$F$30+Inputs!$F$29*F47)
D49: Iteration D5 = g x (C + r_c x D4) | E49: USD m | F49: =Inputs!$F$28*(Inputs!$F$30+Inputs!$F$29*F48)
D50: NPV at the pasted goal-seek tariff and the base rate (Example 13.7; must be 0) | E50: USD m | F50: =-Inputs!$F$30+PV(Inputs!$F$22,Inputs!$F$15,-(Inputs!$F$18*Inputs!$F$34/1000-Inputs!$F$21))
D51: Breakeven tariff, closed form, at the low test rate | E51: USD/MWh | F51: =(Inputs!$F$30/PV(Inputs!$F$35,Inputs!$F$15,-1)+Inputs!$F$21)/Inputs!$F$18*1000
D52: Breakeven tariff, closed form, at the base rate | E52: USD/MWh | F52: =(Inputs!$F$30/PV(Inputs!$F$22,Inputs!$F$15,-1)+Inputs!$F$21)/Inputs!$F$18*1000
D53: Breakeven tariff, closed form, at the high test rate | E53: USD/MWh | F53: =(Inputs!$F$30/PV(Inputs!$F$36,Inputs!$F$15,-1)+Inputs!$F$21)/Inputs!$F$18*1000
...

Sheet Checks
A1: Quebracho Alto (fictional; Illustrative): Chapter 13 practice files
A2: Checks: each check 0 when passing; master check (Example 13.9)
A3: Column D label, E unit, F value or scalar, G row total; first period in column J. Inputs: blue on yellow. Links: green. Checks: 0 when passing.
D7: Sources less uses (Example 13.9) | E7: check | F7: =--(ABS(Calc!F60-Calc!F61)>Inputs!$F$6)
D8: Construction flags sum to the construction months | E8: check | F8: =--(Time!G12<>Inputs!$F$13)
D9: Operations fraction between 0 and 1 in every period | E9: check | F9: =--OR(MIN(Time!J24:AX24)<0,MAX(Time!J24:AX24)>1)
D10: Revenue positive in every operating period (catches the Example 13.5 OFFSET failure) | E10: check | F10: =--(MIN(Calc!J27:AC27)<=0)
D11: Goal-seek tariff still gives NPV = 0 (Example 13.7) | E11: check | F11: =--(ABS(Calc!F50)>Inputs!$F$6)
D12: Closed-form debt solves D = g(C + r_c D) | E12: check | F12: =--(ABS(Calc!F40-Inputs!$F$28*(Inputs!$F$30+Inputs!$F$29*Calc!F40))>Inputs!$F$6)
D13: Iteration D5 within tolerance of the closed form | E13: check | F13: =--(ABS(Calc!F49-Calc!F40)>Inputs!$F$6)
D14: Delay LDs never exceed the cap | E14: check | F14: =--(Calc!G22>Calc!F21)
D15: NPV row equals the annuity form | E15: check | F15: =--(ABS(Calc!F37-Calc!F38)>Inputs!$F$6)
D16: Data table equals the closed-form grid (Excel computes the table on open; blank table = not yet computed) | E16: check | F16: =IF(COUNT(Calc!F65:H67)=0,0,--(MAX(ABS(Calc!F65-Calc!F71),ABS(Calc!G65-Calc!G71),ABS(Calc!H65-Calc!H71),ABS(Calc!F66-Calc!F72),ABS(Calc!G66-Calc!G72),ABS(Calc!H66-Calc!H72),ABS(Calc!F67-Calc!F73),ABS(Calc!G67-Calc!G73),ABS(Calc!H67-Calc!H73))>Inputs!$F$6))
D18: Master check (sum of the checks above; 0 = all pass) | E18: check | F18: =SUM(F7:F16)
D20: Stress test (Section 13.10 step 5): insert a column on Inputs and a row on Calc, change Scenario, and confirm F18 stays 0; then replace Calc row 26 with =OFFSET(Inputs!$E$10,0,J$4) and insert a column at Inputs F: F10 fires (1).
