Workbook
Name Scenario: Inputs!$F$8

Sheet Cover
A1: Case R reference model: Mesa Corta Renewables portfolio (ERCOT)
A2: Case R, Mesa Corta Renewables. USD m nominal unless stated. Illustrative prices: not ERCOT settlement data and not a forecast.
B4: Owner: Lattimer Energy Transition Fund II (Lattimer Infrastructure Partners). Platform: Mesa Corta Renewables LLC; HoldCo: Mesa Corta HoldCo LLC; OpCo: Mesa Corta OpCo LLC.
B5: Assets R1-R8 (603.0 MW wind, 401.1 MWac solar, 250.0 MW / 500 MWh storage). Annual periods 2022-2059, first period in column J.
B6: Python mirror: model/case_r.py (computational source of truth). Verification: model/case_r_verification.md.
B7: Model version R-1.1; inputs_case_r.json version 1.1. Workbook saved with scenario 'base'.
B8: Switches on the Inputs sheet: Scenario (1 base, 2 low, 3 high prices and captures), volume case (1 P50, 2 P90 one-year, 3 P90 ten-year, 4 P99 one-year),
B9: refinancing switch (1 = 2025 USPP refinancing and holdco repricing, 0 = status quo), and sensitivity cells. Debt is always sized on the Operations sizing blocks (base, P50 and P99).
B10: Colors: blue on pale yellow = input; green = link from another sheet; black = calculation; Checks sheet shows 0 when passing, red when failing.
B11: Sign convention: costs and outflows stored positive on calculation sheets and subtracted explicitly.
B12: No circular references: debt sculpting uses forward discount-factor products; USPP series are solved backward from 2043; iterative calculation is off.
B13: Every Case R price is Illustrative: Case Bible illustrative price paths; not ERCOT settlement data and not a forecast.

Sheet Inputs
A1: Inputs
A2: Case R, Mesa Corta Renewables. USD m nominal unless stated. Illustrative prices: not ERCOT settlement data and not a forecast.
D4: Year | J4: =Time!J$4 | K4: =Time!K$4 | L4: =Time!L$4 | M4: =Time!M$4 | N4: =Time!N$4 | O4: =Time!O$4 | P4: =Time!P$4 | Q4: =Time!Q$4 | ... AU4: =Time!AU$4
D5: Period end | J5: =Time!J$6 | K5: =Time!K$6 | L5: =Time!L$6 | M5: =Time!M$6 | N5: =Time!N$6 | O5: =Time!O$6 | P5: =Time!P$6 | Q5: =Time!Q$6 | ... AU5: =Time!AU$6
A7: Switches
D8: Scenario (1 base, 2 low, 3 high prices and captures) | E8: index | F8: 1
D9: Volume case (1 P50, 2 P90 one-year, 3 P90 ten-year, 4 P99 one-year) | E9: index | F9: 1
D10: Refinancing switch (1 = 2025 refinancing, 0 = status quo) | E10: flag | F10: 1
D11: Sensitivity: West solar capture shift | E11: points | F11: 0
D12: Sensitivity: battery revenue low case (1 = on) | E12: flag | F12: 0
D13: Sensitivity: curtailment added | E13: % points | F13: 0
D14: Sensitivity: opex factor | E14: factor | F14: 1
D15: Sensitivity: SOFR shift on unhedged debt | E15: % points | F15: 0
D16: Sizing case price scenario (base) | E16: index | F16: 1
D17: Sizing case volume case (P50) | E17: index | F17: 1
D18: P99 sizing test volume case | E18: index | F18: 4
D19: Sensitivity value in sizing cases | E19: number | F19: 0
D20: Opex factor in sizing cases | E20: factor | F20: 1
A22: General
D23: First model year | E23: year | F23: 2022
D24: Price base year for escalation | E24: year | F24: 2022
D25: Opex inflation | E25: % pa | F25: 2.5
D26: Model end date | E26: date | F26: 58440
D27: Days per year for discounting (unit conversion) | E27: days | F27: 365
D28: Large number for MIN tests | E28: number | F28: 1000000000
D29: Debt service below which ratios are not shown | E29: USD m | F29: 0.001
D30: Standard normal z for P90 | E30: number | F30: 1.2816
D31: Standard normal z for P99 | E31: number | F31: 2.3263
D32: Years in the long-horizon P-value | E32: years | F32: 10
A34: Prices and capture (Illustrative)
D35: Hub ratio to North Hub: West Hub | E35: ratio | F35: 0.968
D36: Hub ratio to North Hub: South Hub | E36: ratio | F36: 0.991
D37: Hub ratio to North Hub: Houston Hub | E37: ratio | F37: 1.012
D38: Low case: capture decline multiplier | E38: x | F38: 1.5
D39: Low case: floor adjustment | E39: ratio | F39: -0.04
D40: High case: capture decline multiplier | E40: x | F40: 0.5
D41: Hub capture ratio 2022: west_wind | E41: ratio | F41: 0.74
D42: Hub capture decline: west_wind | E42: points pa | F42: 0.6
D43: Hub capture floor: west_wind | E43: ratio | F43: 0.62
D44: Hub-to-node basis: west_wind | E44: ratio | F44: 0.04
...

Sheet Time
A1: Time
A2: Case R, Mesa Corta Renewables. USD m nominal unless stated. Illustrative prices: not ERCOT settlement data and not a forecast.
D4: Year | E4: year | J4: =Inputs!$F$23 | K4: =J4+1 | L4: =K4+1 | M4: =L4+1 | N4: =M4+1 | O4: =N4+1 | P4: =O4+1 | Q4: =P4+1 | R4: =Q4+1 | ... AU4: =AT4+1
D5: Period start (prior December 31) | E5: date | J5: =DATE(J4,1,1)-1 | K5: =DATE(K4,1,1)-1 | L5: =DATE(L4,1,1)-1 | M5: =DATE(M4,1,1)-1 | N5: =DATE(N4,1,1)-1 | O5: =DATE(O4,1,1)-1 | P5: =DATE(P4,1,1)-1 | Q5: =DATE(Q4,1,1)-1 | ... AU5: =DATE(AU4,1,1)-1
D6: Period end (December 31) | E6: date | J6: =DATE(J4+1,1,1)-1 | K6: =DATE(K4+1,1,1)-1 | L6: =DATE(L4+1,1,1)-1 | M6: =DATE(M4+1,1,1)-1 | N6: =DATE(N4+1,1,1)-1 | O6: =DATE(O4+1,1,1)-1 | P6: =DATE(P4+1,1,1)-1 | Q6: =DATE(Q4+1,1,1)-1 | ... AU6: =DATE(AU4+1,1,1)-1
D7: Days in period | E7: days | J7: =J6-J5 | K7: =K6-K5 | L7: =L6-L5 | M7: =M6-M5 | N7: =N6-N5 | O7: =O6-O5 | P7: =P6-P5 | Q7: =Q6-Q5 | ... AU7: =AU6-AU5
D8: Years since price base year | E8: years | J8: =J4-Inputs!$F$24 | K8: =K4-Inputs!$F$24 | L8: =L4-Inputs!$F$24 | M8: =M4-Inputs!$F$24 | N8: =N4-Inputs!$F$24 | O8: =O4-Inputs!$F$24 | P8: =P4-Inputs!$F$24 | Q8: =Q4-Inputs!$F$24 | ... AU8: =AU4-Inputs!$F$24
D9: Opex escalation factor | E9: factor | J9: =(1+Inputs!$F$25/100)^J8 | K9: =(1+Inputs!$F$25/100)^K8 | L9: =(1+Inputs!$F$25/100)^L8 | M9: =(1+Inputs!$F$25/100)^M8 | N9: =(1+Inputs!$F$25/100)^N8 | O9: =(1+Inputs!$F$25/100)^O8 | P9: =(1+Inputs!$F$25/100)^P8 | Q9: =(1+Inputs!$F$25/100)^Q8 | ... AU9: =(1+Inputs!$F$25/100)^AU8
D10: Insurance step-up factor | E10: factor | J10: =1+Inputs!$F$234/100*Inputs!$F$233/100*(J4>=Inputs!$F$235) | K10: =1+Inputs!$F$234/100*Inputs!$F$233/100*(K4>=Inputs!$F$235) | L10: =1+Inputs!$F$234/100*Inputs!$F$233/100*(L4>=Inputs!$F$235) | M10: =1+Inputs!$F$234/100*Inputs!$F$233/100*(M4>=Inputs!$F$235) | N10: =1+Inputs!$F$234/100*Inputs!$F$233/100*(N4>=Inputs!$F$235) | O10: =1+Inputs!$F$234/100*Inputs!$F$233/100*(O4>=Inputs!$F$235) | P10: =1+Inputs!$F$234/100*Inputs!$F$233/100*(P4>=Inputs!$F$235) | Q10: =1+Inputs!$F$234/100*Inputs!$F$233/100*(Q4>=Inputs!$F$235) | ... AU10: =1+Inputs!$F$234/100*Inputs!$F$233/100*(AU4>=Inputs!$F$235)

Sheet Operations
A1: Operations: asset yield, hedges, revenue buckets, opex and cash flow
A2: Case R, Mesa Corta Renewables. USD m nominal unless stated. Illustrative prices: not ERCOT settlement data and not a forecast.
D4: Year | J4: =Time!J$4 | K4: =Time!K$4 | L4: =Time!L$4 | M4: =Time!M$4 | N4: =Time!N$4 | O4: =Time!O$4 | P4: =Time!P$4 | Q4: =Time!Q$4 | ... AU4: =Time!AU$4
D5: Period end | J5: =Time!J$6 | K5: =Time!K$6 | L5: =Time!L$6 | M5: =Time!M$6 | N5: =Time!N$6 | O5: =Time!O$6 | P5: =Time!P$6 | Q5: =Time!Q$6 | ... AU5: =Time!AU$6
A7: Yield statistics (normal; sigma_1^2 = sigma_LT^2 + sigma_IAV^2; sigma_10^2 = sigma_LT^2 + sigma_IAV^2/10)
D8: R1 sigma one-year | E8: fraction of P50 | F8: =(1-Inputs!$F$95/100)/Inputs!$F$30
D9: R1 sigma ten-year | E9: fraction of P50 | F9: =(1-Inputs!$F$96/100)/Inputs!$F$30
D10: R1 sigma inter-annual variability | E10: fraction of P50 | F10: =SQRT((Operations!$F$8^2-Operations!$F$9^2)*Inputs!$F$32/(Inputs!$F$32-1))
D11: R1 sigma long-term | E11: fraction of P50 | F11: =SQRT(Operations!$F$9^2-Operations!$F$10^2/Inputs!$F$32)
D12: R1 P99 one-year | E12: % of P50 | F12: =100*(1-Inputs!$F$31*Operations!$F$8)
D13: R1 P99 ten-year | E13: % of P50 | F13: =100*(1-Inputs!$F$31*Operations!$F$9)
D14: R2 sigma one-year | E14: fraction of P50 | F14: =(1-Inputs!$F$106/100)/Inputs!$F$30
D15: R2 sigma ten-year | E15: fraction of P50 | F15: =(1-Inputs!$F$107/100)/Inputs!$F$30
D16: R2 sigma inter-annual variability | E16: fraction of P50 | F16: =SQRT((Operations!$F$14^2-Operations!$F$15^2)*Inputs!$F$32/(Inputs!$F$32-1))
D17: R2 sigma long-term | E17: fraction of P50 | F17: =SQRT(Operations!$F$15^2-Operations!$F$16^2/Inputs!$F$32)
D18: R2 P99 one-year | E18: % of P50 | F18: =100*(1-Inputs!$F$31*Operations!$F$14)
D19: R2 P99 ten-year | E19: % of P50 | F19: =100*(1-Inputs!$F$31*Operations!$F$15)
D20: R3 sigma one-year | E20: fraction of P50 | F20: =(1-Inputs!$F$117/100)/Inputs!$F$30
D21: R3 sigma ten-year | E21: fraction of P50 | F21: =(1-Inputs!$F$118/100)/Inputs!$F$30
D22: R3 sigma inter-annual variability | E22: fraction of P50 | F22: =SQRT((Operations!$F$20^2-Operations!$F$21^2)*Inputs!$F$32/(Inputs!$F$32-1))
D23: R3 sigma long-term | E23: fraction of P50 | F23: =SQRT(Operations!$F$21^2-Operations!$F$22^2/Inputs!$F$32)
D24: R3 P99 one-year | E24: % of P50 | F24: =100*(1-Inputs!$F$31*Operations!$F$20)
D25: R3 P99 ten-year | E25: % of P50 | F25: =100*(1-Inputs!$F$31*Operations!$F$21)
D26: R4 sigma one-year | E26: fraction of P50 | F26: =(1-Inputs!$F$128/100)/Inputs!$F$30
D27: R4 sigma ten-year | E27: fraction of P50 | F27: =(1-Inputs!$F$129/100)/Inputs!$F$30
D28: R4 sigma inter-annual variability | E28: fraction of P50 | F28: =SQRT((Operations!$F$26^2-Operations!$F$27^2)*Inputs!$F$32/(Inputs!$F$32-1))
D29: R4 sigma long-term | E29: fraction of P50 | F29: =SQRT(Operations!$F$27^2-Operations!$F$28^2/Inputs!$F$32)
D30: R4 P99 one-year | E30: % of P50 | F30: =100*(1-Inputs!$F$31*Operations!$F$26)
D31: R4 P99 ten-year | E31: % of P50 | F31: =100*(1-Inputs!$F$31*Operations!$F$27)
D32: R5 sigma one-year | E32: fraction of P50 | F32: =(1-Inputs!$F$139/100)/Inputs!$F$30
D33: R5 sigma ten-year | E33: fraction of P50 | F33: =(1-Inputs!$F$140/100)/Inputs!$F$30
D34: R5 sigma inter-annual variability | E34: fraction of P50 | F34: =SQRT((Operations!$F$32^2-Operations!$F$33^2)*Inputs!$F$32/(Inputs!$F$32-1))
D35: R5 sigma long-term | E35: fraction of P50 | F35: =SQRT(Operations!$F$33^2-Operations!$F$34^2/Inputs!$F$32)
D36: R5 P99 one-year | E36: % of P50 | F36: =100*(1-Inputs!$F$31*Operations!$F$32)
D37: R5 P99 ten-year | E37: % of P50 | F37: =100*(1-Inputs!$F$31*Operations!$F$33)
D38: R8 sigma one-year | E38: fraction of P50 | F38: =(1-Inputs!$F$174/100)/Inputs!$F$30
D39: R8 sigma ten-year | E39: fraction of P50 | F39: =(1-Inputs!$F$175/100)/Inputs!$F$30
D40: R8 sigma inter-annual variability | E40: fraction of P50 | F40: =SQRT((Operations!$F$38^2-Operations!$F$39^2)*Inputs!$F$32/(Inputs!$F$32-1))
D41: R8 sigma long-term | E41: fraction of P50 | F41: =SQRT(Operations!$F$39^2-Operations!$F$40^2/Inputs!$F$32)
D42: R8 P99 one-year | E42: % of P50 | F42: =100*(1-Inputs!$F$31*Operations!$F$38)
...

Sheet Tax
A1: Tax: depreciation of purchase prices, taxable income, NOL and cash tax
A2: Case R, Mesa Corta Renewables. USD m nominal unless stated. Illustrative prices: not ERCOT settlement data and not a forecast.
D4: Year | J4: =Time!J$4 | K4: =Time!K$4 | L4: =Time!L$4 | M4: =Time!M$4 | N4: =Time!N$4 | O4: =Time!O$4 | P4: =Time!P$4 | Q4: =Time!Q$4 | ... AU4: =Time!AU$4
D5: Period end | J5: =Time!J$6 | K5: =Time!K$6 | L5: =Time!L$6 | M5: =Time!M$6 | N5: =Time!N$6 | O5: =Time!O$6 | P5: =Time!P$6 | Q5: =Time!Q$6 | ... AU5: =Time!AU$6
A7: ITC on R7 and R8 (claimed by the fund and transferred)
D8: R7 ITC | E8: USD m | F8: =Inputs!$F$248/100*Inputs!$F$249/100*Inputs!$F$263
D9: R8 ITC | E9: USD m | F9: =Inputs!$F$250/100*Inputs!$F$251/100*Inputs!$F$264
A11: Tax depreciation (bonus in acquisition year, MACRS half-year on the remainder)
D12: Depreciable basis, A1 | E12: USD m | F12: =Inputs!$F$257
D13: Recovery year index, A1 | E13: years | J13: =Time!J$4-YEAR(Inputs!$F$256) | K13: =Time!K$4-YEAR(Inputs!$F$256) | L13: =Time!L$4-YEAR(Inputs!$F$256) | M13: =Time!M$4-YEAR(Inputs!$F$256) | N13: =Time!N$4-YEAR(Inputs!$F$256) | O13: =Time!O$4-YEAR(Inputs!$F$256) | P13: =Time!P$4-YEAR(Inputs!$F$256) | Q13: =Time!Q$4-YEAR(Inputs!$F$256) | ... AU13: =Time!AU$4-YEAR(Inputs!$F$256)
D14: Tax depreciation, A1 | E14: USD m | G14: =SUM(J14:AU14) | J14: =Tax!$F$12*(Inputs!$F$243/100+Inputs!$F$244/100)*(IF(Tax!J13=0,Inputs!$F$245/100,0)+(1-Inputs!$F$245/100)*IF(AND(Tax!J13>=0,Tax!J13<Inputs!$F$84),INDEX(Inputs!$J$82:$AU$82,Tax!J13+1),0))+Tax!$F$12*Inputs!$F$244/100*(IF(Tax!J13=0,0,0))+Tax!$F$12*Inputs!$F$244/100*(1-Inputs!$F$245/100)*(IF(AND(Tax!J13>=0,Tax!J13<Inputs!$F$85),INDEX(Inputs!$J$83:$AU$83,Tax!J13+1),0)-IF(AND(Tax!J13>=0,Tax!J13<Inputs!$F$84),INDEX(Inputs!$J$82:$AU$82,Tax!J13+1),0)) | K14: =Tax!$F$12*(Inputs!$F$243/100+Inputs!$F$244/100)*(IF(Tax!K13=0,Inputs!$F$245/100,0)+(1-Inputs!$F$245/100)*IF(AND(Tax!K13>=0,Tax!K13<Inputs!$F$84),INDEX(Inputs!$J$82:$AU$82,Tax!K13+1),0))+Tax!$F$12*Inputs!$F$244/100*(IF(Tax!K13=0,0,0))+Tax!$F$12*Inputs!$F$244/100*(1-Inputs!$F$245/100)*(IF(AND(Tax!K13>=0,Tax!K13<Inputs!$F$85),INDEX(Inputs!$J$83:$AU$83,Tax!K13+1),0)-IF(AND(Tax!K13>=0,Tax!K13<Inputs!$F$84),INDEX(Inputs!$J$82:$AU$82,Tax!K13+1),0)) | L14: =Tax!$F$12*(Inputs!$F$243/100+Inputs!$F$244/100)*(IF(Tax!L13=0,Inputs!$F$245/100,0)+(1-Inputs!$F$245/100)*IF(AND(Tax!L13>=0,Tax!L13<Inputs!$F$84),INDEX(Inputs!$J$82:$AU$82,Tax!L13+1),0))+Tax!$F$12*Inputs!$F$244/100*(IF(Tax!L13=0,0,0))+Tax!$F$12*Inputs!$F$244/100*(1-Inputs!$F$245/100)*(IF(AND(Tax!L13>=0,Tax!L13<Inputs!$F$85),INDEX(Inputs!$J$83:$AU$83,Tax!L13+1),0)-IF(AND(Tax!L13>=0,Tax!L13<Inputs!$F$84),INDEX(Inputs!$J$82:$AU$82,Tax!L13+1),0)) | M14: =Tax!$F$12*(Inputs!$F$243/100+Inputs!$F$244/100)*(IF(Tax!M13=0,Inputs!$F$245/100,0)+(1-Inputs!$F$245/100)*IF(AND(Tax!M13>=0,Tax!M13<Inputs!$F$84),INDEX(Inputs!$J$82:$AU$82,Tax!M13+1),0))+Tax!$F$12*Inputs!$F$244/100*(IF(Tax!M13=0,0,0))+Tax!$F$12*Inputs!$F$244/100*(1-Inputs!$F$245/100)*(IF(AND(Tax!M13>=0,Tax!M13<Inputs!$F$85),INDEX(Inputs!$J$83:$AU$83,Tax!M13+1),0)-IF(AND(Tax!M13>=0,Tax!M13<Inputs!$F$84),INDEX(Inputs!$J$82:$AU$82,Tax!M13+1),0)) | N14: =Tax!$F$12*(Inputs!$F$243/100+Inputs!$F$244/100)*(IF(Tax!N13=0,Inputs!$F$245/100,0)+(1-Inputs!$F$245/100)*IF(AND(Tax!N13>=0,Tax!N13<Inputs!$F$84),INDEX(Inputs!$J$82:$AU$82,Tax!N13+1),0))+Tax!$F$12*Inputs!$F$244/100*(IF(Tax!N13=0,0,0))+Tax!$F$12*Inputs!$F$244/100*(1-Inputs!$F$245/100)*(IF(AND(Tax!N13>=0,Tax!N13<Inputs!$F$85),INDEX(Inputs!$J$83:$AU$83,Tax!N13+1),0)-IF(AND(Tax!N13>=0,Tax!N13<Inputs!$F$84),INDEX(Inputs!$J$82:$AU$82,Tax!N13+1),0)) | O14: =Tax!$F$12*(Inputs!$F$243/100+Inputs!$F$244/100)*(IF(Tax!O13=0,Inputs!$F$245/100,0)+(1-Inputs!$F$245/100)*IF(AND(Tax!O13>=0,Tax!O13<Inputs!$F$84),INDEX(Inputs!$J$82:$AU$82,Tax!O13+1),0))+Tax!$F$12*Inputs!$F$244/100*(IF(Tax!O13=0,0,0))+Tax!$F$12*Inputs!$F$244/100*(1-Inputs!$F$245/100)*(IF(AND(Tax!O13>=0,Tax!O13<Inputs!$F$85),INDEX(Inputs!$J$83:$AU$83,Tax!O13+1),0)-IF(AND(Tax!O13>=0,Tax!O13<Inputs!$F$84),INDEX(Inputs!$J$82:$AU$82,Tax!O13+1),0)) | P14: =Tax!$F$12*(Inputs!$F$243/100+Inputs!$F$244/100)*(IF(Tax!P13=0,Inputs!$F$245/100,0)+(1-Inputs!$F$245/100)*IF(AND(Tax!P13>=0,Tax!P13<Inputs!$F$84),INDEX(Inputs!$J$82:$AU$82,Tax!P13+1),0))+Tax!$F$12*Inputs!$F$244/100*(IF(Tax!P13=0,0,0))+Tax!$F$12*Inputs!$F$244/100*(1-Inputs!$F$245/100)*(IF(AND(Tax!P13>=0,Tax!P13<Inputs!$F$85),INDEX(Inputs!$J$83:$AU$83,Tax!P13+1),0)-IF(AND(Tax!P13>=0,Tax!P13<Inputs!$F$84),INDEX(Inputs!$J$82:$AU$82,Tax!P13+1),0)) | Q14: =Tax!$F$12*(Inputs!$F$243/100+Inputs!$F$244/100)*(IF(Tax!Q13=0,Inputs!$F$245/100,0)+(1-Inputs!$F$245/100)*IF(AND(Tax!Q13>=0,Tax!Q13<Inputs!$F$84),INDEX(Inputs!$J$82:$AU$82,Tax!Q13+1),0))+Tax!$F$12*Inputs!$F$244/100*(IF(Tax!Q13=0,0,0))+Tax!$F$12*Inputs!$F$244/100*(1-Inputs!$F$245/100)*(IF(AND(Tax!Q13>=0,Tax!Q13<Inputs!$F$85),INDEX(Inputs!$J$83:$AU$83,Tax!Q13+1),0)-IF(AND(Tax!Q13>=0,Tax!Q13<Inputs!$F$84),INDEX(Inputs!$J$82:$AU$82,Tax!Q13+1),0)) | ... AU14: =Tax!$F$12*(Inputs!$F$243/100+Inputs!$F$244/100)*(IF(Tax!AU13=0,Inputs!$F$245/100,0)+(1-Inputs!$F$245/100)*IF(AND(Tax!AU13>=0,Tax!AU13<Inputs!$F$84),INDEX(Inputs!$J$82:$AU$82,Tax!AU13+1),0))+Tax!$F$12*Inputs!$F$244/100*(IF(Tax!AU13=0,0,0))+Tax!$F$12*Inputs!$F$244/100*(1-Inputs!$F$245/100)*(IF(AND(Tax!AU13>=0,Tax!AU13<Inputs!$F$85),INDEX(Inputs!$J$83:$AU$83,Tax!AU13+1),0)-IF(AND(Tax!AU13>=0,Tax!AU13<Inputs!$F$84),INDEX(Inputs!$J$82:$AU$82,Tax!AU13+1),0))
D15: Depreciable basis, A2 | E15: USD m | F15: =Inputs!$F$260
D16: Recovery year index, A2 | E16: years | J16: =Time!J$4-YEAR(Inputs!$F$259) | K16: =Time!K$4-YEAR(Inputs!$F$259) | L16: =Time!L$4-YEAR(Inputs!$F$259) | M16: =Time!M$4-YEAR(Inputs!$F$259) | N16: =Time!N$4-YEAR(Inputs!$F$259) | O16: =Time!O$4-YEAR(Inputs!$F$259) | P16: =Time!P$4-YEAR(Inputs!$F$259) | Q16: =Time!Q$4-YEAR(Inputs!$F$259) | ... AU16: =Time!AU$4-YEAR(Inputs!$F$259)
D17: Tax depreciation, A2 | E17: USD m | G17: =SUM(J17:AU17) | J17: =Tax!$F$15*(Inputs!$F$243/100+Inputs!$F$244/100)*(IF(Tax!J16=0,Inputs!$F$246/100,0)+(1-Inputs!$F$246/100)*IF(AND(Tax!J16>=0,Tax!J16<Inputs!$F$84),INDEX(Inputs!$J$82:$AU$82,Tax!J16+1),0))+Tax!$F$15*Inputs!$F$244/100*(IF(Tax!J16=0,0,0))+Tax!$F$15*Inputs!$F$244/100*(1-Inputs!$F$246/100)*(IF(AND(Tax!J16>=0,Tax!J16<Inputs!$F$85),INDEX(Inputs!$J$83:$AU$83,Tax!J16+1),0)-IF(AND(Tax!J16>=0,Tax!J16<Inputs!$F$84),INDEX(Inputs!$J$82:$AU$82,Tax!J16+1),0)) | K17: =Tax!$F$15*(Inputs!$F$243/100+Inputs!$F$244/100)*(IF(Tax!K16=0,Inputs!$F$246/100,0)+(1-Inputs!$F$246/100)*IF(AND(Tax!K16>=0,Tax!K16<Inputs!$F$84),INDEX(Inputs!$J$82:$AU$82,Tax!K16+1),0))+Tax!$F$15*Inputs!$F$244/100*(IF(Tax!K16=0,0,0))+Tax!$F$15*Inputs!$F$244/100*(1-Inputs!$F$246/100)*(IF(AND(Tax!K16>=0,Tax!K16<Inputs!$F$85),INDEX(Inputs!$J$83:$AU$83,Tax!K16+1),0)-IF(AND(Tax!K16>=0,Tax!K16<Inputs!$F$84),INDEX(Inputs!$J$82:$AU$82,Tax!K16+1),0)) | L17: =Tax!$F$15*(Inputs!$F$243/100+Inputs!$F$244/100)*(IF(Tax!L16=0,Inputs!$F$246/100,0)+(1-Inputs!$F$246/100)*IF(AND(Tax!L16>=0,Tax!L16<Inputs!$F$84),INDEX(Inputs!$J$82:$AU$82,Tax!L16+1),0))+Tax!$F$15*Inputs!$F$244/100*(IF(Tax!L16=0,0,0))+Tax!$F$15*Inputs!$F$244/100*(1-Inputs!$F$246/100)*(IF(AND(Tax!L16>=0,Tax!L16<Inputs!$F$85),INDEX(Inputs!$J$83:$AU$83,Tax!L16+1),0)-IF(AND(Tax!L16>=0,Tax!L16<Inputs!$F$84),INDEX(Inputs!$J$82:$AU$82,Tax!L16+1),0)) | M17: =Tax!$F$15*(Inputs!$F$243/100+Inputs!$F$244/100)*(IF(Tax!M16=0,Inputs!$F$246/100,0)+(1-Inputs!$F$246/100)*IF(AND(Tax!M16>=0,Tax!M16<Inputs!$F$84),INDEX(Inputs!$J$82:$AU$82,Tax!M16+1),0))+Tax!$F$15*Inputs!$F$244/100*(IF(Tax!M16=0,0,0))+Tax!$F$15*Inputs!$F$244/100*(1-Inputs!$F$246/100)*(IF(AND(Tax!M16>=0,Tax!M16<Inputs!$F$85),INDEX(Inputs!$J$83:$AU$83,Tax!M16+1),0)-IF(AND(Tax!M16>=0,Tax!M16<Inputs!$F$84),INDEX(Inputs!$J$82:$AU$82,Tax!M16+1),0)) | N17: =Tax!$F$15*(Inputs!$F$243/100+Inputs!$F$244/100)*(IF(Tax!N16=0,Inputs!$F$246/100,0)+(1-Inputs!$F$246/100)*IF(AND(Tax!N16>=0,Tax!N16<Inputs!$F$84),INDEX(Inputs!$J$82:$AU$82,Tax!N16+1),0))+Tax!$F$15*Inputs!$F$244/100*(IF(Tax!N16=0,0,0))+Tax!$F$15*Inputs!$F$244/100*(1-Inputs!$F$246/100)*(IF(AND(Tax!N16>=0,Tax!N16<Inputs!$F$85),INDEX(Inputs!$J$83:$AU$83,Tax!N16+1),0)-IF(AND(Tax!N16>=0,Tax!N16<Inputs!$F$84),INDEX(Inputs!$J$82:$AU$82,Tax!N16+1),0)) | O17: =Tax!$F$15*(Inputs!$F$243/100+Inputs!$F$244/100)*(IF(Tax!O16=0,Inputs!$F$246/100,0)+(1-Inputs!$F$246/100)*IF(AND(Tax!O16>=0,Tax!O16<Inputs!$F$84),INDEX(Inputs!$J$82:$AU$82,Tax!O16+1),0))+Tax!$F$15*Inputs!$F$244/100*(IF(Tax!O16=0,0,0))+Tax!$F$15*Inputs!$F$244/100*(1-Inputs!$F$246/100)*(IF(AND(Tax!O16>=0,Tax!O16<Inputs!$F$85),INDEX(Inputs!$J$83:$AU$83,Tax!O16+1),0)-IF(AND(Tax!O16>=0,Tax!O16<Inputs!$F$84),INDEX(Inputs!$J$82:$AU$82,Tax!O16+1),0)) | P17: =Tax!$F$15*(Inputs!$F$243/100+Inputs!$F$244/100)*(IF(Tax!P16=0,Inputs!$F$246/100,0)+(1-Inputs!$F$246/100)*IF(AND(Tax!P16>=0,Tax!P16<Inputs!$F$84),INDEX(Inputs!$J$82:$AU$82,Tax!P16+1),0))+Tax!$F$15*Inputs!$F$244/100*(IF(Tax!P16=0,0,0))+Tax!$F$15*Inputs!$F$244/100*(1-Inputs!$F$246/100)*(IF(AND(Tax!P16>=0,Tax!P16<Inputs!$F$85),INDEX(Inputs!$J$83:$AU$83,Tax!P16+1),0)-IF(AND(Tax!P16>=0,Tax!P16<Inputs!$F$84),INDEX(Inputs!$J$82:$AU$82,Tax!P16+1),0)) | Q17: =Tax!$F$15*(Inputs!$F$243/100+Inputs!$F$244/100)*(IF(Tax!Q16=0,Inputs!$F$246/100,0)+(1-Inputs!$F$246/100)*IF(AND(Tax!Q16>=0,Tax!Q16<Inputs!$F$84),INDEX(Inputs!$J$82:$AU$82,Tax!Q16+1),0))+Tax!$F$15*Inputs!$F$244/100*(IF(Tax!Q16=0,0,0))+Tax!$F$15*Inputs!$F$244/100*(1-Inputs!$F$246/100)*(IF(AND(Tax!Q16>=0,Tax!Q16<Inputs!$F$85),INDEX(Inputs!$J$83:$AU$83,Tax!Q16+1),0)-IF(AND(Tax!Q16>=0,Tax!Q16<Inputs!$F$84),INDEX(Inputs!$J$82:$AU$82,Tax!Q16+1),0)) | ... AU17: =Tax!$F$15*(Inputs!$F$243/100+Inputs!$F$244/100)*(IF(Tax!AU16=0,Inputs!$F$246/100,0)+(1-Inputs!$F$246/100)*IF(AND(Tax!AU16>=0,Tax!AU16<Inputs!$F$84),INDEX(Inputs!$J$82:$AU$82,Tax!AU16+1),0))+Tax!$F$15*Inputs!$F$244/100*(IF(Tax!AU16=0,0,0))+Tax!$F$15*Inputs!$F$244/100*(1-Inputs!$F$246/100)*(IF(AND(Tax!AU16>=0,Tax!AU16<Inputs!$F$85),INDEX(Inputs!$J$83:$AU$83,Tax!AU16+1),0)-IF(AND(Tax!AU16>=0,Tax!AU16<Inputs!$F$84),INDEX(Inputs!$J$82:$AU$82,Tax!AU16+1),0))
D18: Depreciable basis, R7 | E18: USD m | F18: =Inputs!$F$263-Inputs!$F$253*Tax!$F$8
D19: Recovery year index, R7 | E19: years | J19: =Time!J$4-YEAR(Inputs!$F$262) | K19: =Time!K$4-YEAR(Inputs!$F$262) | L19: =Time!L$4-YEAR(Inputs!$F$262) | M19: =Time!M$4-YEAR(Inputs!$F$262) | N19: =Time!N$4-YEAR(Inputs!$F$262) | O19: =Time!O$4-YEAR(Inputs!$F$262) | P19: =Time!P$4-YEAR(Inputs!$F$262) | Q19: =Time!Q$4-YEAR(Inputs!$F$262) | ... AU19: =Time!AU$4-YEAR(Inputs!$F$262)
D20: Tax depreciation, R7 | E20: USD m | G20: =SUM(J20:AU20) | J20: =Tax!$F$18*(Inputs!$F$243/100+Inputs!$F$244/100)*(IF(Tax!J19=0,Inputs!$F$247/100,0)+(1-Inputs!$F$247/100)*IF(AND(Tax!J19>=0,Tax!J19<Inputs!$F$84),INDEX(Inputs!$J$82:$AU$82,Tax!J19+1),0))+Tax!$F$18*Inputs!$F$244/100*(IF(Tax!J19=0,0,0))+Tax!$F$18*Inputs!$F$244/100*(1-Inputs!$F$247/100)*(IF(AND(Tax!J19>=0,Tax!J19<Inputs!$F$85),INDEX(Inputs!$J$83:$AU$83,Tax!J19+1),0)-IF(AND(Tax!J19>=0,Tax!J19<Inputs!$F$84),INDEX(Inputs!$J$82:$AU$82,Tax!J19+1),0)) | K20: =Tax!$F$18*(Inputs!$F$243/100+Inputs!$F$244/100)*(IF(Tax!K19=0,Inputs!$F$247/100,0)+(1-Inputs!$F$247/100)*IF(AND(Tax!K19>=0,Tax!K19<Inputs!$F$84),INDEX(Inputs!$J$82:$AU$82,Tax!K19+1),0))+Tax!$F$18*Inputs!$F$244/100*(IF(Tax!K19=0,0,0))+Tax!$F$18*Inputs!$F$244/100*(1-Inputs!$F$247/100)*(IF(AND(Tax!K19>=0,Tax!K19<Inputs!$F$85),INDEX(Inputs!$J$83:$AU$83,Tax!K19+1),0)-IF(AND(Tax!K19>=0,Tax!K19<Inputs!$F$84),INDEX(Inputs!$J$82:$AU$82,Tax!K19+1),0)) | L20: =Tax!$F$18*(Inputs!$F$243/100+Inputs!$F$244/100)*(IF(Tax!L19=0,Inputs!$F$247/100,0)+(1-Inputs!$F$247/100)*IF(AND(Tax!L19>=0,Tax!L19<Inputs!$F$84),INDEX(Inputs!$J$82:$AU$82,Tax!L19+1),0))+Tax!$F$18*Inputs!$F$244/100*(IF(Tax!L19=0,0,0))+Tax!$F$18*Inputs!$F$244/100*(1-Inputs!$F$247/100)*(IF(AND(Tax!L19>=0,Tax!L19<Inputs!$F$85),INDEX(Inputs!$J$83:$AU$83,Tax!L19+1),0)-IF(AND(Tax!L19>=0,Tax!L19<Inputs!$F$84),INDEX(Inputs!$J$82:$AU$82,Tax!L19+1),0)) | M20: =Tax!$F$18*(Inputs!$F$243/100+Inputs!$F$244/100)*(IF(Tax!M19=0,Inputs!$F$247/100,0)+(1-Inputs!$F$247/100)*IF(AND(Tax!M19>=0,Tax!M19<Inputs!$F$84),INDEX(Inputs!$J$82:$AU$82,Tax!M19+1),0))+Tax!$F$18*Inputs!$F$244/100*(IF(Tax!M19=0,0,0))+Tax!$F$18*Inputs!$F$244/100*(1-Inputs!$F$247/100)*(IF(AND(Tax!M19>=0,Tax!M19<Inputs!$F$85),INDEX(Inputs!$J$83:$AU$83,Tax!M19+1),0)-IF(AND(Tax!M19>=0,Tax!M19<Inputs!$F$84),INDEX(Inputs!$J$82:$AU$82,Tax!M19+1),0)) | N20: =Tax!$F$18*(Inputs!$F$243/100+Inputs!$F$244/100)*(IF(Tax!N19=0,Inputs!$F$247/100,0)+(1-Inputs!$F$247/100)*IF(AND(Tax!N19>=0,Tax!N19<Inputs!$F$84),INDEX(Inputs!$J$82:$AU$82,Tax!N19+1),0))+Tax!$F$18*Inputs!$F$244/100*(IF(Tax!N19=0,0,0))+Tax!$F$18*Inputs!$F$244/100*(1-Inputs!$F$247/100)*(IF(AND(Tax!N19>=0,Tax!N19<Inputs!$F$85),INDEX(Inputs!$J$83:$AU$83,Tax!N19+1),0)-IF(AND(Tax!N19>=0,Tax!N19<Inputs!$F$84),INDEX(Inputs!$J$82:$AU$82,Tax!N19+1),0)) | O20: =Tax!$F$18*(Inputs!$F$243/100+Inputs!$F$244/100)*(IF(Tax!O19=0,Inputs!$F$247/100,0)+(1-Inputs!$F$247/100)*IF(AND(Tax!O19>=0,Tax!O19<Inputs!$F$84),INDEX(Inputs!$J$82:$AU$82,Tax!O19+1),0))+Tax!$F$18*Inputs!$F$244/100*(IF(Tax!O19=0,0,0))+Tax!$F$18*Inputs!$F$244/100*(1-Inputs!$F$247/100)*(IF(AND(Tax!O19>=0,Tax!O19<Inputs!$F$85),INDEX(Inputs!$J$83:$AU$83,Tax!O19+1),0)-IF(AND(Tax!O19>=0,Tax!O19<Inputs!$F$84),INDEX(Inputs!$J$82:$AU$82,Tax!O19+1),0)) | P20: =Tax!$F$18*(Inputs!$F$243/100+Inputs!$F$244/100)*(IF(Tax!P19=0,Inputs!$F$247/100,0)+(1-Inputs!$F$247/100)*IF(AND(Tax!P19>=0,Tax!P19<Inputs!$F$84),INDEX(Inputs!$J$82:$AU$82,Tax!P19+1),0))+Tax!$F$18*Inputs!$F$244/100*(IF(Tax!P19=0,0,0))+Tax!$F$18*Inputs!$F$244/100*(1-Inputs!$F$247/100)*(IF(AND(Tax!P19>=0,Tax!P19<Inputs!$F$85),INDEX(Inputs!$J$83:$AU$83,Tax!P19+1),0)-IF(AND(Tax!P19>=0,Tax!P19<Inputs!$F$84),INDEX(Inputs!$J$82:$AU$82,Tax!P19+1),0)) | Q20: =Tax!$F$18*(Inputs!$F$243/100+Inputs!$F$244/100)*(IF(Tax!Q19=0,Inputs!$F$247/100,0)+(1-Inputs!$F$247/100)*IF(AND(Tax!Q19>=0,Tax!Q19<Inputs!$F$84),INDEX(Inputs!$J$82:$AU$82,Tax!Q19+1),0))+Tax!$F$18*Inputs!$F$244/100*(IF(Tax!Q19=0,0,0))+Tax!$F$18*Inputs!$F$244/100*(1-Inputs!$F$247/100)*(IF(AND(Tax!Q19>=0,Tax!Q19<Inputs!$F$85),INDEX(Inputs!$J$83:$AU$83,Tax!Q19+1),0)-IF(AND(Tax!Q19>=0,Tax!Q19<Inputs!$F$84),INDEX(Inputs!$J$82:$AU$82,Tax!Q19+1),0)) | ... AU20: =Tax!$F$18*(Inputs!$F$243/100+Inputs!$F$244/100)*(IF(Tax!AU19=0,Inputs!$F$247/100,0)+(1-Inputs!$F$247/100)*IF(AND(Tax!AU19>=0,Tax!AU19<Inputs!$F$84),INDEX(Inputs!$J$82:$AU$82,Tax!AU19+1),0))+Tax!$F$18*Inputs!$F$244/100*(IF(Tax!AU19=0,0,0))+Tax!$F$18*Inputs!$F$244/100*(1-Inputs!$F$247/100)*(IF(AND(Tax!AU19>=0,Tax!AU19<Inputs!$F$85),INDEX(Inputs!$J$83:$AU$83,Tax!AU19+1),0)-IF(AND(Tax!AU19>=0,Tax!AU19<Inputs!$F$84),INDEX(Inputs!$J$82:$AU$82,Tax!AU19+1),0))
D21: Depreciable basis, R8 | E21: USD m | F21: =Inputs!$F$264-Inputs!$F$253*Tax!$F$9
D22: Recovery year index, R8 | E22: years | J22: =Time!J$4-YEAR(Inputs!$F$262) | K22: =Time!K$4-YEAR(Inputs!$F$262) | L22: =Time!L$4-YEAR(Inputs!$F$262) | M22: =Time!M$4-YEAR(Inputs!$F$262) | N22: =Time!N$4-YEAR(Inputs!$F$262) | O22: =Time!O$4-YEAR(Inputs!$F$262) | P22: =Time!P$4-YEAR(Inputs!$F$262) | Q22: =Time!Q$4-YEAR(Inputs!$F$262) | ... AU22: =Time!AU$4-YEAR(Inputs!$F$262)
D23: Tax depreciation, R8 | E23: USD m | G23: =SUM(J23:AU23) | J23: =Tax!$F$21*(Inputs!$F$243/100+Inputs!$F$244/100)*(IF(Tax!J22=0,Inputs!$F$247/100,0)+(1-Inputs!$F$247/100)*IF(AND(Tax!J22>=0,Tax!J22<Inputs!$F$84),INDEX(Inputs!$J$82:$AU$82,Tax!J22+1),0))+Tax!$F$21*Inputs!$F$244/100*(IF(Tax!J22=0,0,0))+Tax!$F$21*Inputs!$F$244/100*(1-Inputs!$F$247/100)*(IF(AND(Tax!J22>=0,Tax!J22<Inputs!$F$85),INDEX(Inputs!$J$83:$AU$83,Tax!J22+1),0)-IF(AND(Tax!J22>=0,Tax!J22<Inputs!$F$84),INDEX(Inputs!$J$82:$AU$82,Tax!J22+1),0)) | K23: =Tax!$F$21*(Inputs!$F$243/100+Inputs!$F$244/100)*(IF(Tax!K22=0,Inputs!$F$247/100,0)+(1-Inputs!$F$247/100)*IF(AND(Tax!K22>=0,Tax!K22<Inputs!$F$84),INDEX(Inputs!$J$82:$AU$82,Tax!K22+1),0))+Tax!$F$21*Inputs!$F$244/100*(IF(Tax!K22=0,0,0))+Tax!$F$21*Inputs!$F$244/100*(1-Inputs!$F$247/100)*(IF(AND(Tax!K22>=0,Tax!K22<Inputs!$F$85),INDEX(Inputs!$J$83:$AU$83,Tax!K22+1),0)-IF(AND(Tax!K22>=0,Tax!K22<Inputs!$F$84),INDEX(Inputs!$J$82:$AU$82,Tax!K22+1),0)) | L23: =Tax!$F$21*(Inputs!$F$243/100+Inputs!$F$244/100)*(IF(Tax!L22=0,Inputs!$F$247/100,0)+(1-Inputs!$F$247/100)*IF(AND(Tax!L22>=0,Tax!L22<Inputs!$F$84),INDEX(Inputs!$J$82:$AU$82,Tax!L22+1),0))+Tax!$F$21*Inputs!$F$244/100*(IF(Tax!L22=0,0,0))+Tax!$F$21*Inputs!$F$244/100*(1-Inputs!$F$247/100)*(IF(AND(Tax!L22>=0,Tax!L22<Inputs!$F$85),INDEX(Inputs!$J$83:$AU$83,Tax!L22+1),0)-IF(AND(Tax!L22>=0,Tax!L22<Inputs!$F$84),INDEX(Inputs!$J$82:$AU$82,Tax!L22+1),0)) | M23: =Tax!$F$21*(Inputs!$F$243/100+Inputs!$F$244/100)*(IF(Tax!M22=0,Inputs!$F$247/100,0)+(1-Inputs!$F$247/100)*IF(AND(Tax!M22>=0,Tax!M22<Inputs!$F$84),INDEX(Inputs!$J$82:$AU$82,Tax!M22+1),0))+Tax!$F$21*Inputs!$F$244/100*(IF(Tax!M22=0,0,0))+Tax!$F$21*Inputs!$F$244/100*(1-Inputs!$F$247/100)*(IF(AND(Tax!M22>=0,Tax!M22<Inputs!$F$85),INDEX(Inputs!$J$83:$AU$83,Tax!M22+1),0)-IF(AND(Tax!M22>=0,Tax!M22<Inputs!$F$84),INDEX(Inputs!$J$82:$AU$82,Tax!M22+1),0)) | N23: =Tax!$F$21*(Inputs!$F$243/100+Inputs!$F$244/100)*(IF(Tax!N22=0,Inputs!$F$247/100,0)+(1-Inputs!$F$247/100)*IF(AND(Tax!N22>=0,Tax!N22<Inputs!$F$84),INDEX(Inputs!$J$82:$AU$82,Tax!N22+1),0))+Tax!$F$21*Inputs!$F$244/100*(IF(Tax!N22=0,0,0))+Tax!$F$21*Inputs!$F$244/100*(1-Inputs!$F$247/100)*(IF(AND(Tax!N22>=0,Tax!N22<Inputs!$F$85),INDEX(Inputs!$J$83:$AU$83,Tax!N22+1),0)-IF(AND(Tax!N22>=0,Tax!N22<Inputs!$F$84),INDEX(Inputs!$J$82:$AU$82,Tax!N22+1),0)) | O23: =Tax!$F$21*(Inputs!$F$243/100+Inputs!$F$244/100)*(IF(Tax!O22=0,Inputs!$F$247/100,0)+(1-Inputs!$F$247/100)*IF(AND(Tax!O22>=0,Tax!O22<Inputs!$F$84),INDEX(Inputs!$J$82:$AU$82,Tax!O22+1),0))+Tax!$F$21*Inputs!$F$244/100*(IF(Tax!O22=0,0,0))+Tax!$F$21*Inputs!$F$244/100*(1-Inputs!$F$247/100)*(IF(AND(Tax!O22>=0,Tax!O22<Inputs!$F$85),INDEX(Inputs!$J$83:$AU$83,Tax!O22+1),0)-IF(AND(Tax!O22>=0,Tax!O22<Inputs!$F$84),INDEX(Inputs!$J$82:$AU$82,Tax!O22+1),0)) | P23: =Tax!$F$21*(Inputs!$F$243/100+Inputs!$F$244/100)*(IF(Tax!P22=0,Inputs!$F$247/100,0)+(1-Inputs!$F$247/100)*IF(AND(Tax!P22>=0,Tax!P22<Inputs!$F$84),INDEX(Inputs!$J$82:$AU$82,Tax!P22+1),0))+Tax!$F$21*Inputs!$F$244/100*(IF(Tax!P22=0,0,0))+Tax!$F$21*Inputs!$F$244/100*(1-Inputs!$F$247/100)*(IF(AND(Tax!P22>=0,Tax!P22<Inputs!$F$85),INDEX(Inputs!$J$83:$AU$83,Tax!P22+1),0)-IF(AND(Tax!P22>=0,Tax!P22<Inputs!$F$84),INDEX(Inputs!$J$82:$AU$82,Tax!P22+1),0)) | Q23: =Tax!$F$21*(Inputs!$F$243/100+Inputs!$F$244/100)*(IF(Tax!Q22=0,Inputs!$F$247/100,0)+(1-Inputs!$F$247/100)*IF(AND(Tax!Q22>=0,Tax!Q22<Inputs!$F$84),INDEX(Inputs!$J$82:$AU$82,Tax!Q22+1),0))+Tax!$F$21*Inputs!$F$244/100*(IF(Tax!Q22=0,0,0))+Tax!$F$21*Inputs!$F$244/100*(1-Inputs!$F$247/100)*(IF(AND(Tax!Q22>=0,Tax!Q22<Inputs!$F$85),INDEX(Inputs!$J$83:$AU$83,Tax!Q22+1),0)-IF(AND(Tax!Q22>=0,Tax!Q22<Inputs!$F$84),INDEX(Inputs!$J$82:$AU$82,Tax!Q22+1),0)) | ... AU23: =Tax!$F$21*(Inputs!$F$243/100+Inputs!$F$244/100)*(IF(Tax!AU22=0,Inputs!$F$247/100,0)+(1-Inputs!$F$247/100)*IF(AND(Tax!AU22>=0,Tax!AU22<Inputs!$F$84),INDEX(Inputs!$J$82:$AU$82,Tax!AU22+1),0))+Tax!$F$21*Inputs!$F$244/100*(IF(Tax!AU22=0,0,0))+Tax!$F$21*Inputs!$F$244/100*(1-Inputs!$F$247/100)*(IF(AND(Tax!AU22>=0,Tax!AU22<Inputs!$F$85),INDEX(Inputs!$J$83:$AU$83,Tax!AU22+1),0)-IF(AND(Tax!AU22>=0,Tax!AU22<Inputs!$F$84),INDEX(Inputs!$J$82:$AU$82,Tax!AU22+1),0))
D24: Tax depreciation, total | E24: USD m | G24: =SUM(J24:AU24) | J24: =Tax!J14+Tax!J17+Tax!J20+Tax!J23 | K24: =Tax!K14+Tax!K17+Tax!K20+Tax!K23 | L24: =Tax!L14+Tax!L17+Tax!L20+Tax!L23 | M24: =Tax!M14+Tax!M17+Tax!M20+Tax!M23 | N24: =Tax!N14+Tax!N17+Tax!N20+Tax!N23 | O24: =Tax!O14+Tax!O17+Tax!O20+Tax!O23 | P24: =Tax!P14+Tax!P17+Tax!P20+Tax!P23 | Q24: =Tax!Q14+Tax!Q17+Tax!Q20+Tax!Q23 | ... AU24: =Tax!AU14+Tax!AU17+Tax!AU20+Tax!AU23
D25: Taxable operating income (Mesa shares) less asset management | E25: USD m | J25: =Operations!J95+Operations!J137+Operations!J180+Operations!J223+Operations!J266+Operations!J298+Operations!J331+Operations!J373-Operations!J384 | K25: =Operations!K95+Operations!K137+Operations!K180+Operations!K223+Operations!K266+Operations!K298+Operations!K331+Operations!K373-Operations!K384 | L25: =Operations!L95+Operations!L137+Operations!L180+Operations!L223+Operations!L266+Operations!L298+Operations!L331+Operations!L373-Operations!L384 | M25: =Operations!M95+Operations!M137+Operations!M180+Operations!M223+Operations!M266+Operations!M298+Operations!M331+Operations!M373-Operations!M384 | N25: =Operations!N95+Operations!N137+Operations!N180+Operations!N223+Operations!N266+Operations!N298+Operations!N331+Operations!N373-Operations!N384 | O25: =Operations!O95+Operations!O137+Operations!O180+Operations!O223+Operations!O266+Operations!O298+Operations!O331+Operations!O373-Operations!O384 | P25: =Operations!P95+Operations!P137+Operations!P180+Operations!P223+Operations!P266+Operations!P298+Operations!P331+Operations!P373-Operations!P384 | Q25: =Operations!Q95+Operations!Q137+Operations!Q180+Operations!Q223+Operations!Q266+Operations!Q298+Operations!Q331+Operations!Q373-Operations!Q384 | ... AU25: =Operations!AU95+Operations!AU137+Operations!AU180+Operations!AU223+Operations!AU266+Operations!AU298+Operations!AU331+Operations!AU373-Operations!AU384
A27: Taxable income, NOL and cash tax (Mesa Corta modeled as a taxable blocker)
D28: Interest deducted (opco TL, Redfern, USPP, holdco) | E28: USD m | J28: =Debt!J15+Debt!J24+Debt!J32+Debt!J47+Debt!J54+Debt!J61 | K28: =Debt!K15+Debt!K24+Debt!K32+Debt!K47+Debt!K54+Debt!K61 | L28: =Debt!L15+Debt!L24+Debt!L32+Debt!L47+Debt!L54+Debt!L61 | M28: =Debt!M15+Debt!M24+Debt!M32+Debt!M47+Debt!M54+Debt!M61 | N28: =Debt!N15+Debt!N24+Debt!N32+Debt!N47+Debt!N54+Debt!N61 | O28: =Debt!O15+Debt!O24+Debt!O32+Debt!O47+Debt!O54+Debt!O61 | P28: =Debt!P15+Debt!P24+Debt!P32+Debt!P47+Debt!P54+Debt!P61 | Q28: =Debt!Q15+Debt!Q24+Debt!Q32+Debt!Q47+Debt!Q54+Debt!Q61 | ... AU28: =Debt!AU15+Debt!AU24+Debt!AU32+Debt!AU47+Debt!AU54+Debt!AU61
D29: Taxable income before NOL | E29: USD m | J29: =Tax!J25-Tax!J24-Tax!J28 | K29: =Tax!K25-Tax!K24-Tax!K28 | L29: =Tax!L25-Tax!L24-Tax!L28 | M29: =Tax!M25-Tax!M24-Tax!M28 | N29: =Tax!N25-Tax!N24-Tax!N28 | O29: =Tax!O25-Tax!O24-Tax!O28 | P29: =Tax!P25-Tax!P24-Tax!P28 | Q29: =Tax!Q25-Tax!Q24-Tax!Q28 | ... AU29: =Tax!AU25-Tax!AU24-Tax!AU28
D30: NOL opening | E30: USD m | J30: =I33 | K30: =J33 | L30: =K33 | M30: =L33 | N30: =M33 | O30: =N33 | P30: =O33 | Q30: =P33 | ... AU30: =AT33
D31: NOL used (limited to 80% of taxable income) | E31: USD m | G31: =SUM(J31:AU31) | J31: =MIN(Tax!J30,Inputs!$F$242/100*MAX(Tax!J29,0)) | K31: =MIN(Tax!K30,Inputs!$F$242/100*MAX(Tax!K29,0)) | L31: =MIN(Tax!L30,Inputs!$F$242/100*MAX(Tax!L29,0)) | M31: =MIN(Tax!M30,Inputs!$F$242/100*MAX(Tax!M29,0)) | N31: =MIN(Tax!N30,Inputs!$F$242/100*MAX(Tax!N29,0)) | O31: =MIN(Tax!O30,Inputs!$F$242/100*MAX(Tax!O29,0)) | P31: =MIN(Tax!P30,Inputs!$F$242/100*MAX(Tax!P29,0)) | Q31: =MIN(Tax!Q30,Inputs!$F$242/100*MAX(Tax!Q29,0)) | ... AU31: =MIN(Tax!AU30,Inputs!$F$242/100*MAX(Tax!AU29,0))
D32: Cash tax | E32: USD m | G32: =SUM(J32:AU32) | J32: =Inputs!$F$241/100*(MAX(Tax!J29,0)-Tax!J31) | K32: =Inputs!$F$241/100*(MAX(Tax!K29,0)-Tax!K31) | L32: =Inputs!$F$241/100*(MAX(Tax!L29,0)-Tax!L31) | M32: =Inputs!$F$241/100*(MAX(Tax!M29,0)-Tax!M31) | N32: =Inputs!$F$241/100*(MAX(Tax!N29,0)-Tax!N31) | O32: =Inputs!$F$241/100*(MAX(Tax!O29,0)-Tax!O31) | P32: =Inputs!$F$241/100*(MAX(Tax!P29,0)-Tax!P31) | Q32: =Inputs!$F$241/100*(MAX(Tax!Q29,0)-Tax!Q31) | ... AU32: =Inputs!$F$241/100*(MAX(Tax!AU29,0)-Tax!AU31)
D33: NOL closing | E33: USD m | J33: =Tax!J30-Tax!J31+MAX(-Tax!J29,0) | K33: =Tax!K30-Tax!K31+MAX(-Tax!K29,0) | L33: =Tax!L30-Tax!L31+MAX(-Tax!L29,0) | M33: =Tax!M30-Tax!M31+MAX(-Tax!M29,0) | N33: =Tax!N30-Tax!N31+MAX(-Tax!N29,0) | O33: =Tax!O30-Tax!O31+MAX(-Tax!O29,0) | P33: =Tax!P30-Tax!P31+MAX(-Tax!P29,0) | Q33: =Tax!Q30-Tax!Q31+MAX(-Tax!Q29,0) | ... AU33: =Tax!AU30-Tax!AU31+MAX(-Tax!AU29,0)

Sheet Funding
A1: Funding: debt sizing (base P50 and P99 sizing blocks), sources and uses, 2025 refinancing
A2: Case R, Mesa Corta Renewables. USD m nominal unless stated. Illustrative prices: not ERCOT settlement data and not a forecast.
D4: Year | J4: =Time!J$4 | K4: =Time!K$4 | L4: =Time!L$4 | M4: =Time!M$4 | N4: =Time!N$4 | O4: =Time!O$4 | P4: =Time!P$4 | Q4: =Time!Q$4 | ... AU4: =Time!AU$4
D5: Period end | J5: =Time!J$6 | K5: =Time!K$6 | L5: =Time!L$6 | M5: =Time!M$6 | N5: =Time!N$6 | O5: =Time!O$6 | P5: =Time!P$6 | Q5: =Time!Q$6 | ... AU5: =Time!AU$6
A7: Opco term loan, March 22, 2022 (A1 group, sculpted to December 31, 2040)
D8: Interest period fraction (loan date to notional end) | E8: fraction | J8: =MAX(0,MIN(Inputs!$F$270,Time!J$6)-MAX(Inputs!$F$269,Time!J$5))/Time!J$7 | K8: =MAX(0,MIN(Inputs!$F$270,Time!K$6)-MAX(Inputs!$F$269,Time!K$5))/Time!K$7 | L8: =MAX(0,MIN(Inputs!$F$270,Time!L$6)-MAX(Inputs!$F$269,Time!L$5))/Time!L$7 | M8: =MAX(0,MIN(Inputs!$F$270,Time!M$6)-MAX(Inputs!$F$269,Time!M$5))/Time!M$7 | N8: =MAX(0,MIN(Inputs!$F$270,Time!N$6)-MAX(Inputs!$F$269,Time!N$5))/Time!N$7 | O8: =MAX(0,MIN(Inputs!$F$270,Time!O$6)-MAX(Inputs!$F$269,Time!O$5))/Time!O$7 | P8: =MAX(0,MIN(Inputs!$F$270,Time!P$6)-MAX(Inputs!$F$269,Time!P$5))/Time!P$7 | Q8: =MAX(0,MIN(Inputs!$F$270,Time!Q$6)-MAX(Inputs!$F$269,Time!Q$5))/Time!Q$7 | ... AU8: =MAX(0,MIN(Inputs!$F$270,Time!AU$6)-MAX(Inputs!$F$269,Time!AU$5))/Time!AU$7
D9: Fraction of year before margin step | E9: fraction | J9: =MAX(0,MIN(Inputs!$F$273,Time!J$6)-Time!J$5)/Time!J$7 | K9: =MAX(0,MIN(Inputs!$F$273,Time!K$6)-Time!K$5)/Time!K$7 | L9: =MAX(0,MIN(Inputs!$F$273,Time!L$6)-Time!L$5)/Time!L$7 | M9: =MAX(0,MIN(Inputs!$F$273,Time!M$6)-Time!M$5)/Time!M$7 | N9: =MAX(0,MIN(Inputs!$F$273,Time!N$6)-Time!N$5)/Time!N$7 | O9: =MAX(0,MIN(Inputs!$F$273,Time!O$6)-Time!O$5)/Time!O$7 | P9: =MAX(0,MIN(Inputs!$F$273,Time!P$6)-Time!P$5)/Time!P$7 | Q9: =MAX(0,MIN(Inputs!$F$273,Time!Q$6)-Time!Q$5)/Time!Q$7 | ... AU9: =MAX(0,MIN(Inputs!$F$273,Time!AU$6)-Time!AU$5)/Time!AU$7
D10: Margin | E10: % | J10: =Inputs!$F$272-(Inputs!$F$272-Inputs!$F$271)*Funding!J9 | K10: =Inputs!$F$272-(Inputs!$F$272-Inputs!$F$271)*Funding!K9 | L10: =Inputs!$F$272-(Inputs!$F$272-Inputs!$F$271)*Funding!L9 | M10: =Inputs!$F$272-(Inputs!$F$272-Inputs!$F$271)*Funding!M9 | N10: =Inputs!$F$272-(Inputs!$F$272-Inputs!$F$271)*Funding!N9 | O10: =Inputs!$F$272-(Inputs!$F$272-Inputs!$F$271)*Funding!O9 | P10: =Inputs!$F$272-(Inputs!$F$272-Inputs!$F$271)*Funding!P9 | Q10: =Inputs!$F$272-(Inputs!$F$272-Inputs!$F$271)*Funding!Q9 | ... AU10: =Inputs!$F$272-(Inputs!$F$272-Inputs!$F$271)*Funding!AU9
D11: Hedged share (hedge ratio x fraction of year before swap end) | E11: fraction | J11: =Inputs!$F$279/100*MAX(0,MIN(Inputs!$F$281,Time!J$6)-Time!J$5)/Time!J$7 | K11: =Inputs!$F$279/100*MAX(0,MIN(Inputs!$F$281,Time!K$6)-Time!K$5)/Time!K$7 | L11: =Inputs!$F$279/100*MAX(0,MIN(Inputs!$F$281,Time!L$6)-Time!L$5)/Time!L$7 | M11: =Inputs!$F$279/100*MAX(0,MIN(Inputs!$F$281,Time!M$6)-Time!M$5)/Time!M$7 | N11: =Inputs!$F$279/100*MAX(0,MIN(Inputs!$F$281,Time!N$6)-Time!N$5)/Time!N$7 | O11: =Inputs!$F$279/100*MAX(0,MIN(Inputs!$F$281,Time!O$6)-Time!O$5)/Time!O$7 | P11: =Inputs!$F$279/100*MAX(0,MIN(Inputs!$F$281,Time!P$6)-Time!P$5)/Time!P$7 | Q11: =Inputs!$F$279/100*MAX(0,MIN(Inputs!$F$281,Time!Q$6)-Time!Q$5)/Time!Q$7 | ... AU11: =Inputs!$F$279/100*MAX(0,MIN(Inputs!$F$281,Time!AU$6)-Time!AU$5)/Time!AU$7
D12: All-in sizing rate | E12: % | J12: =Funding!J11*Inputs!$F$280+(1-Funding!J11)*Inputs!J80+Funding!J10 | K12: =Funding!K11*Inputs!$F$280+(1-Funding!K11)*Inputs!K80+Funding!K10 | L12: =Funding!L11*Inputs!$F$280+(1-Funding!L11)*Inputs!L80+Funding!L10 | M12: =Funding!M11*Inputs!$F$280+(1-Funding!M11)*Inputs!M80+Funding!M10 | N12: =Funding!N11*Inputs!$F$280+(1-Funding!N11)*Inputs!N80+Funding!N10 | O12: =Funding!O11*Inputs!$F$280+(1-Funding!O11)*Inputs!O80+Funding!O10 | P12: =Funding!P11*Inputs!$F$280+(1-Funding!P11)*Inputs!P80+Funding!P10 | Q12: =Funding!Q11*Inputs!$F$280+(1-Funding!Q11)*Inputs!Q80+Funding!Q10 | ... AU12: =Funding!AU11*Inputs!$F$280+(1-Funding!AU11)*Inputs!AU80+Funding!AU10
D13: Debt-service capacity by bucket (CFADS / bucket DSCR) | E13: USD m | J13: =Operations!J777/Inputs!$F$275+Operations!J778/Inputs!$F$276+Operations!J779/Inputs!$F$277 | K13: =Operations!K777/Inputs!$F$275+Operations!K778/Inputs!$F$276+Operations!K779/Inputs!$F$277 | L13: =Operations!L777/Inputs!$F$275+Operations!L778/Inputs!$F$276+Operations!L779/Inputs!$F$277 | M13: =Operations!M777/Inputs!$F$275+Operations!M778/Inputs!$F$276+Operations!M779/Inputs!$F$277 | N13: =Operations!N777/Inputs!$F$275+Operations!N778/Inputs!$F$276+Operations!N779/Inputs!$F$277 | O13: =Operations!O777/Inputs!$F$275+Operations!O778/Inputs!$F$276+Operations!O779/Inputs!$F$277 | P13: =Operations!P777/Inputs!$F$275+Operations!P778/Inputs!$F$276+Operations!P779/Inputs!$F$277 | Q13: =Operations!Q777/Inputs!$F$275+Operations!Q778/Inputs!$F$276+Operations!Q779/Inputs!$F$277 | ... AU13: =Operations!AU777/Inputs!$F$275+Operations!AU778/Inputs!$F$276+Operations!AU779/Inputs!$F$277
D14: Debt-service capacity at P99 (P99 CFADS / 1.00x) | E14: USD m | J14: =Operations!J1142/Inputs!$F$278 | K14: =Operations!K1142/Inputs!$F$278 | L14: =Operations!L1142/Inputs!$F$278 | M14: =Operations!M1142/Inputs!$F$278 | N14: =Operations!N1142/Inputs!$F$278 | O14: =Operations!O1142/Inputs!$F$278 | P14: =Operations!P1142/Inputs!$F$278 | Q14: =Operations!Q1142/Inputs!$F$278 | ... AU14: =Operations!AU1142/Inputs!$F$278
D15: Sculpted debt service | E15: USD m | G15: =SUM(J15:AU15) | J15: =IF(Funding!J8>0,MAX(0,MIN(Funding!J13,Funding!J14)),0) | K15: =IF(Funding!K8>0,MAX(0,MIN(Funding!K13,Funding!K14)),0) | L15: =IF(Funding!L8>0,MAX(0,MIN(Funding!L13,Funding!L14)),0) | M15: =IF(Funding!M8>0,MAX(0,MIN(Funding!M13,Funding!M14)),0) | N15: =IF(Funding!N8>0,MAX(0,MIN(Funding!N13,Funding!N14)),0) | O15: =IF(Funding!O8>0,MAX(0,MIN(Funding!O13,Funding!O14)),0) | P15: =IF(Funding!P8>0,MAX(0,MIN(Funding!P13,Funding!P14)),0) | Q15: =IF(Funding!Q8>0,MAX(0,MIN(Funding!Q13,Funding!Q14)),0) | ... AU15: =IF(Funding!AU8>0,MAX(0,MIN(Funding!AU13,Funding!AU14)),0)
D16: Discount factor to loan date | E16: factor | J16: =IF(Time!J$4=Inputs!$F$23,1,I16)/(1+Funding!J12/100*Funding!J8) | K16: =IF(Time!K$4=Inputs!$F$23,1,J16)/(1+Funding!K12/100*Funding!K8) | L16: =IF(Time!L$4=Inputs!$F$23,1,K16)/(1+Funding!L12/100*Funding!L8) | M16: =IF(Time!M$4=Inputs!$F$23,1,L16)/(1+Funding!M12/100*Funding!M8) | N16: =IF(Time!N$4=Inputs!$F$23,1,M16)/(1+Funding!N12/100*Funding!N8) | O16: =IF(Time!O$4=Inputs!$F$23,1,N16)/(1+Funding!O12/100*Funding!O8) | P16: =IF(Time!P$4=Inputs!$F$23,1,O16)/(1+Funding!P12/100*Funding!P8) | Q16: =IF(Time!Q$4=Inputs!$F$23,1,P16)/(1+Funding!Q12/100*Funding!Q8) | ... AU16: =IF(Time!AU$4=Inputs!$F$23,1,AT16)/(1+Funding!AU12/100*Funding!AU8)
D17: Opco term loan amount (PV of sculpted debt service) | E17: USD m | F17: =SUMPRODUCT(Funding!$J$15:$AU$15,Funding!$J$16:$AU$16)
D18: PV of contracted debt-service capacity | E18: USD m | F18: =SUMPRODUCT(Operations!$J$777:$AU$777/Inputs!$F$275,Funding!$J$16:$AU$16,--(Funding!$J$8:$AU$8>0))
D19: PV of hedged debt-service capacity | E19: USD m | F19: =SUMPRODUCT(Operations!$J$778:$AU$778/Inputs!$F$276,Funding!$J$16:$AU$16,--(Funding!$J$8:$AU$8>0))
D20: PV of merchant debt-service capacity | E20: USD m | F20: =SUMPRODUCT(Operations!$J$779:$AU$779/Inputs!$F$277,Funding!$J$16:$AU$16,--(Funding!$J$8:$AU$8>0))
D21: Years in which the P99 test binds | E21: years | F21: =SUMPRODUCT(--(Funding!$J$14:$AU$14<Funding!$J$13:$AU$13),--(Funding!$J$8:$AU$8>0))
D22: Sculpted schedule: opening balance | E22: USD m | J22: =IF(Time!J$4=YEAR(Inputs!$F$269),Funding!$F$17,I25) | K22: =IF(Time!K$4=YEAR(Inputs!$F$269),Funding!$F$17,J25) | L22: =IF(Time!L$4=YEAR(Inputs!$F$269),Funding!$F$17,K25) | M22: =IF(Time!M$4=YEAR(Inputs!$F$269),Funding!$F$17,L25) | N22: =IF(Time!N$4=YEAR(Inputs!$F$269),Funding!$F$17,M25) | O22: =IF(Time!O$4=YEAR(Inputs!$F$269),Funding!$F$17,N25) | P22: =IF(Time!P$4=YEAR(Inputs!$F$269),Funding!$F$17,O25) | Q22: =IF(Time!Q$4=YEAR(Inputs!$F$269),Funding!$F$17,P25) | ... AU22: =IF(Time!AU$4=YEAR(Inputs!$F$269),Funding!$F$17,AT25)
D23: Sculpted schedule: interest | E23: USD m | J23: =Funding!J22*Funding!J12/100*Funding!J8 | K23: =Funding!K22*Funding!K12/100*Funding!K8 | L23: =Funding!L22*Funding!L12/100*Funding!L8 | M23: =Funding!M22*Funding!M12/100*Funding!M8 | N23: =Funding!N22*Funding!N12/100*Funding!N8 | O23: =Funding!O22*Funding!O12/100*Funding!O8 | P23: =Funding!P22*Funding!P12/100*Funding!P8 | Q23: =Funding!Q22*Funding!Q12/100*Funding!Q8 | ... AU23: =Funding!AU22*Funding!AU12/100*Funding!AU8
D24: Sculpted schedule: principal | E24: USD m | G24: =SUM(J24:AU24) | J24: =IF(Funding!J8>0,Funding!J15-Funding!J23,0) | K24: =IF(Funding!K8>0,Funding!K15-Funding!K23,0) | L24: =IF(Funding!L8>0,Funding!L15-Funding!L23,0) | M24: =IF(Funding!M8>0,Funding!M15-Funding!M23,0) | N24: =IF(Funding!N8>0,Funding!N15-Funding!N23,0) | O24: =IF(Funding!O8>0,Funding!O15-Funding!O23,0) | P24: =IF(Funding!P8>0,Funding!P15-Funding!P23,0) | Q24: =IF(Funding!Q8>0,Funding!Q15-Funding!Q23,0) | ... AU24: =IF(Funding!AU8>0,Funding!AU15-Funding!AU23,0)
D25: Sculpted schedule: closing balance | E25: USD m | J25: =Funding!J22-Funding!J24 | K25: =Funding!K22-Funding!K24 | L25: =Funding!L22-Funding!L24 | M25: =Funding!M22-Funding!M24 | N25: =Funding!N22-Funding!N24 | O25: =Funding!O22-Funding!O24 | P25: =Funding!P22-Funding!P24 | Q25: =Funding!Q22-Funding!Q24 | ... AU25: =Funding!AU22-Funding!AU24
D26: Base P50 distributions from A1 group (CFADS less sculpted debt service) | E26: USD m | J26: =Operations!J771-Funding!J15 | K26: =Operations!K771-Funding!K15 | L26: =Operations!L771-Funding!L15 | M26: =Operations!M771-Funding!M15 | N26: =Operations!N771-Funding!N15 | O26: =Operations!O771-Funding!O15 | P26: =Operations!P771-Funding!P15 | Q26: =Operations!Q771-Funding!Q15 | ... AU26: =Operations!AU771-Funding!AU15
A28: Holdco term loan B, March 22, 2022
D29: Interest period fraction to maturity | E29: fraction | J29: =MAX(0,MIN(Inputs!$F$283,Time!J$6)-MAX(Inputs!$F$282,Time!J$5))/Time!J$7 | K29: =MAX(0,MIN(Inputs!$F$283,Time!K$6)-MAX(Inputs!$F$282,Time!K$5))/Time!K$7 | L29: =MAX(0,MIN(Inputs!$F$283,Time!L$6)-MAX(Inputs!$F$282,Time!L$5))/Time!L$7 | M29: =MAX(0,MIN(Inputs!$F$283,Time!M$6)-MAX(Inputs!$F$282,Time!M$5))/Time!M$7 | N29: =MAX(0,MIN(Inputs!$F$283,Time!N$6)-MAX(Inputs!$F$282,Time!N$5))/Time!N$7 | O29: =MAX(0,MIN(Inputs!$F$283,Time!O$6)-MAX(Inputs!$F$282,Time!O$5))/Time!O$7 | P29: =MAX(0,MIN(Inputs!$F$283,Time!P$6)-MAX(Inputs!$F$282,Time!P$5))/Time!P$7 | Q29: =MAX(0,MIN(Inputs!$F$283,Time!Q$6)-MAX(Inputs!$F$282,Time!Q$5))/Time!Q$7 | ... AU29: =MAX(0,MIN(Inputs!$F$283,Time!AU$6)-MAX(Inputs!$F$282,Time!AU$5))/Time!AU$7
D30: Rate (SOFR floored + margin) | E30: % | J30: =MAX(Inputs!J80,Inputs!$F$285)+Inputs!$F$284 | K30: =MAX(Inputs!K80,Inputs!$F$285)+Inputs!$F$284 | L30: =MAX(Inputs!L80,Inputs!$F$285)+Inputs!$F$284 | M30: =MAX(Inputs!M80,Inputs!$F$285)+Inputs!$F$284 | N30: =MAX(Inputs!N80,Inputs!$F$285)+Inputs!$F$284 | O30: =MAX(Inputs!O80,Inputs!$F$285)+Inputs!$F$284 | P30: =MAX(Inputs!P80,Inputs!$F$285)+Inputs!$F$284 | Q30: =MAX(Inputs!Q80,Inputs!$F$285)+Inputs!$F$284 | ... AU30: =MAX(Inputs!AU80,Inputs!$F$285)+Inputs!$F$284
D31: Scheduled amortization per unit of face | E31: factor | J31: =Inputs!$F$287/100*Funding!J29 | K31: =Inputs!$F$287/100*Funding!K29 | L31: =Inputs!$F$287/100*Funding!L29 | M31: =Inputs!$F$287/100*Funding!M29 | N31: =Inputs!$F$287/100*Funding!N29 | O31: =Inputs!$F$287/100*Funding!O29 | P31: =Inputs!$F$287/100*Funding!P29 | Q31: =Inputs!$F$287/100*Funding!Q29 | ... AU31: =Inputs!$F$287/100*Funding!AU29
D32: Scheduled balance per unit of face | E32: factor | J32: =IF(Time!J$4=Inputs!$F$23,1,I32-I31) | K32: =IF(Time!K$4=Inputs!$F$23,1,J32-J31) | L32: =IF(Time!L$4=Inputs!$F$23,1,K32-K31) | M32: =IF(Time!M$4=Inputs!$F$23,1,L32-L31) | N32: =IF(Time!N$4=Inputs!$F$23,1,M32-M31) | O32: =IF(Time!O$4=Inputs!$F$23,1,N32-N31) | P32: =IF(Time!P$4=Inputs!$F$23,1,O32-O31) | Q32: =IF(Time!Q$4=Inputs!$F$23,1,P32-P31) | ... AU32: =IF(Time!AU$4=Inputs!$F$23,1,AT32-AT31)
D33: Debt service per unit of face | E33: factor | J33: =Funding!J32*Funding!J30/100*Funding!J29+Funding!J31 | K33: =Funding!K32*Funding!K30/100*Funding!K29+Funding!K31 | L33: =Funding!L32*Funding!L30/100*Funding!L29+Funding!L31 | M33: =Funding!M32*Funding!M30/100*Funding!M29+Funding!M31 | N33: =Funding!N32*Funding!N30/100*Funding!N29+Funding!N31 | O33: =Funding!O32*Funding!O30/100*Funding!O29+Funding!O31 | P33: =Funding!P32*Funding!P30/100*Funding!P29+Funding!P31 | Q33: =Funding!Q32*Funding!Q30/100*Funding!Q29+Funding!Q31 | ... AU33: =Funding!AU32*Funding!AU30/100*Funding!AU29+Funding!AU31
D34: Coverage test year flag | E34: flag | J34: =(Time!J$4>=Inputs!$F$291)*(Time!J$4<=Inputs!$F$292) | K34: =(Time!K$4>=Inputs!$F$291)*(Time!K$4<=Inputs!$F$292) | L34: =(Time!L$4>=Inputs!$F$291)*(Time!L$4<=Inputs!$F$292) | M34: =(Time!M$4>=Inputs!$F$291)*(Time!M$4<=Inputs!$F$292) | N34: =(Time!N$4>=Inputs!$F$291)*(Time!N$4<=Inputs!$F$292) | O34: =(Time!O$4>=Inputs!$F$291)*(Time!O$4<=Inputs!$F$292) | P34: =(Time!P$4>=Inputs!$F$291)*(Time!P$4<=Inputs!$F$292) | Q34: =(Time!Q$4>=Inputs!$F$291)*(Time!Q$4<=Inputs!$F$292) | ... AU34: =(Time!AU$4>=Inputs!$F$291)*(Time!AU$4<=Inputs!$F$292)
D35: Face supported at 1.75x coverage | E35: USD m | J35: =IF(Funding!J34>0,Funding!J26/(Inputs!$F$289*IF(Funding!J33>0,Funding!J33,1)),Inputs!$F$28) | K35: =IF(Funding!K34>0,Funding!K26/(Inputs!$F$289*IF(Funding!K33>0,Funding!K33,1)),Inputs!$F$28) | L35: =IF(Funding!L34>0,Funding!L26/(Inputs!$F$289*IF(Funding!L33>0,Funding!L33,1)),Inputs!$F$28) | M35: =IF(Funding!M34>0,Funding!M26/(Inputs!$F$289*IF(Funding!M33>0,Funding!M33,1)),Inputs!$F$28) | N35: =IF(Funding!N34>0,Funding!N26/(Inputs!$F$289*IF(Funding!N33>0,Funding!N33,1)),Inputs!$F$28) | O35: =IF(Funding!O34>0,Funding!O26/(Inputs!$F$289*IF(Funding!O33>0,Funding!O33,1)),Inputs!$F$28) | P35: =IF(Funding!P34>0,Funding!P26/(Inputs!$F$289*IF(Funding!P33>0,Funding!P33,1)),Inputs!$F$28) | Q35: =IF(Funding!Q34>0,Funding!Q26/(Inputs!$F$289*IF(Funding!Q33>0,Funding!Q33,1)),Inputs!$F$28) | ... AU35: =IF(Funding!AU34>0,Funding!AU26/(Inputs!$F$289*IF(Funding!AU33>0,Funding!AU33,1)),Inputs!$F$28)
D36: Face supported by coverage (minimum over test years) | E36: USD m | F36: =MIN(Funding!$J$35:$AU$35)
D37: Opco equity value at March 22, 2022: years from valuation date | E37: years | J37: =MAX(0,(Time!J$6-Inputs!$F$256)/Inputs!$F$27) | K37: =MAX(0,(Time!K$6-Inputs!$F$256)/Inputs!$F$27) | L37: =MAX(0,(Time!L$6-Inputs!$F$256)/Inputs!$F$27) | M37: =MAX(0,(Time!M$6-Inputs!$F$256)/Inputs!$F$27) | N37: =MAX(0,(Time!N$6-Inputs!$F$256)/Inputs!$F$27) | O37: =MAX(0,(Time!O$6-Inputs!$F$256)/Inputs!$F$27) | P37: =MAX(0,(Time!P$6-Inputs!$F$256)/Inputs!$F$27) | Q37: =MAX(0,(Time!Q$6-Inputs!$F$256)/Inputs!$F$27) | ... AU37: =MAX(0,(Time!AU$6-Inputs!$F$256)/Inputs!$F$27)
D38: Opco equity value at March 22, 2022: levered discount factor weighted by revenue bucket | E38: factor | J38: =(Time!J$6>=Inputs!$F$256)*(Operations!J774*(1+Inputs!$F$336/100)^(-Funding!J37)+Operations!J775*(1+Inputs!$F$337/100)^(-Funding!J37)+Operations!J776*(1+Inputs!$F$338/100)^(-Funding!J37)) | K38: =(Time!K$6>=Inputs!$F$256)*(Operations!K774*(1+Inputs!$F$336/100)^(-Funding!K37)+Operations!K775*(1+Inputs!$F$337/100)^(-Funding!K37)+Operations!K776*(1+Inputs!$F$338/100)^(-Funding!K37)) | L38: =(Time!L$6>=Inputs!$F$256)*(Operations!L774*(1+Inputs!$F$336/100)^(-Funding!L37)+Operations!L775*(1+Inputs!$F$337/100)^(-Funding!L37)+Operations!L776*(1+Inputs!$F$338/100)^(-Funding!L37)) | M38: =(Time!M$6>=Inputs!$F$256)*(Operations!M774*(1+Inputs!$F$336/100)^(-Funding!M37)+Operations!M775*(1+Inputs!$F$337/100)^(-Funding!M37)+Operations!M776*(1+Inputs!$F$338/100)^(-Funding!M37)) | N38: =(Time!N$6>=Inputs!$F$256)*(Operations!N774*(1+Inputs!$F$336/100)^(-Funding!N37)+Operations!N775*(1+Inputs!$F$337/100)^(-Funding!N37)+Operations!N776*(1+Inputs!$F$338/100)^(-Funding!N37)) | O38: =(Time!O$6>=Inputs!$F$256)*(Operations!O774*(1+Inputs!$F$336/100)^(-Funding!O37)+Operations!O775*(1+Inputs!$F$337/100)^(-Funding!O37)+Operations!O776*(1+Inputs!$F$338/100)^(-Funding!O37)) | P38: =(Time!P$6>=Inputs!$F$256)*(Operations!P774*(1+Inputs!$F$336/100)^(-Funding!P37)+Operations!P775*(1+Inputs!$F$337/100)^(-Funding!P37)+Operations!P776*(1+Inputs!$F$338/100)^(-Funding!P37)) | Q38: =(Time!Q$6>=Inputs!$F$256)*(Operations!Q774*(1+Inputs!$F$336/100)^(-Funding!Q37)+Operations!Q775*(1+Inputs!$F$337/100)^(-Funding!Q37)+Operations!Q776*(1+Inputs!$F$338/100)^(-Funding!Q37)) | ... AU38: =(Time!AU$6>=Inputs!$F$256)*(Operations!AU774*(1+Inputs!$F$336/100)^(-Funding!AU37)+Operations!AU775*(1+Inputs!$F$337/100)^(-Funding!AU37)+Operations!AU776*(1+Inputs!$F$338/100)^(-Funding!AU37))
D39: Opco equity value at levered equity rates | E39: USD m | F39: =SUMPRODUCT(Funding!$J$26:$AU$26,Funding!$J$38:$AU$38)
D40: Cap: 45% of opco equity value | E40: USD m | F40: =Inputs!$F$290/100*Funding!$F$39
D41: Holdco TLB face | E41: USD m | F41: =MIN(Funding!$F$36,Funding!$F$40)
A43: Redfern term loan, August 31, 2023 (toll cash flow only)
D44: Interest period fraction | E44: fraction | J44: =MAX(0,MIN(Inputs!$F$294,Time!J$6)-MAX(Inputs!$F$293,Time!J$5))/Time!J$7 | K44: =MAX(0,MIN(Inputs!$F$294,Time!K$6)-MAX(Inputs!$F$293,Time!K$5))/Time!K$7 | L44: =MAX(0,MIN(Inputs!$F$294,Time!L$6)-MAX(Inputs!$F$293,Time!L$5))/Time!L$7 | M44: =MAX(0,MIN(Inputs!$F$294,Time!M$6)-MAX(Inputs!$F$293,Time!M$5))/Time!M$7 | N44: =MAX(0,MIN(Inputs!$F$294,Time!N$6)-MAX(Inputs!$F$293,Time!N$5))/Time!N$7 | O44: =MAX(0,MIN(Inputs!$F$294,Time!O$6)-MAX(Inputs!$F$293,Time!O$5))/Time!O$7 | P44: =MAX(0,MIN(Inputs!$F$294,Time!P$6)-MAX(Inputs!$F$293,Time!P$5))/Time!P$7 | Q44: =MAX(0,MIN(Inputs!$F$294,Time!Q$6)-MAX(Inputs!$F$293,Time!Q$5))/Time!Q$7 | ... AU44: =MAX(0,MIN(Inputs!$F$294,Time!AU$6)-MAX(Inputs!$F$293,Time!AU$5))/Time!AU$7
...

Sheet Debt
A1: Debt: live schedules (sized amounts held fixed)
A2: Case R, Mesa Corta Renewables. USD m nominal unless stated. Illustrative prices: not ERCOT settlement data and not a forecast.
D4: Year | J4: =Time!J$4 | K4: =Time!K$4 | L4: =Time!L$4 | M4: =Time!M$4 | N4: =Time!N$4 | O4: =Time!O$4 | P4: =Time!P$4 | Q4: =Time!Q$4 | ... AU4: =Time!AU$4
D5: Period end | J5: =Time!J$6 | K5: =Time!K$6 | L5: =Time!L$6 | M5: =Time!M$6 | N5: =Time!N$6 | O5: =Time!O$6 | P5: =Time!P$6 | Q5: =Time!Q$6 | ... AU5: =Time!AU$6
A7: Flags
D8: Post-refinancing flag | E8: flag | J8: =(Inputs!$F$10=1)*(Time!J$4>Inputs!$F$307) | K8: =(Inputs!$F$10=1)*(Time!K$4>Inputs!$F$307) | L8: =(Inputs!$F$10=1)*(Time!L$4>Inputs!$F$307) | M8: =(Inputs!$F$10=1)*(Time!M$4>Inputs!$F$307) | N8: =(Inputs!$F$10=1)*(Time!N$4>Inputs!$F$307) | O8: =(Inputs!$F$10=1)*(Time!O$4>Inputs!$F$307) | P8: =(Inputs!$F$10=1)*(Time!P$4>Inputs!$F$307) | Q8: =(Inputs!$F$10=1)*(Time!Q$4>Inputs!$F$307) | ... AU8: =(Inputs!$F$10=1)*(Time!AU$4>Inputs!$F$307)
D9: Refinancing year flag | E9: flag | J9: =(Inputs!$F$10=1)*(Time!J$4=Inputs!$F$307) | K9: =(Inputs!$F$10=1)*(Time!K$4=Inputs!$F$307) | L9: =(Inputs!$F$10=1)*(Time!L$4=Inputs!$F$307) | M9: =(Inputs!$F$10=1)*(Time!M$4=Inputs!$F$307) | N9: =(Inputs!$F$10=1)*(Time!N$4=Inputs!$F$307) | O9: =(Inputs!$F$10=1)*(Time!O$4=Inputs!$F$307) | P9: =(Inputs!$F$10=1)*(Time!P$4=Inputs!$F$307) | Q9: =(Inputs!$F$10=1)*(Time!Q$4=Inputs!$F$307) | ... AU9: =(Inputs!$F$10=1)*(Time!AU$4=Inputs!$F$307)
D10: SOFR including sensitivity | E10: % | J10: =Inputs!J80+Inputs!$F$15 | K10: =Inputs!K80+Inputs!$F$15 | L10: =Inputs!L80+Inputs!$F$15 | M10: =Inputs!M80+Inputs!$F$15 | N10: =Inputs!N80+Inputs!$F$15 | O10: =Inputs!O80+Inputs!$F$15 | P10: =Inputs!P80+Inputs!$F$15 | Q10: =Inputs!Q80+Inputs!$F$15 | ... AU10: =Inputs!AU80+Inputs!$F$15
A12: Opco term loan
D13: All-in rate (unhedged share at live SOFR) | E13: % | J13: =Funding!J11*Inputs!$F$280+(1-Funding!J11)*Debt!J10+Funding!J10 | K13: =Funding!K11*Inputs!$F$280+(1-Funding!K11)*Debt!K10+Funding!K10 | L13: =Funding!L11*Inputs!$F$280+(1-Funding!L11)*Debt!L10+Funding!L10 | M13: =Funding!M11*Inputs!$F$280+(1-Funding!M11)*Debt!M10+Funding!M10 | N13: =Funding!N11*Inputs!$F$280+(1-Funding!N11)*Debt!N10+Funding!N10 | O13: =Funding!O11*Inputs!$F$280+(1-Funding!O11)*Debt!O10+Funding!O10 | P13: =Funding!P11*Inputs!$F$280+(1-Funding!P11)*Debt!P10+Funding!P10 | Q13: =Funding!Q11*Inputs!$F$280+(1-Funding!Q11)*Debt!Q10+Funding!Q10 | ... AU13: =Funding!AU11*Inputs!$F$280+(1-Funding!AU11)*Debt!AU10+Funding!AU10
D14: Opening balance | E14: USD m | J14: =IF(Time!J$4=YEAR(Inputs!$F$269),Funding!$F$17,I19) | K14: =IF(Time!K$4=YEAR(Inputs!$F$269),Funding!$F$17,J19) | L14: =IF(Time!L$4=YEAR(Inputs!$F$269),Funding!$F$17,K19) | M14: =IF(Time!M$4=YEAR(Inputs!$F$269),Funding!$F$17,L19) | N14: =IF(Time!N$4=YEAR(Inputs!$F$269),Funding!$F$17,M19) | O14: =IF(Time!O$4=YEAR(Inputs!$F$269),Funding!$F$17,N19) | P14: =IF(Time!P$4=YEAR(Inputs!$F$269),Funding!$F$17,O19) | Q14: =IF(Time!Q$4=YEAR(Inputs!$F$269),Funding!$F$17,P19) | ... AU14: =IF(Time!AU$4=YEAR(Inputs!$F$269),Funding!$F$17,AT19)
D15: Interest | E15: USD m | G15: =SUM(J15:AU15) | J15: =Debt!J14*Debt!J13/100*Funding!J8 | K15: =Debt!K14*Debt!K13/100*Funding!K8 | L15: =Debt!L14*Debt!L13/100*Funding!L8 | M15: =Debt!M14*Debt!M13/100*Funding!M8 | N15: =Debt!N14*Debt!N13/100*Funding!N8 | O15: =Debt!O14*Debt!O13/100*Funding!O8 | P15: =Debt!P14*Debt!P13/100*Funding!P8 | Q15: =Debt!Q14*Debt!Q13/100*Funding!Q8 | ... AU15: =Debt!AU14*Debt!AU13/100*Funding!AU8
D16: Scheduled principal | E16: USD m | G16: =SUM(J16:AU16) | J16: =MIN(Debt!J14,Funding!J24)*(1-Debt!J8) | K16: =MIN(Debt!K14,Funding!K24)*(1-Debt!K8) | L16: =MIN(Debt!L14,Funding!L24)*(1-Debt!L8) | M16: =MIN(Debt!M14,Funding!M24)*(1-Debt!M8) | N16: =MIN(Debt!N14,Funding!N24)*(1-Debt!N8) | O16: =MIN(Debt!O14,Funding!O24)*(1-Debt!O8) | P16: =MIN(Debt!P14,Funding!P24)*(1-Debt!P8) | Q16: =MIN(Debt!Q14,Funding!Q24)*(1-Debt!Q8) | ... AU16: =MIN(Debt!AU14,Funding!AU24)*(1-Debt!AU8)
D17: Prepayment from refinancing | E17: USD m | G17: =SUM(J17:AU17) | J17: =Debt!J9*(Debt!J14-Debt!J16) | K17: =Debt!K9*(Debt!K14-Debt!K16) | L17: =Debt!L9*(Debt!L14-Debt!L16) | M17: =Debt!M9*(Debt!M14-Debt!M16) | N17: =Debt!N9*(Debt!N14-Debt!N16) | O17: =Debt!O9*(Debt!O14-Debt!O16) | P17: =Debt!P9*(Debt!P14-Debt!P16) | Q17: =Debt!Q9*(Debt!Q14-Debt!Q16) | ... AU17: =Debt!AU9*(Debt!AU14-Debt!AU16)
D18: Debt service (interest and scheduled principal) | E18: USD m | G18: =SUM(J18:AU18) | J18: =Debt!J15+Debt!J16 | K18: =Debt!K15+Debt!K16 | L18: =Debt!L15+Debt!L16 | M18: =Debt!M15+Debt!M16 | N18: =Debt!N15+Debt!N16 | O18: =Debt!O15+Debt!O16 | P18: =Debt!P15+Debt!P16 | Q18: =Debt!Q15+Debt!Q16 | ... AU18: =Debt!AU15+Debt!AU16
D19: Closing balance | E19: USD m | J19: =Debt!J14-Debt!J16-Debt!J17 | K19: =Debt!K14-Debt!K16-Debt!K17 | L19: =Debt!L14-Debt!L16-Debt!L17 | M19: =Debt!M14-Debt!M16-Debt!M17 | N19: =Debt!N14-Debt!N16-Debt!N17 | O19: =Debt!O14-Debt!O16-Debt!O17 | P19: =Debt!P14-Debt!P16-Debt!P17 | Q19: =Debt!Q14-Debt!Q16-Debt!Q17 | ... AU19: =Debt!AU14-Debt!AU16-Debt!AU17
A21: Redfern term loan
D22: All-in rate | E22: % | J22: =Inputs!$F$298/100*Inputs!$F$299+(1-Inputs!$F$298/100)*Debt!J10+Inputs!$F$295 | K22: =Inputs!$F$298/100*Inputs!$F$299+(1-Inputs!$F$298/100)*Debt!K10+Inputs!$F$295 | L22: =Inputs!$F$298/100*Inputs!$F$299+(1-Inputs!$F$298/100)*Debt!L10+Inputs!$F$295 | M22: =Inputs!$F$298/100*Inputs!$F$299+(1-Inputs!$F$298/100)*Debt!M10+Inputs!$F$295 | N22: =Inputs!$F$298/100*Inputs!$F$299+(1-Inputs!$F$298/100)*Debt!N10+Inputs!$F$295 | O22: =Inputs!$F$298/100*Inputs!$F$299+(1-Inputs!$F$298/100)*Debt!O10+Inputs!$F$295 | P22: =Inputs!$F$298/100*Inputs!$F$299+(1-Inputs!$F$298/100)*Debt!P10+Inputs!$F$295 | Q22: =Inputs!$F$298/100*Inputs!$F$299+(1-Inputs!$F$298/100)*Debt!Q10+Inputs!$F$295 | ... AU22: =Inputs!$F$298/100*Inputs!$F$299+(1-Inputs!$F$298/100)*Debt!AU10+Inputs!$F$295
D23: Opening balance | E23: USD m | J23: =IF(Time!J$4=YEAR(Inputs!$F$293),Funding!$F$50,I28) | K23: =IF(Time!K$4=YEAR(Inputs!$F$293),Funding!$F$50,J28) | L23: =IF(Time!L$4=YEAR(Inputs!$F$293),Funding!$F$50,K28) | M23: =IF(Time!M$4=YEAR(Inputs!$F$293),Funding!$F$50,L28) | N23: =IF(Time!N$4=YEAR(Inputs!$F$293),Funding!$F$50,M28) | O23: =IF(Time!O$4=YEAR(Inputs!$F$293),Funding!$F$50,N28) | P23: =IF(Time!P$4=YEAR(Inputs!$F$293),Funding!$F$50,O28) | Q23: =IF(Time!Q$4=YEAR(Inputs!$F$293),Funding!$F$50,P28) | ... AU23: =IF(Time!AU$4=YEAR(Inputs!$F$293),Funding!$F$50,AT28)
D24: Interest | E24: USD m | G24: =SUM(J24:AU24) | J24: =Debt!J23*Debt!J22/100*Funding!J44 | K24: =Debt!K23*Debt!K22/100*Funding!K44 | L24: =Debt!L23*Debt!L22/100*Funding!L44 | M24: =Debt!M23*Debt!M22/100*Funding!M44 | N24: =Debt!N23*Debt!N22/100*Funding!N44 | O24: =Debt!O23*Debt!O22/100*Funding!O44 | P24: =Debt!P23*Debt!P22/100*Funding!P44 | Q24: =Debt!Q23*Debt!Q22/100*Funding!Q44 | ... AU24: =Debt!AU23*Debt!AU22/100*Funding!AU44
D25: Scheduled principal | E25: USD m | G25: =SUM(J25:AU25) | J25: =MIN(Debt!J23,Funding!J52)*(1-Debt!J8) | K25: =MIN(Debt!K23,Funding!K52)*(1-Debt!K8) | L25: =MIN(Debt!L23,Funding!L52)*(1-Debt!L8) | M25: =MIN(Debt!M23,Funding!M52)*(1-Debt!M8) | N25: =MIN(Debt!N23,Funding!N52)*(1-Debt!N8) | O25: =MIN(Debt!O23,Funding!O52)*(1-Debt!O8) | P25: =MIN(Debt!P23,Funding!P52)*(1-Debt!P8) | Q25: =MIN(Debt!Q23,Funding!Q52)*(1-Debt!Q8) | ... AU25: =MIN(Debt!AU23,Funding!AU52)*(1-Debt!AU8)
